2025-06-11 18:43:24,114 - INFO - ✅ BTCUSDT-M5 シグナルランナーが初期化されました。
2025-06-11 18:43:37,160 - INFO - BTCUSDT-M5 シグナル監視ループを開始します。
2025-06-11 18:43:37,160 - INFO - BTCUSDT: MT5クライアントを初期化しています...
2025-06-11 18:43:37,161 - INFO - ✅ BTCUSDT: MT5クライアントの初期化に成功しました。
2025-06-11 18:43:37,161 - INFO - BTCUSDT: 新しい足 (M5) が形成されました。データ取得とシグナル判定を実行します。
2025-06-11 18:43:37,162 - ERROR - BTCUSDT: シグナル監視ループで予期せぬエラーが発生しました: module 'MetaTrader5' has no attribute 'is_connected'
Traceback (most recent call last):
  File "c:\Users\pc\OneDrive\Desktop\phantom_alert_bot\signal_runner_loop.py", line 190, in _run
    df, latest_time_tokyo = self._get_current_ohlc()
                            ~~~~~~~~~~~~~~~~~~~~~~^^
  File "c:\Users\pc\OneDrive\Desktop\phantom_alert_bot\signal_runner_loop.py", line 85, in _get_current_ohlc
    if not self._initialize_mt5():
           ~~~~~~~~~~~~~~~~~~~~^^
  File "c:\Users\pc\OneDrive\Desktop\phantom_alert_bot\signal_runner_loop.py", line 65, in _initialize_mt5
    if not self.mt5_initialized or not mt5.is_connected():
                                       ^^^^^^^^^^^^^^^^
AttributeError: module 'MetaTrader5' has no attribute 'is_connected'
2025-06-11 18:44:37,168 - INFO - BTCUSDT: 新しい足 (M5) が形成されました。データ取得とシグナル判定を実行します。
2025-06-11 18:44:37,169 - ERROR - BTCUSDT: シグナル監視ループで予期せぬエラーが発生しました: module 'MetaTrader5' has no attribute 'is_connected'
Traceback (most recent call last):
  File "c:\Users\pc\OneDrive\Desktop\phantom_alert_bot\signal_runner_loop.py", line 190, in _run
    df, latest_time_tokyo = self._get_current_ohlc()
                            ~~~~~~~~~~~~~~~~~~~~~~^^
  File "c:\Users\pc\OneDrive\Desktop\phantom_alert_bot\signal_runner_loop.py", line 85, in _get_current_ohlc
    if not self._initialize_mt5():
           ~~~~~~~~~~~~~~~~~~~~^^
  File "c:\Users\pc\OneDrive\Desktop\phantom_alert_bot\signal_runner_loop.py", line 65, in _initialize_mt5
    if not self.mt5_initialized or not mt5.is_connected():
                                       ^^^^^^^^^^^^^^^^
AttributeError: module 'MetaTrader5' has no attribute 'is_connected'
2025-06-11 18:45:37,172 - INFO - BTCUSDT: 新しい足 (M5) が形成されました。データ取得とシグナル判定を実行します。
2025-06-11 18:45:37,172 - ERROR - BTCUSDT: シグナル監視ループで予期せぬエラーが発生しました: module 'MetaTrader5' has no attribute 'is_connected'
Traceback (most recent call last):
  File "c:\Users\pc\OneDrive\Desktop\phantom_alert_bot\signal_runner_loop.py", line 190, in _run
    df, latest_time_tokyo = self._get_current_ohlc()
                            ~~~~~~~~~~~~~~~~~~~~~~^^
  File "c:\Users\pc\OneDrive\Desktop\phantom_alert_bot\signal_runner_loop.py", line 85, in _get_current_ohlc
    if not self._initialize_mt5():
           ~~~~~~~~~~~~~~~~~~~~^^
  File "c:\Users\pc\OneDrive\Desktop\phantom_alert_bot\signal_runner_loop.py", line 65, in _initialize_mt5
    if not self.mt5_initialized or not mt5.is_connected():
                                       ^^^^^^^^^^^^^^^^
AttributeError: module 'MetaTrader5' has no attribute 'is_connected'
2025-06-11 18:46:37,174 - INFO - BTCUSDT: 新しい足 (M5) が形成されました。データ取得とシグナル判定を実行します。
2025-06-11 18:46:37,174 - ERROR - BTCUSDT: シグナル監視ループで予期せぬエラーが発生しました: module 'MetaTrader5' has no attribute 'is_connected'
Traceback (most recent call last):
  File "c:\Users\pc\OneDrive\Desktop\phantom_alert_bot\signal_runner_loop.py", line 190, in _run
    df, latest_time_tokyo = self._get_current_ohlc()
                            ~~~~~~~~~~~~~~~~~~~~~~^^
  File "c:\Users\pc\OneDrive\Desktop\phantom_alert_bot\signal_runner_loop.py", line 85, in _get_current_ohlc
    if not self._initialize_mt5():
           ~~~~~~~~~~~~~~~~~~~~^^
  File "c:\Users\pc\OneDrive\Desktop\phantom_alert_bot\signal_runner_loop.py", line 65, in _initialize_mt5
    if not self.mt5_initialized or not mt5.is_connected():
                                       ^^^^^^^^^^^^^^^^
AttributeError: module 'MetaTrader5' has no attribute 'is_connected'
2025-06-11 18:47:37,176 - INFO - BTCUSDT: 新しい足 (M5) が形成されました。データ取得とシグナル判定を実行します。
2025-06-11 18:47:37,177 - ERROR - BTCUSDT: シグナル監視ループで予期せぬエラーが発生しました: module 'MetaTrader5' has no attribute 'is_connected'
Traceback (most recent call last):
  File "c:\Users\pc\OneDrive\Desktop\phantom_alert_bot\signal_runner_loop.py", line 190, in _run
    df, latest_time_tokyo = self._get_current_ohlc()
                            ~~~~~~~~~~~~~~~~~~~~~~^^
  File "c:\Users\pc\OneDrive\Desktop\phantom_alert_bot\signal_runner_loop.py", line 85, in _get_current_ohlc
    if not self._initialize_mt5():
           ~~~~~~~~~~~~~~~~~~~~^^
  File "c:\Users\pc\OneDrive\Desktop\phantom_alert_bot\signal_runner_loop.py", line 65, in _initialize_mt5
    if not self.mt5_initialized or not mt5.is_connected():
                                       ^^^^^^^^^^^^^^^^
AttributeError: module 'MetaTrader5' has no attribute 'is_connected'
2025-06-11 18:48:37,180 - INFO - BTCUSDT: 新しい足 (M5) が形成されました。データ取得とシグナル判定を実行します。
2025-06-11 18:48:37,180 - ERROR - BTCUSDT: シグナル監視ループで予期せぬエラーが発生しました: module 'MetaTrader5' has no attribute 'is_connected'
Traceback (most recent call last):
  File "c:\Users\pc\OneDrive\Desktop\phantom_alert_bot\signal_runner_loop.py", line 190, in _run
    df, latest_time_tokyo = self._get_current_ohlc()
                            ~~~~~~~~~~~~~~~~~~~~~~^^
  File "c:\Users\pc\OneDrive\Desktop\phantom_alert_bot\signal_runner_loop.py", line 85, in _get_current_ohlc
    if not self._initialize_mt5():
           ~~~~~~~~~~~~~~~~~~~~^^
  File "c:\Users\pc\OneDrive\Desktop\phantom_alert_bot\signal_runner_loop.py", line 65, in _initialize_mt5
    if not self.mt5_initialized or not mt5.is_connected():
                                       ^^^^^^^^^^^^^^^^
AttributeError: module 'MetaTrader5' has no attribute 'is_connected'
2025-06-11 18:49:37,182 - INFO - BTCUSDT: 新しい足 (M5) が形成されました。データ取得とシグナル判定を実行します。
2025-06-11 18:49:37,183 - ERROR - BTCUSDT: シグナル監視ループで予期せぬエラーが発生しました: module 'MetaTrader5' has no attribute 'is_connected'
Traceback (most recent call last):
  File "c:\Users\pc\OneDrive\Desktop\phantom_alert_bot\signal_runner_loop.py", line 190, in _run
    df, latest_time_tokyo = self._get_current_ohlc()
                            ~~~~~~~~~~~~~~~~~~~~~~^^
  File "c:\Users\pc\OneDrive\Desktop\phantom_alert_bot\signal_runner_loop.py", line 85, in _get_current_ohlc
    if not self._initialize_mt5():
           ~~~~~~~~~~~~~~~~~~~~^^
  File "c:\Users\pc\OneDrive\Desktop\phantom_alert_bot\signal_runner_loop.py", line 65, in _initialize_mt5
    if not self.mt5_initialized or not mt5.is_connected():
                                       ^^^^^^^^^^^^^^^^
AttributeError: module 'MetaTrader5' has no attribute 'is_connected'
2025-06-11 18:54:29,464 - INFO - ✅ BTCUSDT-M5 シグナルランナーが初期化されました。
2025-06-11 18:54:42,513 - INFO - BTCUSDT-M5 シグナル監視ループを開始します。
2025-06-11 18:54:42,515 - INFO - BTCUSDT: MT5クライアントを初期化しています...
2025-06-11 18:54:42,517 - INFO - ✅ BTCUSDT: MT5クライアントの初期化に成功しました。
2025-06-11 18:54:42,519 - INFO - BTCUSDT: 新しい足 (M5) が形成されました。データ取得とシグナル判定を実行します。
2025-06-11 18:54:42,563 - ERROR - BTCUSDT: シグナル監視ループで予期せぬエラーが発生しました: generate_signal() got an unexpected keyword argument 'logic'
Traceback (most recent call last):
  File "c:\Users\pc\OneDrive\Desktop\phantom_alert_bot\signal_runner_loop.py", line 177, in _run
    signal_info = generate_signal(df, mode="realtime", logic=DEFAULT_LOGIC) # modeとlogicを渡す
TypeError: generate_signal() got an unexpected keyword argument 'logic'
2025-06-11 18:55:42,565 - INFO - BTCUSDT: 新しい足 (M5) が形成されました。データ取得とシグナル判定を実行します。
2025-06-11 18:55:42,567 - ERROR - BTCUSDT: シグナル監視ループで予期せぬエラーが発生しました: generate_signal() got an unexpected keyword argument 'logic'
Traceback (most recent call last):
  File "c:\Users\pc\OneDrive\Desktop\phantom_alert_bot\signal_runner_loop.py", line 177, in _run
    signal_info = generate_signal(df, mode="realtime", logic=DEFAULT_LOGIC) # modeとlogicを渡す
TypeError: generate_signal() got an unexpected keyword argument 'logic'
2025-06-11 18:56:42,568 - INFO - BTCUSDT: 新しい足 (M5) が形成されました。データ取得とシグナル判定を実行します。
2025-06-11 18:56:42,575 - ERROR - BTCUSDT: シグナル監視ループで予期せぬエラーが発生しました: generate_signal() got an unexpected keyword argument 'logic'
Traceback (most recent call last):
  File "c:\Users\pc\OneDrive\Desktop\phantom_alert_bot\signal_runner_loop.py", line 177, in _run
    signal_info = generate_signal(df, mode="realtime", logic=DEFAULT_LOGIC) # modeとlogicを渡す
TypeError: generate_signal() got an unexpected keyword argument 'logic'
2025-06-11 18:57:42,579 - INFO - BTCUSDT: 新しい足 (M5) が形成されました。データ取得とシグナル判定を実行します。
2025-06-11 18:57:42,586 - ERROR - BTCUSDT: シグナル監視ループで予期せぬエラーが発生しました: generate_signal() got an unexpected keyword argument 'logic'
Traceback (most recent call last):
  File "c:\Users\pc\OneDrive\Desktop\phantom_alert_bot\signal_runner_loop.py", line 177, in _run
    signal_info = generate_signal(df, mode="realtime", logic=DEFAULT_LOGIC) # modeとlogicを渡す
TypeError: generate_signal() got an unexpected keyword argument 'logic'
2025-06-11 18:58:42,589 - INFO - BTCUSDT: 新しい足 (M5) が形成されました。データ取得とシグナル判定を実行します。
2025-06-11 18:58:42,593 - ERROR - BTCUSDT: シグナル監視ループで予期せぬエラーが発生しました: generate_signal() got an unexpected keyword argument 'logic'
Traceback (most recent call last):
  File "c:\Users\pc\OneDrive\Desktop\phantom_alert_bot\signal_runner_loop.py", line 177, in _run
    signal_info = generate_signal(df, mode="realtime", logic=DEFAULT_LOGIC) # modeとlogicを渡す
TypeError: generate_signal() got an unexpected keyword argument 'logic'
2025-06-11 18:59:42,595 - INFO - BTCUSDT: 新しい足 (M5) が形成されました。データ取得とシグナル判定を実行します。
2025-06-11 18:59:42,599 - ERROR - BTCUSDT: シグナル監視ループで予期せぬエラーが発生しました: generate_signal() got an unexpected keyword argument 'logic'
Traceback (most recent call last):
  File "c:\Users\pc\OneDrive\Desktop\phantom_alert_bot\signal_runner_loop.py", line 177, in _run
    signal_info = generate_signal(df, mode="realtime", logic=DEFAULT_LOGIC) # modeとlogicを渡す
TypeError: generate_signal() got an unexpected keyword argument 'logic'
2025-06-12 00:09:30,906 - INFO - ✅ BTCUSDT-M5 シグナルランナーが初期化されました。
2025-06-12 00:09:43,997 - INFO - BTCUSDT-M5 シグナル監視ループを開始します。
2025-06-12 00:09:43,998 - INFO - BTCUSDT: MT5クライアントを初期化しています...
2025-06-12 00:09:44,001 - INFO - ✅ BTCUSDT: MT5クライアントの初期化に成功しました。
2025-06-12 00:09:44,003 - INFO - BTCUSDT: 新しい足 (M5) が形成されました。データ取得とシグナル判定を実行します。
2025-06-12 00:09:44,046 - INFO - BTCUSDT-M5 シグナル判定結果: Balanced Sell Signal (Confluence: MACD Dead Cross, Stochastic Dead Cross)
2025-06-12 00:09:44,047 - ERROR - BTCUSDT: シグナル監視ループで予期せぬエラーが発生しました: 'SignalRunner' object has no attribute '_generate_chart_and_upload'
Traceback (most recent call last):
  File "c:\Users\pc\OneDrive\Desktop\phantom_alert_bot\signal_runner_loop.py", line 199, in _run
    uploaded_image_url = self._generate_chart_and_upload(df, signal_info, image_filename)
                         ^^^^^^^^^^^^^^^^^^^^^^^^^^^^^^^
AttributeError: 'SignalRunner' object has no attribute '_generate_chart_and_upload'
2025-06-12 00:10:15,489 - INFO - ✅ BTCUSDT-M5 シグナルランナーが初期化されました。
2025-06-12 00:10:28,528 - INFO - BTCUSDT-M5 シグナル監視ループを開始します。
2025-06-12 00:10:28,529 - INFO - BTCUSDT: MT5クライアントを初期化しています...
2025-06-12 00:10:28,530 - INFO - ✅ BTCUSDT: MT5クライアントの初期化に成功しました。
2025-06-12 00:10:28,530 - INFO - BTCUSDT: 新しい足 (M5) が形成されました。データ取得とシグナル判定を実行します。
2025-06-12 00:10:28,566 - INFO - BTCUSDT-M5 シグナル判定結果: Balanced Sell Signal (Confluence: MACD Dead Cross, Stochastic Dead Cross)
2025-06-12 00:10:28,567 - ERROR - BTCUSDT: シグナル監視ループで予期せぬエラーが発生しました: 'SignalRunner' object has no attribute '_generate_chart_and_upload'
Traceback (most recent call last):
  File "C:\Users\pc\OneDrive\Desktop\phantom_alert_bot\signal_runner_loop.py", line 199, in _run
    uploaded_image_url = self._generate_chart_and_upload(df, signal_info, image_filename)
                         ^^^^^^^^^^^^^^^^^^^^^^^^^^^^^^^
AttributeError: 'SignalRunner' object has no attribute '_generate_chart_and_upload'
2025-06-12 00:10:44,048 - INFO - BTCUSDT: 新しい足 (M5) が形成されました。データ取得とシグナル判定を実行します。
2025-06-12 00:10:44,095 - INFO - BTCUSDT-M5 シグナル判定結果: Balanced Sell Signal (Confluence: MACD Dead Cross, Stochastic Dead Cross)
2025-06-12 00:10:44,096 - ERROR - BTCUSDT: シグナル監視ループで予期せぬエラーが発生しました: 'SignalRunner' object has no attribute '_generate_chart_and_upload'
Traceback (most recent call last):
  File "c:\Users\pc\OneDrive\Desktop\phantom_alert_bot\signal_runner_loop.py", line 199, in _run
    uploaded_image_url = self._generate_chart_and_upload(df, signal_info, image_filename)
                         ^^^^^^^^^^^^^^^^^^^^^^^^^^^^^^^
AttributeError: 'SignalRunner' object has no attribute '_generate_chart_and_upload'
2025-06-12 00:11:00,899 - INFO - ✅ BTCUSDT-M5 シグナルランナーが初期化されました。
2025-06-12 00:11:02,794 - INFO - ✅ BTCUSDT-M5 シグナルランナーが初期化されました。
2025-06-12 00:11:13,928 - INFO - BTCUSDT-M5 シグナル監視ループを開始します。
2025-06-12 00:11:13,929 - INFO - BTCUSDT: MT5クライアントを初期化しています...
2025-06-12 00:11:13,929 - INFO - ✅ BTCUSDT: MT5クライアントの初期化に成功しました。
2025-06-12 00:11:13,930 - INFO - BTCUSDT: 新しい足 (M5) が形成されました。データ取得とシグナル判定を実行します。
2025-06-12 00:11:13,956 - INFO - BTCUSDT-M5 シグナル判定結果: Balanced Sell Signal (Confluence: MACD Dead Cross, Stochastic Dead Cross)
2025-06-12 00:11:13,956 - ERROR - BTCUSDT: シグナル監視ループで予期せぬエラーが発生しました: 'SignalRunner' object has no attribute '_generate_chart_and_upload'
Traceback (most recent call last):
  File "C:\Users\pc\OneDrive\Desktop\phantom_alert_bot\signal_runner_loop.py", line 199, in _run
    uploaded_image_url = self._generate_chart_and_upload(df, signal_info, image_filename)
                         ^^^^^^^^^^^^^^^^^^^^^^^^^^^^^^^
AttributeError: 'SignalRunner' object has no attribute '_generate_chart_and_upload'
2025-06-12 00:11:15,833 - INFO - BTCUSDT-M5 シグナル監視ループを開始します。
2025-06-12 00:11:15,833 - INFO - BTCUSDT: MT5クライアントを初期化しています...
2025-06-12 00:11:15,833 - INFO - ✅ BTCUSDT: MT5クライアントの初期化に成功しました。
2025-06-12 00:11:15,835 - INFO - BTCUSDT: 新しい足 (M5) が形成されました。データ取得とシグナル判定を実行します。
2025-06-12 00:11:15,856 - INFO - BTCUSDT-M5 シグナル判定結果: Balanced Sell Signal (Confluence: MACD Dead Cross, Stochastic Dead Cross)
2025-06-12 00:11:15,856 - ERROR - BTCUSDT: シグナル監視ループで予期せぬエラーが発生しました: 'SignalRunner' object has no attribute '_generate_chart_and_upload'
Traceback (most recent call last):
  File "C:\Users\pc\OneDrive\Desktop\phantom_alert_bot\signal_runner_loop.py", line 199, in _run
    uploaded_image_url = self._generate_chart_and_upload(df, signal_info, image_filename)
                         ^^^^^^^^^^^^^^^^^^^^^^^^^^^^^^^
AttributeError: 'SignalRunner' object has no attribute '_generate_chart_and_upload'
2025-06-12 00:11:28,569 - INFO - BTCUSDT: 新しい足 (M5) が形成されました。データ取得とシグナル判定を実行します。
2025-06-12 00:11:28,614 - INFO - BTCUSDT-M5 シグナル判定結果: Balanced Sell Signal (Confluence: MACD Dead Cross, Stochastic Dead Cross)
2025-06-12 00:11:28,615 - ERROR - BTCUSDT: シグナル監視ループで予期せぬエラーが発生しました: 'SignalRunner' object has no attribute '_generate_chart_and_upload'
Traceback (most recent call last):
  File "C:\Users\pc\OneDrive\Desktop\phantom_alert_bot\signal_runner_loop.py", line 199, in _run
    uploaded_image_url = self._generate_chart_and_upload(df, signal_info, image_filename)
                         ^^^^^^^^^^^^^^^^^^^^^^^^^^^^^^^
AttributeError: 'SignalRunner' object has no attribute '_generate_chart_and_upload'
2025-06-12 00:11:44,099 - INFO - BTCUSDT: 新しい足 (M5) が形成されました。データ取得とシグナル判定を実行します。
2025-06-12 00:11:44,130 - INFO - BTCUSDT-M5 シグナル判定結果: Balanced Sell Signal (Confluence: MACD Dead Cross, Stochastic Dead Cross)
2025-06-12 00:11:44,144 - ERROR - BTCUSDT: シグナル監視ループで予期せぬエラーが発生しました: 'SignalRunner' object has no attribute '_generate_chart_and_upload'
Traceback (most recent call last):
  File "c:\Users\pc\OneDrive\Desktop\phantom_alert_bot\signal_runner_loop.py", line 199, in _run
    uploaded_image_url = self._generate_chart_and_upload(df, signal_info, image_filename)
                         ^^^^^^^^^^^^^^^^^^^^^^^^^^^^^^^
AttributeError: 'SignalRunner' object has no attribute '_generate_chart_and_upload'
2025-06-12 00:12:13,958 - INFO - BTCUSDT: 新しい足 (M5) が形成されました。データ取得とシグナル判定を実行します。
2025-06-12 00:12:14,009 - INFO - BTCUSDT-M5 シグナル判定結果: Balanced Sell Signal (Confluence: MACD Dead Cross, Stochastic Dead Cross)
2025-06-12 00:12:14,010 - ERROR - BTCUSDT: シグナル監視ループで予期せぬエラーが発生しました: 'SignalRunner' object has no attribute '_generate_chart_and_upload'
Traceback (most recent call last):
  File "C:\Users\pc\OneDrive\Desktop\phantom_alert_bot\signal_runner_loop.py", line 199, in _run
    uploaded_image_url = self._generate_chart_and_upload(df, signal_info, image_filename)
                         ^^^^^^^^^^^^^^^^^^^^^^^^^^^^^^^
AttributeError: 'SignalRunner' object has no attribute '_generate_chart_and_upload'
2025-06-12 00:12:15,857 - INFO - BTCUSDT: 新しい足 (M5) が形成されました。データ取得とシグナル判定を実行します。
2025-06-12 00:12:15,912 - INFO - BTCUSDT-M5 シグナル判定結果: Balanced Sell Signal (Confluence: MACD Dead Cross, Stochastic Dead Cross)
2025-06-12 00:12:15,912 - ERROR - BTCUSDT: シグナル監視ループで予期せぬエラーが発生しました: 'SignalRunner' object has no attribute '_generate_chart_and_upload'
Traceback (most recent call last):
  File "C:\Users\pc\OneDrive\Desktop\phantom_alert_bot\signal_runner_loop.py", line 199, in _run
    uploaded_image_url = self._generate_chart_and_upload(df, signal_info, image_filename)
                         ^^^^^^^^^^^^^^^^^^^^^^^^^^^^^^^
AttributeError: 'SignalRunner' object has no attribute '_generate_chart_and_upload'
2025-06-12 00:12:28,616 - INFO - BTCUSDT: 新しい足 (M5) が形成されました。データ取得とシグナル判定を実行します。
2025-06-12 00:12:28,658 - INFO - BTCUSDT-M5 シグナル判定結果: Balanced Sell Signal (Confluence: MACD Dead Cross, Stochastic Dead Cross)
2025-06-12 00:12:28,659 - ERROR - BTCUSDT: シグナル監視ループで予期せぬエラーが発生しました: 'SignalRunner' object has no attribute '_generate_chart_and_upload'
Traceback (most recent call last):
  File "C:\Users\pc\OneDrive\Desktop\phantom_alert_bot\signal_runner_loop.py", line 199, in _run
    uploaded_image_url = self._generate_chart_and_upload(df, signal_info, image_filename)
                         ^^^^^^^^^^^^^^^^^^^^^^^^^^^^^^^
AttributeError: 'SignalRunner' object has no attribute '_generate_chart_and_upload'
2025-06-12 00:12:44,147 - INFO - BTCUSDT: 新しい足 (M5) が形成されました。データ取得とシグナル判定を実行します。
2025-06-12 00:12:44,168 - INFO - BTCUSDT-M5 シグナル判定結果: Balanced Sell Signal (Confluence: MACD Dead Cross, Stochastic Dead Cross)
2025-06-12 00:12:44,168 - ERROR - BTCUSDT: シグナル監視ループで予期せぬエラーが発生しました: 'SignalRunner' object has no attribute '_generate_chart_and_upload'
Traceback (most recent call last):
  File "c:\Users\pc\OneDrive\Desktop\phantom_alert_bot\signal_runner_loop.py", line 199, in _run
    uploaded_image_url = self._generate_chart_and_upload(df, signal_info, image_filename)
                         ^^^^^^^^^^^^^^^^^^^^^^^^^^^^^^^
AttributeError: 'SignalRunner' object has no attribute '_generate_chart_and_upload'
2025-06-12 00:13:14,011 - INFO - BTCUSDT: 新しい足 (M5) が形成されました。データ取得とシグナル判定を実行します。
2025-06-12 00:13:14,038 - INFO - BTCUSDT-M5 シグナル判定結果: Balanced Sell Signal (Confluence: MACD Dead Cross, Stochastic Dead Cross)
2025-06-12 00:13:14,038 - ERROR - BTCUSDT: シグナル監視ループで予期せぬエラーが発生しました: 'SignalRunner' object has no attribute '_generate_chart_and_upload'
Traceback (most recent call last):
  File "C:\Users\pc\OneDrive\Desktop\phantom_alert_bot\signal_runner_loop.py", line 199, in _run
    uploaded_image_url = self._generate_chart_and_upload(df, signal_info, image_filename)
                         ^^^^^^^^^^^^^^^^^^^^^^^^^^^^^^^
AttributeError: 'SignalRunner' object has no attribute '_generate_chart_and_upload'
2025-06-12 00:13:15,914 - INFO - BTCUSDT: 新しい足 (M5) が形成されました。データ取得とシグナル判定を実行します。
2025-06-12 00:13:15,951 - INFO - BTCUSDT-M5 シグナル判定結果: Balanced Sell Signal (Confluence: MACD Dead Cross, Stochastic Dead Cross)
2025-06-12 00:13:15,952 - ERROR - BTCUSDT: シグナル監視ループで予期せぬエラーが発生しました: 'SignalRunner' object has no attribute '_generate_chart_and_upload'
Traceback (most recent call last):
  File "C:\Users\pc\OneDrive\Desktop\phantom_alert_bot\signal_runner_loop.py", line 199, in _run
    uploaded_image_url = self._generate_chart_and_upload(df, signal_info, image_filename)
                         ^^^^^^^^^^^^^^^^^^^^^^^^^^^^^^^
AttributeError: 'SignalRunner' object has no attribute '_generate_chart_and_upload'
2025-06-12 00:13:28,660 - INFO - BTCUSDT: 新しい足 (M5) が形成されました。データ取得とシグナル判定を実行します。
2025-06-12 00:13:28,697 - INFO - BTCUSDT-M5 シグナル判定結果: Balanced Sell Signal (Confluence: MACD Dead Cross, Stochastic Dead Cross)
2025-06-12 00:13:28,698 - ERROR - BTCUSDT: シグナル監視ループで予期せぬエラーが発生しました: 'SignalRunner' object has no attribute '_generate_chart_and_upload'
Traceback (most recent call last):
  File "C:\Users\pc\OneDrive\Desktop\phantom_alert_bot\signal_runner_loop.py", line 199, in _run
    uploaded_image_url = self._generate_chart_and_upload(df, signal_info, image_filename)
                         ^^^^^^^^^^^^^^^^^^^^^^^^^^^^^^^
AttributeError: 'SignalRunner' object has no attribute '_generate_chart_and_upload'
2025-06-12 00:13:44,169 - INFO - BTCUSDT: 新しい足 (M5) が形成されました。データ取得とシグナル判定を実行します。
2025-06-12 00:13:44,192 - INFO - BTCUSDT-M5 シグナル判定結果: Balanced Sell Signal (Confluence: MACD Dead Cross, Stochastic Dead Cross)
2025-06-12 00:13:44,193 - ERROR - BTCUSDT: シグナル監視ループで予期せぬエラーが発生しました: 'SignalRunner' object has no attribute '_generate_chart_and_upload'
Traceback (most recent call last):
  File "c:\Users\pc\OneDrive\Desktop\phantom_alert_bot\signal_runner_loop.py", line 199, in _run
    uploaded_image_url = self._generate_chart_and_upload(df, signal_info, image_filename)
                         ^^^^^^^^^^^^^^^^^^^^^^^^^^^^^^^
AttributeError: 'SignalRunner' object has no attribute '_generate_chart_and_upload'
2025-06-12 00:14:14,040 - INFO - BTCUSDT: 新しい足 (M5) が形成されました。データ取得とシグナル判定を実行します。
2025-06-12 00:14:14,068 - INFO - BTCUSDT-M5 シグナル判定結果: Balanced Sell Signal (Confluence: MACD Dead Cross, Stochastic Dead Cross)
2025-06-12 00:14:14,069 - ERROR - BTCUSDT: シグナル監視ループで予期せぬエラーが発生しました: 'SignalRunner' object has no attribute '_generate_chart_and_upload'
Traceback (most recent call last):
  File "C:\Users\pc\OneDrive\Desktop\phantom_alert_bot\signal_runner_loop.py", line 199, in _run
    uploaded_image_url = self._generate_chart_and_upload(df, signal_info, image_filename)
                         ^^^^^^^^^^^^^^^^^^^^^^^^^^^^^^^
AttributeError: 'SignalRunner' object has no attribute '_generate_chart_and_upload'
2025-06-12 00:14:15,954 - INFO - BTCUSDT: 新しい足 (M5) が形成されました。データ取得とシグナル判定を実行します。
2025-06-12 00:14:16,063 - INFO - BTCUSDT-M5 シグナル判定結果: Balanced Sell Signal (Confluence: MACD Dead Cross, Stochastic Dead Cross)
2025-06-12 00:14:16,063 - ERROR - BTCUSDT: シグナル監視ループで予期せぬエラーが発生しました: 'SignalRunner' object has no attribute '_generate_chart_and_upload'
Traceback (most recent call last):
  File "C:\Users\pc\OneDrive\Desktop\phantom_alert_bot\signal_runner_loop.py", line 199, in _run
    uploaded_image_url = self._generate_chart_and_upload(df, signal_info, image_filename)
                         ^^^^^^^^^^^^^^^^^^^^^^^^^^^^^^^
AttributeError: 'SignalRunner' object has no attribute '_generate_chart_and_upload'
2025-06-12 00:14:28,707 - INFO - BTCUSDT: 新しい足 (M5) が形成されました。データ取得とシグナル判定を実行します。
2025-06-12 00:14:28,752 - INFO - BTCUSDT-M5 シグナル判定結果: Balanced Sell Signal (Confluence: MACD Dead Cross, Stochastic Dead Cross)
2025-06-12 00:14:28,752 - ERROR - BTCUSDT: シグナル監視ループで予期せぬエラーが発生しました: 'SignalRunner' object has no attribute '_generate_chart_and_upload'
Traceback (most recent call last):
  File "C:\Users\pc\OneDrive\Desktop\phantom_alert_bot\signal_runner_loop.py", line 199, in _run
    uploaded_image_url = self._generate_chart_and_upload(df, signal_info, image_filename)
                         ^^^^^^^^^^^^^^^^^^^^^^^^^^^^^^^
AttributeError: 'SignalRunner' object has no attribute '_generate_chart_and_upload'
2025-06-12 00:14:44,195 - INFO - BTCUSDT: 新しい足 (M5) が形成されました。データ取得とシグナル判定を実行します。
2025-06-12 00:14:44,240 - INFO - BTCUSDT-M5 シグナル判定結果: Balanced Sell Signal (Confluence: MACD Dead Cross, Stochastic Dead Cross)
2025-06-12 00:14:44,241 - ERROR - BTCUSDT: シグナル監視ループで予期せぬエラーが発生しました: 'SignalRunner' object has no attribute '_generate_chart_and_upload'
Traceback (most recent call last):
  File "c:\Users\pc\OneDrive\Desktop\phantom_alert_bot\signal_runner_loop.py", line 199, in _run
    uploaded_image_url = self._generate_chart_and_upload(df, signal_info, image_filename)
                         ^^^^^^^^^^^^^^^^^^^^^^^^^^^^^^^
AttributeError: 'SignalRunner' object has no attribute '_generate_chart_and_upload'
2025-06-12 00:15:14,071 - INFO - BTCUSDT: 新しい足 (M5) が形成されました。データ取得とシグナル判定を実行します。
2025-06-12 00:15:14,105 - INFO - BTCUSDT-M5 シグナル判定結果: No signal
2025-06-12 00:15:14,106 - INFO - BTCUSDT-M5: シグナルなし。
2025-06-12 00:15:14,106 - ERROR - BTCUSDT: シグナル監視ループで予期せぬエラーが発生しました: cannot access local variable 'uploaded_image_url' where it is not associated with a value
Traceback (most recent call last):
  File "C:\Users\pc\OneDrive\Desktop\phantom_alert_bot\signal_runner_loop.py", line 230, in _run
UnboundLocalError: cannot access local variable 'uploaded_image_url' where it is not associated with a value
2025-06-12 00:15:16,065 - INFO - BTCUSDT: 新しい足 (M5) が形成されました。データ取得とシグナル判定を実行します。
2025-06-12 00:15:16,096 - INFO - BTCUSDT-M5 シグナル判定結果: No signal
2025-06-12 00:15:16,096 - INFO - BTCUSDT-M5: シグナルなし。
2025-06-12 00:15:16,096 - ERROR - BTCUSDT: シグナル監視ループで予期せぬエラーが発生しました: cannot access local variable 'uploaded_image_url' where it is not associated with a value
Traceback (most recent call last):
  File "C:\Users\pc\OneDrive\Desktop\phantom_alert_bot\signal_runner_loop.py", line 230, in _run
UnboundLocalError: cannot access local variable 'uploaded_image_url' where it is not associated with a value
2025-06-12 00:15:28,755 - INFO - BTCUSDT: 新しい足 (M5) が形成されました。データ取得とシグナル判定を実行します。
2025-06-12 00:15:28,791 - INFO - BTCUSDT-M5 シグナル判定結果: No signal
2025-06-12 00:15:28,792 - INFO - BTCUSDT-M5: シグナルなし。
2025-06-12 00:15:28,792 - ERROR - BTCUSDT: シグナル監視ループで予期せぬエラーが発生しました: cannot access local variable 'uploaded_image_url' where it is not associated with a value
Traceback (most recent call last):
  File "C:\Users\pc\OneDrive\Desktop\phantom_alert_bot\signal_runner_loop.py", line 230, in _run
UnboundLocalError: cannot access local variable 'uploaded_image_url' where it is not associated with a value
2025-06-12 00:15:44,242 - INFO - BTCUSDT: 新しい足 (M5) が形成されました。データ取得とシグナル判定を実行します。
2025-06-12 00:15:44,276 - INFO - BTCUSDT-M5 シグナル判定結果: No signal
2025-06-12 00:15:44,277 - INFO - BTCUSDT-M5: シグナルなし。
2025-06-12 00:15:44,277 - ERROR - BTCUSDT: シグナル監視ループで予期せぬエラーが発生しました: cannot access local variable 'uploaded_image_url' where it is not associated with a value
Traceback (most recent call last):
  File "c:\Users\pc\OneDrive\Desktop\phantom_alert_bot\signal_runner_loop.py", line 230, in _run
UnboundLocalError: cannot access local variable 'uploaded_image_url' where it is not associated with a value
2025-06-12 00:16:14,108 - INFO - BTCUSDT: 新しい足 (M5) が形成されました。データ取得とシグナル判定を実行します。
2025-06-12 00:16:14,158 - INFO - BTCUSDT-M5 シグナル判定結果: No signal
2025-06-12 00:16:14,158 - INFO - BTCUSDT-M5: シグナルなし。
2025-06-12 00:16:14,159 - ERROR - BTCUSDT: シグナル監視ループで予期せぬエラーが発生しました: cannot access local variable 'uploaded_image_url' where it is not associated with a value
Traceback (most recent call last):
  File "C:\Users\pc\OneDrive\Desktop\phantom_alert_bot\signal_runner_loop.py", line 230, in _run
UnboundLocalError: cannot access local variable 'uploaded_image_url' where it is not associated with a value
2025-06-12 00:16:16,098 - INFO - BTCUSDT: 新しい足 (M5) が形成されました。データ取得とシグナル判定を実行します。
2025-06-12 00:16:16,118 - INFO - BTCUSDT-M5 シグナル判定結果: No signal
2025-06-12 00:16:16,118 - INFO - BTCUSDT-M5: シグナルなし。
2025-06-12 00:16:16,119 - ERROR - BTCUSDT: シグナル監視ループで予期せぬエラーが発生しました: cannot access local variable 'uploaded_image_url' where it is not associated with a value
Traceback (most recent call last):
  File "C:\Users\pc\OneDrive\Desktop\phantom_alert_bot\signal_runner_loop.py", line 230, in _run
UnboundLocalError: cannot access local variable 'uploaded_image_url' where it is not associated with a value
2025-06-12 00:16:28,794 - INFO - BTCUSDT: 新しい足 (M5) が形成されました。データ取得とシグナル判定を実行します。
2025-06-12 00:16:28,817 - INFO - BTCUSDT-M5 シグナル判定結果: No signal
2025-06-12 00:16:28,818 - INFO - BTCUSDT-M5: シグナルなし。
2025-06-12 00:16:28,818 - ERROR - BTCUSDT: シグナル監視ループで予期せぬエラーが発生しました: cannot access local variable 'uploaded_image_url' where it is not associated with a value
Traceback (most recent call last):
  File "C:\Users\pc\OneDrive\Desktop\phantom_alert_bot\signal_runner_loop.py", line 230, in _run
UnboundLocalError: cannot access local variable 'uploaded_image_url' where it is not associated with a value
2025-06-12 00:16:44,279 - INFO - BTCUSDT: 新しい足 (M5) が形成されました。データ取得とシグナル判定を実行します。
2025-06-12 00:16:44,313 - INFO - BTCUSDT-M5 シグナル判定結果: No signal
2025-06-12 00:16:44,325 - INFO - BTCUSDT-M5: シグナルなし。
2025-06-12 00:16:44,339 - ERROR - BTCUSDT: シグナル監視ループで予期せぬエラーが発生しました: cannot access local variable 'uploaded_image_url' where it is not associated with a value
Traceback (most recent call last):
  File "c:\Users\pc\OneDrive\Desktop\phantom_alert_bot\signal_runner_loop.py", line 230, in _run
UnboundLocalError: cannot access local variable 'uploaded_image_url' where it is not associated with a value
2025-06-12 00:17:14,160 - INFO - BTCUSDT: 新しい足 (M5) が形成されました。データ取得とシグナル判定を実行します。
2025-06-12 00:17:14,205 - INFO - BTCUSDT-M5 シグナル判定結果: No signal
2025-06-12 00:17:14,205 - INFO - BTCUSDT-M5: シグナルなし。
2025-06-12 00:17:14,205 - ERROR - BTCUSDT: シグナル監視ループで予期せぬエラーが発生しました: cannot access local variable 'uploaded_image_url' where it is not associated with a value
Traceback (most recent call last):
  File "C:\Users\pc\OneDrive\Desktop\phantom_alert_bot\signal_runner_loop.py", line 230, in _run
UnboundLocalError: cannot access local variable 'uploaded_image_url' where it is not associated with a value
2025-06-12 00:17:16,121 - INFO - BTCUSDT: 新しい足 (M5) が形成されました。データ取得とシグナル判定を実行します。
2025-06-12 00:17:16,161 - INFO - BTCUSDT-M5 シグナル判定結果: No signal
2025-06-12 00:17:16,161 - INFO - BTCUSDT-M5: シグナルなし。
2025-06-12 00:17:16,161 - ERROR - BTCUSDT: シグナル監視ループで予期せぬエラーが発生しました: cannot access local variable 'uploaded_image_url' where it is not associated with a value
Traceback (most recent call last):
  File "C:\Users\pc\OneDrive\Desktop\phantom_alert_bot\signal_runner_loop.py", line 230, in _run
UnboundLocalError: cannot access local variable 'uploaded_image_url' where it is not associated with a value
2025-06-12 00:17:28,820 - INFO - BTCUSDT: 新しい足 (M5) が形成されました。データ取得とシグナル判定を実行します。
2025-06-12 00:17:28,871 - INFO - BTCUSDT-M5 シグナル判定結果: No signal
2025-06-12 00:17:28,871 - INFO - BTCUSDT-M5: シグナルなし。
2025-06-12 00:17:28,872 - ERROR - BTCUSDT: シグナル監視ループで予期せぬエラーが発生しました: cannot access local variable 'uploaded_image_url' where it is not associated with a value
Traceback (most recent call last):
  File "C:\Users\pc\OneDrive\Desktop\phantom_alert_bot\signal_runner_loop.py", line 230, in _run
UnboundLocalError: cannot access local variable 'uploaded_image_url' where it is not associated with a value
2025-06-12 00:17:44,344 - INFO - BTCUSDT: 新しい足 (M5) が形成されました。データ取得とシグナル判定を実行します。
2025-06-12 00:17:44,381 - INFO - BTCUSDT-M5 シグナル判定結果: No signal
2025-06-12 00:17:44,381 - INFO - BTCUSDT-M5: シグナルなし。
2025-06-12 00:17:44,381 - ERROR - BTCUSDT: シグナル監視ループで予期せぬエラーが発生しました: cannot access local variable 'uploaded_image_url' where it is not associated with a value
Traceback (most recent call last):
  File "c:\Users\pc\OneDrive\Desktop\phantom_alert_bot\signal_runner_loop.py", line 230, in _run
UnboundLocalError: cannot access local variable 'uploaded_image_url' where it is not associated with a value
2025-06-12 00:18:14,207 - INFO - BTCUSDT: 新しい足 (M5) が形成されました。データ取得とシグナル判定を実行します。
2025-06-12 00:18:14,264 - INFO - BTCUSDT-M5 シグナル判定結果: No signal
2025-06-12 00:18:14,265 - INFO - BTCUSDT-M5: シグナルなし。
2025-06-12 00:18:14,265 - ERROR - BTCUSDT: シグナル監視ループで予期せぬエラーが発生しました: cannot access local variable 'uploaded_image_url' where it is not associated with a value
Traceback (most recent call last):
  File "C:\Users\pc\OneDrive\Desktop\phantom_alert_bot\signal_runner_loop.py", line 230, in _run
UnboundLocalError: cannot access local variable 'uploaded_image_url' where it is not associated with a value
2025-06-12 00:18:16,163 - INFO - BTCUSDT: 新しい足 (M5) が形成されました。データ取得とシグナル判定を実行します。
2025-06-12 00:18:16,207 - INFO - BTCUSDT-M5 シグナル判定結果: No signal
2025-06-12 00:18:16,207 - INFO - BTCUSDT-M5: シグナルなし。
2025-06-12 00:18:16,209 - ERROR - BTCUSDT: シグナル監視ループで予期せぬエラーが発生しました: cannot access local variable 'uploaded_image_url' where it is not associated with a value
Traceback (most recent call last):
  File "C:\Users\pc\OneDrive\Desktop\phantom_alert_bot\signal_runner_loop.py", line 230, in _run
UnboundLocalError: cannot access local variable 'uploaded_image_url' where it is not associated with a value
2025-06-12 00:18:28,873 - INFO - BTCUSDT: 新しい足 (M5) が形成されました。データ取得とシグナル判定を実行します。
2025-06-12 00:18:28,940 - INFO - BTCUSDT-M5 シグナル判定結果: No signal
2025-06-12 00:18:28,941 - INFO - BTCUSDT-M5: シグナルなし。
2025-06-12 00:18:28,941 - ERROR - BTCUSDT: シグナル監視ループで予期せぬエラーが発生しました: cannot access local variable 'uploaded_image_url' where it is not associated with a value
Traceback (most recent call last):
  File "C:\Users\pc\OneDrive\Desktop\phantom_alert_bot\signal_runner_loop.py", line 230, in _run
UnboundLocalError: cannot access local variable 'uploaded_image_url' where it is not associated with a value
2025-06-12 00:18:44,383 - INFO - BTCUSDT: 新しい足 (M5) が形成されました。データ取得とシグナル判定を実行します。
2025-06-12 00:18:44,415 - INFO - BTCUSDT-M5 シグナル判定結果: No signal
2025-06-12 00:18:44,416 - INFO - BTCUSDT-M5: シグナルなし。
2025-06-12 00:18:44,416 - ERROR - BTCUSDT: シグナル監視ループで予期せぬエラーが発生しました: cannot access local variable 'uploaded_image_url' where it is not associated with a value
Traceback (most recent call last):
  File "c:\Users\pc\OneDrive\Desktop\phantom_alert_bot\signal_runner_loop.py", line 230, in _run
UnboundLocalError: cannot access local variable 'uploaded_image_url' where it is not associated with a value
2025-06-12 00:19:14,267 - INFO - BTCUSDT: 新しい足 (M5) が形成されました。データ取得とシグナル判定を実行します。
2025-06-12 00:19:14,286 - INFO - BTCUSDT-M5 シグナル判定結果: No signal
2025-06-12 00:19:14,287 - INFO - BTCUSDT-M5: シグナルなし。
2025-06-12 00:19:14,287 - ERROR - BTCUSDT: シグナル監視ループで予期せぬエラーが発生しました: cannot access local variable 'uploaded_image_url' where it is not associated with a value
Traceback (most recent call last):
  File "C:\Users\pc\OneDrive\Desktop\phantom_alert_bot\signal_runner_loop.py", line 230, in _run
UnboundLocalError: cannot access local variable 'uploaded_image_url' where it is not associated with a value
2025-06-12 00:19:16,210 - INFO - BTCUSDT: 新しい足 (M5) が形成されました。データ取得とシグナル判定を実行します。
2025-06-12 00:19:16,263 - INFO - BTCUSDT-M5 シグナル判定結果: No signal
2025-06-12 00:19:16,264 - INFO - BTCUSDT-M5: シグナルなし。
2025-06-12 00:19:16,265 - ERROR - BTCUSDT: シグナル監視ループで予期せぬエラーが発生しました: cannot access local variable 'uploaded_image_url' where it is not associated with a value
Traceback (most recent call last):
  File "C:\Users\pc\OneDrive\Desktop\phantom_alert_bot\signal_runner_loop.py", line 230, in _run
UnboundLocalError: cannot access local variable 'uploaded_image_url' where it is not associated with a value
2025-06-12 00:19:44,419 - INFO - BTCUSDT: 新しい足 (M5) が形成されました。データ取得とシグナル判定を実行します。
2025-06-12 00:19:44,441 - INFO - BTCUSDT-M5 シグナル判定結果: No signal
2025-06-12 00:19:44,442 - INFO - BTCUSDT-M5: シグナルなし。
2025-06-12 00:19:44,442 - ERROR - BTCUSDT: シグナル監視ループで予期せぬエラーが発生しました: cannot access local variable 'uploaded_image_url' where it is not associated with a value
Traceback (most recent call last):
  File "c:\Users\pc\OneDrive\Desktop\phantom_alert_bot\signal_runner_loop.py", line 230, in _run
UnboundLocalError: cannot access local variable 'uploaded_image_url' where it is not associated with a value
2025-06-12 00:20:14,294 - INFO - BTCUSDT: 新しい足 (M5) が形成されました。データ取得とシグナル判定を実行します。
2025-06-12 00:20:14,356 - INFO - BTCUSDT-M5 シグナル判定結果: No signal
2025-06-12 00:20:14,357 - INFO - BTCUSDT-M5: シグナルなし。
2025-06-12 00:20:14,357 - ERROR - BTCUSDT: シグナル監視ループで予期せぬエラーが発生しました: cannot access local variable 'uploaded_image_url' where it is not associated with a value
Traceback (most recent call last):
  File "C:\Users\pc\OneDrive\Desktop\phantom_alert_bot\signal_runner_loop.py", line 230, in _run
UnboundLocalError: cannot access local variable 'uploaded_image_url' where it is not associated with a value
2025-06-12 00:20:16,267 - INFO - BTCUSDT: 新しい足 (M5) が形成されました。データ取得とシグナル判定を実行します。
2025-06-12 00:20:16,293 - INFO - BTCUSDT-M5 シグナル判定結果: No signal
2025-06-12 00:20:16,293 - INFO - BTCUSDT-M5: シグナルなし。
2025-06-12 00:20:16,294 - ERROR - BTCUSDT: シグナル監視ループで予期せぬエラーが発生しました: cannot access local variable 'uploaded_image_url' where it is not associated with a value
Traceback (most recent call last):
  File "C:\Users\pc\OneDrive\Desktop\phantom_alert_bot\signal_runner_loop.py", line 230, in _run
UnboundLocalError: cannot access local variable 'uploaded_image_url' where it is not associated with a value
2025-06-12 00:20:44,444 - INFO - BTCUSDT: 新しい足 (M5) が形成されました。データ取得とシグナル判定を実行します。
2025-06-12 00:20:44,496 - INFO - BTCUSDT-M5 シグナル判定結果: No signal
2025-06-12 00:20:44,497 - INFO - BTCUSDT-M5: シグナルなし。
2025-06-12 00:20:44,498 - ERROR - BTCUSDT: シグナル監視ループで予期せぬエラーが発生しました: cannot access local variable 'uploaded_image_url' where it is not associated with a value
Traceback (most recent call last):
  File "c:\Users\pc\OneDrive\Desktop\phantom_alert_bot\signal_runner_loop.py", line 230, in _run
UnboundLocalError: cannot access local variable 'uploaded_image_url' where it is not associated with a value
2025-06-12 00:21:14,370 - INFO - BTCUSDT: 新しい足 (M5) が形成されました。データ取得とシグナル判定を実行します。
2025-06-12 00:21:14,393 - INFO - BTCUSDT-M5 シグナル判定結果: No signal
2025-06-12 00:21:14,394 - INFO - BTCUSDT-M5: シグナルなし。
2025-06-12 00:21:14,395 - ERROR - BTCUSDT: シグナル監視ループで予期せぬエラーが発生しました: cannot access local variable 'uploaded_image_url' where it is not associated with a value
Traceback (most recent call last):
  File "C:\Users\pc\OneDrive\Desktop\phantom_alert_bot\signal_runner_loop.py", line 230, in _run
UnboundLocalError: cannot access local variable 'uploaded_image_url' where it is not associated with a value
2025-06-12 00:21:16,295 - INFO - BTCUSDT: 新しい足 (M5) が形成されました。データ取得とシグナル判定を実行します。
2025-06-12 00:21:16,320 - INFO - BTCUSDT-M5 シグナル判定結果: No signal
2025-06-12 00:21:16,321 - INFO - BTCUSDT-M5: シグナルなし。
2025-06-12 00:21:16,321 - ERROR - BTCUSDT: シグナル監視ループで予期せぬエラーが発生しました: cannot access local variable 'uploaded_image_url' where it is not associated with a value
Traceback (most recent call last):
  File "C:\Users\pc\OneDrive\Desktop\phantom_alert_bot\signal_runner_loop.py", line 230, in _run
UnboundLocalError: cannot access local variable 'uploaded_image_url' where it is not associated with a value
2025-06-12 00:21:44,501 - INFO - BTCUSDT: 新しい足 (M5) が形成されました。データ取得とシグナル判定を実行します。
2025-06-12 00:21:44,549 - INFO - BTCUSDT-M5 シグナル判定結果: No signal
2025-06-12 00:21:44,551 - INFO - BTCUSDT-M5: シグナルなし。
2025-06-12 00:21:44,551 - ERROR - BTCUSDT: シグナル監視ループで予期せぬエラーが発生しました: cannot access local variable 'uploaded_image_url' where it is not associated with a value
Traceback (most recent call last):
  File "c:\Users\pc\OneDrive\Desktop\phantom_alert_bot\signal_runner_loop.py", line 230, in _run
UnboundLocalError: cannot access local variable 'uploaded_image_url' where it is not associated with a value
2025-06-12 00:22:14,397 - INFO - BTCUSDT: 新しい足 (M5) が形成されました。データ取得とシグナル判定を実行します。
2025-06-12 00:22:14,432 - INFO - BTCUSDT-M5 シグナル判定結果: No signal
2025-06-12 00:22:14,433 - INFO - BTCUSDT-M5: シグナルなし。
2025-06-12 00:22:14,433 - ERROR - BTCUSDT: シグナル監視ループで予期せぬエラーが発生しました: cannot access local variable 'uploaded_image_url' where it is not associated with a value
Traceback (most recent call last):
  File "C:\Users\pc\OneDrive\Desktop\phantom_alert_bot\signal_runner_loop.py", line 230, in _run
UnboundLocalError: cannot access local variable 'uploaded_image_url' where it is not associated with a value
2025-06-12 00:22:16,323 - INFO - BTCUSDT: 新しい足 (M5) が形成されました。データ取得とシグナル判定を実行します。
2025-06-12 00:22:16,348 - INFO - BTCUSDT-M5 シグナル判定結果: No signal
2025-06-12 00:22:16,349 - INFO - BTCUSDT-M5: シグナルなし。
2025-06-12 00:22:16,349 - ERROR - BTCUSDT: シグナル監視ループで予期せぬエラーが発生しました: cannot access local variable 'uploaded_image_url' where it is not associated with a value
Traceback (most recent call last):
  File "C:\Users\pc\OneDrive\Desktop\phantom_alert_bot\signal_runner_loop.py", line 230, in _run
UnboundLocalError: cannot access local variable 'uploaded_image_url' where it is not associated with a value
2025-06-12 00:22:44,552 - INFO - BTCUSDT: 新しい足 (M5) が形成されました。データ取得とシグナル判定を実行します。
2025-06-12 00:22:44,593 - INFO - BTCUSDT-M5 シグナル判定結果: No signal
2025-06-12 00:22:44,593 - INFO - BTCUSDT-M5: シグナルなし。
2025-06-12 00:22:44,594 - ERROR - BTCUSDT: シグナル監視ループで予期せぬエラーが発生しました: cannot access local variable 'uploaded_image_url' where it is not associated with a value
Traceback (most recent call last):
  File "c:\Users\pc\OneDrive\Desktop\phantom_alert_bot\signal_runner_loop.py", line 230, in _run
UnboundLocalError: cannot access local variable 'uploaded_image_url' where it is not associated with a value
2025-06-12 00:23:14,435 - INFO - BTCUSDT: 新しい足 (M5) が形成されました。データ取得とシグナル判定を実行します。
2025-06-12 00:23:14,475 - INFO - BTCUSDT-M5 シグナル判定結果: No signal
2025-06-12 00:23:14,476 - INFO - BTCUSDT-M5: シグナルなし。
2025-06-12 00:23:14,477 - ERROR - BTCUSDT: シグナル監視ループで予期せぬエラーが発生しました: cannot access local variable 'uploaded_image_url' where it is not associated with a value
Traceback (most recent call last):
  File "C:\Users\pc\OneDrive\Desktop\phantom_alert_bot\signal_runner_loop.py", line 230, in _run
UnboundLocalError: cannot access local variable 'uploaded_image_url' where it is not associated with a value
2025-06-12 00:23:16,350 - INFO - BTCUSDT: 新しい足 (M5) が形成されました。データ取得とシグナル判定を実行します。
2025-06-12 00:23:16,403 - INFO - BTCUSDT-M5 シグナル判定結果: No signal
2025-06-12 00:23:16,404 - INFO - BTCUSDT-M5: シグナルなし。
2025-06-12 00:23:16,404 - ERROR - BTCUSDT: シグナル監視ループで予期せぬエラーが発生しました: cannot access local variable 'uploaded_image_url' where it is not associated with a value
Traceback (most recent call last):
  File "C:\Users\pc\OneDrive\Desktop\phantom_alert_bot\signal_runner_loop.py", line 230, in _run
UnboundLocalError: cannot access local variable 'uploaded_image_url' where it is not associated with a value
2025-06-12 00:23:44,596 - INFO - BTCUSDT: 新しい足 (M5) が形成されました。データ取得とシグナル判定を実行します。
2025-06-12 00:23:44,653 - INFO - BTCUSDT-M5 シグナル判定結果: No signal
2025-06-12 00:23:44,654 - INFO - BTCUSDT-M5: シグナルなし。
2025-06-12 00:23:44,655 - ERROR - BTCUSDT: シグナル監視ループで予期せぬエラーが発生しました: cannot access local variable 'uploaded_image_url' where it is not associated with a value
Traceback (most recent call last):
  File "c:\Users\pc\OneDrive\Desktop\phantom_alert_bot\signal_runner_loop.py", line 230, in _run
UnboundLocalError: cannot access local variable 'uploaded_image_url' where it is not associated with a value
2025-06-12 00:24:14,479 - INFO - BTCUSDT: 新しい足 (M5) が形成されました。データ取得とシグナル判定を実行します。
2025-06-12 00:24:14,499 - INFO - BTCUSDT-M5 シグナル判定結果: No signal
2025-06-12 00:24:14,499 - INFO - BTCUSDT-M5: シグナルなし。
2025-06-12 00:24:14,500 - ERROR - BTCUSDT: シグナル監視ループで予期せぬエラーが発生しました: cannot access local variable 'uploaded_image_url' where it is not associated with a value
Traceback (most recent call last):
  File "C:\Users\pc\OneDrive\Desktop\phantom_alert_bot\signal_runner_loop.py", line 230, in _run
UnboundLocalError: cannot access local variable 'uploaded_image_url' where it is not associated with a value
2025-06-12 00:24:16,406 - INFO - BTCUSDT: 新しい足 (M5) が形成されました。データ取得とシグナル判定を実行します。
2025-06-12 00:24:16,427 - INFO - BTCUSDT-M5 シグナル判定結果: No signal
2025-06-12 00:24:16,428 - INFO - BTCUSDT-M5: シグナルなし。
2025-06-12 00:24:16,428 - ERROR - BTCUSDT: シグナル監視ループで予期せぬエラーが発生しました: cannot access local variable 'uploaded_image_url' where it is not associated with a value
Traceback (most recent call last):
  File "C:\Users\pc\OneDrive\Desktop\phantom_alert_bot\signal_runner_loop.py", line 230, in _run
UnboundLocalError: cannot access local variable 'uploaded_image_url' where it is not associated with a value
2025-06-12 00:24:44,658 - INFO - BTCUSDT: 新しい足 (M5) が形成されました。データ取得とシグナル判定を実行します。
2025-06-12 00:24:44,706 - INFO - BTCUSDT-M5 シグナル判定結果: No signal
2025-06-12 00:24:44,706 - INFO - BTCUSDT-M5: シグナルなし。
2025-06-12 00:24:44,707 - ERROR - BTCUSDT: シグナル監視ループで予期せぬエラーが発生しました: cannot access local variable 'uploaded_image_url' where it is not associated with a value
Traceback (most recent call last):
  File "c:\Users\pc\OneDrive\Desktop\phantom_alert_bot\signal_runner_loop.py", line 230, in _run
UnboundLocalError: cannot access local variable 'uploaded_image_url' where it is not associated with a value
2025-06-12 00:25:14,501 - INFO - BTCUSDT: 新しい足 (M5) が形成されました。データ取得とシグナル判定を実行します。
2025-06-12 00:25:14,527 - INFO - BTCUSDT-M5 シグナル判定結果: No signal
2025-06-12 00:25:14,527 - INFO - BTCUSDT-M5: シグナルなし。
2025-06-12 00:25:14,527 - ERROR - BTCUSDT: シグナル監視ループで予期せぬエラーが発生しました: cannot access local variable 'uploaded_image_url' where it is not associated with a value
Traceback (most recent call last):
  File "C:\Users\pc\OneDrive\Desktop\phantom_alert_bot\signal_runner_loop.py", line 230, in _run
UnboundLocalError: cannot access local variable 'uploaded_image_url' where it is not associated with a value
2025-06-12 00:25:16,429 - INFO - BTCUSDT: 新しい足 (M5) が形成されました。データ取得とシグナル判定を実行します。
2025-06-12 00:25:16,468 - INFO - BTCUSDT-M5 シグナル判定結果: No signal
2025-06-12 00:25:16,469 - INFO - BTCUSDT-M5: シグナルなし。
2025-06-12 00:25:16,469 - ERROR - BTCUSDT: シグナル監視ループで予期せぬエラーが発生しました: cannot access local variable 'uploaded_image_url' where it is not associated with a value
Traceback (most recent call last):
  File "C:\Users\pc\OneDrive\Desktop\phantom_alert_bot\signal_runner_loop.py", line 230, in _run
UnboundLocalError: cannot access local variable 'uploaded_image_url' where it is not associated with a value
2025-06-12 00:25:44,708 - INFO - BTCUSDT: 新しい足 (M5) が形成されました。データ取得とシグナル判定を実行します。
2025-06-12 00:25:44,765 - INFO - BTCUSDT-M5 シグナル判定結果: No signal
2025-06-12 00:25:44,766 - INFO - BTCUSDT-M5: シグナルなし。
2025-06-12 00:25:44,767 - ERROR - BTCUSDT: シグナル監視ループで予期せぬエラーが発生しました: cannot access local variable 'uploaded_image_url' where it is not associated with a value
Traceback (most recent call last):
  File "c:\Users\pc\OneDrive\Desktop\phantom_alert_bot\signal_runner_loop.py", line 230, in _run
UnboundLocalError: cannot access local variable 'uploaded_image_url' where it is not associated with a value
2025-06-12 00:26:14,528 - INFO - BTCUSDT: 新しい足 (M5) が形成されました。データ取得とシグナル判定を実行します。
2025-06-12 00:26:14,555 - INFO - BTCUSDT-M5 シグナル判定結果: No signal
2025-06-12 00:26:14,555 - INFO - BTCUSDT-M5: シグナルなし。
2025-06-12 00:26:14,556 - ERROR - BTCUSDT: シグナル監視ループで予期せぬエラーが発生しました: cannot access local variable 'uploaded_image_url' where it is not associated with a value
Traceback (most recent call last):
  File "C:\Users\pc\OneDrive\Desktop\phantom_alert_bot\signal_runner_loop.py", line 230, in _run
UnboundLocalError: cannot access local variable 'uploaded_image_url' where it is not associated with a value
2025-06-12 00:26:16,470 - INFO - BTCUSDT: 新しい足 (M5) が形成されました。データ取得とシグナル判定を実行します。
2025-06-12 00:26:16,514 - INFO - BTCUSDT-M5 シグナル判定結果: No signal
2025-06-12 00:26:16,515 - INFO - BTCUSDT-M5: シグナルなし。
2025-06-12 00:26:16,515 - ERROR - BTCUSDT: シグナル監視ループで予期せぬエラーが発生しました: cannot access local variable 'uploaded_image_url' where it is not associated with a value
Traceback (most recent call last):
  File "C:\Users\pc\OneDrive\Desktop\phantom_alert_bot\signal_runner_loop.py", line 230, in _run
UnboundLocalError: cannot access local variable 'uploaded_image_url' where it is not associated with a value
2025-06-12 00:26:44,769 - INFO - BTCUSDT: 新しい足 (M5) が形成されました。データ取得とシグナル判定を実行します。
2025-06-12 00:26:44,789 - INFO - BTCUSDT-M5 シグナル判定結果: No signal
2025-06-12 00:26:44,789 - INFO - BTCUSDT-M5: シグナルなし。
2025-06-12 00:26:44,790 - ERROR - BTCUSDT: シグナル監視ループで予期せぬエラーが発生しました: cannot access local variable 'uploaded_image_url' where it is not associated with a value
Traceback (most recent call last):
  File "c:\Users\pc\OneDrive\Desktop\phantom_alert_bot\signal_runner_loop.py", line 230, in _run
UnboundLocalError: cannot access local variable 'uploaded_image_url' where it is not associated with a value
2025-06-12 00:27:14,557 - INFO - BTCUSDT: 新しい足 (M5) が形成されました。データ取得とシグナル判定を実行します。
2025-06-12 00:27:14,604 - INFO - BTCUSDT-M5 シグナル判定結果: No signal
2025-06-12 00:27:14,605 - INFO - BTCUSDT-M5: シグナルなし。
2025-06-12 00:27:14,606 - ERROR - BTCUSDT: シグナル監視ループで予期せぬエラーが発生しました: cannot access local variable 'uploaded_image_url' where it is not associated with a value
Traceback (most recent call last):
  File "C:\Users\pc\OneDrive\Desktop\phantom_alert_bot\signal_runner_loop.py", line 230, in _run
UnboundLocalError: cannot access local variable 'uploaded_image_url' where it is not associated with a value
2025-06-12 00:27:16,517 - INFO - BTCUSDT: 新しい足 (M5) が形成されました。データ取得とシグナル判定を実行します。
2025-06-12 00:27:16,536 - INFO - BTCUSDT-M5 シグナル判定結果: No signal
2025-06-12 00:27:16,536 - INFO - BTCUSDT-M5: シグナルなし。
2025-06-12 00:27:16,536 - ERROR - BTCUSDT: シグナル監視ループで予期せぬエラーが発生しました: cannot access local variable 'uploaded_image_url' where it is not associated with a value
Traceback (most recent call last):
  File "C:\Users\pc\OneDrive\Desktop\phantom_alert_bot\signal_runner_loop.py", line 230, in _run
UnboundLocalError: cannot access local variable 'uploaded_image_url' where it is not associated with a value
2025-06-12 00:27:44,791 - INFO - BTCUSDT: 新しい足 (M5) が形成されました。データ取得とシグナル判定を実行します。
2025-06-12 00:27:44,832 - INFO - BTCUSDT-M5 シグナル判定結果: No signal
2025-06-12 00:27:44,833 - INFO - BTCUSDT-M5: シグナルなし。
2025-06-12 00:27:44,833 - ERROR - BTCUSDT: シグナル監視ループで予期せぬエラーが発生しました: cannot access local variable 'uploaded_image_url' where it is not associated with a value
Traceback (most recent call last):
  File "c:\Users\pc\OneDrive\Desktop\phantom_alert_bot\signal_runner_loop.py", line 230, in _run
UnboundLocalError: cannot access local variable 'uploaded_image_url' where it is not associated with a value
2025-06-12 00:28:14,608 - INFO - BTCUSDT: 新しい足 (M5) が形成されました。データ取得とシグナル判定を実行します。
2025-06-12 00:28:14,659 - INFO - BTCUSDT-M5 シグナル判定結果: No signal
2025-06-12 00:28:14,660 - INFO - BTCUSDT-M5: シグナルなし。
2025-06-12 00:28:14,661 - ERROR - BTCUSDT: シグナル監視ループで予期せぬエラーが発生しました: cannot access local variable 'uploaded_image_url' where it is not associated with a value
Traceback (most recent call last):
  File "C:\Users\pc\OneDrive\Desktop\phantom_alert_bot\signal_runner_loop.py", line 230, in _run
UnboundLocalError: cannot access local variable 'uploaded_image_url' where it is not associated with a value
2025-06-12 00:28:16,540 - INFO - BTCUSDT: 新しい足 (M5) が形成されました。データ取得とシグナル判定を実行します。
2025-06-12 00:28:16,611 - INFO - BTCUSDT-M5 シグナル判定結果: No signal
2025-06-12 00:28:16,612 - INFO - BTCUSDT-M5: シグナルなし。
2025-06-12 00:28:16,612 - ERROR - BTCUSDT: シグナル監視ループで予期せぬエラーが発生しました: cannot access local variable 'uploaded_image_url' where it is not associated with a value
Traceback (most recent call last):
  File "C:\Users\pc\OneDrive\Desktop\phantom_alert_bot\signal_runner_loop.py", line 230, in _run
UnboundLocalError: cannot access local variable 'uploaded_image_url' where it is not associated with a value
2025-06-12 00:28:44,835 - INFO - BTCUSDT: 新しい足 (M5) が形成されました。データ取得とシグナル判定を実行します。
2025-06-12 00:28:44,860 - INFO - BTCUSDT-M5 シグナル判定結果: No signal
2025-06-12 00:28:44,861 - INFO - BTCUSDT-M5: シグナルなし。
2025-06-12 00:28:44,862 - ERROR - BTCUSDT: シグナル監視ループで予期せぬエラーが発生しました: cannot access local variable 'uploaded_image_url' where it is not associated with a value
Traceback (most recent call last):
  File "c:\Users\pc\OneDrive\Desktop\phantom_alert_bot\signal_runner_loop.py", line 230, in _run
UnboundLocalError: cannot access local variable 'uploaded_image_url' where it is not associated with a value
2025-06-12 00:29:14,664 - INFO - BTCUSDT: 新しい足 (M5) が形成されました。データ取得とシグナル判定を実行します。
2025-06-12 00:29:14,723 - INFO - BTCUSDT-M5 シグナル判定結果: No signal
2025-06-12 00:29:14,724 - INFO - BTCUSDT-M5: シグナルなし。
2025-06-12 00:29:14,724 - ERROR - BTCUSDT: シグナル監視ループで予期せぬエラーが発生しました: cannot access local variable 'uploaded_image_url' where it is not associated with a value
Traceback (most recent call last):
  File "C:\Users\pc\OneDrive\Desktop\phantom_alert_bot\signal_runner_loop.py", line 230, in _run
UnboundLocalError: cannot access local variable 'uploaded_image_url' where it is not associated with a value
2025-06-12 00:29:16,615 - INFO - BTCUSDT: 新しい足 (M5) が形成されました。データ取得とシグナル判定を実行します。
2025-06-12 00:29:16,681 - INFO - BTCUSDT-M5 シグナル判定結果: No signal
2025-06-12 00:29:16,681 - INFO - BTCUSDT-M5: シグナルなし。
2025-06-12 00:29:16,684 - ERROR - BTCUSDT: シグナル監視ループで予期せぬエラーが発生しました: cannot access local variable 'uploaded_image_url' where it is not associated with a value
Traceback (most recent call last):
  File "C:\Users\pc\OneDrive\Desktop\phantom_alert_bot\signal_runner_loop.py", line 230, in _run
UnboundLocalError: cannot access local variable 'uploaded_image_url' where it is not associated with a value
2025-06-12 00:29:44,863 - INFO - BTCUSDT: 新しい足 (M5) が形成されました。データ取得とシグナル判定を実行します。
2025-06-12 00:29:44,894 - INFO - BTCUSDT-M5 シグナル判定結果: No signal
2025-06-12 00:29:44,895 - INFO - BTCUSDT-M5: シグナルなし。
2025-06-12 00:29:44,895 - ERROR - BTCUSDT: シグナル監視ループで予期せぬエラーが発生しました: cannot access local variable 'uploaded_image_url' where it is not associated with a value
Traceback (most recent call last):
  File "c:\Users\pc\OneDrive\Desktop\phantom_alert_bot\signal_runner_loop.py", line 230, in _run
UnboundLocalError: cannot access local variable 'uploaded_image_url' where it is not associated with a value
2025-06-12 00:30:14,726 - INFO - BTCUSDT: 新しい足 (M5) が形成されました。データ取得とシグナル判定を実行します。
2025-06-12 00:30:14,750 - INFO - BTCUSDT-M5 シグナル判定結果: No signal
2025-06-12 00:30:14,751 - INFO - BTCUSDT-M5: シグナルなし。
2025-06-12 00:30:14,751 - ERROR - BTCUSDT: シグナル監視ループで予期せぬエラーが発生しました: cannot access local variable 'uploaded_image_url' where it is not associated with a value
Traceback (most recent call last):
  File "C:\Users\pc\OneDrive\Desktop\phantom_alert_bot\signal_runner_loop.py", line 230, in _run
UnboundLocalError: cannot access local variable 'uploaded_image_url' where it is not associated with a value
2025-06-12 00:30:16,686 - INFO - BTCUSDT: 新しい足 (M5) が形成されました。データ取得とシグナル判定を実行します。
2025-06-12 00:30:16,709 - INFO - BTCUSDT-M5 シグナル判定結果: No signal
2025-06-12 00:30:16,710 - INFO - BTCUSDT-M5: シグナルなし。
2025-06-12 00:30:16,710 - ERROR - BTCUSDT: シグナル監視ループで予期せぬエラーが発生しました: cannot access local variable 'uploaded_image_url' where it is not associated with a value
Traceback (most recent call last):
  File "C:\Users\pc\OneDrive\Desktop\phantom_alert_bot\signal_runner_loop.py", line 230, in _run
UnboundLocalError: cannot access local variable 'uploaded_image_url' where it is not associated with a value
2025-06-12 00:30:44,897 - INFO - BTCUSDT: 新しい足 (M5) が形成されました。データ取得とシグナル判定を実行します。
2025-06-12 00:30:44,925 - INFO - BTCUSDT-M5 シグナル判定結果: No signal
2025-06-12 00:30:44,926 - INFO - BTCUSDT-M5: シグナルなし。
2025-06-12 00:30:44,927 - ERROR - BTCUSDT: シグナル監視ループで予期せぬエラーが発生しました: cannot access local variable 'uploaded_image_url' where it is not associated with a value
Traceback (most recent call last):
  File "c:\Users\pc\OneDrive\Desktop\phantom_alert_bot\signal_runner_loop.py", line 230, in _run
UnboundLocalError: cannot access local variable 'uploaded_image_url' where it is not associated with a value
2025-06-12 00:31:14,753 - INFO - BTCUSDT: 新しい足 (M5) が形成されました。データ取得とシグナル判定を実行します。
2025-06-12 00:31:14,781 - INFO - BTCUSDT-M5 シグナル判定結果: No signal
2025-06-12 00:31:14,781 - INFO - BTCUSDT-M5: シグナルなし。
2025-06-12 00:31:14,782 - ERROR - BTCUSDT: シグナル監視ループで予期せぬエラーが発生しました: cannot access local variable 'uploaded_image_url' where it is not associated with a value
Traceback (most recent call last):
  File "C:\Users\pc\OneDrive\Desktop\phantom_alert_bot\signal_runner_loop.py", line 230, in _run
UnboundLocalError: cannot access local variable 'uploaded_image_url' where it is not associated with a value
2025-06-12 00:31:16,718 - INFO - BTCUSDT: 新しい足 (M5) が形成されました。データ取得とシグナル判定を実行します。
2025-06-12 00:31:16,745 - INFO - BTCUSDT-M5 シグナル判定結果: No signal
2025-06-12 00:31:16,746 - INFO - BTCUSDT-M5: シグナルなし。
2025-06-12 00:31:16,746 - ERROR - BTCUSDT: シグナル監視ループで予期せぬエラーが発生しました: cannot access local variable 'uploaded_image_url' where it is not associated with a value
Traceback (most recent call last):
  File "C:\Users\pc\OneDrive\Desktop\phantom_alert_bot\signal_runner_loop.py", line 230, in _run
UnboundLocalError: cannot access local variable 'uploaded_image_url' where it is not associated with a value
2025-06-12 00:31:44,928 - INFO - BTCUSDT: 新しい足 (M5) が形成されました。データ取得とシグナル判定を実行します。
2025-06-12 00:31:44,969 - INFO - BTCUSDT-M5 シグナル判定結果: No signal
2025-06-12 00:31:44,969 - INFO - BTCUSDT-M5: シグナルなし。
2025-06-12 00:31:44,970 - ERROR - BTCUSDT: シグナル監視ループで予期せぬエラーが発生しました: cannot access local variable 'uploaded_image_url' where it is not associated with a value
Traceback (most recent call last):
  File "c:\Users\pc\OneDrive\Desktop\phantom_alert_bot\signal_runner_loop.py", line 230, in _run
UnboundLocalError: cannot access local variable 'uploaded_image_url' where it is not associated with a value
2025-06-12 00:32:14,783 - INFO - BTCUSDT: 新しい足 (M5) が形成されました。データ取得とシグナル判定を実行します。
2025-06-12 00:32:14,810 - INFO - BTCUSDT-M5 シグナル判定結果: No signal
2025-06-12 00:32:14,810 - INFO - BTCUSDT-M5: シグナルなし。
2025-06-12 00:32:14,811 - ERROR - BTCUSDT: シグナル監視ループで予期せぬエラーが発生しました: cannot access local variable 'uploaded_image_url' where it is not associated with a value
Traceback (most recent call last):
  File "C:\Users\pc\OneDrive\Desktop\phantom_alert_bot\signal_runner_loop.py", line 230, in _run
UnboundLocalError: cannot access local variable 'uploaded_image_url' where it is not associated with a value
2025-06-12 00:32:16,748 - INFO - BTCUSDT: 新しい足 (M5) が形成されました。データ取得とシグナル判定を実行します。
2025-06-12 00:32:16,780 - INFO - BTCUSDT-M5 シグナル判定結果: No signal
2025-06-12 00:32:16,780 - INFO - BTCUSDT-M5: シグナルなし。
2025-06-12 00:32:16,781 - ERROR - BTCUSDT: シグナル監視ループで予期せぬエラーが発生しました: cannot access local variable 'uploaded_image_url' where it is not associated with a value
Traceback (most recent call last):
  File "C:\Users\pc\OneDrive\Desktop\phantom_alert_bot\signal_runner_loop.py", line 230, in _run
UnboundLocalError: cannot access local variable 'uploaded_image_url' where it is not associated with a value
2025-06-12 00:32:44,972 - INFO - BTCUSDT: 新しい足 (M5) が形成されました。データ取得とシグナル判定を実行します。
2025-06-12 00:32:45,016 - INFO - BTCUSDT-M5 シグナル判定結果: No signal
2025-06-12 00:32:45,017 - INFO - BTCUSDT-M5: シグナルなし。
2025-06-12 00:32:45,018 - ERROR - BTCUSDT: シグナル監視ループで予期せぬエラーが発生しました: cannot access local variable 'uploaded_image_url' where it is not associated with a value
Traceback (most recent call last):
  File "c:\Users\pc\OneDrive\Desktop\phantom_alert_bot\signal_runner_loop.py", line 230, in _run
UnboundLocalError: cannot access local variable 'uploaded_image_url' where it is not associated with a value
2025-06-12 00:33:14,812 - INFO - BTCUSDT: 新しい足 (M5) が形成されました。データ取得とシグナル判定を実行します。
2025-06-12 00:33:14,837 - INFO - BTCUSDT-M5 シグナル判定結果: No signal
2025-06-12 00:33:14,838 - INFO - BTCUSDT-M5: シグナルなし。
2025-06-12 00:33:14,838 - ERROR - BTCUSDT: シグナル監視ループで予期せぬエラーが発生しました: cannot access local variable 'uploaded_image_url' where it is not associated with a value
Traceback (most recent call last):
  File "C:\Users\pc\OneDrive\Desktop\phantom_alert_bot\signal_runner_loop.py", line 230, in _run
UnboundLocalError: cannot access local variable 'uploaded_image_url' where it is not associated with a value
2025-06-12 00:33:16,783 - INFO - BTCUSDT: 新しい足 (M5) が形成されました。データ取得とシグナル判定を実行します。
2025-06-12 00:33:16,813 - INFO - BTCUSDT-M5 シグナル判定結果: No signal
2025-06-12 00:33:16,814 - INFO - BTCUSDT-M5: シグナルなし。
2025-06-12 00:33:16,814 - ERROR - BTCUSDT: シグナル監視ループで予期せぬエラーが発生しました: cannot access local variable 'uploaded_image_url' where it is not associated with a value
Traceback (most recent call last):
  File "C:\Users\pc\OneDrive\Desktop\phantom_alert_bot\signal_runner_loop.py", line 230, in _run
UnboundLocalError: cannot access local variable 'uploaded_image_url' where it is not associated with a value
2025-06-12 00:33:45,020 - INFO - BTCUSDT: 新しい足 (M5) が形成されました。データ取得とシグナル判定を実行します。
2025-06-12 00:33:45,045 - INFO - BTCUSDT-M5 シグナル判定結果: No signal
2025-06-12 00:33:45,047 - INFO - BTCUSDT-M5: シグナルなし。
2025-06-12 00:33:45,048 - ERROR - BTCUSDT: シグナル監視ループで予期せぬエラーが発生しました: cannot access local variable 'uploaded_image_url' where it is not associated with a value
Traceback (most recent call last):
  File "c:\Users\pc\OneDrive\Desktop\phantom_alert_bot\signal_runner_loop.py", line 230, in _run
UnboundLocalError: cannot access local variable 'uploaded_image_url' where it is not associated with a value
2025-06-12 00:34:14,840 - INFO - BTCUSDT: 新しい足 (M5) が形成されました。データ取得とシグナル判定を実行します。
2025-06-12 00:34:14,873 - INFO - BTCUSDT-M5 シグナル判定結果: No signal
2025-06-12 00:34:14,874 - INFO - BTCUSDT-M5: シグナルなし。
2025-06-12 00:34:14,874 - ERROR - BTCUSDT: シグナル監視ループで予期せぬエラーが発生しました: cannot access local variable 'uploaded_image_url' where it is not associated with a value
Traceback (most recent call last):
  File "C:\Users\pc\OneDrive\Desktop\phantom_alert_bot\signal_runner_loop.py", line 230, in _run
UnboundLocalError: cannot access local variable 'uploaded_image_url' where it is not associated with a value
2025-06-12 00:34:16,818 - INFO - BTCUSDT: 新しい足 (M5) が形成されました。データ取得とシグナル判定を実行します。
2025-06-12 00:34:16,870 - INFO - BTCUSDT-M5 シグナル判定結果: No signal
2025-06-12 00:34:16,871 - INFO - BTCUSDT-M5: シグナルなし。
2025-06-12 00:34:16,871 - ERROR - BTCUSDT: シグナル監視ループで予期せぬエラーが発生しました: cannot access local variable 'uploaded_image_url' where it is not associated with a value
Traceback (most recent call last):
  File "C:\Users\pc\OneDrive\Desktop\phantom_alert_bot\signal_runner_loop.py", line 230, in _run
UnboundLocalError: cannot access local variable 'uploaded_image_url' where it is not associated with a value
2025-06-12 00:34:45,049 - INFO - BTCUSDT: 新しい足 (M5) が形成されました。データ取得とシグナル判定を実行します。
2025-06-12 00:34:45,103 - INFO - BTCUSDT-M5 シグナル判定結果: No signal
2025-06-12 00:34:45,103 - INFO - BTCUSDT-M5: シグナルなし。
2025-06-12 00:34:45,105 - ERROR - BTCUSDT: シグナル監視ループで予期せぬエラーが発生しました: cannot access local variable 'uploaded_image_url' where it is not associated with a value
Traceback (most recent call last):
  File "c:\Users\pc\OneDrive\Desktop\phantom_alert_bot\signal_runner_loop.py", line 230, in _run
UnboundLocalError: cannot access local variable 'uploaded_image_url' where it is not associated with a value
2025-06-12 00:35:14,876 - INFO - BTCUSDT: 新しい足 (M5) が形成されました。データ取得とシグナル判定を実行します。
2025-06-12 00:35:14,921 - INFO - BTCUSDT-M5 シグナル判定結果: No signal
2025-06-12 00:35:14,922 - INFO - BTCUSDT-M5: シグナルなし。
2025-06-12 00:35:14,922 - ERROR - BTCUSDT: シグナル監視ループで予期せぬエラーが発生しました: cannot access local variable 'uploaded_image_url' where it is not associated with a value
Traceback (most recent call last):
  File "C:\Users\pc\OneDrive\Desktop\phantom_alert_bot\signal_runner_loop.py", line 230, in _run
UnboundLocalError: cannot access local variable 'uploaded_image_url' where it is not associated with a value
2025-06-12 00:35:16,873 - INFO - BTCUSDT: 新しい足 (M5) が形成されました。データ取得とシグナル判定を実行します。
2025-06-12 00:35:16,918 - INFO - BTCUSDT-M5 シグナル判定結果: No signal
2025-06-12 00:35:16,918 - INFO - BTCUSDT-M5: シグナルなし。
2025-06-12 00:35:16,919 - ERROR - BTCUSDT: シグナル監視ループで予期せぬエラーが発生しました: cannot access local variable 'uploaded_image_url' where it is not associated with a value
Traceback (most recent call last):
  File "C:\Users\pc\OneDrive\Desktop\phantom_alert_bot\signal_runner_loop.py", line 230, in _run
UnboundLocalError: cannot access local variable 'uploaded_image_url' where it is not associated with a value
2025-06-12 00:35:45,108 - INFO - BTCUSDT: 新しい足 (M5) が形成されました。データ取得とシグナル判定を実行します。
2025-06-12 00:35:45,146 - INFO - BTCUSDT-M5 シグナル判定結果: No signal
2025-06-12 00:35:45,147 - INFO - BTCUSDT-M5: シグナルなし。
2025-06-12 00:35:45,147 - ERROR - BTCUSDT: シグナル監視ループで予期せぬエラーが発生しました: cannot access local variable 'uploaded_image_url' where it is not associated with a value
Traceback (most recent call last):
  File "c:\Users\pc\OneDrive\Desktop\phantom_alert_bot\signal_runner_loop.py", line 230, in _run
UnboundLocalError: cannot access local variable 'uploaded_image_url' where it is not associated with a value
2025-06-12 00:36:14,928 - INFO - BTCUSDT: 新しい足 (M5) が形成されました。データ取得とシグナル判定を実行します。
2025-06-12 00:36:14,949 - INFO - BTCUSDT-M5 シグナル判定結果: No signal
2025-06-12 00:36:14,949 - INFO - BTCUSDT-M5: シグナルなし。
2025-06-12 00:36:14,949 - ERROR - BTCUSDT: シグナル監視ループで予期せぬエラーが発生しました: cannot access local variable 'uploaded_image_url' where it is not associated with a value
Traceback (most recent call last):
  File "C:\Users\pc\OneDrive\Desktop\phantom_alert_bot\signal_runner_loop.py", line 230, in _run
UnboundLocalError: cannot access local variable 'uploaded_image_url' where it is not associated with a value
2025-06-12 00:36:16,921 - INFO - BTCUSDT: 新しい足 (M5) が形成されました。データ取得とシグナル判定を実行します。
2025-06-12 00:36:16,946 - INFO - BTCUSDT-M5 シグナル判定結果: No signal
2025-06-12 00:36:16,946 - INFO - BTCUSDT-M5: シグナルなし。
2025-06-12 00:36:16,947 - ERROR - BTCUSDT: シグナル監視ループで予期せぬエラーが発生しました: cannot access local variable 'uploaded_image_url' where it is not associated with a value
Traceback (most recent call last):
  File "C:\Users\pc\OneDrive\Desktop\phantom_alert_bot\signal_runner_loop.py", line 230, in _run
UnboundLocalError: cannot access local variable 'uploaded_image_url' where it is not associated with a value
2025-06-12 00:36:45,149 - INFO - BTCUSDT: 新しい足 (M5) が形成されました。データ取得とシグナル判定を実行します。
2025-06-12 00:36:45,221 - INFO - BTCUSDT-M5 シグナル判定結果: No signal
2025-06-12 00:36:45,221 - INFO - BTCUSDT-M5: シグナルなし。
2025-06-12 00:36:45,222 - ERROR - BTCUSDT: シグナル監視ループで予期せぬエラーが発生しました: cannot access local variable 'uploaded_image_url' where it is not associated with a value
Traceback (most recent call last):
  File "c:\Users\pc\OneDrive\Desktop\phantom_alert_bot\signal_runner_loop.py", line 230, in _run
UnboundLocalError: cannot access local variable 'uploaded_image_url' where it is not associated with a value
2025-06-12 00:37:14,951 - INFO - BTCUSDT: 新しい足 (M5) が形成されました。データ取得とシグナル判定を実行します。
2025-06-12 00:37:15,024 - INFO - BTCUSDT-M5 シグナル判定結果: No signal
2025-06-12 00:37:15,024 - INFO - BTCUSDT-M5: シグナルなし。
2025-06-12 00:37:15,024 - ERROR - BTCUSDT: シグナル監視ループで予期せぬエラーが発生しました: cannot access local variable 'uploaded_image_url' where it is not associated with a value
Traceback (most recent call last):
  File "C:\Users\pc\OneDrive\Desktop\phantom_alert_bot\signal_runner_loop.py", line 230, in _run
UnboundLocalError: cannot access local variable 'uploaded_image_url' where it is not associated with a value
2025-06-12 00:37:16,948 - INFO - BTCUSDT: 新しい足 (M5) が形成されました。データ取得とシグナル判定を実行します。
2025-06-12 00:37:17,013 - INFO - BTCUSDT-M5 シグナル判定結果: No signal
2025-06-12 00:37:17,014 - INFO - BTCUSDT-M5: シグナルなし。
2025-06-12 00:37:17,014 - ERROR - BTCUSDT: シグナル監視ループで予期せぬエラーが発生しました: cannot access local variable 'uploaded_image_url' where it is not associated with a value
Traceback (most recent call last):
  File "C:\Users\pc\OneDrive\Desktop\phantom_alert_bot\signal_runner_loop.py", line 230, in _run
UnboundLocalError: cannot access local variable 'uploaded_image_url' where it is not associated with a value
2025-06-12 00:37:45,223 - INFO - BTCUSDT: 新しい足 (M5) が形成されました。データ取得とシグナル判定を実行します。
2025-06-12 00:37:45,297 - INFO - BTCUSDT-M5 シグナル判定結果: No signal
2025-06-12 00:37:45,297 - INFO - BTCUSDT-M5: シグナルなし。
2025-06-12 00:37:45,298 - ERROR - BTCUSDT: シグナル監視ループで予期せぬエラーが発生しました: cannot access local variable 'uploaded_image_url' where it is not associated with a value
Traceback (most recent call last):
  File "c:\Users\pc\OneDrive\Desktop\phantom_alert_bot\signal_runner_loop.py", line 230, in _run
UnboundLocalError: cannot access local variable 'uploaded_image_url' where it is not associated with a value
2025-06-12 00:38:15,026 - INFO - BTCUSDT: 新しい足 (M5) が形成されました。データ取得とシグナル判定を実行します。
2025-06-12 00:38:15,066 - INFO - BTCUSDT-M5 シグナル判定結果: No signal
2025-06-12 00:38:15,066 - INFO - BTCUSDT-M5: シグナルなし。
2025-06-12 00:38:15,066 - ERROR - BTCUSDT: シグナル監視ループで予期せぬエラーが発生しました: cannot access local variable 'uploaded_image_url' where it is not associated with a value
Traceback (most recent call last):
  File "C:\Users\pc\OneDrive\Desktop\phantom_alert_bot\signal_runner_loop.py", line 230, in _run
UnboundLocalError: cannot access local variable 'uploaded_image_url' where it is not associated with a value
2025-06-12 00:38:17,017 - INFO - BTCUSDT: 新しい足 (M5) が形成されました。データ取得とシグナル判定を実行します。
2025-06-12 00:38:17,039 - INFO - BTCUSDT-M5 シグナル判定結果: No signal
2025-06-12 00:38:17,039 - INFO - BTCUSDT-M5: シグナルなし。
2025-06-12 00:38:17,039 - ERROR - BTCUSDT: シグナル監視ループで予期せぬエラーが発生しました: cannot access local variable 'uploaded_image_url' where it is not associated with a value
Traceback (most recent call last):
  File "C:\Users\pc\OneDrive\Desktop\phantom_alert_bot\signal_runner_loop.py", line 230, in _run
UnboundLocalError: cannot access local variable 'uploaded_image_url' where it is not associated with a value
2025-06-12 00:38:45,300 - INFO - BTCUSDT: 新しい足 (M5) が形成されました。データ取得とシグナル判定を実行します。
2025-06-12 00:38:45,377 - INFO - BTCUSDT-M5 シグナル判定結果: No signal
2025-06-12 00:38:45,378 - INFO - BTCUSDT-M5: シグナルなし。
2025-06-12 00:38:45,379 - ERROR - BTCUSDT: シグナル監視ループで予期せぬエラーが発生しました: cannot access local variable 'uploaded_image_url' where it is not associated with a value
Traceback (most recent call last):
  File "c:\Users\pc\OneDrive\Desktop\phantom_alert_bot\signal_runner_loop.py", line 230, in _run
UnboundLocalError: cannot access local variable 'uploaded_image_url' where it is not associated with a value
2025-06-12 00:39:15,068 - INFO - BTCUSDT: 新しい足 (M5) が形成されました。データ取得とシグナル判定を実行します。
2025-06-12 00:39:15,138 - INFO - BTCUSDT-M5 シグナル判定結果: No signal
2025-06-12 00:39:15,139 - INFO - BTCUSDT-M5: シグナルなし。
2025-06-12 00:39:15,139 - ERROR - BTCUSDT: シグナル監視ループで予期せぬエラーが発生しました: cannot access local variable 'uploaded_image_url' where it is not associated with a value
Traceback (most recent call last):
  File "C:\Users\pc\OneDrive\Desktop\phantom_alert_bot\signal_runner_loop.py", line 230, in _run
UnboundLocalError: cannot access local variable 'uploaded_image_url' where it is not associated with a value
2025-06-12 00:39:17,041 - INFO - BTCUSDT: 新しい足 (M5) が形成されました。データ取得とシグナル判定を実行します。
2025-06-12 00:39:17,136 - INFO - BTCUSDT-M5 シグナル判定結果: No signal
2025-06-12 00:39:17,136 - INFO - BTCUSDT-M5: シグナルなし。
2025-06-12 00:39:17,137 - ERROR - BTCUSDT: シグナル監視ループで予期せぬエラーが発生しました: cannot access local variable 'uploaded_image_url' where it is not associated with a value
Traceback (most recent call last):
  File "C:\Users\pc\OneDrive\Desktop\phantom_alert_bot\signal_runner_loop.py", line 230, in _run
UnboundLocalError: cannot access local variable 'uploaded_image_url' where it is not associated with a value
2025-06-12 00:39:45,382 - INFO - BTCUSDT: 新しい足 (M5) が形成されました。データ取得とシグナル判定を実行します。
2025-06-12 00:39:45,454 - INFO - BTCUSDT-M5 シグナル判定結果: No signal
2025-06-12 00:39:45,456 - INFO - BTCUSDT-M5: シグナルなし。
2025-06-12 00:39:45,456 - ERROR - BTCUSDT: シグナル監視ループで予期せぬエラーが発生しました: cannot access local variable 'uploaded_image_url' where it is not associated with a value
Traceback (most recent call last):
  File "c:\Users\pc\OneDrive\Desktop\phantom_alert_bot\signal_runner_loop.py", line 230, in _run
UnboundLocalError: cannot access local variable 'uploaded_image_url' where it is not associated with a value
2025-06-12 00:40:15,141 - INFO - BTCUSDT: 新しい足 (M5) が形成されました。データ取得とシグナル判定を実行します。
2025-06-12 00:40:15,201 - INFO - BTCUSDT-M5 シグナル判定結果: No signal
2025-06-12 00:40:15,202 - INFO - BTCUSDT-M5: シグナルなし。
2025-06-12 00:40:15,202 - ERROR - BTCUSDT: シグナル監視ループで予期せぬエラーが発生しました: cannot access local variable 'uploaded_image_url' where it is not associated with a value
Traceback (most recent call last):
  File "C:\Users\pc\OneDrive\Desktop\phantom_alert_bot\signal_runner_loop.py", line 230, in _run
UnboundLocalError: cannot access local variable 'uploaded_image_url' where it is not associated with a value
2025-06-12 00:40:17,138 - INFO - BTCUSDT: 新しい足 (M5) が形成されました。データ取得とシグナル判定を実行します。
2025-06-12 00:40:17,209 - INFO - BTCUSDT-M5 シグナル判定結果: No signal
2025-06-12 00:40:17,210 - INFO - BTCUSDT-M5: シグナルなし。
2025-06-12 00:40:17,210 - ERROR - BTCUSDT: シグナル監視ループで予期せぬエラーが発生しました: cannot access local variable 'uploaded_image_url' where it is not associated with a value
Traceback (most recent call last):
  File "C:\Users\pc\OneDrive\Desktop\phantom_alert_bot\signal_runner_loop.py", line 230, in _run
UnboundLocalError: cannot access local variable 'uploaded_image_url' where it is not associated with a value
2025-06-12 00:40:45,457 - INFO - BTCUSDT: 新しい足 (M5) が形成されました。データ取得とシグナル判定を実行します。
2025-06-12 00:40:45,494 - INFO - BTCUSDT-M5 シグナル判定結果: No signal
2025-06-12 00:40:45,494 - INFO - BTCUSDT-M5: シグナルなし。
2025-06-12 00:40:45,496 - ERROR - BTCUSDT: シグナル監視ループで予期せぬエラーが発生しました: cannot access local variable 'uploaded_image_url' where it is not associated with a value
Traceback (most recent call last):
  File "c:\Users\pc\OneDrive\Desktop\phantom_alert_bot\signal_runner_loop.py", line 230, in _run
UnboundLocalError: cannot access local variable 'uploaded_image_url' where it is not associated with a value
2025-06-12 00:41:15,203 - INFO - BTCUSDT: 新しい足 (M5) が形成されました。データ取得とシグナル判定を実行します。
2025-06-12 00:41:15,284 - INFO - BTCUSDT-M5 シグナル判定結果: No signal
2025-06-12 00:41:15,284 - INFO - BTCUSDT-M5: シグナルなし。
2025-06-12 00:41:15,285 - ERROR - BTCUSDT: シグナル監視ループで予期せぬエラーが発生しました: cannot access local variable 'uploaded_image_url' where it is not associated with a value
Traceback (most recent call last):
  File "C:\Users\pc\OneDrive\Desktop\phantom_alert_bot\signal_runner_loop.py", line 230, in _run
UnboundLocalError: cannot access local variable 'uploaded_image_url' where it is not associated with a value
2025-06-12 00:41:17,211 - INFO - BTCUSDT: 新しい足 (M5) が形成されました。データ取得とシグナル判定を実行します。
2025-06-12 00:41:17,311 - INFO - BTCUSDT-M5 シグナル判定結果: No signal
2025-06-12 00:41:17,344 - INFO - BTCUSDT-M5: シグナルなし。
2025-06-12 00:41:17,352 - ERROR - BTCUSDT: シグナル監視ループで予期せぬエラーが発生しました: cannot access local variable 'uploaded_image_url' where it is not associated with a value
Traceback (most recent call last):
  File "C:\Users\pc\OneDrive\Desktop\phantom_alert_bot\signal_runner_loop.py", line 230, in _run
UnboundLocalError: cannot access local variable 'uploaded_image_url' where it is not associated with a value
2025-06-12 00:41:45,497 - INFO - BTCUSDT: 新しい足 (M5) が形成されました。データ取得とシグナル判定を実行します。
2025-06-12 00:41:45,583 - INFO - BTCUSDT-M5 シグナル判定結果: No signal
2025-06-12 00:41:45,584 - INFO - BTCUSDT-M5: シグナルなし。
2025-06-12 00:41:45,584 - ERROR - BTCUSDT: シグナル監視ループで予期せぬエラーが発生しました: cannot access local variable 'uploaded_image_url' where it is not associated with a value
Traceback (most recent call last):
  File "c:\Users\pc\OneDrive\Desktop\phantom_alert_bot\signal_runner_loop.py", line 230, in _run
UnboundLocalError: cannot access local variable 'uploaded_image_url' where it is not associated with a value
2025-06-12 00:42:15,287 - INFO - BTCUSDT: 新しい足 (M5) が形成されました。データ取得とシグナル判定を実行します。
2025-06-12 00:42:15,357 - INFO - BTCUSDT-M5 シグナル判定結果: No signal
2025-06-12 00:42:15,357 - INFO - BTCUSDT-M5: シグナルなし。
2025-06-12 00:42:15,358 - ERROR - BTCUSDT: シグナル監視ループで予期せぬエラーが発生しました: cannot access local variable 'uploaded_image_url' where it is not associated with a value
Traceback (most recent call last):
  File "C:\Users\pc\OneDrive\Desktop\phantom_alert_bot\signal_runner_loop.py", line 230, in _run
UnboundLocalError: cannot access local variable 'uploaded_image_url' where it is not associated with a value
2025-06-12 00:42:17,360 - INFO - BTCUSDT: 新しい足 (M5) が形成されました。データ取得とシグナル判定を実行します。
2025-06-12 00:42:17,450 - INFO - BTCUSDT-M5 シグナル判定結果: No signal
2025-06-12 00:42:17,451 - INFO - BTCUSDT-M5: シグナルなし。
2025-06-12 00:42:17,451 - ERROR - BTCUSDT: シグナル監視ループで予期せぬエラーが発生しました: cannot access local variable 'uploaded_image_url' where it is not associated with a value
Traceback (most recent call last):
  File "C:\Users\pc\OneDrive\Desktop\phantom_alert_bot\signal_runner_loop.py", line 230, in _run
UnboundLocalError: cannot access local variable 'uploaded_image_url' where it is not associated with a value
2025-06-12 00:42:45,587 - INFO - BTCUSDT: 新しい足 (M5) が形成されました。データ取得とシグナル判定を実行します。
2025-06-12 00:42:45,653 - INFO - BTCUSDT-M5 シグナル判定結果: No signal
2025-06-12 00:42:45,654 - INFO - BTCUSDT-M5: シグナルなし。
2025-06-12 00:42:45,655 - ERROR - BTCUSDT: シグナル監視ループで予期せぬエラーが発生しました: cannot access local variable 'uploaded_image_url' where it is not associated with a value
Traceback (most recent call last):
  File "c:\Users\pc\OneDrive\Desktop\phantom_alert_bot\signal_runner_loop.py", line 230, in _run
UnboundLocalError: cannot access local variable 'uploaded_image_url' where it is not associated with a value
2025-06-12 00:43:15,360 - INFO - BTCUSDT: 新しい足 (M5) が形成されました。データ取得とシグナル判定を実行します。
2025-06-12 00:43:15,445 - INFO - BTCUSDT-M5 シグナル判定結果: No signal
2025-06-12 00:43:15,450 - INFO - BTCUSDT-M5: シグナルなし。
2025-06-12 00:43:15,450 - ERROR - BTCUSDT: シグナル監視ループで予期せぬエラーが発生しました: cannot access local variable 'uploaded_image_url' where it is not associated with a value
Traceback (most recent call last):
  File "C:\Users\pc\OneDrive\Desktop\phantom_alert_bot\signal_runner_loop.py", line 230, in _run
UnboundLocalError: cannot access local variable 'uploaded_image_url' where it is not associated with a value
2025-06-12 00:43:17,454 - INFO - BTCUSDT: 新しい足 (M5) が形成されました。データ取得とシグナル判定を実行します。
2025-06-12 00:43:17,501 - INFO - BTCUSDT-M5 シグナル判定結果: No signal
2025-06-12 00:43:17,501 - INFO - BTCUSDT-M5: シグナルなし。
2025-06-12 00:43:17,502 - ERROR - BTCUSDT: シグナル監視ループで予期せぬエラーが発生しました: cannot access local variable 'uploaded_image_url' where it is not associated with a value
Traceback (most recent call last):
  File "C:\Users\pc\OneDrive\Desktop\phantom_alert_bot\signal_runner_loop.py", line 230, in _run
UnboundLocalError: cannot access local variable 'uploaded_image_url' where it is not associated with a value
2025-06-12 00:43:45,657 - INFO - BTCUSDT: 新しい足 (M5) が形成されました。データ取得とシグナル判定を実行します。
2025-06-12 00:43:45,728 - INFO - BTCUSDT-M5 シグナル判定結果: No signal
2025-06-12 00:43:45,729 - INFO - BTCUSDT-M5: シグナルなし。
2025-06-12 00:43:45,729 - ERROR - BTCUSDT: シグナル監視ループで予期せぬエラーが発生しました: cannot access local variable 'uploaded_image_url' where it is not associated with a value
Traceback (most recent call last):
  File "c:\Users\pc\OneDrive\Desktop\phantom_alert_bot\signal_runner_loop.py", line 230, in _run
UnboundLocalError: cannot access local variable 'uploaded_image_url' where it is not associated with a value
2025-06-12 00:44:15,452 - INFO - BTCUSDT: 新しい足 (M5) が形成されました。データ取得とシグナル判定を実行します。
2025-06-12 00:44:15,505 - INFO - BTCUSDT-M5 シグナル判定結果: No signal
2025-06-12 00:44:15,506 - INFO - BTCUSDT-M5: シグナルなし。
2025-06-12 00:44:15,507 - ERROR - BTCUSDT: シグナル監視ループで予期せぬエラーが発生しました: cannot access local variable 'uploaded_image_url' where it is not associated with a value
Traceback (most recent call last):
  File "C:\Users\pc\OneDrive\Desktop\phantom_alert_bot\signal_runner_loop.py", line 230, in _run
UnboundLocalError: cannot access local variable 'uploaded_image_url' where it is not associated with a value
2025-06-12 00:44:17,504 - INFO - BTCUSDT: 新しい足 (M5) が形成されました。データ取得とシグナル判定を実行します。
2025-06-12 00:44:17,564 - INFO - BTCUSDT-M5 シグナル判定結果: No signal
2025-06-12 00:44:17,564 - INFO - BTCUSDT-M5: シグナルなし。
2025-06-12 00:44:17,565 - ERROR - BTCUSDT: シグナル監視ループで予期せぬエラーが発生しました: cannot access local variable 'uploaded_image_url' where it is not associated with a value
Traceback (most recent call last):
  File "C:\Users\pc\OneDrive\Desktop\phantom_alert_bot\signal_runner_loop.py", line 230, in _run
UnboundLocalError: cannot access local variable 'uploaded_image_url' where it is not associated with a value
2025-06-12 00:44:45,731 - INFO - BTCUSDT: 新しい足 (M5) が形成されました。データ取得とシグナル判定を実行します。
2025-06-12 00:44:45,814 - INFO - BTCUSDT-M5 シグナル判定結果: No signal
2025-06-12 00:44:45,814 - INFO - BTCUSDT-M5: シグナルなし。
2025-06-12 00:44:45,819 - ERROR - BTCUSDT: シグナル監視ループで予期せぬエラーが発生しました: cannot access local variable 'uploaded_image_url' where it is not associated with a value
Traceback (most recent call last):
  File "c:\Users\pc\OneDrive\Desktop\phantom_alert_bot\signal_runner_loop.py", line 230, in _run
UnboundLocalError: cannot access local variable 'uploaded_image_url' where it is not associated with a value
2025-06-12 00:45:15,509 - INFO - BTCUSDT: 新しい足 (M5) が形成されました。データ取得とシグナル判定を実行します。
2025-06-12 00:45:15,583 - INFO - BTCUSDT-M5 シグナル判定結果: No signal
2025-06-12 00:45:15,584 - INFO - BTCUSDT-M5: シグナルなし。
2025-06-12 00:45:15,584 - ERROR - BTCUSDT: シグナル監視ループで予期せぬエラーが発生しました: cannot access local variable 'uploaded_image_url' where it is not associated with a value
Traceback (most recent call last):
  File "C:\Users\pc\OneDrive\Desktop\phantom_alert_bot\signal_runner_loop.py", line 230, in _run
UnboundLocalError: cannot access local variable 'uploaded_image_url' where it is not associated with a value
2025-06-12 00:45:17,567 - INFO - BTCUSDT: 新しい足 (M5) が形成されました。データ取得とシグナル判定を実行します。
2025-06-12 00:45:17,643 - INFO - BTCUSDT-M5 シグナル判定結果: No signal
2025-06-12 00:45:17,645 - INFO - BTCUSDT-M5: シグナルなし。
2025-06-12 00:45:17,646 - ERROR - BTCUSDT: シグナル監視ループで予期せぬエラーが発生しました: cannot access local variable 'uploaded_image_url' where it is not associated with a value
Traceback (most recent call last):
  File "C:\Users\pc\OneDrive\Desktop\phantom_alert_bot\signal_runner_loop.py", line 230, in _run
UnboundLocalError: cannot access local variable 'uploaded_image_url' where it is not associated with a value
2025-06-12 00:45:45,822 - INFO - BTCUSDT: 新しい足 (M5) が形成されました。データ取得とシグナル判定を実行します。
2025-06-12 00:45:45,857 - INFO - BTCUSDT-M5 シグナル判定結果: No signal
2025-06-12 00:45:45,858 - INFO - BTCUSDT-M5: シグナルなし。
2025-06-12 00:45:45,859 - ERROR - BTCUSDT: シグナル監視ループで予期せぬエラーが発生しました: cannot access local variable 'uploaded_image_url' where it is not associated with a value
Traceback (most recent call last):
  File "c:\Users\pc\OneDrive\Desktop\phantom_alert_bot\signal_runner_loop.py", line 230, in _run
UnboundLocalError: cannot access local variable 'uploaded_image_url' where it is not associated with a value
2025-06-12 00:46:15,586 - INFO - BTCUSDT: 新しい足 (M5) が形成されました。データ取得とシグナル判定を実行します。
2025-06-12 00:46:15,660 - INFO - BTCUSDT-M5 シグナル判定結果: No signal
2025-06-12 00:46:15,661 - INFO - BTCUSDT-M5: シグナルなし。
2025-06-12 00:46:15,661 - ERROR - BTCUSDT: シグナル監視ループで予期せぬエラーが発生しました: cannot access local variable 'uploaded_image_url' where it is not associated with a value
Traceback (most recent call last):
  File "C:\Users\pc\OneDrive\Desktop\phantom_alert_bot\signal_runner_loop.py", line 230, in _run
UnboundLocalError: cannot access local variable 'uploaded_image_url' where it is not associated with a value
2025-06-12 00:46:17,647 - INFO - BTCUSDT: 新しい足 (M5) が形成されました。データ取得とシグナル判定を実行します。
2025-06-12 00:46:17,702 - INFO - BTCUSDT-M5 シグナル判定結果: No signal
2025-06-12 00:46:17,702 - INFO - BTCUSDT-M5: シグナルなし。
2025-06-12 00:46:17,703 - ERROR - BTCUSDT: シグナル監視ループで予期せぬエラーが発生しました: cannot access local variable 'uploaded_image_url' where it is not associated with a value
Traceback (most recent call last):
  File "C:\Users\pc\OneDrive\Desktop\phantom_alert_bot\signal_runner_loop.py", line 230, in _run
UnboundLocalError: cannot access local variable 'uploaded_image_url' where it is not associated with a value
2025-06-12 00:46:45,860 - INFO - BTCUSDT: 新しい足 (M5) が形成されました。データ取得とシグナル判定を実行します。
2025-06-12 00:46:45,903 - INFO - BTCUSDT-M5 シグナル判定結果: No signal
2025-06-12 00:46:45,903 - INFO - BTCUSDT-M5: シグナルなし。
2025-06-12 00:46:45,904 - ERROR - BTCUSDT: シグナル監視ループで予期せぬエラーが発生しました: cannot access local variable 'uploaded_image_url' where it is not associated with a value
Traceback (most recent call last):
  File "c:\Users\pc\OneDrive\Desktop\phantom_alert_bot\signal_runner_loop.py", line 230, in _run
UnboundLocalError: cannot access local variable 'uploaded_image_url' where it is not associated with a value
2025-06-12 00:47:15,663 - INFO - BTCUSDT: 新しい足 (M5) が形成されました。データ取得とシグナル判定を実行します。
2025-06-12 00:47:15,694 - INFO - BTCUSDT-M5 シグナル判定結果: No signal
2025-06-12 00:47:15,694 - INFO - BTCUSDT-M5: シグナルなし。
2025-06-12 00:47:15,694 - ERROR - BTCUSDT: シグナル監視ループで予期せぬエラーが発生しました: cannot access local variable 'uploaded_image_url' where it is not associated with a value
Traceback (most recent call last):
  File "C:\Users\pc\OneDrive\Desktop\phantom_alert_bot\signal_runner_loop.py", line 230, in _run
UnboundLocalError: cannot access local variable 'uploaded_image_url' where it is not associated with a value
2025-06-12 00:47:17,704 - INFO - BTCUSDT: 新しい足 (M5) が形成されました。データ取得とシグナル判定を実行します。
2025-06-12 00:47:17,751 - INFO - BTCUSDT-M5 シグナル判定結果: No signal
2025-06-12 00:47:17,752 - INFO - BTCUSDT-M5: シグナルなし。
2025-06-12 00:47:17,752 - ERROR - BTCUSDT: シグナル監視ループで予期せぬエラーが発生しました: cannot access local variable 'uploaded_image_url' where it is not associated with a value
Traceback (most recent call last):
  File "C:\Users\pc\OneDrive\Desktop\phantom_alert_bot\signal_runner_loop.py", line 230, in _run
UnboundLocalError: cannot access local variable 'uploaded_image_url' where it is not associated with a value
2025-06-12 10:40:26,314 - INFO - ✅ BTCUSDT-M5 シグナルランナーが初期化されました。
2025-06-12 10:40:39,373 - INFO - BTCUSDT-M5 シグナル監視ループを開始します。
2025-06-12 10:40:39,375 - INFO - BTCUSDT: MT5クライアントを初期化しています...
2025-06-12 10:40:39,376 - INFO - ✅ BTCUSDT: MT5クライアントの初期化に成功しました。
2025-06-12 10:40:39,376 - INFO - BTCUSDT: 新しい足 (M5) が形成されました。データ取得とシグナル判定を実行します。
2025-06-12 10:40:39,442 - ERROR - BTCUSDT: シグナル監視ループで予期せぬエラーが発生しました: 'MACD_Signal'
Traceback (most recent call last):
  File "C:\Users\pc\AppData\Local\Programs\Python\Python312\Lib\site-packages\pandas\core\indexes\base.py", line 3812, in get_loc
    return self._engine.get_loc(casted_key)
           ^^^^^^^^^^^^^^^^^^^^^^^^^^^^^^^^
  File "pandas/_libs/index.pyx", line 167, in pandas._libs.index.IndexEngine.get_loc
  File "pandas/_libs/index.pyx", line 196, in pandas._libs.index.IndexEngine.get_loc
  File "pandas/_libs/hashtable_class_helper.pxi", line 7088, in pandas._libs.hashtable.PyObjectHashTable.get_item
  File "pandas/_libs/hashtable_class_helper.pxi", line 7096, in pandas._libs.hashtable.PyObjectHashTable.get_item
KeyError: 'MACD_Signal'

The above exception was the direct cause of the following exception:

Traceback (most recent call last):
  File "c:\Users\pc\OneDrive\Desktop\phantom_alert_bot\signal_runner_loop.py", line 196, in _run
    signal_info = generate_signal(df, mode="realtime", logic=DEFAULT_LOGIC) # modeとlogicを渡す
                  ^^^^^^^^^^^^^^^^^^^^^^^^^^^^^^^^^^^^^^^^^^^^^^^^^^^^^^^^^
  File "c:\Users\pc\OneDrive\Desktop\phantom_alert_bot\signal_generator.py", line 71, in generate_signal
    signal_info = _generate_balanced_signal(df_ind, current_price)
                  ^^^^^^^^^^^^^^^^^^^^^^^^^^^^^^^^^^^^^^^^^^^^^^^^
  File "c:\Users\pc\OneDrive\Desktop\phantom_alert_bot\signal_generator.py", line 192, in _generate_balanced_signal
    macd_buy = (df_ind['MACD'].iloc[-1] > df_ind['MACD_Signal'].iloc[-1]) # MACDゴールデンクロス
                                          ~~~~~~^^^^^^^^^^^^^^^
  File "C:\Users\pc\AppData\Local\Programs\Python\Python312\Lib\site-packages\pandas\core\frame.py", line 4107, in __getitem__
    indexer = self.columns.get_loc(key)
              ^^^^^^^^^^^^^^^^^^^^^^^^^
  File "C:\Users\pc\AppData\Local\Programs\Python\Python312\Lib\site-packages\pandas\core\indexes\base.py", line 3819, in get_loc
    raise KeyError(key) from err
KeyError: 'MACD_Signal'
2025-06-13 01:18:32,303 - INFO - ✅ BTCUSDT-M5 シグナルランナーが初期化されました。
2025-06-13 01:18:45,350 - INFO - BTCUSDT-M5 シグナル監視ループを開始します。
2025-06-13 01:18:45,353 - INFO - BTCUSDT: MT5クライアントを初期化しています...
2025-06-13 01:18:45,358 - INFO - ✅ BTCUSDT: MT5クライアントの初期化に成功しました。
2025-06-13 01:18:45,360 - INFO - BTCUSDT: 新しい足 (M5) が形成されました。データ取得とシグナル判定を実行します。
2025-06-13 01:18:45,375 - ERROR - BTCUSDT: シグナル監視ループで予期せぬエラーが発生しました: Cannot convert tz-naive timestamps, use tz_localize to localize
Traceback (most recent call last):
  File "C:\Users\pc\OneDrive\Desktop\phantom_alert_bot\signal_runner_loop.py", line 192, in _run
    df, latest_time_tokyo = self._get_current_ohlc()
                            ^^^^^^^^^^^^^^^^^^^^^^^^
  File "C:\Users\pc\OneDrive\Desktop\phantom_alert_bot\signal_runner_loop.py", line 116, in _get_current_ohlc
    df.index = df.index.tz_convert('Asia/Tokyo') # チャート描画時などのため
               ^^^^^^^^^^^^^^^^^^^^^^^^^^^^^^^^^
  File "C:\Users\pc\OneDrive\Desktop\phantom_alert_bot\venv\Lib\site-packages\pandas\core\indexes\datetimes.py", line 283, in tz_convert
    arr = self._data.tz_convert(tz)
          ^^^^^^^^^^^^^^^^^^^^^^^^^
  File "C:\Users\pc\OneDrive\Desktop\phantom_alert_bot\venv\Lib\site-packages\pandas\core\arrays\datetimes.py", line 917, in tz_convert
    raise TypeError(
TypeError: Cannot convert tz-naive timestamps, use tz_localize to localize
2025-06-13 01:19:45,379 - INFO - BTCUSDT: 新しい足 (M5) が形成されました。データ取得とシグナル判定を実行します。
2025-06-13 01:19:45,388 - ERROR - BTCUSDT: シグナル監視ループで予期せぬエラーが発生しました: Cannot convert tz-naive timestamps, use tz_localize to localize
Traceback (most recent call last):
  File "C:\Users\pc\OneDrive\Desktop\phantom_alert_bot\signal_runner_loop.py", line 192, in _run
    df, latest_time_tokyo = self._get_current_ohlc()
                            ^^^^^^^^^^^^^^^^^^^^^^^^
  File "C:\Users\pc\OneDrive\Desktop\phantom_alert_bot\signal_runner_loop.py", line 116, in _get_current_ohlc
    df.index = df.index.tz_convert('Asia/Tokyo') # チャート描画時などのため
               ^^^^^^^^^^^^^^^^^^^^^^^^^^^^^^^^^
  File "C:\Users\pc\OneDrive\Desktop\phantom_alert_bot\venv\Lib\site-packages\pandas\core\indexes\datetimes.py", line 283, in tz_convert
    arr = self._data.tz_convert(tz)
          ^^^^^^^^^^^^^^^^^^^^^^^^^
  File "C:\Users\pc\OneDrive\Desktop\phantom_alert_bot\venv\Lib\site-packages\pandas\core\arrays\datetimes.py", line 917, in tz_convert
    raise TypeError(
TypeError: Cannot convert tz-naive timestamps, use tz_localize to localize
2025-06-13 01:20:45,393 - INFO - BTCUSDT: 新しい足 (M5) が形成されました。データ取得とシグナル判定を実行します。
2025-06-13 01:20:45,395 - ERROR - BTCUSDT: シグナル監視ループで予期せぬエラーが発生しました: Cannot convert tz-naive timestamps, use tz_localize to localize
Traceback (most recent call last):
  File "C:\Users\pc\OneDrive\Desktop\phantom_alert_bot\signal_runner_loop.py", line 192, in _run
    df, latest_time_tokyo = self._get_current_ohlc()
                            ^^^^^^^^^^^^^^^^^^^^^^^^
  File "C:\Users\pc\OneDrive\Desktop\phantom_alert_bot\signal_runner_loop.py", line 116, in _get_current_ohlc
    df.index = df.index.tz_convert('Asia/Tokyo') # チャート描画時などのため
               ^^^^^^^^^^^^^^^^^^^^^^^^^^^^^^^^^
  File "C:\Users\pc\OneDrive\Desktop\phantom_alert_bot\venv\Lib\site-packages\pandas\core\indexes\datetimes.py", line 283, in tz_convert
    arr = self._data.tz_convert(tz)
          ^^^^^^^^^^^^^^^^^^^^^^^^^
  File "C:\Users\pc\OneDrive\Desktop\phantom_alert_bot\venv\Lib\site-packages\pandas\core\arrays\datetimes.py", line 917, in tz_convert
    raise TypeError(
TypeError: Cannot convert tz-naive timestamps, use tz_localize to localize
2025-06-13 01:21:45,396 - INFO - BTCUSDT: 新しい足 (M5) が形成されました。データ取得とシグナル判定を実行します。
2025-06-13 01:21:45,399 - ERROR - BTCUSDT: シグナル監視ループで予期せぬエラーが発生しました: Cannot convert tz-naive timestamps, use tz_localize to localize
Traceback (most recent call last):
  File "C:\Users\pc\OneDrive\Desktop\phantom_alert_bot\signal_runner_loop.py", line 192, in _run
    df, latest_time_tokyo = self._get_current_ohlc()
                            ^^^^^^^^^^^^^^^^^^^^^^^^
  File "C:\Users\pc\OneDrive\Desktop\phantom_alert_bot\signal_runner_loop.py", line 116, in _get_current_ohlc
    df.index = df.index.tz_convert('Asia/Tokyo') # チャート描画時などのため
               ^^^^^^^^^^^^^^^^^^^^^^^^^^^^^^^^^
  File "C:\Users\pc\OneDrive\Desktop\phantom_alert_bot\venv\Lib\site-packages\pandas\core\indexes\datetimes.py", line 283, in tz_convert
    arr = self._data.tz_convert(tz)
          ^^^^^^^^^^^^^^^^^^^^^^^^^
  File "C:\Users\pc\OneDrive\Desktop\phantom_alert_bot\venv\Lib\site-packages\pandas\core\arrays\datetimes.py", line 917, in tz_convert
    raise TypeError(
TypeError: Cannot convert tz-naive timestamps, use tz_localize to localize
2025-06-13 01:22:45,400 - INFO - BTCUSDT: 新しい足 (M5) が形成されました。データ取得とシグナル判定を実行します。
2025-06-13 01:22:45,402 - ERROR - BTCUSDT: シグナル監視ループで予期せぬエラーが発生しました: Cannot convert tz-naive timestamps, use tz_localize to localize
Traceback (most recent call last):
  File "C:\Users\pc\OneDrive\Desktop\phantom_alert_bot\signal_runner_loop.py", line 192, in _run
    df, latest_time_tokyo = self._get_current_ohlc()
                            ^^^^^^^^^^^^^^^^^^^^^^^^
  File "C:\Users\pc\OneDrive\Desktop\phantom_alert_bot\signal_runner_loop.py", line 116, in _get_current_ohlc
    df.index = df.index.tz_convert('Asia/Tokyo') # チャート描画時などのため
               ^^^^^^^^^^^^^^^^^^^^^^^^^^^^^^^^^
  File "C:\Users\pc\OneDrive\Desktop\phantom_alert_bot\venv\Lib\site-packages\pandas\core\indexes\datetimes.py", line 283, in tz_convert
    arr = self._data.tz_convert(tz)
          ^^^^^^^^^^^^^^^^^^^^^^^^^
  File "C:\Users\pc\OneDrive\Desktop\phantom_alert_bot\venv\Lib\site-packages\pandas\core\arrays\datetimes.py", line 917, in tz_convert
    raise TypeError(
TypeError: Cannot convert tz-naive timestamps, use tz_localize to localize
2025-06-13 01:23:45,404 - INFO - BTCUSDT: 新しい足 (M5) が形成されました。データ取得とシグナル判定を実行します。
2025-06-13 01:23:45,411 - ERROR - BTCUSDT: シグナル監視ループで予期せぬエラーが発生しました: Cannot convert tz-naive timestamps, use tz_localize to localize
Traceback (most recent call last):
  File "C:\Users\pc\OneDrive\Desktop\phantom_alert_bot\signal_runner_loop.py", line 192, in _run
    df, latest_time_tokyo = self._get_current_ohlc()
                            ^^^^^^^^^^^^^^^^^^^^^^^^
  File "C:\Users\pc\OneDrive\Desktop\phantom_alert_bot\signal_runner_loop.py", line 116, in _get_current_ohlc
    df.index = df.index.tz_convert('Asia/Tokyo') # チャート描画時などのため
               ^^^^^^^^^^^^^^^^^^^^^^^^^^^^^^^^^
  File "C:\Users\pc\OneDrive\Desktop\phantom_alert_bot\venv\Lib\site-packages\pandas\core\indexes\datetimes.py", line 283, in tz_convert
    arr = self._data.tz_convert(tz)
          ^^^^^^^^^^^^^^^^^^^^^^^^^
  File "C:\Users\pc\OneDrive\Desktop\phantom_alert_bot\venv\Lib\site-packages\pandas\core\arrays\datetimes.py", line 917, in tz_convert
    raise TypeError(
TypeError: Cannot convert tz-naive timestamps, use tz_localize to localize
2025-06-13 01:24:45,413 - INFO - BTCUSDT: 新しい足 (M5) が形成されました。データ取得とシグナル判定を実行します。
2025-06-13 01:24:45,418 - ERROR - BTCUSDT: シグナル監視ループで予期せぬエラーが発生しました: Cannot convert tz-naive timestamps, use tz_localize to localize
Traceback (most recent call last):
  File "C:\Users\pc\OneDrive\Desktop\phantom_alert_bot\signal_runner_loop.py", line 192, in _run
    df, latest_time_tokyo = self._get_current_ohlc()
                            ^^^^^^^^^^^^^^^^^^^^^^^^
  File "C:\Users\pc\OneDrive\Desktop\phantom_alert_bot\signal_runner_loop.py", line 116, in _get_current_ohlc
    df.index = df.index.tz_convert('Asia/Tokyo') # チャート描画時などのため
               ^^^^^^^^^^^^^^^^^^^^^^^^^^^^^^^^^
  File "C:\Users\pc\OneDrive\Desktop\phantom_alert_bot\venv\Lib\site-packages\pandas\core\indexes\datetimes.py", line 283, in tz_convert
    arr = self._data.tz_convert(tz)
          ^^^^^^^^^^^^^^^^^^^^^^^^^
  File "C:\Users\pc\OneDrive\Desktop\phantom_alert_bot\venv\Lib\site-packages\pandas\core\arrays\datetimes.py", line 917, in tz_convert
    raise TypeError(
TypeError: Cannot convert tz-naive timestamps, use tz_localize to localize
2025-06-13 01:25:45,421 - INFO - BTCUSDT: 新しい足 (M5) が形成されました。データ取得とシグナル判定を実行します。
2025-06-13 01:25:45,431 - ERROR - BTCUSDT: シグナル監視ループで予期せぬエラーが発生しました: Cannot convert tz-naive timestamps, use tz_localize to localize
Traceback (most recent call last):
  File "C:\Users\pc\OneDrive\Desktop\phantom_alert_bot\signal_runner_loop.py", line 192, in _run
    df, latest_time_tokyo = self._get_current_ohlc()
                            ^^^^^^^^^^^^^^^^^^^^^^^^
  File "C:\Users\pc\OneDrive\Desktop\phantom_alert_bot\signal_runner_loop.py", line 116, in _get_current_ohlc
    df.index = df.index.tz_convert('Asia/Tokyo') # チャート描画時などのため
               ^^^^^^^^^^^^^^^^^^^^^^^^^^^^^^^^^
  File "C:\Users\pc\OneDrive\Desktop\phantom_alert_bot\venv\Lib\site-packages\pandas\core\indexes\datetimes.py", line 283, in tz_convert
    arr = self._data.tz_convert(tz)
          ^^^^^^^^^^^^^^^^^^^^^^^^^
  File "C:\Users\pc\OneDrive\Desktop\phantom_alert_bot\venv\Lib\site-packages\pandas\core\arrays\datetimes.py", line 917, in tz_convert
    raise TypeError(
TypeError: Cannot convert tz-naive timestamps, use tz_localize to localize
2025-06-13 01:26:45,436 - INFO - BTCUSDT: 新しい足 (M5) が形成されました。データ取得とシグナル判定を実行します。
2025-06-13 01:26:45,438 - ERROR - BTCUSDT: シグナル監視ループで予期せぬエラーが発生しました: Cannot convert tz-naive timestamps, use tz_localize to localize
Traceback (most recent call last):
  File "C:\Users\pc\OneDrive\Desktop\phantom_alert_bot\signal_runner_loop.py", line 192, in _run
    df, latest_time_tokyo = self._get_current_ohlc()
                            ^^^^^^^^^^^^^^^^^^^^^^^^
  File "C:\Users\pc\OneDrive\Desktop\phantom_alert_bot\signal_runner_loop.py", line 116, in _get_current_ohlc
    df.index = df.index.tz_convert('Asia/Tokyo') # チャート描画時などのため
               ^^^^^^^^^^^^^^^^^^^^^^^^^^^^^^^^^
  File "C:\Users\pc\OneDrive\Desktop\phantom_alert_bot\venv\Lib\site-packages\pandas\core\indexes\datetimes.py", line 283, in tz_convert
    arr = self._data.tz_convert(tz)
          ^^^^^^^^^^^^^^^^^^^^^^^^^
  File "C:\Users\pc\OneDrive\Desktop\phantom_alert_bot\venv\Lib\site-packages\pandas\core\arrays\datetimes.py", line 917, in tz_convert
    raise TypeError(
TypeError: Cannot convert tz-naive timestamps, use tz_localize to localize
2025-06-13 01:27:45,439 - INFO - BTCUSDT: 新しい足 (M5) が形成されました。データ取得とシグナル判定を実行します。
2025-06-13 01:27:45,448 - ERROR - BTCUSDT: シグナル監視ループで予期せぬエラーが発生しました: Cannot convert tz-naive timestamps, use tz_localize to localize
Traceback (most recent call last):
  File "C:\Users\pc\OneDrive\Desktop\phantom_alert_bot\signal_runner_loop.py", line 192, in _run
    df, latest_time_tokyo = self._get_current_ohlc()
                            ^^^^^^^^^^^^^^^^^^^^^^^^
  File "C:\Users\pc\OneDrive\Desktop\phantom_alert_bot\signal_runner_loop.py", line 116, in _get_current_ohlc
    df.index = df.index.tz_convert('Asia/Tokyo') # チャート描画時などのため
               ^^^^^^^^^^^^^^^^^^^^^^^^^^^^^^^^^
  File "C:\Users\pc\OneDrive\Desktop\phantom_alert_bot\venv\Lib\site-packages\pandas\core\indexes\datetimes.py", line 283, in tz_convert
    arr = self._data.tz_convert(tz)
          ^^^^^^^^^^^^^^^^^^^^^^^^^
  File "C:\Users\pc\OneDrive\Desktop\phantom_alert_bot\venv\Lib\site-packages\pandas\core\arrays\datetimes.py", line 917, in tz_convert
    raise TypeError(
TypeError: Cannot convert tz-naive timestamps, use tz_localize to localize
2025-06-13 01:28:45,452 - INFO - BTCUSDT: 新しい足 (M5) が形成されました。データ取得とシグナル判定を実行します。
2025-06-13 01:28:45,460 - ERROR - BTCUSDT: シグナル監視ループで予期せぬエラーが発生しました: Cannot convert tz-naive timestamps, use tz_localize to localize
Traceback (most recent call last):
  File "C:\Users\pc\OneDrive\Desktop\phantom_alert_bot\signal_runner_loop.py", line 192, in _run
    if self.line_notifier:
                        ^^^
  File "C:\Users\pc\OneDrive\Desktop\phantom_alert_bot\signal_runner_loop.py", line 116, in _get_current_ohlc
  File "C:\Users\pc\OneDrive\Desktop\phantom_alert_bot\venv\Lib\site-packages\pandas\core\indexes\datetimes.py", line 283, in tz_convert
    arr = self._data.tz_convert(tz)
          ^^^^^^^^^^^^^^^^^^^^^^^^^
  File "C:\Users\pc\OneDrive\Desktop\phantom_alert_bot\venv\Lib\site-packages\pandas\core\arrays\datetimes.py", line 917, in tz_convert
    raise TypeError(
TypeError: Cannot convert tz-naive timestamps, use tz_localize to localize
