2025-06-11 18:43:24,097 - INFO - ✅ EURUSD-M15 シグナルランナーが初期化されました。
2025-06-11 18:43:30,139 - INFO - EURUSD-M15 シグナル監視ループを開始します。
2025-06-11 18:43:30,140 - INFO - EURUSD: MT5クライアントを初期化しています...
2025-06-11 18:43:30,142 - INFO - ✅ EURUSD: MT5クライアントの初期化に成功しました。
2025-06-11 18:43:30,142 - INFO - EURUSD: 新しい足 (M15) が形成されました。データ取得とシグナル判定を実行します。
2025-06-11 18:43:30,143 - ERROR - EURUSD: シグナル監視ループで予期せぬエラーが発生しました: module 'MetaTrader5' has no attribute 'is_connected'
Traceback (most recent call last):
  File "c:\Users\pc\OneDrive\Desktop\phantom_alert_bot\signal_runner_loop.py", line 190, in _run
    df, latest_time_tokyo = self._get_current_ohlc()
                            ~~~~~~~~~~~~~~~~~~~~~~^^
  File "c:\Users\pc\OneDrive\Desktop\phantom_alert_bot\signal_runner_loop.py", line 85, in _get_current_ohlc
    if not self._initialize_mt5():
           ~~~~~~~~~~~~~~~~~~~~^^
  File "c:\Users\pc\OneDrive\Desktop\phantom_alert_bot\signal_runner_loop.py", line 65, in _initialize_mt5
    if not self.mt5_initialized or not mt5.is_connected():
                                       ^^^^^^^^^^^^^^^^
AttributeError: module 'MetaTrader5' has no attribute 'is_connected'
2025-06-11 18:46:30,148 - INFO - EURUSD: 新しい足 (M15) が形成されました。データ取得とシグナル判定を実行します。
2025-06-11 18:46:30,149 - ERROR - EURUSD: シグナル監視ループで予期せぬエラーが発生しました: module 'MetaTrader5' has no attribute 'is_connected'
Traceback (most recent call last):
  File "c:\Users\pc\OneDrive\Desktop\phantom_alert_bot\signal_runner_loop.py", line 190, in _run
    df, latest_time_tokyo = self._get_current_ohlc()
                            ~~~~~~~~~~~~~~~~~~~~~~^^
  File "c:\Users\pc\OneDrive\Desktop\phantom_alert_bot\signal_runner_loop.py", line 85, in _get_current_ohlc
    if not self._initialize_mt5():
           ~~~~~~~~~~~~~~~~~~~~^^
  File "c:\Users\pc\OneDrive\Desktop\phantom_alert_bot\signal_runner_loop.py", line 65, in _initialize_mt5
    if not self.mt5_initialized or not mt5.is_connected():
                                       ^^^^^^^^^^^^^^^^
AttributeError: module 'MetaTrader5' has no attribute 'is_connected'
2025-06-11 18:49:30,154 - INFO - EURUSD: 新しい足 (M15) が形成されました。データ取得とシグナル判定を実行します。
2025-06-11 18:49:30,155 - ERROR - EURUSD: シグナル監視ループで予期せぬエラーが発生しました: module 'MetaTrader5' has no attribute 'is_connected'
Traceback (most recent call last):
  File "c:\Users\pc\OneDrive\Desktop\phantom_alert_bot\signal_runner_loop.py", line 190, in _run
    df, latest_time_tokyo = self._get_current_ohlc()
                            ~~~~~~~~~~~~~~~~~~~~~~^^
  File "c:\Users\pc\OneDrive\Desktop\phantom_alert_bot\signal_runner_loop.py", line 85, in _get_current_ohlc
    if not self._initialize_mt5():
           ~~~~~~~~~~~~~~~~~~~~^^
  File "c:\Users\pc\OneDrive\Desktop\phantom_alert_bot\signal_runner_loop.py", line 65, in _initialize_mt5
    if not self.mt5_initialized or not mt5.is_connected():
                                       ^^^^^^^^^^^^^^^^
AttributeError: module 'MetaTrader5' has no attribute 'is_connected'
2025-06-11 18:54:29,451 - INFO - ✅ EURUSD-M15 シグナルランナーが初期化されました。
2025-06-11 18:54:35,487 - INFO - EURUSD-M15 シグナル監視ループを開始します。
2025-06-11 18:54:35,489 - INFO - EURUSD: MT5クライアントを初期化しています...
2025-06-11 18:54:35,491 - INFO - ✅ EURUSD: MT5クライアントの初期化に成功しました。
2025-06-11 18:54:35,492 - INFO - EURUSD: 新しい足 (M15) が形成されました。データ取得とシグナル判定を実行します。
2025-06-11 18:54:35,544 - ERROR - EURUSD: シグナル監視ループで予期せぬエラーが発生しました: generate_signal() got an unexpected keyword argument 'logic'
Traceback (most recent call last):
  File "c:\Users\pc\OneDrive\Desktop\phantom_alert_bot\signal_runner_loop.py", line 177, in _run
    signal_info = generate_signal(df, mode="realtime", logic=DEFAULT_LOGIC) # modeとlogicを渡す
TypeError: generate_signal() got an unexpected keyword argument 'logic'
2025-06-11 18:57:35,545 - INFO - EURUSD: 新しい足 (M15) が形成されました。データ取得とシグナル判定を実行します。
2025-06-11 18:57:35,548 - ERROR - EURUSD: シグナル監視ループで予期せぬエラーが発生しました: generate_signal() got an unexpected keyword argument 'logic'
Traceback (most recent call last):
  File "c:\Users\pc\OneDrive\Desktop\phantom_alert_bot\signal_runner_loop.py", line 177, in _run
    signal_info = generate_signal(df, mode="realtime", logic=DEFAULT_LOGIC) # modeとlogicを渡す
TypeError: generate_signal() got an unexpected keyword argument 'logic'
2025-06-12 00:09:30,861 - INFO - ✅ EURUSD-M15 シグナルランナーが初期化されました。
2025-06-12 00:09:36,974 - INFO - EURUSD-M15 シグナル監視ループを開始します。
2025-06-12 00:09:36,975 - INFO - EURUSD: MT5クライアントを初期化しています...
2025-06-12 00:09:36,975 - INFO - ✅ EURUSD: MT5クライアントの初期化に成功しました。
2025-06-12 00:09:36,975 - INFO - EURUSD: 新しい足 (M15) が形成されました。データ取得とシグナル判定を実行します。
2025-06-12 00:09:36,996 - INFO - EURUSD-M15 シグナル判定結果: No signal
2025-06-12 00:09:36,996 - INFO - EURUSD-M15: シグナルなし。
2025-06-12 00:09:36,997 - ERROR - EURUSD: シグナル監視ループで予期せぬエラーが発生しました: cannot access local variable 'uploaded_image_url' where it is not associated with a value
Traceback (most recent call last):
  File "c:\Users\pc\OneDrive\Desktop\phantom_alert_bot\signal_runner_loop.py", line 230, in _run
    image_url=uploaded_image_url # ImgurのURLを保存
              ^^^^^^^^^^^^^^^^^^
UnboundLocalError: cannot access local variable 'uploaded_image_url' where it is not associated with a value
2025-06-12 00:10:15,481 - INFO - ✅ EURUSD-M15 シグナルランナーが初期化されました。
2025-06-12 00:10:21,511 - INFO - EURUSD-M15 シグナル監視ループを開始します。
2025-06-12 00:10:21,512 - INFO - EURUSD: MT5クライアントを初期化しています...
2025-06-12 00:10:21,512 - INFO - ✅ EURUSD: MT5クライアントの初期化に成功しました。
2025-06-12 00:10:21,513 - INFO - EURUSD: 新しい足 (M15) が形成されました。データ取得とシグナル判定を実行します。
2025-06-12 00:10:21,539 - INFO - EURUSD-M15 シグナル判定結果: No signal
2025-06-12 00:10:21,540 - INFO - EURUSD-M15: シグナルなし。
2025-06-12 00:10:21,540 - ERROR - EURUSD: シグナル監視ループで予期せぬエラーが発生しました: cannot access local variable 'uploaded_image_url' where it is not associated with a value
Traceback (most recent call last):
  File "C:\Users\pc\OneDrive\Desktop\phantom_alert_bot\signal_runner_loop.py", line 230, in _run
    image_url=uploaded_image_url # ImgurのURLを保存
              ^^^^^^^^^^^^^^^^^^
UnboundLocalError: cannot access local variable 'uploaded_image_url' where it is not associated with a value
2025-06-12 00:11:00,888 - INFO - ✅ EURUSD-M15 シグナルランナーが初期化されました。
2025-06-12 00:11:02,787 - INFO - ✅ EURUSD-M15 シグナルランナーが初期化されました。
2025-06-12 00:11:06,914 - INFO - EURUSD-M15 シグナル監視ループを開始します。
2025-06-12 00:11:06,915 - INFO - EURUSD: MT5クライアントを初期化しています...
2025-06-12 00:11:06,915 - INFO - ✅ EURUSD: MT5クライアントの初期化に成功しました。
2025-06-12 00:11:06,917 - INFO - EURUSD: 新しい足 (M15) が形成されました。データ取得とシグナル判定を実行します。
2025-06-12 00:11:06,943 - INFO - EURUSD-M15 シグナル判定結果: No signal
2025-06-12 00:11:06,943 - INFO - EURUSD-M15: シグナルなし。
2025-06-12 00:11:06,944 - ERROR - EURUSD: シグナル監視ループで予期せぬエラーが発生しました: cannot access local variable 'uploaded_image_url' where it is not associated with a value
Traceback (most recent call last):
  File "C:\Users\pc\OneDrive\Desktop\phantom_alert_bot\signal_runner_loop.py", line 230, in _run
    image_url=uploaded_image_url # ImgurのURLを保存
              ^^^^^^^^^^^^^^^^^^
UnboundLocalError: cannot access local variable 'uploaded_image_url' where it is not associated with a value
2025-06-12 00:11:08,810 - INFO - EURUSD-M15 シグナル監視ループを開始します。
2025-06-12 00:11:08,812 - INFO - EURUSD: MT5クライアントを初期化しています...
2025-06-12 00:11:08,813 - INFO - ✅ EURUSD: MT5クライアントの初期化に成功しました。
2025-06-12 00:11:08,813 - INFO - EURUSD: 新しい足 (M15) が形成されました。データ取得とシグナル判定を実行します。
2025-06-12 00:11:08,862 - INFO - EURUSD-M15 シグナル判定結果: No signal
2025-06-12 00:11:08,863 - INFO - EURUSD-M15: シグナルなし。
2025-06-12 00:11:08,863 - ERROR - EURUSD: シグナル監視ループで予期せぬエラーが発生しました: cannot access local variable 'uploaded_image_url' where it is not associated with a value
Traceback (most recent call last):
  File "C:\Users\pc\OneDrive\Desktop\phantom_alert_bot\signal_runner_loop.py", line 230, in _run
    image_url=uploaded_image_url # ImgurのURLを保存
              ^^^^^^^^^^^^^^^^^^
UnboundLocalError: cannot access local variable 'uploaded_image_url' where it is not associated with a value
2025-06-12 00:12:36,998 - INFO - EURUSD: 新しい足 (M15) が形成されました。データ取得とシグナル判定を実行します。
2025-06-12 00:12:37,020 - INFO - EURUSD-M15 シグナル判定結果: No signal
2025-06-12 00:12:37,020 - INFO - EURUSD-M15: シグナルなし。
2025-06-12 00:12:37,020 - ERROR - EURUSD: シグナル監視ループで予期せぬエラーが発生しました: cannot access local variable 'uploaded_image_url' where it is not associated with a value
Traceback (most recent call last):
  File "c:\Users\pc\OneDrive\Desktop\phantom_alert_bot\signal_runner_loop.py", line 230, in _run
    image_url=uploaded_image_url # ImgurのURLを保存
              ^^^^^^^^^^^^^^^^^^
UnboundLocalError: cannot access local variable 'uploaded_image_url' where it is not associated with a value
2025-06-12 00:13:21,542 - INFO - EURUSD: 新しい足 (M15) が形成されました。データ取得とシグナル判定を実行します。
2025-06-12 00:13:21,560 - INFO - EURUSD-M15 シグナル判定結果: No signal
2025-06-12 00:13:21,560 - INFO - EURUSD-M15: シグナルなし。
2025-06-12 00:13:21,560 - ERROR - EURUSD: シグナル監視ループで予期せぬエラーが発生しました: cannot access local variable 'uploaded_image_url' where it is not associated with a value
Traceback (most recent call last):
  File "C:\Users\pc\OneDrive\Desktop\phantom_alert_bot\signal_runner_loop.py", line 230, in _run
    image_url=uploaded_image_url # ImgurのURLを保存
              ^^^^^^^^^^^^^^^^^^
UnboundLocalError: cannot access local variable 'uploaded_image_url' where it is not associated with a value
2025-06-12 00:14:06,948 - INFO - EURUSD: 新しい足 (M15) が形成されました。データ取得とシグナル判定を実行します。
2025-06-12 00:14:07,011 - INFO - EURUSD-M15 シグナル判定結果: No signal
2025-06-12 00:14:07,011 - INFO - EURUSD-M15: シグナルなし。
2025-06-12 00:14:07,013 - ERROR - EURUSD: シグナル監視ループで予期せぬエラーが発生しました: cannot access local variable 'uploaded_image_url' where it is not associated with a value
Traceback (most recent call last):
  File "C:\Users\pc\OneDrive\Desktop\phantom_alert_bot\signal_runner_loop.py", line 230, in _run
    image_url=uploaded_image_url # ImgurのURLを保存
              ^^^^^^^^^^^^^^^^^^
UnboundLocalError: cannot access local variable 'uploaded_image_url' where it is not associated with a value
2025-06-12 00:14:08,865 - INFO - EURUSD: 新しい足 (M15) が形成されました。データ取得とシグナル判定を実行します。
2025-06-12 00:14:08,884 - INFO - EURUSD-M15 シグナル判定結果: No signal
2025-06-12 00:14:08,884 - INFO - EURUSD-M15: シグナルなし。
2025-06-12 00:14:08,884 - ERROR - EURUSD: シグナル監視ループで予期せぬエラーが発生しました: cannot access local variable 'uploaded_image_url' where it is not associated with a value
Traceback (most recent call last):
  File "C:\Users\pc\OneDrive\Desktop\phantom_alert_bot\signal_runner_loop.py", line 230, in _run
    image_url=uploaded_image_url # ImgurのURLを保存
              ^^^^^^^^^^^^^^^^^^
UnboundLocalError: cannot access local variable 'uploaded_image_url' where it is not associated with a value
2025-06-12 00:15:37,022 - INFO - EURUSD: 新しい足 (M15) が形成されました。データ取得とシグナル判定を実行します。
2025-06-12 00:15:37,056 - INFO - EURUSD-M15 シグナル判定結果: No signal
2025-06-12 00:15:37,056 - INFO - EURUSD-M15: シグナルなし。
2025-06-12 00:15:37,057 - ERROR - EURUSD: シグナル監視ループで予期せぬエラーが発生しました: cannot access local variable 'uploaded_image_url' where it is not associated with a value
Traceback (most recent call last):
  File "c:\Users\pc\OneDrive\Desktop\phantom_alert_bot\signal_runner_loop.py", line 230, in _run
UnboundLocalError: cannot access local variable 'uploaded_image_url' where it is not associated with a value
2025-06-12 00:16:21,562 - INFO - EURUSD: 新しい足 (M15) が形成されました。データ取得とシグナル判定を実行します。
2025-06-12 00:16:21,587 - INFO - EURUSD-M15 シグナル判定結果: No signal
2025-06-12 00:16:21,587 - INFO - EURUSD-M15: シグナルなし。
2025-06-12 00:16:21,587 - ERROR - EURUSD: シグナル監視ループで予期せぬエラーが発生しました: cannot access local variable 'uploaded_image_url' where it is not associated with a value
Traceback (most recent call last):
  File "C:\Users\pc\OneDrive\Desktop\phantom_alert_bot\signal_runner_loop.py", line 230, in _run
UnboundLocalError: cannot access local variable 'uploaded_image_url' where it is not associated with a value
2025-06-12 00:17:07,014 - INFO - EURUSD: 新しい足 (M15) が形成されました。データ取得とシグナル判定を実行します。
2025-06-12 00:17:07,034 - INFO - EURUSD-M15 シグナル判定結果: No signal
2025-06-12 00:17:07,035 - INFO - EURUSD-M15: シグナルなし。
2025-06-12 00:17:07,035 - ERROR - EURUSD: シグナル監視ループで予期せぬエラーが発生しました: cannot access local variable 'uploaded_image_url' where it is not associated with a value
Traceback (most recent call last):
  File "C:\Users\pc\OneDrive\Desktop\phantom_alert_bot\signal_runner_loop.py", line 230, in _run
UnboundLocalError: cannot access local variable 'uploaded_image_url' where it is not associated with a value
2025-06-12 00:17:08,886 - INFO - EURUSD: 新しい足 (M15) が形成されました。データ取得とシグナル判定を実行します。
2025-06-12 00:17:08,932 - INFO - EURUSD-M15 シグナル判定結果: No signal
2025-06-12 00:17:08,934 - INFO - EURUSD-M15: シグナルなし。
2025-06-12 00:17:08,935 - ERROR - EURUSD: シグナル監視ループで予期せぬエラーが発生しました: cannot access local variable 'uploaded_image_url' where it is not associated with a value
Traceback (most recent call last):
  File "C:\Users\pc\OneDrive\Desktop\phantom_alert_bot\signal_runner_loop.py", line 230, in _run
UnboundLocalError: cannot access local variable 'uploaded_image_url' where it is not associated with a value
2025-06-12 00:18:37,058 - INFO - EURUSD: 新しい足 (M15) が形成されました。データ取得とシグナル判定を実行します。
2025-06-12 00:18:37,081 - INFO - EURUSD-M15 シグナル判定結果: No signal
2025-06-12 00:18:37,082 - INFO - EURUSD-M15: シグナルなし。
2025-06-12 00:18:37,082 - ERROR - EURUSD: シグナル監視ループで予期せぬエラーが発生しました: cannot access local variable 'uploaded_image_url' where it is not associated with a value
Traceback (most recent call last):
  File "c:\Users\pc\OneDrive\Desktop\phantom_alert_bot\signal_runner_loop.py", line 230, in _run
UnboundLocalError: cannot access local variable 'uploaded_image_url' where it is not associated with a value
2025-06-12 00:20:07,036 - INFO - EURUSD: 新しい足 (M15) が形成されました。データ取得とシグナル判定を実行します。
2025-06-12 00:20:07,058 - INFO - EURUSD-M15 シグナル判定結果: No signal
2025-06-12 00:20:07,059 - INFO - EURUSD-M15: シグナルなし。
2025-06-12 00:20:07,059 - ERROR - EURUSD: シグナル監視ループで予期せぬエラーが発生しました: cannot access local variable 'uploaded_image_url' where it is not associated with a value
Traceback (most recent call last):
  File "C:\Users\pc\OneDrive\Desktop\phantom_alert_bot\signal_runner_loop.py", line 230, in _run
UnboundLocalError: cannot access local variable 'uploaded_image_url' where it is not associated with a value
2025-06-12 00:20:08,937 - INFO - EURUSD: 新しい足 (M15) が形成されました。データ取得とシグナル判定を実行します。
2025-06-12 00:20:08,964 - INFO - EURUSD-M15 シグナル判定結果: No signal
2025-06-12 00:20:08,964 - INFO - EURUSD-M15: シグナルなし。
2025-06-12 00:20:08,964 - ERROR - EURUSD: シグナル監視ループで予期せぬエラーが発生しました: cannot access local variable 'uploaded_image_url' where it is not associated with a value
Traceback (most recent call last):
  File "C:\Users\pc\OneDrive\Desktop\phantom_alert_bot\signal_runner_loop.py", line 230, in _run
UnboundLocalError: cannot access local variable 'uploaded_image_url' where it is not associated with a value
2025-06-12 00:21:37,084 - INFO - EURUSD: 新しい足 (M15) が形成されました。データ取得とシグナル判定を実行します。
2025-06-12 00:21:37,115 - INFO - EURUSD-M15 シグナル判定結果: No signal
2025-06-12 00:21:37,116 - INFO - EURUSD-M15: シグナルなし。
2025-06-12 00:21:37,116 - ERROR - EURUSD: シグナル監視ループで予期せぬエラーが発生しました: cannot access local variable 'uploaded_image_url' where it is not associated with a value
Traceback (most recent call last):
  File "c:\Users\pc\OneDrive\Desktop\phantom_alert_bot\signal_runner_loop.py", line 230, in _run
UnboundLocalError: cannot access local variable 'uploaded_image_url' where it is not associated with a value
2025-06-12 00:23:07,061 - INFO - EURUSD: 新しい足 (M15) が形成されました。データ取得とシグナル判定を実行します。
2025-06-12 00:23:07,112 - INFO - EURUSD-M15 シグナル判定結果: No signal
2025-06-12 00:23:07,113 - INFO - EURUSD-M15: シグナルなし。
2025-06-12 00:23:07,114 - ERROR - EURUSD: シグナル監視ループで予期せぬエラーが発生しました: cannot access local variable 'uploaded_image_url' where it is not associated with a value
Traceback (most recent call last):
  File "C:\Users\pc\OneDrive\Desktop\phantom_alert_bot\signal_runner_loop.py", line 230, in _run
UnboundLocalError: cannot access local variable 'uploaded_image_url' where it is not associated with a value
2025-06-12 00:23:08,965 - INFO - EURUSD: 新しい足 (M15) が形成されました。データ取得とシグナル判定を実行します。
2025-06-12 00:23:09,015 - INFO - EURUSD-M15 シグナル判定結果: No signal
2025-06-12 00:23:09,016 - INFO - EURUSD-M15: シグナルなし。
2025-06-12 00:23:09,017 - ERROR - EURUSD: シグナル監視ループで予期せぬエラーが発生しました: cannot access local variable 'uploaded_image_url' where it is not associated with a value
Traceback (most recent call last):
  File "C:\Users\pc\OneDrive\Desktop\phantom_alert_bot\signal_runner_loop.py", line 230, in _run
UnboundLocalError: cannot access local variable 'uploaded_image_url' where it is not associated with a value
2025-06-12 00:24:37,118 - INFO - EURUSD: 新しい足 (M15) が形成されました。データ取得とシグナル判定を実行します。
2025-06-12 00:24:37,141 - INFO - EURUSD-M15 シグナル判定結果: No signal
2025-06-12 00:24:37,142 - INFO - EURUSD-M15: シグナルなし。
2025-06-12 00:24:37,142 - ERROR - EURUSD: シグナル監視ループで予期せぬエラーが発生しました: cannot access local variable 'uploaded_image_url' where it is not associated with a value
Traceback (most recent call last):
  File "c:\Users\pc\OneDrive\Desktop\phantom_alert_bot\signal_runner_loop.py", line 230, in _run
UnboundLocalError: cannot access local variable 'uploaded_image_url' where it is not associated with a value
2025-06-12 00:26:07,115 - INFO - EURUSD: 新しい足 (M15) が形成されました。データ取得とシグナル判定を実行します。
2025-06-12 00:26:07,137 - INFO - EURUSD-M15 シグナル判定結果: No signal
2025-06-12 00:26:07,138 - INFO - EURUSD-M15: シグナルなし。
2025-06-12 00:26:07,138 - ERROR - EURUSD: シグナル監視ループで予期せぬエラーが発生しました: cannot access local variable 'uploaded_image_url' where it is not associated with a value
Traceback (most recent call last):
  File "C:\Users\pc\OneDrive\Desktop\phantom_alert_bot\signal_runner_loop.py", line 230, in _run
UnboundLocalError: cannot access local variable 'uploaded_image_url' where it is not associated with a value
2025-06-12 00:26:09,019 - INFO - EURUSD: 新しい足 (M15) が形成されました。データ取得とシグナル判定を実行します。
2025-06-12 00:26:09,051 - INFO - EURUSD-M15 シグナル判定結果: No signal
2025-06-12 00:26:09,052 - INFO - EURUSD-M15: シグナルなし。
2025-06-12 00:26:09,053 - ERROR - EURUSD: シグナル監視ループで予期せぬエラーが発生しました: cannot access local variable 'uploaded_image_url' where it is not associated with a value
Traceback (most recent call last):
  File "C:\Users\pc\OneDrive\Desktop\phantom_alert_bot\signal_runner_loop.py", line 230, in _run
UnboundLocalError: cannot access local variable 'uploaded_image_url' where it is not associated with a value
2025-06-12 00:27:37,143 - INFO - EURUSD: 新しい足 (M15) が形成されました。データ取得とシグナル判定を実行します。
2025-06-12 00:27:37,181 - INFO - EURUSD-M15 シグナル判定結果: No signal
2025-06-12 00:27:37,182 - INFO - EURUSD-M15: シグナルなし。
2025-06-12 00:27:37,184 - ERROR - EURUSD: シグナル監視ループで予期せぬエラーが発生しました: cannot access local variable 'uploaded_image_url' where it is not associated with a value
Traceback (most recent call last):
  File "c:\Users\pc\OneDrive\Desktop\phantom_alert_bot\signal_runner_loop.py", line 230, in _run
UnboundLocalError: cannot access local variable 'uploaded_image_url' where it is not associated with a value
2025-06-12 00:29:07,140 - INFO - EURUSD: 新しい足 (M15) が形成されました。データ取得とシグナル判定を実行します。
2025-06-12 00:29:07,164 - INFO - EURUSD-M15 シグナル判定結果: No signal
2025-06-12 00:29:07,164 - INFO - EURUSD-M15: シグナルなし。
2025-06-12 00:29:07,164 - ERROR - EURUSD: シグナル監視ループで予期せぬエラーが発生しました: cannot access local variable 'uploaded_image_url' where it is not associated with a value
Traceback (most recent call last):
  File "C:\Users\pc\OneDrive\Desktop\phantom_alert_bot\signal_runner_loop.py", line 230, in _run
UnboundLocalError: cannot access local variable 'uploaded_image_url' where it is not associated with a value
2025-06-12 00:29:09,054 - INFO - EURUSD: 新しい足 (M15) が形成されました。データ取得とシグナル判定を実行します。
2025-06-12 00:29:09,111 - INFO - EURUSD-M15 シグナル判定結果: No signal
2025-06-12 00:29:09,111 - INFO - EURUSD-M15: シグナルなし。
2025-06-12 00:29:09,111 - ERROR - EURUSD: シグナル監視ループで予期せぬエラーが発生しました: cannot access local variable 'uploaded_image_url' where it is not associated with a value
Traceback (most recent call last):
  File "C:\Users\pc\OneDrive\Desktop\phantom_alert_bot\signal_runner_loop.py", line 230, in _run
UnboundLocalError: cannot access local variable 'uploaded_image_url' where it is not associated with a value
2025-06-12 00:30:37,187 - INFO - EURUSD: 新しい足 (M15) が形成されました。データ取得とシグナル判定を実行します。
2025-06-12 00:30:37,213 - INFO - EURUSD-M15 シグナル判定結果: No signal
2025-06-12 00:30:37,213 - INFO - EURUSD-M15: シグナルなし。
2025-06-12 00:30:37,214 - ERROR - EURUSD: シグナル監視ループで予期せぬエラーが発生しました: cannot access local variable 'uploaded_image_url' where it is not associated with a value
Traceback (most recent call last):
  File "c:\Users\pc\OneDrive\Desktop\phantom_alert_bot\signal_runner_loop.py", line 230, in _run
UnboundLocalError: cannot access local variable 'uploaded_image_url' where it is not associated with a value
2025-06-12 00:32:07,166 - INFO - EURUSD: 新しい足 (M15) が形成されました。データ取得とシグナル判定を実行します。
2025-06-12 00:32:07,195 - INFO - EURUSD-M15 シグナル判定結果: No signal
2025-06-12 00:32:07,195 - INFO - EURUSD-M15: シグナルなし。
2025-06-12 00:32:07,197 - ERROR - EURUSD: シグナル監視ループで予期せぬエラーが発生しました: cannot access local variable 'uploaded_image_url' where it is not associated with a value
Traceback (most recent call last):
  File "C:\Users\pc\OneDrive\Desktop\phantom_alert_bot\signal_runner_loop.py", line 230, in _run
UnboundLocalError: cannot access local variable 'uploaded_image_url' where it is not associated with a value
2025-06-12 00:32:09,113 - INFO - EURUSD: 新しい足 (M15) が形成されました。データ取得とシグナル判定を実行します。
2025-06-12 00:32:09,155 - INFO - EURUSD-M15 シグナル判定結果: No signal
2025-06-12 00:32:09,158 - INFO - EURUSD-M15: シグナルなし。
2025-06-12 00:32:09,160 - ERROR - EURUSD: シグナル監視ループで予期せぬエラーが発生しました: cannot access local variable 'uploaded_image_url' where it is not associated with a value
Traceback (most recent call last):
  File "C:\Users\pc\OneDrive\Desktop\phantom_alert_bot\signal_runner_loop.py", line 230, in _run
UnboundLocalError: cannot access local variable 'uploaded_image_url' where it is not associated with a value
2025-06-12 00:33:37,215 - INFO - EURUSD: 新しい足 (M15) が形成されました。データ取得とシグナル判定を実行します。
2025-06-12 00:33:37,239 - INFO - EURUSD-M15 シグナル判定結果: No signal
2025-06-12 00:33:37,240 - INFO - EURUSD-M15: シグナルなし。
2025-06-12 00:33:37,240 - ERROR - EURUSD: シグナル監視ループで予期せぬエラーが発生しました: cannot access local variable 'uploaded_image_url' where it is not associated with a value
Traceback (most recent call last):
  File "c:\Users\pc\OneDrive\Desktop\phantom_alert_bot\signal_runner_loop.py", line 230, in _run
UnboundLocalError: cannot access local variable 'uploaded_image_url' where it is not associated with a value
2025-06-12 00:35:07,198 - INFO - EURUSD: 新しい足 (M15) が形成されました。データ取得とシグナル判定を実行します。
2025-06-12 00:35:07,225 - INFO - EURUSD-M15 シグナル判定結果: No signal
2025-06-12 00:35:07,225 - INFO - EURUSD-M15: シグナルなし。
2025-06-12 00:35:07,226 - ERROR - EURUSD: シグナル監視ループで予期せぬエラーが発生しました: cannot access local variable 'uploaded_image_url' where it is not associated with a value
Traceback (most recent call last):
  File "C:\Users\pc\OneDrive\Desktop\phantom_alert_bot\signal_runner_loop.py", line 230, in _run
UnboundLocalError: cannot access local variable 'uploaded_image_url' where it is not associated with a value
2025-06-12 00:35:09,162 - INFO - EURUSD: 新しい足 (M15) が形成されました。データ取得とシグナル判定を実行します。
2025-06-12 00:35:09,190 - INFO - EURUSD-M15 シグナル判定結果: No signal
2025-06-12 00:35:09,192 - INFO - EURUSD-M15: シグナルなし。
2025-06-12 00:35:09,192 - ERROR - EURUSD: シグナル監視ループで予期せぬエラーが発生しました: cannot access local variable 'uploaded_image_url' where it is not associated with a value
Traceback (most recent call last):
  File "C:\Users\pc\OneDrive\Desktop\phantom_alert_bot\signal_runner_loop.py", line 230, in _run
UnboundLocalError: cannot access local variable 'uploaded_image_url' where it is not associated with a value
2025-06-12 00:36:37,242 - INFO - EURUSD: 新しい足 (M15) が形成されました。データ取得とシグナル判定を実行します。
2025-06-12 00:36:37,272 - INFO - EURUSD-M15 シグナル判定結果: No signal
2025-06-12 00:36:37,272 - INFO - EURUSD-M15: シグナルなし。
2025-06-12 00:36:37,272 - ERROR - EURUSD: シグナル監視ループで予期せぬエラーが発生しました: cannot access local variable 'uploaded_image_url' where it is not associated with a value
Traceback (most recent call last):
  File "c:\Users\pc\OneDrive\Desktop\phantom_alert_bot\signal_runner_loop.py", line 230, in _run
UnboundLocalError: cannot access local variable 'uploaded_image_url' where it is not associated with a value
2025-06-12 00:38:07,227 - INFO - EURUSD: 新しい足 (M15) が形成されました。データ取得とシグナル判定を実行します。
2025-06-12 00:38:07,262 - INFO - EURUSD-M15 シグナル判定結果: No signal
2025-06-12 00:38:07,263 - INFO - EURUSD-M15: シグナルなし。
2025-06-12 00:38:07,263 - ERROR - EURUSD: シグナル監視ループで予期せぬエラーが発生しました: cannot access local variable 'uploaded_image_url' where it is not associated with a value
Traceback (most recent call last):
  File "C:\Users\pc\OneDrive\Desktop\phantom_alert_bot\signal_runner_loop.py", line 230, in _run
UnboundLocalError: cannot access local variable 'uploaded_image_url' where it is not associated with a value
2025-06-12 00:38:09,193 - INFO - EURUSD: 新しい足 (M15) が形成されました。データ取得とシグナル判定を実行します。
2025-06-12 00:38:09,259 - INFO - EURUSD-M15 シグナル判定結果: No signal
2025-06-12 00:38:09,259 - INFO - EURUSD-M15: シグナルなし。
2025-06-12 00:38:09,260 - ERROR - EURUSD: シグナル監視ループで予期せぬエラーが発生しました: cannot access local variable 'uploaded_image_url' where it is not associated with a value
Traceback (most recent call last):
  File "C:\Users\pc\OneDrive\Desktop\phantom_alert_bot\signal_runner_loop.py", line 230, in _run
UnboundLocalError: cannot access local variable 'uploaded_image_url' where it is not associated with a value
2025-06-12 00:39:37,274 - INFO - EURUSD: 新しい足 (M15) が形成されました。データ取得とシグナル判定を実行します。
2025-06-12 00:39:37,301 - INFO - EURUSD-M15 シグナル判定結果: No signal
2025-06-12 00:39:37,302 - INFO - EURUSD-M15: シグナルなし。
2025-06-12 00:39:37,302 - ERROR - EURUSD: シグナル監視ループで予期せぬエラーが発生しました: cannot access local variable 'uploaded_image_url' where it is not associated with a value
Traceback (most recent call last):
  File "c:\Users\pc\OneDrive\Desktop\phantom_alert_bot\signal_runner_loop.py", line 230, in _run
UnboundLocalError: cannot access local variable 'uploaded_image_url' where it is not associated with a value
2025-06-12 00:41:07,265 - INFO - EURUSD: 新しい足 (M15) が形成されました。データ取得とシグナル判定を実行します。
2025-06-12 00:41:07,288 - INFO - EURUSD-M15 シグナル判定結果: No signal
2025-06-12 00:41:07,288 - INFO - EURUSD-M15: シグナルなし。
2025-06-12 00:41:07,289 - ERROR - EURUSD: シグナル監視ループで予期せぬエラーが発生しました: cannot access local variable 'uploaded_image_url' where it is not associated with a value
Traceback (most recent call last):
  File "C:\Users\pc\OneDrive\Desktop\phantom_alert_bot\signal_runner_loop.py", line 230, in _run
UnboundLocalError: cannot access local variable 'uploaded_image_url' where it is not associated with a value
2025-06-12 00:41:09,262 - INFO - EURUSD: 新しい足 (M15) が形成されました。データ取得とシグナル判定を実行します。
2025-06-12 00:41:09,322 - INFO - EURUSD-M15 シグナル判定結果: No signal
2025-06-12 00:41:09,322 - INFO - EURUSD-M15: シグナルなし。
2025-06-12 00:41:09,323 - ERROR - EURUSD: シグナル監視ループで予期せぬエラーが発生しました: cannot access local variable 'uploaded_image_url' where it is not associated with a value
Traceback (most recent call last):
  File "C:\Users\pc\OneDrive\Desktop\phantom_alert_bot\signal_runner_loop.py", line 230, in _run
UnboundLocalError: cannot access local variable 'uploaded_image_url' where it is not associated with a value
2025-06-12 00:42:37,304 - INFO - EURUSD: 新しい足 (M15) が形成されました。データ取得とシグナル判定を実行します。
2025-06-12 00:42:37,355 - INFO - EURUSD-M15 シグナル判定結果: No signal
2025-06-12 00:42:37,356 - INFO - EURUSD-M15: シグナルなし。
2025-06-12 00:42:37,356 - ERROR - EURUSD: シグナル監視ループで予期せぬエラーが発生しました: cannot access local variable 'uploaded_image_url' where it is not associated with a value
Traceback (most recent call last):
  File "c:\Users\pc\OneDrive\Desktop\phantom_alert_bot\signal_runner_loop.py", line 230, in _run
UnboundLocalError: cannot access local variable 'uploaded_image_url' where it is not associated with a value
2025-06-12 00:44:07,290 - INFO - EURUSD: 新しい足 (M15) が形成されました。データ取得とシグナル判定を実行します。
2025-06-12 00:44:07,319 - INFO - EURUSD-M15 シグナル判定結果: No signal
2025-06-12 00:44:07,320 - INFO - EURUSD-M15: シグナルなし。
2025-06-12 00:44:07,320 - ERROR - EURUSD: シグナル監視ループで予期せぬエラーが発生しました: cannot access local variable 'uploaded_image_url' where it is not associated with a value
Traceback (most recent call last):
  File "C:\Users\pc\OneDrive\Desktop\phantom_alert_bot\signal_runner_loop.py", line 230, in _run
UnboundLocalError: cannot access local variable 'uploaded_image_url' where it is not associated with a value
2025-06-12 00:44:09,325 - INFO - EURUSD: 新しい足 (M15) が形成されました。データ取得とシグナル判定を実行します。
2025-06-12 00:44:09,458 - INFO - EURUSD-M15 シグナル判定結果: No signal
2025-06-12 00:44:09,463 - INFO - EURUSD-M15: シグナルなし。
2025-06-12 00:44:09,465 - ERROR - EURUSD: シグナル監視ループで予期せぬエラーが発生しました: cannot access local variable 'uploaded_image_url' where it is not associated with a value
Traceback (most recent call last):
  File "C:\Users\pc\OneDrive\Desktop\phantom_alert_bot\signal_runner_loop.py", line 230, in _run
UnboundLocalError: cannot access local variable 'uploaded_image_url' where it is not associated with a value
2025-06-12 00:45:37,357 - INFO - EURUSD: 新しい足 (M15) が形成されました。データ取得とシグナル判定を実行します。
2025-06-12 00:45:37,397 - INFO - EURUSD-M15 シグナル判定結果: No signal
2025-06-12 00:45:37,398 - INFO - EURUSD-M15: シグナルなし。
2025-06-12 00:45:37,400 - ERROR - EURUSD: シグナル監視ループで予期せぬエラーが発生しました: cannot access local variable 'uploaded_image_url' where it is not associated with a value
Traceback (most recent call last):
  File "c:\Users\pc\OneDrive\Desktop\phantom_alert_bot\signal_runner_loop.py", line 230, in _run
UnboundLocalError: cannot access local variable 'uploaded_image_url' where it is not associated with a value
2025-06-12 00:47:07,321 - INFO - EURUSD: 新しい足 (M15) が形成されました。データ取得とシグナル判定を実行します。
2025-06-12 00:47:07,555 - INFO - EURUSD-M15 シグナル判定結果: No signal
2025-06-12 00:47:07,555 - INFO - EURUSD-M15: シグナルなし。
2025-06-12 00:47:07,556 - ERROR - EURUSD: シグナル監視ループで予期せぬエラーが発生しました: cannot access local variable 'uploaded_image_url' where it is not associated with a value
Traceback (most recent call last):
  File "C:\Users\pc\OneDrive\Desktop\phantom_alert_bot\signal_runner_loop.py", line 230, in _run
UnboundLocalError: cannot access local variable 'uploaded_image_url' where it is not associated with a value
2025-06-12 00:47:09,466 - INFO - EURUSD: 新しい足 (M15) が形成されました。データ取得とシグナル判定を実行します。
2025-06-12 00:47:09,486 - INFO - EURUSD-M15 シグナル判定結果: No signal
2025-06-12 00:47:09,486 - INFO - EURUSD-M15: シグナルなし。
2025-06-12 00:47:09,487 - ERROR - EURUSD: シグナル監視ループで予期せぬエラーが発生しました: cannot access local variable 'uploaded_image_url' where it is not associated with a value
Traceback (most recent call last):
  File "C:\Users\pc\OneDrive\Desktop\phantom_alert_bot\signal_runner_loop.py", line 230, in _run
UnboundLocalError: cannot access local variable 'uploaded_image_url' where it is not associated with a value
2025-06-12 10:40:26,288 - INFO - ✅ EURUSD-M15 シグナルランナーが初期化されました。
2025-06-12 10:40:32,349 - INFO - EURUSD-M15 シグナル監視ループを開始します。
2025-06-12 10:40:32,351 - INFO - EURUSD: MT5クライアントを初期化しています...
2025-06-12 10:40:32,354 - INFO - ✅ EURUSD: MT5クライアントの初期化に成功しました。
2025-06-12 10:40:32,356 - INFO - EURUSD: 新しい足 (M15) が形成されました。データ取得とシグナル判定を実行します。
2025-06-12 10:40:32,442 - ERROR - EURUSD: シグナル監視ループで予期せぬエラーが発生しました: 'MACD_Signal'
Traceback (most recent call last):
  File "C:\Users\pc\AppData\Local\Programs\Python\Python312\Lib\site-packages\pandas\core\indexes\base.py", line 3812, in get_loc
    return self._engine.get_loc(casted_key)
           ^^^^^^^^^^^^^^^^^^^^^^^^^^^^^^^^
  File "pandas/_libs/index.pyx", line 167, in pandas._libs.index.IndexEngine.get_loc
  File "pandas/_libs/index.pyx", line 196, in pandas._libs.index.IndexEngine.get_loc
  File "pandas/_libs/hashtable_class_helper.pxi", line 7088, in pandas._libs.hashtable.PyObjectHashTable.get_item
  File "pandas/_libs/hashtable_class_helper.pxi", line 7096, in pandas._libs.hashtable.PyObjectHashTable.get_item
KeyError: 'MACD_Signal'

The above exception was the direct cause of the following exception:

Traceback (most recent call last):
  File "c:\Users\pc\OneDrive\Desktop\phantom_alert_bot\signal_runner_loop.py", line 196, in _run
    signal_info = generate_signal(df, mode="realtime", logic=DEFAULT_LOGIC) # modeとlogicを渡す
                  ^^^^^^^^^^^^^^^^^^^^^^^^^^^^^^^^^^^^^^^^^^^^^^^^^^^^^^^^^
  File "c:\Users\pc\OneDrive\Desktop\phantom_alert_bot\signal_generator.py", line 71, in generate_signal
    signal_info = _generate_balanced_signal(df_ind, current_price)
                  ^^^^^^^^^^^^^^^^^^^^^^^^^^^^^^^^^^^^^^^^^^^^^^^^
  File "c:\Users\pc\OneDrive\Desktop\phantom_alert_bot\signal_generator.py", line 192, in _generate_balanced_signal
    macd_buy = (df_ind['MACD'].iloc[-1] > df_ind['MACD_Signal'].iloc[-1]) # MACDゴールデンクロス
                                          ~~~~~~^^^^^^^^^^^^^^^
  File "C:\Users\pc\AppData\Local\Programs\Python\Python312\Lib\site-packages\pandas\core\frame.py", line 4107, in __getitem__
    indexer = self.columns.get_loc(key)
              ^^^^^^^^^^^^^^^^^^^^^^^^^
  File "C:\Users\pc\AppData\Local\Programs\Python\Python312\Lib\site-packages\pandas\core\indexes\base.py", line 3819, in get_loc
    raise KeyError(key) from err
KeyError: 'MACD_Signal'
2025-06-13 01:18:32,289 - INFO - ✅ EURUSD-M15 シグナルランナーが初期化されました。
2025-06-13 01:18:38,320 - INFO - EURUSD-M15 シグナル監視ループを開始します。
2025-06-13 01:18:38,323 - INFO - EURUSD: MT5クライアントを初期化しています...
2025-06-13 01:18:38,327 - INFO - ✅ EURUSD: MT5クライアントの初期化に成功しました。
2025-06-13 01:18:38,328 - INFO - EURUSD: 新しい足 (M15) が形成されました。データ取得とシグナル判定を実行します。
2025-06-13 01:18:38,346 - ERROR - EURUSD: シグナル監視ループで予期せぬエラーが発生しました: Cannot convert tz-naive timestamps, use tz_localize to localize
Traceback (most recent call last):
  File "C:\Users\pc\OneDrive\Desktop\phantom_alert_bot\signal_runner_loop.py", line 192, in _run
    df, latest_time_tokyo = self._get_current_ohlc()
                            ^^^^^^^^^^^^^^^^^^^^^^^^
  File "C:\Users\pc\OneDrive\Desktop\phantom_alert_bot\signal_runner_loop.py", line 116, in _get_current_ohlc
    df.index = df.index.tz_convert('Asia/Tokyo') # チャート描画時などのため
               ^^^^^^^^^^^^^^^^^^^^^^^^^^^^^^^^^
  File "C:\Users\pc\OneDrive\Desktop\phantom_alert_bot\venv\Lib\site-packages\pandas\core\indexes\datetimes.py", line 283, in tz_convert
    arr = self._data.tz_convert(tz)
          ^^^^^^^^^^^^^^^^^^^^^^^^^
  File "C:\Users\pc\OneDrive\Desktop\phantom_alert_bot\venv\Lib\site-packages\pandas\core\arrays\datetimes.py", line 917, in tz_convert
    raise TypeError(
TypeError: Cannot convert tz-naive timestamps, use tz_localize to localize
2025-06-13 01:21:38,349 - INFO - EURUSD: 新しい足 (M15) が形成されました。データ取得とシグナル判定を実行します。
2025-06-13 01:21:38,357 - ERROR - EURUSD: シグナル監視ループで予期せぬエラーが発生しました: Cannot convert tz-naive timestamps, use tz_localize to localize
Traceback (most recent call last):
  File "C:\Users\pc\OneDrive\Desktop\phantom_alert_bot\signal_runner_loop.py", line 192, in _run
    df, latest_time_tokyo = self._get_current_ohlc()
                            ^^^^^^^^^^^^^^^^^^^^^^^^
  File "C:\Users\pc\OneDrive\Desktop\phantom_alert_bot\signal_runner_loop.py", line 116, in _get_current_ohlc
    df.index = df.index.tz_convert('Asia/Tokyo') # チャート描画時などのため
               ^^^^^^^^^^^^^^^^^^^^^^^^^^^^^^^^^
  File "C:\Users\pc\OneDrive\Desktop\phantom_alert_bot\venv\Lib\site-packages\pandas\core\indexes\datetimes.py", line 283, in tz_convert
    arr = self._data.tz_convert(tz)
          ^^^^^^^^^^^^^^^^^^^^^^^^^
  File "C:\Users\pc\OneDrive\Desktop\phantom_alert_bot\venv\Lib\site-packages\pandas\core\arrays\datetimes.py", line 917, in tz_convert
    raise TypeError(
TypeError: Cannot convert tz-naive timestamps, use tz_localize to localize
2025-06-13 01:24:38,360 - INFO - EURUSD: 新しい足 (M15) が形成されました。データ取得とシグナル判定を実行します。
2025-06-13 01:24:38,369 - ERROR - EURUSD: シグナル監視ループで予期せぬエラーが発生しました: Cannot convert tz-naive timestamps, use tz_localize to localize
Traceback (most recent call last):
  File "C:\Users\pc\OneDrive\Desktop\phantom_alert_bot\signal_runner_loop.py", line 192, in _run
    df, latest_time_tokyo = self._get_current_ohlc()
                            ^^^^^^^^^^^^^^^^^^^^^^^^
  File "C:\Users\pc\OneDrive\Desktop\phantom_alert_bot\signal_runner_loop.py", line 116, in _get_current_ohlc
    df.index = df.index.tz_convert('Asia/Tokyo') # チャート描画時などのため
               ^^^^^^^^^^^^^^^^^^^^^^^^^^^^^^^^^
  File "C:\Users\pc\OneDrive\Desktop\phantom_alert_bot\venv\Lib\site-packages\pandas\core\indexes\datetimes.py", line 283, in tz_convert
    arr = self._data.tz_convert(tz)
          ^^^^^^^^^^^^^^^^^^^^^^^^^
  File "C:\Users\pc\OneDrive\Desktop\phantom_alert_bot\venv\Lib\site-packages\pandas\core\arrays\datetimes.py", line 917, in tz_convert
    raise TypeError(
TypeError: Cannot convert tz-naive timestamps, use tz_localize to localize
2025-06-13 01:27:38,372 - INFO - EURUSD: 新しい足 (M15) が形成されました。データ取得とシグナル判定を実行します。
2025-06-13 01:27:38,381 - ERROR - EURUSD: シグナル監視ループで予期せぬエラーが発生しました: Cannot convert tz-naive timestamps, use tz_localize to localize
Traceback (most recent call last):
  File "C:\Users\pc\OneDrive\Desktop\phantom_alert_bot\signal_runner_loop.py", line 192, in _run
    df, latest_time_tokyo = self._get_current_ohlc()
                            ^^^^^^^^^^^^^^^^^^^^^^^^
  File "C:\Users\pc\OneDrive\Desktop\phantom_alert_bot\signal_runner_loop.py", line 116, in _get_current_ohlc
    df.index = df.index.tz_convert('Asia/Tokyo') # チャート描画時などのため
               ^^^^^^^^^^^^^^^^^^^^^^^^^^^^^^^^^
  File "C:\Users\pc\OneDrive\Desktop\phantom_alert_bot\venv\Lib\site-packages\pandas\core\indexes\datetimes.py", line 283, in tz_convert
    arr = self._data.tz_convert(tz)
          ^^^^^^^^^^^^^^^^^^^^^^^^^
  File "C:\Users\pc\OneDrive\Desktop\phantom_alert_bot\venv\Lib\site-packages\pandas\core\arrays\datetimes.py", line 917, in tz_convert
    raise TypeError(
TypeError: Cannot convert tz-naive timestamps, use tz_localize to localize
