2025-06-11 18:43:24,094 - INFO - ✅ EURUSD-M5 シグナルランナーが初期化されました。
2025-06-11 18:43:29,136 - INFO - EURUSD-M5 シグナル監視ループを開始します。
2025-06-11 18:43:29,137 - INFO - EURUSD: MT5クライアントを初期化しています...
2025-06-11 18:43:29,138 - INFO - ✅ EURUSD: MT5クライアントの初期化に成功しました。
2025-06-11 18:43:29,139 - INFO - EURUSD: 新しい足 (M5) が形成されました。データ取得とシグナル判定を実行します。
2025-06-11 18:43:29,139 - ERROR - EURUSD: シグナル監視ループで予期せぬエラーが発生しました: module 'MetaTrader5' has no attribute 'is_connected'
Traceback (most recent call last):
  File "c:\Users\pc\OneDrive\Desktop\phantom_alert_bot\signal_runner_loop.py", line 190, in _run
    df, latest_time_tokyo = self._get_current_ohlc()
                            ~~~~~~~~~~~~~~~~~~~~~~^^
  File "c:\Users\pc\OneDrive\Desktop\phantom_alert_bot\signal_runner_loop.py", line 85, in _get_current_ohlc
    if not self._initialize_mt5():
           ~~~~~~~~~~~~~~~~~~~~^^
  File "c:\Users\pc\OneDrive\Desktop\phantom_alert_bot\signal_runner_loop.py", line 65, in _initialize_mt5
    if not self.mt5_initialized or not mt5.is_connected():
                                       ^^^^^^^^^^^^^^^^
AttributeError: module 'MetaTrader5' has no attribute 'is_connected'
2025-06-11 18:44:29,142 - INFO - EURUSD: 新しい足 (M5) が形成されました。データ取得とシグナル判定を実行します。
2025-06-11 18:44:29,144 - ERROR - EURUSD: シグナル監視ループで予期せぬエラーが発生しました: module 'MetaTrader5' has no attribute 'is_connected'
Traceback (most recent call last):
  File "c:\Users\pc\OneDrive\Desktop\phantom_alert_bot\signal_runner_loop.py", line 190, in _run
    df, latest_time_tokyo = self._get_current_ohlc()
                            ~~~~~~~~~~~~~~~~~~~~~~^^
  File "c:\Users\pc\OneDrive\Desktop\phantom_alert_bot\signal_runner_loop.py", line 85, in _get_current_ohlc
    if not self._initialize_mt5():
           ~~~~~~~~~~~~~~~~~~~~^^
  File "c:\Users\pc\OneDrive\Desktop\phantom_alert_bot\signal_runner_loop.py", line 65, in _initialize_mt5
    if not self.mt5_initialized or not mt5.is_connected():
                                       ^^^^^^^^^^^^^^^^
AttributeError: module 'MetaTrader5' has no attribute 'is_connected'
2025-06-11 18:45:29,147 - INFO - EURUSD: 新しい足 (M5) が形成されました。データ取得とシグナル判定を実行します。
2025-06-11 18:45:29,149 - ERROR - EURUSD: シグナル監視ループで予期せぬエラーが発生しました: module 'MetaTrader5' has no attribute 'is_connected'
Traceback (most recent call last):
  File "c:\Users\pc\OneDrive\Desktop\phantom_alert_bot\signal_runner_loop.py", line 190, in _run
    df, latest_time_tokyo = self._get_current_ohlc()
                            ~~~~~~~~~~~~~~~~~~~~~~^^
  File "c:\Users\pc\OneDrive\Desktop\phantom_alert_bot\signal_runner_loop.py", line 85, in _get_current_ohlc
    if not self._initialize_mt5():
           ~~~~~~~~~~~~~~~~~~~~^^
  File "c:\Users\pc\OneDrive\Desktop\phantom_alert_bot\signal_runner_loop.py", line 65, in _initialize_mt5
    if not self.mt5_initialized or not mt5.is_connected():
                                       ^^^^^^^^^^^^^^^^
AttributeError: module 'MetaTrader5' has no attribute 'is_connected'
2025-06-11 18:46:29,153 - INFO - EURUSD: 新しい足 (M5) が形成されました。データ取得とシグナル判定を実行します。
2025-06-11 18:46:29,154 - ERROR - EURUSD: シグナル監視ループで予期せぬエラーが発生しました: module 'MetaTrader5' has no attribute 'is_connected'
Traceback (most recent call last):
  File "c:\Users\pc\OneDrive\Desktop\phantom_alert_bot\signal_runner_loop.py", line 190, in _run
    df, latest_time_tokyo = self._get_current_ohlc()
                            ~~~~~~~~~~~~~~~~~~~~~~^^
  File "c:\Users\pc\OneDrive\Desktop\phantom_alert_bot\signal_runner_loop.py", line 85, in _get_current_ohlc
    if not self._initialize_mt5():
           ~~~~~~~~~~~~~~~~~~~~^^
  File "c:\Users\pc\OneDrive\Desktop\phantom_alert_bot\signal_runner_loop.py", line 65, in _initialize_mt5
    if not self.mt5_initialized or not mt5.is_connected():
                                       ^^^^^^^^^^^^^^^^
AttributeError: module 'MetaTrader5' has no attribute 'is_connected'
2025-06-11 18:47:29,156 - INFO - EURUSD: 新しい足 (M5) が形成されました。データ取得とシグナル判定を実行します。
2025-06-11 18:47:29,157 - ERROR - EURUSD: シグナル監視ループで予期せぬエラーが発生しました: module 'MetaTrader5' has no attribute 'is_connected'
Traceback (most recent call last):
  File "c:\Users\pc\OneDrive\Desktop\phantom_alert_bot\signal_runner_loop.py", line 190, in _run
    df, latest_time_tokyo = self._get_current_ohlc()
                            ~~~~~~~~~~~~~~~~~~~~~~^^
  File "c:\Users\pc\OneDrive\Desktop\phantom_alert_bot\signal_runner_loop.py", line 85, in _get_current_ohlc
    if not self._initialize_mt5():
           ~~~~~~~~~~~~~~~~~~~~^^
  File "c:\Users\pc\OneDrive\Desktop\phantom_alert_bot\signal_runner_loop.py", line 65, in _initialize_mt5
    if not self.mt5_initialized or not mt5.is_connected():
                                       ^^^^^^^^^^^^^^^^
AttributeError: module 'MetaTrader5' has no attribute 'is_connected'
2025-06-11 18:48:29,161 - INFO - EURUSD: 新しい足 (M5) が形成されました。データ取得とシグナル判定を実行します。
2025-06-11 18:48:29,163 - ERROR - EURUSD: シグナル監視ループで予期せぬエラーが発生しました: module 'MetaTrader5' has no attribute 'is_connected'
Traceback (most recent call last):
  File "c:\Users\pc\OneDrive\Desktop\phantom_alert_bot\signal_runner_loop.py", line 190, in _run
    df, latest_time_tokyo = self._get_current_ohlc()
                            ~~~~~~~~~~~~~~~~~~~~~~^^
  File "c:\Users\pc\OneDrive\Desktop\phantom_alert_bot\signal_runner_loop.py", line 85, in _get_current_ohlc
    if not self._initialize_mt5():
           ~~~~~~~~~~~~~~~~~~~~^^
  File "c:\Users\pc\OneDrive\Desktop\phantom_alert_bot\signal_runner_loop.py", line 65, in _initialize_mt5
    if not self.mt5_initialized or not mt5.is_connected():
                                       ^^^^^^^^^^^^^^^^
AttributeError: module 'MetaTrader5' has no attribute 'is_connected'
2025-06-11 18:49:29,167 - INFO - EURUSD: 新しい足 (M5) が形成されました。データ取得とシグナル判定を実行します。
2025-06-11 18:49:29,168 - ERROR - EURUSD: シグナル監視ループで予期せぬエラーが発生しました: module 'MetaTrader5' has no attribute 'is_connected'
Traceback (most recent call last):
  File "c:\Users\pc\OneDrive\Desktop\phantom_alert_bot\signal_runner_loop.py", line 190, in _run
    df, latest_time_tokyo = self._get_current_ohlc()
                            ~~~~~~~~~~~~~~~~~~~~~~^^
  File "c:\Users\pc\OneDrive\Desktop\phantom_alert_bot\signal_runner_loop.py", line 85, in _get_current_ohlc
    if not self._initialize_mt5():
           ~~~~~~~~~~~~~~~~~~~~^^
  File "c:\Users\pc\OneDrive\Desktop\phantom_alert_bot\signal_runner_loop.py", line 65, in _initialize_mt5
    if not self.mt5_initialized or not mt5.is_connected():
                                       ^^^^^^^^^^^^^^^^
AttributeError: module 'MetaTrader5' has no attribute 'is_connected'
2025-06-11 18:50:29,171 - INFO - EURUSD: 新しい足 (M5) が形成されました。データ取得とシグナル判定を実行します。
2025-06-11 18:50:29,172 - ERROR - EURUSD: シグナル監視ループで予期せぬエラーが発生しました: module 'MetaTrader5' has no attribute 'is_connected'
Traceback (most recent call last):
  File "c:\Users\pc\OneDrive\Desktop\phantom_alert_bot\signal_runner_loop.py", line 190, in _run
  File "c:\Users\pc\OneDrive\Desktop\phantom_alert_bot\signal_runner_loop.py", line 85, in _get_current_ohlc
    self.logger.info(f"✅ {self.symbol}: MT5クライアントをシャットダウンしました。")
       ^^^^^^^^^^^^^^^^^^^^^
  File "c:\Users\pc\OneDrive\Desktop\phantom_alert_bot\signal_runner_loop.py", line 65, in _initialize_mt5
    # mt5.is_connected() は最新のMetaTrader5 APIには存在しないため削除
AttributeError: module 'MetaTrader5' has no attribute 'is_connected'
2025-06-11 18:54:29,446 - INFO - ✅ EURUSD-M5 シグナルランナーが初期化されました。
2025-06-11 18:54:34,483 - INFO - EURUSD-M5 シグナル監視ループを開始します。
2025-06-11 18:54:34,485 - INFO - EURUSD: MT5クライアントを初期化しています...
2025-06-11 18:54:34,487 - INFO - ✅ EURUSD: MT5クライアントの初期化に成功しました。
2025-06-11 18:54:34,489 - INFO - EURUSD: 新しい足 (M5) が形成されました。データ取得とシグナル判定を実行します。
2025-06-11 18:54:34,542 - ERROR - EURUSD: シグナル監視ループで予期せぬエラーが発生しました: generate_signal() got an unexpected keyword argument 'logic'
Traceback (most recent call last):
  File "c:\Users\pc\OneDrive\Desktop\phantom_alert_bot\signal_runner_loop.py", line 177, in _run
    signal_info = generate_signal(df, mode="realtime", logic=DEFAULT_LOGIC) # modeとlogicを渡す
TypeError: generate_signal() got an unexpected keyword argument 'logic'
2025-06-11 18:55:34,544 - INFO - EURUSD: 新しい足 (M5) が形成されました。データ取得とシグナル判定を実行します。
2025-06-11 18:55:34,552 - ERROR - EURUSD: シグナル監視ループで予期せぬエラーが発生しました: generate_signal() got an unexpected keyword argument 'logic'
Traceback (most recent call last):
  File "c:\Users\pc\OneDrive\Desktop\phantom_alert_bot\signal_runner_loop.py", line 177, in _run
    signal_info = generate_signal(df, mode="realtime", logic=DEFAULT_LOGIC) # modeとlogicを渡す
TypeError: generate_signal() got an unexpected keyword argument 'logic'
2025-06-11 18:56:34,555 - INFO - EURUSD: 新しい足 (M5) が形成されました。データ取得とシグナル判定を実行します。
2025-06-11 18:56:34,562 - ERROR - EURUSD: シグナル監視ループで予期せぬエラーが発生しました: generate_signal() got an unexpected keyword argument 'logic'
Traceback (most recent call last):
  File "c:\Users\pc\OneDrive\Desktop\phantom_alert_bot\signal_runner_loop.py", line 177, in _run
    signal_info = generate_signal(df, mode="realtime", logic=DEFAULT_LOGIC) # modeとlogicを渡す
TypeError: generate_signal() got an unexpected keyword argument 'logic'
2025-06-11 18:57:34,566 - INFO - EURUSD: 新しい足 (M5) が形成されました。データ取得とシグナル判定を実行します。
2025-06-11 18:57:34,574 - ERROR - EURUSD: シグナル監視ループで予期せぬエラーが発生しました: generate_signal() got an unexpected keyword argument 'logic'
Traceback (most recent call last):
  File "c:\Users\pc\OneDrive\Desktop\phantom_alert_bot\signal_runner_loop.py", line 177, in _run
    signal_info = generate_signal(df, mode="realtime", logic=DEFAULT_LOGIC) # modeとlogicを渡す
TypeError: generate_signal() got an unexpected keyword argument 'logic'
2025-06-11 18:58:34,577 - INFO - EURUSD: 新しい足 (M5) が形成されました。データ取得とシグナル判定を実行します。
2025-06-11 18:58:34,579 - ERROR - EURUSD: シグナル監視ループで予期せぬエラーが発生しました: generate_signal() got an unexpected keyword argument 'logic'
Traceback (most recent call last):
  File "c:\Users\pc\OneDrive\Desktop\phantom_alert_bot\signal_runner_loop.py", line 177, in _run
    signal_info = generate_signal(df, mode="realtime", logic=DEFAULT_LOGIC) # modeとlogicを渡す
TypeError: generate_signal() got an unexpected keyword argument 'logic'
2025-06-11 18:59:34,581 - INFO - EURUSD: 新しい足 (M5) が形成されました。データ取得とシグナル判定を実行します。
2025-06-11 18:59:34,587 - ERROR - EURUSD: シグナル監視ループで予期せぬエラーが発生しました: generate_signal() got an unexpected keyword argument 'logic'
Traceback (most recent call last):
  File "c:\Users\pc\OneDrive\Desktop\phantom_alert_bot\signal_runner_loop.py", line 177, in _run
    signal_info = generate_signal(df, mode="realtime", logic=DEFAULT_LOGIC) # modeとlogicを渡す
TypeError: generate_signal() got an unexpected keyword argument 'logic'
2025-06-12 00:09:30,859 - INFO - ✅ EURUSD-M5 シグナルランナーが初期化されました。
2025-06-12 00:09:35,970 - INFO - EURUSD-M5 シグナル監視ループを開始します。
2025-06-12 00:09:35,972 - INFO - EURUSD: MT5クライアントを初期化しています...
2025-06-12 00:09:35,975 - INFO - ✅ EURUSD: MT5クライアントの初期化に成功しました。
2025-06-12 00:09:35,975 - INFO - EURUSD: 新しい足 (M5) が形成されました。データ取得とシグナル判定を実行します。
2025-06-12 00:09:36,010 - INFO - EURUSD-M5 シグナル判定結果: Balanced Sell Signal (Confluence: MACD Dead Cross, Stochastic Dead Cross)
2025-06-12 00:09:36,011 - ERROR - EURUSD: シグナル監視ループで予期せぬエラーが発生しました: 'SignalRunner' object has no attribute '_generate_chart_and_upload'
Traceback (most recent call last):
  File "c:\Users\pc\OneDrive\Desktop\phantom_alert_bot\signal_runner_loop.py", line 199, in _run
    uploaded_image_url = self._generate_chart_and_upload(df, signal_info, image_filename)
                         ^^^^^^^^^^^^^^^^^^^^^^^^^^^^^^^
AttributeError: 'SignalRunner' object has no attribute '_generate_chart_and_upload'
2025-06-12 00:10:15,479 - INFO - ✅ EURUSD-M5 シグナルランナーが初期化されました。
2025-06-12 00:10:20,508 - INFO - EURUSD-M5 シグナル監視ループを開始します。
2025-06-12 00:10:20,509 - INFO - EURUSD: MT5クライアントを初期化しています...
2025-06-12 00:10:20,512 - INFO - ✅ EURUSD: MT5クライアントの初期化に成功しました。
2025-06-12 00:10:20,512 - INFO - EURUSD: 新しい足 (M5) が形成されました。データ取得とシグナル判定を実行します。
2025-06-12 00:10:20,546 - INFO - EURUSD-M5 シグナル判定結果: Balanced Sell Signal (Confluence: MACD Dead Cross, Stochastic Dead Cross)
2025-06-12 00:10:20,548 - ERROR - EURUSD: シグナル監視ループで予期せぬエラーが発生しました: 'SignalRunner' object has no attribute '_generate_chart_and_upload'
Traceback (most recent call last):
  File "C:\Users\pc\OneDrive\Desktop\phantom_alert_bot\signal_runner_loop.py", line 199, in _run
    uploaded_image_url = self._generate_chart_and_upload(df, signal_info, image_filename)
                         ^^^^^^^^^^^^^^^^^^^^^^^^^^^^^^^
AttributeError: 'SignalRunner' object has no attribute '_generate_chart_and_upload'
2025-06-12 00:10:36,012 - INFO - EURUSD: 新しい足 (M5) が形成されました。データ取得とシグナル判定を実行します。
2025-06-12 00:10:36,043 - INFO - EURUSD-M5 シグナル判定結果: Balanced Sell Signal (Confluence: MACD Dead Cross, Stochastic Dead Cross)
2025-06-12 00:10:36,045 - ERROR - EURUSD: シグナル監視ループで予期せぬエラーが発生しました: 'SignalRunner' object has no attribute '_generate_chart_and_upload'
Traceback (most recent call last):
  File "c:\Users\pc\OneDrive\Desktop\phantom_alert_bot\signal_runner_loop.py", line 199, in _run
    uploaded_image_url = self._generate_chart_and_upload(df, signal_info, image_filename)
                         ^^^^^^^^^^^^^^^^^^^^^^^^^^^^^^^
AttributeError: 'SignalRunner' object has no attribute '_generate_chart_and_upload'
2025-06-12 00:11:00,887 - INFO - ✅ EURUSD-M5 シグナルランナーが初期化されました。
2025-06-12 00:11:02,785 - INFO - ✅ EURUSD-M5 シグナルランナーが初期化されました。
2025-06-12 00:11:05,912 - INFO - EURUSD-M5 シグナル監視ループを開始します。
2025-06-12 00:11:05,914 - INFO - EURUSD: MT5クライアントを初期化しています...
2025-06-12 00:11:05,916 - INFO - ✅ EURUSD: MT5クライアントの初期化に成功しました。
2025-06-12 00:11:05,916 - INFO - EURUSD: 新しい足 (M5) が形成されました。データ取得とシグナル判定を実行します。
2025-06-12 00:11:05,960 - INFO - EURUSD-M5 シグナル判定結果: Balanced Sell Signal (Confluence: MACD Dead Cross, Stochastic Dead Cross)
2025-06-12 00:11:05,961 - ERROR - EURUSD: シグナル監視ループで予期せぬエラーが発生しました: 'SignalRunner' object has no attribute '_generate_chart_and_upload'
Traceback (most recent call last):
  File "C:\Users\pc\OneDrive\Desktop\phantom_alert_bot\signal_runner_loop.py", line 199, in _run
    uploaded_image_url = self._generate_chart_and_upload(df, signal_info, image_filename)
                         ^^^^^^^^^^^^^^^^^^^^^^^^^^^^^^^
AttributeError: 'SignalRunner' object has no attribute '_generate_chart_and_upload'
2025-06-12 00:11:07,808 - INFO - EURUSD-M5 シグナル監視ループを開始します。
2025-06-12 00:11:07,809 - INFO - EURUSD: MT5クライアントを初期化しています...
2025-06-12 00:11:07,810 - INFO - ✅ EURUSD: MT5クライアントの初期化に成功しました。
2025-06-12 00:11:07,810 - INFO - EURUSD: 新しい足 (M5) が形成されました。データ取得とシグナル判定を実行します。
2025-06-12 00:11:07,850 - INFO - EURUSD-M5 シグナル判定結果: Balanced Sell Signal (Confluence: MACD Dead Cross, Stochastic Dead Cross)
2025-06-12 00:11:07,851 - ERROR - EURUSD: シグナル監視ループで予期せぬエラーが発生しました: 'SignalRunner' object has no attribute '_generate_chart_and_upload'
Traceback (most recent call last):
  File "C:\Users\pc\OneDrive\Desktop\phantom_alert_bot\signal_runner_loop.py", line 199, in _run
    uploaded_image_url = self._generate_chart_and_upload(df, signal_info, image_filename)
                         ^^^^^^^^^^^^^^^^^^^^^^^^^^^^^^^
AttributeError: 'SignalRunner' object has no attribute '_generate_chart_and_upload'
2025-06-12 00:11:20,549 - INFO - EURUSD: 新しい足 (M5) が形成されました。データ取得とシグナル判定を実行します。
2025-06-12 00:11:20,576 - INFO - EURUSD-M5 シグナル判定結果: Balanced Sell Signal (Confluence: MACD Dead Cross, Stochastic Dead Cross)
2025-06-12 00:11:20,576 - ERROR - EURUSD: シグナル監視ループで予期せぬエラーが発生しました: 'SignalRunner' object has no attribute '_generate_chart_and_upload'
Traceback (most recent call last):
  File "C:\Users\pc\OneDrive\Desktop\phantom_alert_bot\signal_runner_loop.py", line 199, in _run
    uploaded_image_url = self._generate_chart_and_upload(df, signal_info, image_filename)
                         ^^^^^^^^^^^^^^^^^^^^^^^^^^^^^^^
AttributeError: 'SignalRunner' object has no attribute '_generate_chart_and_upload'
2025-06-12 00:11:36,047 - INFO - EURUSD: 新しい足 (M5) が形成されました。データ取得とシグナル判定を実行します。
2025-06-12 00:11:36,072 - INFO - EURUSD-M5 シグナル判定結果: Balanced Sell Signal (Confluence: MACD Dead Cross, Stochastic Dead Cross)
2025-06-12 00:11:36,072 - ERROR - EURUSD: シグナル監視ループで予期せぬエラーが発生しました: 'SignalRunner' object has no attribute '_generate_chart_and_upload'
Traceback (most recent call last):
  File "c:\Users\pc\OneDrive\Desktop\phantom_alert_bot\signal_runner_loop.py", line 199, in _run
    uploaded_image_url = self._generate_chart_and_upload(df, signal_info, image_filename)
                         ^^^^^^^^^^^^^^^^^^^^^^^^^^^^^^^
AttributeError: 'SignalRunner' object has no attribute '_generate_chart_and_upload'
2025-06-12 00:12:05,962 - INFO - EURUSD: 新しい足 (M5) が形成されました。データ取得とシグナル判定を実行します。
2025-06-12 00:12:06,006 - INFO - EURUSD-M5 シグナル判定結果: Balanced Sell Signal (Confluence: MACD Dead Cross, Stochastic Dead Cross)
2025-06-12 00:12:06,007 - ERROR - EURUSD: シグナル監視ループで予期せぬエラーが発生しました: 'SignalRunner' object has no attribute '_generate_chart_and_upload'
Traceback (most recent call last):
  File "C:\Users\pc\OneDrive\Desktop\phantom_alert_bot\signal_runner_loop.py", line 199, in _run
    uploaded_image_url = self._generate_chart_and_upload(df, signal_info, image_filename)
                         ^^^^^^^^^^^^^^^^^^^^^^^^^^^^^^^
AttributeError: 'SignalRunner' object has no attribute '_generate_chart_and_upload'
2025-06-12 00:12:07,853 - INFO - EURUSD: 新しい足 (M5) が形成されました。データ取得とシグナル判定を実行します。
2025-06-12 00:12:07,897 - INFO - EURUSD-M5 シグナル判定結果: Balanced Sell Signal (Confluence: MACD Dead Cross, Stochastic Dead Cross)
2025-06-12 00:12:07,897 - ERROR - EURUSD: シグナル監視ループで予期せぬエラーが発生しました: 'SignalRunner' object has no attribute '_generate_chart_and_upload'
Traceback (most recent call last):
  File "C:\Users\pc\OneDrive\Desktop\phantom_alert_bot\signal_runner_loop.py", line 199, in _run
    uploaded_image_url = self._generate_chart_and_upload(df, signal_info, image_filename)
                         ^^^^^^^^^^^^^^^^^^^^^^^^^^^^^^^
AttributeError: 'SignalRunner' object has no attribute '_generate_chart_and_upload'
2025-06-12 00:12:20,578 - INFO - EURUSD: 新しい足 (M5) が形成されました。データ取得とシグナル判定を実行します。
2025-06-12 00:12:20,642 - INFO - EURUSD-M5 シグナル判定結果: Balanced Sell Signal (Confluence: MACD Dead Cross, Stochastic Dead Cross)
2025-06-12 00:12:20,643 - ERROR - EURUSD: シグナル監視ループで予期せぬエラーが発生しました: 'SignalRunner' object has no attribute '_generate_chart_and_upload'
Traceback (most recent call last):
  File "C:\Users\pc\OneDrive\Desktop\phantom_alert_bot\signal_runner_loop.py", line 199, in _run
    uploaded_image_url = self._generate_chart_and_upload(df, signal_info, image_filename)
                         ^^^^^^^^^^^^^^^^^^^^^^^^^^^^^^^
AttributeError: 'SignalRunner' object has no attribute '_generate_chart_and_upload'
2025-06-12 00:12:36,073 - INFO - EURUSD: 新しい足 (M5) が形成されました。データ取得とシグナル判定を実行します。
2025-06-12 00:12:36,094 - INFO - EURUSD-M5 シグナル判定結果: Balanced Sell Signal (Confluence: MACD Dead Cross, Stochastic Dead Cross)
2025-06-12 00:12:36,094 - ERROR - EURUSD: シグナル監視ループで予期せぬエラーが発生しました: 'SignalRunner' object has no attribute '_generate_chart_and_upload'
Traceback (most recent call last):
  File "c:\Users\pc\OneDrive\Desktop\phantom_alert_bot\signal_runner_loop.py", line 199, in _run
    uploaded_image_url = self._generate_chart_and_upload(df, signal_info, image_filename)
                         ^^^^^^^^^^^^^^^^^^^^^^^^^^^^^^^
AttributeError: 'SignalRunner' object has no attribute '_generate_chart_and_upload'
2025-06-12 00:13:06,009 - INFO - EURUSD: 新しい足 (M5) が形成されました。データ取得とシグナル判定を実行します。
2025-06-12 00:13:06,033 - INFO - EURUSD-M5 シグナル判定結果: Balanced Sell Signal (Confluence: MACD Dead Cross, Stochastic Dead Cross)
2025-06-12 00:13:06,033 - ERROR - EURUSD: シグナル監視ループで予期せぬエラーが発生しました: 'SignalRunner' object has no attribute '_generate_chart_and_upload'
Traceback (most recent call last):
  File "C:\Users\pc\OneDrive\Desktop\phantom_alert_bot\signal_runner_loop.py", line 199, in _run
    uploaded_image_url = self._generate_chart_and_upload(df, signal_info, image_filename)
                         ^^^^^^^^^^^^^^^^^^^^^^^^^^^^^^^
AttributeError: 'SignalRunner' object has no attribute '_generate_chart_and_upload'
2025-06-12 00:13:07,899 - INFO - EURUSD: 新しい足 (M5) が形成されました。データ取得とシグナル判定を実行します。
2025-06-12 00:13:07,921 - INFO - EURUSD-M5 シグナル判定結果: Balanced Sell Signal (Confluence: MACD Dead Cross, Stochastic Dead Cross)
2025-06-12 00:13:07,921 - ERROR - EURUSD: シグナル監視ループで予期せぬエラーが発生しました: 'SignalRunner' object has no attribute '_generate_chart_and_upload'
Traceback (most recent call last):
  File "C:\Users\pc\OneDrive\Desktop\phantom_alert_bot\signal_runner_loop.py", line 199, in _run
    uploaded_image_url = self._generate_chart_and_upload(df, signal_info, image_filename)
                         ^^^^^^^^^^^^^^^^^^^^^^^^^^^^^^^
AttributeError: 'SignalRunner' object has no attribute '_generate_chart_and_upload'
2025-06-12 00:13:20,644 - INFO - EURUSD: 新しい足 (M5) が形成されました。データ取得とシグナル判定を実行します。
2025-06-12 00:13:20,693 - INFO - EURUSD-M5 シグナル判定結果: Balanced Sell Signal (Confluence: MACD Dead Cross, Stochastic Dead Cross)
2025-06-12 00:13:20,693 - ERROR - EURUSD: シグナル監視ループで予期せぬエラーが発生しました: 'SignalRunner' object has no attribute '_generate_chart_and_upload'
Traceback (most recent call last):
  File "C:\Users\pc\OneDrive\Desktop\phantom_alert_bot\signal_runner_loop.py", line 199, in _run
    uploaded_image_url = self._generate_chart_and_upload(df, signal_info, image_filename)
                         ^^^^^^^^^^^^^^^^^^^^^^^^^^^^^^^
AttributeError: 'SignalRunner' object has no attribute '_generate_chart_and_upload'
2025-06-12 00:13:36,096 - INFO - EURUSD: 新しい足 (M5) が形成されました。データ取得とシグナル判定を実行します。
2025-06-12 00:13:36,115 - INFO - EURUSD-M5 シグナル判定結果: Balanced Sell Signal (Confluence: MACD Dead Cross, Stochastic Dead Cross)
2025-06-12 00:13:36,116 - ERROR - EURUSD: シグナル監視ループで予期せぬエラーが発生しました: 'SignalRunner' object has no attribute '_generate_chart_and_upload'
Traceback (most recent call last):
  File "c:\Users\pc\OneDrive\Desktop\phantom_alert_bot\signal_runner_loop.py", line 199, in _run
    uploaded_image_url = self._generate_chart_and_upload(df, signal_info, image_filename)
                         ^^^^^^^^^^^^^^^^^^^^^^^^^^^^^^^
AttributeError: 'SignalRunner' object has no attribute '_generate_chart_and_upload'
2025-06-12 00:14:06,035 - INFO - EURUSD: 新しい足 (M5) が形成されました。データ取得とシグナル判定を実行します。
2025-06-12 00:14:06,056 - INFO - EURUSD-M5 シグナル判定結果: Balanced Sell Signal (Confluence: MACD Dead Cross, Stochastic Dead Cross)
2025-06-12 00:14:06,056 - ERROR - EURUSD: シグナル監視ループで予期せぬエラーが発生しました: 'SignalRunner' object has no attribute '_generate_chart_and_upload'
Traceback (most recent call last):
  File "C:\Users\pc\OneDrive\Desktop\phantom_alert_bot\signal_runner_loop.py", line 199, in _run
    uploaded_image_url = self._generate_chart_and_upload(df, signal_info, image_filename)
                         ^^^^^^^^^^^^^^^^^^^^^^^^^^^^^^^
AttributeError: 'SignalRunner' object has no attribute '_generate_chart_and_upload'
2025-06-12 00:14:07,922 - INFO - EURUSD: 新しい足 (M5) が形成されました。データ取得とシグナル判定を実行します。
2025-06-12 00:14:07,944 - INFO - EURUSD-M5 シグナル判定結果: Balanced Sell Signal (Confluence: MACD Dead Cross, Stochastic Dead Cross)
2025-06-12 00:14:07,944 - ERROR - EURUSD: シグナル監視ループで予期せぬエラーが発生しました: 'SignalRunner' object has no attribute '_generate_chart_and_upload'
Traceback (most recent call last):
  File "C:\Users\pc\OneDrive\Desktop\phantom_alert_bot\signal_runner_loop.py", line 199, in _run
    uploaded_image_url = self._generate_chart_and_upload(df, signal_info, image_filename)
                         ^^^^^^^^^^^^^^^^^^^^^^^^^^^^^^^
AttributeError: 'SignalRunner' object has no attribute '_generate_chart_and_upload'
2025-06-12 00:14:20,696 - INFO - EURUSD: 新しい足 (M5) が形成されました。データ取得とシグナル判定を実行します。
2025-06-12 00:14:20,728 - INFO - EURUSD-M5 シグナル判定結果: Balanced Sell Signal (Confluence: MACD Dead Cross, Stochastic Dead Cross)
2025-06-12 00:14:20,728 - ERROR - EURUSD: シグナル監視ループで予期せぬエラーが発生しました: 'SignalRunner' object has no attribute '_generate_chart_and_upload'
Traceback (most recent call last):
  File "C:\Users\pc\OneDrive\Desktop\phantom_alert_bot\signal_runner_loop.py", line 199, in _run
    uploaded_image_url = self._generate_chart_and_upload(df, signal_info, image_filename)
                         ^^^^^^^^^^^^^^^^^^^^^^^^^^^^^^^
AttributeError: 'SignalRunner' object has no attribute '_generate_chart_and_upload'
2025-06-12 00:14:36,117 - INFO - EURUSD: 新しい足 (M5) が形成されました。データ取得とシグナル判定を実行します。
2025-06-12 00:14:36,137 - INFO - EURUSD-M5 シグナル判定結果: Balanced Sell Signal (Confluence: MACD Dead Cross, Stochastic Dead Cross)
2025-06-12 00:14:36,138 - ERROR - EURUSD: シグナル監視ループで予期せぬエラーが発生しました: 'SignalRunner' object has no attribute '_generate_chart_and_upload'
Traceback (most recent call last):
  File "c:\Users\pc\OneDrive\Desktop\phantom_alert_bot\signal_runner_loop.py", line 199, in _run
    uploaded_image_url = self._generate_chart_and_upload(df, signal_info, image_filename)
                         ^^^^^^^^^^^^^^^^^^^^^^^^^^^^^^^
AttributeError: 'SignalRunner' object has no attribute '_generate_chart_and_upload'
2025-06-12 00:15:06,057 - INFO - EURUSD: 新しい足 (M5) が形成されました。データ取得とシグナル判定を実行します。
2025-06-12 00:15:06,080 - INFO - EURUSD-M5 シグナル判定結果: No signal
2025-06-12 00:15:06,081 - INFO - EURUSD-M5: シグナルなし。
2025-06-12 00:15:06,081 - ERROR - EURUSD: シグナル監視ループで予期せぬエラーが発生しました: cannot access local variable 'uploaded_image_url' where it is not associated with a value
Traceback (most recent call last):
  File "C:\Users\pc\OneDrive\Desktop\phantom_alert_bot\signal_runner_loop.py", line 230, in _run
    image_url=uploaded_image_url # ImgurのURLを保存
              ^^^^^^^^^^^^^^^^^^
UnboundLocalError: cannot access local variable 'uploaded_image_url' where it is not associated with a value
2025-06-12 00:15:07,945 - INFO - EURUSD: 新しい足 (M5) が形成されました。データ取得とシグナル判定を実行します。
2025-06-12 00:15:07,978 - INFO - EURUSD-M5 シグナル判定結果: No signal
2025-06-12 00:15:07,979 - INFO - EURUSD-M5: シグナルなし。
2025-06-12 00:15:07,979 - ERROR - EURUSD: シグナル監視ループで予期せぬエラーが発生しました: cannot access local variable 'uploaded_image_url' where it is not associated with a value
Traceback (most recent call last):
  File "C:\Users\pc\OneDrive\Desktop\phantom_alert_bot\signal_runner_loop.py", line 230, in _run
    image_url=uploaded_image_url # ImgurのURLを保存
              ^^^^^^^^^^^^^^^^^^
UnboundLocalError: cannot access local variable 'uploaded_image_url' where it is not associated with a value
2025-06-12 00:15:20,730 - INFO - EURUSD: 新しい足 (M5) が形成されました。データ取得とシグナル判定を実行します。
2025-06-12 00:15:20,760 - INFO - EURUSD-M5 シグナル判定結果: No signal
2025-06-12 00:15:20,760 - INFO - EURUSD-M5: シグナルなし。
2025-06-12 00:15:20,760 - ERROR - EURUSD: シグナル監視ループで予期せぬエラーが発生しました: cannot access local variable 'uploaded_image_url' where it is not associated with a value
Traceback (most recent call last):
  File "C:\Users\pc\OneDrive\Desktop\phantom_alert_bot\signal_runner_loop.py", line 230, in _run
UnboundLocalError: cannot access local variable 'uploaded_image_url' where it is not associated with a value
2025-06-12 00:15:36,139 - INFO - EURUSD: 新しい足 (M5) が形成されました。データ取得とシグナル判定を実行します。
2025-06-12 00:15:36,160 - INFO - EURUSD-M5 シグナル判定結果: No signal
2025-06-12 00:15:36,161 - INFO - EURUSD-M5: シグナルなし。
2025-06-12 00:15:36,161 - ERROR - EURUSD: シグナル監視ループで予期せぬエラーが発生しました: cannot access local variable 'uploaded_image_url' where it is not associated with a value
Traceback (most recent call last):
  File "c:\Users\pc\OneDrive\Desktop\phantom_alert_bot\signal_runner_loop.py", line 230, in _run
UnboundLocalError: cannot access local variable 'uploaded_image_url' where it is not associated with a value
2025-06-12 00:16:06,082 - INFO - EURUSD: 新しい足 (M5) が形成されました。データ取得とシグナル判定を実行します。
2025-06-12 00:16:06,105 - INFO - EURUSD-M5 シグナル判定結果: No signal
2025-06-12 00:16:06,105 - INFO - EURUSD-M5: シグナルなし。
2025-06-12 00:16:06,105 - ERROR - EURUSD: シグナル監視ループで予期せぬエラーが発生しました: cannot access local variable 'uploaded_image_url' where it is not associated with a value
Traceback (most recent call last):
  File "C:\Users\pc\OneDrive\Desktop\phantom_alert_bot\signal_runner_loop.py", line 230, in _run
UnboundLocalError: cannot access local variable 'uploaded_image_url' where it is not associated with a value
2025-06-12 00:16:07,980 - INFO - EURUSD: 新しい足 (M5) が形成されました。データ取得とシグナル判定を実行します。
2025-06-12 00:16:08,022 - INFO - EURUSD-M5 シグナル判定結果: No signal
2025-06-12 00:16:08,022 - INFO - EURUSD-M5: シグナルなし。
2025-06-12 00:16:08,024 - ERROR - EURUSD: シグナル監視ループで予期せぬエラーが発生しました: cannot access local variable 'uploaded_image_url' where it is not associated with a value
Traceback (most recent call last):
  File "C:\Users\pc\OneDrive\Desktop\phantom_alert_bot\signal_runner_loop.py", line 230, in _run
UnboundLocalError: cannot access local variable 'uploaded_image_url' where it is not associated with a value
2025-06-12 00:16:20,762 - INFO - EURUSD: 新しい足 (M5) が形成されました。データ取得とシグナル判定を実行します。
2025-06-12 00:16:20,787 - INFO - EURUSD-M5 シグナル判定結果: No signal
2025-06-12 00:16:20,787 - INFO - EURUSD-M5: シグナルなし。
2025-06-12 00:16:20,788 - ERROR - EURUSD: シグナル監視ループで予期せぬエラーが発生しました: cannot access local variable 'uploaded_image_url' where it is not associated with a value
Traceback (most recent call last):
  File "C:\Users\pc\OneDrive\Desktop\phantom_alert_bot\signal_runner_loop.py", line 230, in _run
UnboundLocalError: cannot access local variable 'uploaded_image_url' where it is not associated with a value
2025-06-12 00:16:36,163 - INFO - EURUSD: 新しい足 (M5) が形成されました。データ取得とシグナル判定を実行します。
2025-06-12 00:16:36,187 - INFO - EURUSD-M5 シグナル判定結果: No signal
2025-06-12 00:16:36,187 - INFO - EURUSD-M5: シグナルなし。
2025-06-12 00:16:36,188 - ERROR - EURUSD: シグナル監視ループで予期せぬエラーが発生しました: cannot access local variable 'uploaded_image_url' where it is not associated with a value
Traceback (most recent call last):
  File "c:\Users\pc\OneDrive\Desktop\phantom_alert_bot\signal_runner_loop.py", line 230, in _run
UnboundLocalError: cannot access local variable 'uploaded_image_url' where it is not associated with a value
2025-06-12 00:17:06,107 - INFO - EURUSD: 新しい足 (M5) が形成されました。データ取得とシグナル判定を実行します。
2025-06-12 00:17:06,137 - INFO - EURUSD-M5 シグナル判定結果: No signal
2025-06-12 00:17:06,140 - INFO - EURUSD-M5: シグナルなし。
2025-06-12 00:17:06,146 - ERROR - EURUSD: シグナル監視ループで予期せぬエラーが発生しました: cannot access local variable 'uploaded_image_url' where it is not associated with a value
Traceback (most recent call last):
  File "C:\Users\pc\OneDrive\Desktop\phantom_alert_bot\signal_runner_loop.py", line 230, in _run
UnboundLocalError: cannot access local variable 'uploaded_image_url' where it is not associated with a value
2025-06-12 00:17:08,028 - INFO - EURUSD: 新しい足 (M5) が形成されました。データ取得とシグナル判定を実行します。
2025-06-12 00:17:08,068 - INFO - EURUSD-M5 シグナル判定結果: No signal
2025-06-12 00:17:08,069 - INFO - EURUSD-M5: シグナルなし。
2025-06-12 00:17:08,069 - ERROR - EURUSD: シグナル監視ループで予期せぬエラーが発生しました: cannot access local variable 'uploaded_image_url' where it is not associated with a value
Traceback (most recent call last):
  File "C:\Users\pc\OneDrive\Desktop\phantom_alert_bot\signal_runner_loop.py", line 230, in _run
UnboundLocalError: cannot access local variable 'uploaded_image_url' where it is not associated with a value
2025-06-12 00:17:20,792 - INFO - EURUSD: 新しい足 (M5) が形成されました。データ取得とシグナル判定を実行します。
2025-06-12 00:17:20,834 - INFO - EURUSD-M5 シグナル判定結果: No signal
2025-06-12 00:17:20,835 - INFO - EURUSD-M5: シグナルなし。
2025-06-12 00:17:20,835 - ERROR - EURUSD: シグナル監視ループで予期せぬエラーが発生しました: cannot access local variable 'uploaded_image_url' where it is not associated with a value
Traceback (most recent call last):
  File "C:\Users\pc\OneDrive\Desktop\phantom_alert_bot\signal_runner_loop.py", line 230, in _run
UnboundLocalError: cannot access local variable 'uploaded_image_url' where it is not associated with a value
2025-06-12 00:17:36,189 - INFO - EURUSD: 新しい足 (M5) が形成されました。データ取得とシグナル判定を実行します。
2025-06-12 00:17:36,211 - INFO - EURUSD-M5 シグナル判定結果: No signal
2025-06-12 00:17:36,211 - INFO - EURUSD-M5: シグナルなし。
2025-06-12 00:17:36,211 - ERROR - EURUSD: シグナル監視ループで予期せぬエラーが発生しました: cannot access local variable 'uploaded_image_url' where it is not associated with a value
Traceback (most recent call last):
  File "c:\Users\pc\OneDrive\Desktop\phantom_alert_bot\signal_runner_loop.py", line 230, in _run
UnboundLocalError: cannot access local variable 'uploaded_image_url' where it is not associated with a value
2025-06-12 00:18:06,151 - INFO - EURUSD: 新しい足 (M5) が形成されました。データ取得とシグナル判定を実行します。
2025-06-12 00:18:06,173 - INFO - EURUSD-M5 シグナル判定結果: No signal
2025-06-12 00:18:06,173 - INFO - EURUSD-M5: シグナルなし。
2025-06-12 00:18:06,173 - ERROR - EURUSD: シグナル監視ループで予期せぬエラーが発生しました: cannot access local variable 'uploaded_image_url' where it is not associated with a value
Traceback (most recent call last):
  File "C:\Users\pc\OneDrive\Desktop\phantom_alert_bot\signal_runner_loop.py", line 230, in _run
UnboundLocalError: cannot access local variable 'uploaded_image_url' where it is not associated with a value
2025-06-12 00:18:08,070 - INFO - EURUSD: 新しい足 (M5) が形成されました。データ取得とシグナル判定を実行します。
2025-06-12 00:18:08,118 - INFO - EURUSD-M5 シグナル判定結果: No signal
2025-06-12 00:18:08,118 - INFO - EURUSD-M5: シグナルなし。
2025-06-12 00:18:08,119 - ERROR - EURUSD: シグナル監視ループで予期せぬエラーが発生しました: cannot access local variable 'uploaded_image_url' where it is not associated with a value
Traceback (most recent call last):
  File "C:\Users\pc\OneDrive\Desktop\phantom_alert_bot\signal_runner_loop.py", line 230, in _run
UnboundLocalError: cannot access local variable 'uploaded_image_url' where it is not associated with a value
2025-06-12 00:18:20,837 - INFO - EURUSD: 新しい足 (M5) が形成されました。データ取得とシグナル判定を実行します。
2025-06-12 00:18:20,893 - INFO - EURUSD-M5 シグナル判定結果: No signal
2025-06-12 00:18:20,893 - INFO - EURUSD-M5: シグナルなし。
2025-06-12 00:18:20,894 - ERROR - EURUSD: シグナル監視ループで予期せぬエラーが発生しました: cannot access local variable 'uploaded_image_url' where it is not associated with a value
Traceback (most recent call last):
  File "C:\Users\pc\OneDrive\Desktop\phantom_alert_bot\signal_runner_loop.py", line 230, in _run
UnboundLocalError: cannot access local variable 'uploaded_image_url' where it is not associated with a value
2025-06-12 00:18:36,212 - INFO - EURUSD: 新しい足 (M5) が形成されました。データ取得とシグナル判定を実行します。
2025-06-12 00:18:36,235 - INFO - EURUSD-M5 シグナル判定結果: No signal
2025-06-12 00:18:36,236 - INFO - EURUSD-M5: シグナルなし。
2025-06-12 00:18:36,237 - ERROR - EURUSD: シグナル監視ループで予期せぬエラーが発生しました: cannot access local variable 'uploaded_image_url' where it is not associated with a value
Traceback (most recent call last):
  File "c:\Users\pc\OneDrive\Desktop\phantom_alert_bot\signal_runner_loop.py", line 230, in _run
UnboundLocalError: cannot access local variable 'uploaded_image_url' where it is not associated with a value
2025-06-12 00:19:06,174 - INFO - EURUSD: 新しい足 (M5) が形成されました。データ取得とシグナル判定を実行します。
2025-06-12 00:19:06,199 - INFO - EURUSD-M5 シグナル判定結果: No signal
2025-06-12 00:19:06,199 - INFO - EURUSD-M5: シグナルなし。
2025-06-12 00:19:06,199 - ERROR - EURUSD: シグナル監視ループで予期せぬエラーが発生しました: cannot access local variable 'uploaded_image_url' where it is not associated with a value
Traceback (most recent call last):
  File "C:\Users\pc\OneDrive\Desktop\phantom_alert_bot\signal_runner_loop.py", line 230, in _run
UnboundLocalError: cannot access local variable 'uploaded_image_url' where it is not associated with a value
2025-06-12 00:19:08,120 - INFO - EURUSD: 新しい足 (M5) が形成されました。データ取得とシグナル判定を実行します。
2025-06-12 00:19:08,148 - INFO - EURUSD-M5 シグナル判定結果: No signal
2025-06-12 00:19:08,149 - INFO - EURUSD-M5: シグナルなし。
2025-06-12 00:19:08,151 - ERROR - EURUSD: シグナル監視ループで予期せぬエラーが発生しました: cannot access local variable 'uploaded_image_url' where it is not associated with a value
Traceback (most recent call last):
  File "C:\Users\pc\OneDrive\Desktop\phantom_alert_bot\signal_runner_loop.py", line 230, in _run
UnboundLocalError: cannot access local variable 'uploaded_image_url' where it is not associated with a value
2025-06-12 00:19:36,239 - INFO - EURUSD: 新しい足 (M5) が形成されました。データ取得とシグナル判定を実行します。
2025-06-12 00:19:36,259 - INFO - EURUSD-M5 シグナル判定結果: No signal
2025-06-12 00:19:36,260 - INFO - EURUSD-M5: シグナルなし。
2025-06-12 00:19:36,261 - ERROR - EURUSD: シグナル監視ループで予期せぬエラーが発生しました: cannot access local variable 'uploaded_image_url' where it is not associated with a value
Traceback (most recent call last):
  File "c:\Users\pc\OneDrive\Desktop\phantom_alert_bot\signal_runner_loop.py", line 230, in _run
UnboundLocalError: cannot access local variable 'uploaded_image_url' where it is not associated with a value
2025-06-12 00:20:06,201 - INFO - EURUSD: 新しい足 (M5) が形成されました。データ取得とシグナル判定を実行します。
2025-06-12 00:20:06,224 - INFO - EURUSD-M5 シグナル判定結果: No signal
2025-06-12 00:20:06,224 - INFO - EURUSD-M5: シグナルなし。
2025-06-12 00:20:06,225 - ERROR - EURUSD: シグナル監視ループで予期せぬエラーが発生しました: cannot access local variable 'uploaded_image_url' where it is not associated with a value
Traceback (most recent call last):
  File "C:\Users\pc\OneDrive\Desktop\phantom_alert_bot\signal_runner_loop.py", line 230, in _run
UnboundLocalError: cannot access local variable 'uploaded_image_url' where it is not associated with a value
2025-06-12 00:20:08,152 - INFO - EURUSD: 新しい足 (M5) が形成されました。データ取得とシグナル判定を実行します。
2025-06-12 00:20:08,173 - INFO - EURUSD-M5 シグナル判定結果: No signal
2025-06-12 00:20:08,173 - INFO - EURUSD-M5: シグナルなし。
2025-06-12 00:20:08,174 - ERROR - EURUSD: シグナル監視ループで予期せぬエラーが発生しました: cannot access local variable 'uploaded_image_url' where it is not associated with a value
Traceback (most recent call last):
  File "C:\Users\pc\OneDrive\Desktop\phantom_alert_bot\signal_runner_loop.py", line 230, in _run
UnboundLocalError: cannot access local variable 'uploaded_image_url' where it is not associated with a value
2025-06-12 00:20:36,262 - INFO - EURUSD: 新しい足 (M5) が形成されました。データ取得とシグナル判定を実行します。
2025-06-12 00:20:36,286 - INFO - EURUSD-M5 シグナル判定結果: No signal
2025-06-12 00:20:36,287 - INFO - EURUSD-M5: シグナルなし。
2025-06-12 00:20:36,287 - ERROR - EURUSD: シグナル監視ループで予期せぬエラーが発生しました: cannot access local variable 'uploaded_image_url' where it is not associated with a value
Traceback (most recent call last):
  File "c:\Users\pc\OneDrive\Desktop\phantom_alert_bot\signal_runner_loop.py", line 230, in _run
UnboundLocalError: cannot access local variable 'uploaded_image_url' where it is not associated with a value
2025-06-12 00:21:06,226 - INFO - EURUSD: 新しい足 (M5) が形成されました。データ取得とシグナル判定を実行します。
2025-06-12 00:21:06,247 - INFO - EURUSD-M5 シグナル判定結果: No signal
2025-06-12 00:21:06,249 - INFO - EURUSD-M5: シグナルなし。
2025-06-12 00:21:06,249 - ERROR - EURUSD: シグナル監視ループで予期せぬエラーが発生しました: cannot access local variable 'uploaded_image_url' where it is not associated with a value
Traceback (most recent call last):
  File "C:\Users\pc\OneDrive\Desktop\phantom_alert_bot\signal_runner_loop.py", line 230, in _run
UnboundLocalError: cannot access local variable 'uploaded_image_url' where it is not associated with a value
2025-06-12 00:21:08,175 - INFO - EURUSD: 新しい足 (M5) が形成されました。データ取得とシグナル判定を実行します。
2025-06-12 00:21:08,225 - INFO - EURUSD-M5 シグナル判定結果: No signal
2025-06-12 00:21:08,226 - INFO - EURUSD-M5: シグナルなし。
2025-06-12 00:21:08,227 - ERROR - EURUSD: シグナル監視ループで予期せぬエラーが発生しました: cannot access local variable 'uploaded_image_url' where it is not associated with a value
Traceback (most recent call last):
  File "C:\Users\pc\OneDrive\Desktop\phantom_alert_bot\signal_runner_loop.py", line 230, in _run
UnboundLocalError: cannot access local variable 'uploaded_image_url' where it is not associated with a value
2025-06-12 00:21:36,289 - INFO - EURUSD: 新しい足 (M5) が形成されました。データ取得とシグナル判定を実行します。
2025-06-12 00:21:36,313 - INFO - EURUSD-M5 シグナル判定結果: No signal
2025-06-12 00:21:36,314 - INFO - EURUSD-M5: シグナルなし。
2025-06-12 00:21:36,314 - ERROR - EURUSD: シグナル監視ループで予期せぬエラーが発生しました: cannot access local variable 'uploaded_image_url' where it is not associated with a value
Traceback (most recent call last):
  File "c:\Users\pc\OneDrive\Desktop\phantom_alert_bot\signal_runner_loop.py", line 230, in _run
UnboundLocalError: cannot access local variable 'uploaded_image_url' where it is not associated with a value
2025-06-12 00:22:06,250 - INFO - EURUSD: 新しい足 (M5) が形成されました。データ取得とシグナル判定を実行します。
2025-06-12 00:22:06,283 - INFO - EURUSD-M5 シグナル判定結果: No signal
2025-06-12 00:22:06,284 - INFO - EURUSD-M5: シグナルなし。
2025-06-12 00:22:06,284 - ERROR - EURUSD: シグナル監視ループで予期せぬエラーが発生しました: cannot access local variable 'uploaded_image_url' where it is not associated with a value
Traceback (most recent call last):
  File "C:\Users\pc\OneDrive\Desktop\phantom_alert_bot\signal_runner_loop.py", line 230, in _run
UnboundLocalError: cannot access local variable 'uploaded_image_url' where it is not associated with a value
2025-06-12 00:22:08,229 - INFO - EURUSD: 新しい足 (M5) が形成されました。データ取得とシグナル判定を実行します。
2025-06-12 00:22:08,277 - INFO - EURUSD-M5 シグナル判定結果: No signal
2025-06-12 00:22:08,279 - INFO - EURUSD-M5: シグナルなし。
2025-06-12 00:22:08,280 - ERROR - EURUSD: シグナル監視ループで予期せぬエラーが発生しました: cannot access local variable 'uploaded_image_url' where it is not associated with a value
Traceback (most recent call last):
  File "C:\Users\pc\OneDrive\Desktop\phantom_alert_bot\signal_runner_loop.py", line 230, in _run
UnboundLocalError: cannot access local variable 'uploaded_image_url' where it is not associated with a value
2025-06-12 00:22:36,316 - INFO - EURUSD: 新しい足 (M5) が形成されました。データ取得とシグナル判定を実行します。
2025-06-12 00:22:36,345 - INFO - EURUSD-M5 シグナル判定結果: No signal
2025-06-12 00:22:36,345 - INFO - EURUSD-M5: シグナルなし。
2025-06-12 00:22:36,346 - ERROR - EURUSD: シグナル監視ループで予期せぬエラーが発生しました: cannot access local variable 'uploaded_image_url' where it is not associated with a value
Traceback (most recent call last):
  File "c:\Users\pc\OneDrive\Desktop\phantom_alert_bot\signal_runner_loop.py", line 230, in _run
UnboundLocalError: cannot access local variable 'uploaded_image_url' where it is not associated with a value
2025-06-12 00:23:06,285 - INFO - EURUSD: 新しい足 (M5) が形成されました。データ取得とシグナル判定を実行します。
2025-06-12 00:23:06,307 - INFO - EURUSD-M5 シグナル判定結果: No signal
2025-06-12 00:23:06,308 - INFO - EURUSD-M5: シグナルなし。
2025-06-12 00:23:06,308 - ERROR - EURUSD: シグナル監視ループで予期せぬエラーが発生しました: cannot access local variable 'uploaded_image_url' where it is not associated with a value
Traceback (most recent call last):
  File "C:\Users\pc\OneDrive\Desktop\phantom_alert_bot\signal_runner_loop.py", line 230, in _run
UnboundLocalError: cannot access local variable 'uploaded_image_url' where it is not associated with a value
2025-06-12 00:23:08,282 - INFO - EURUSD: 新しい足 (M5) が形成されました。データ取得とシグナル判定を実行します。
2025-06-12 00:23:08,329 - INFO - EURUSD-M5 シグナル判定結果: No signal
2025-06-12 00:23:08,330 - INFO - EURUSD-M5: シグナルなし。
2025-06-12 00:23:08,331 - ERROR - EURUSD: シグナル監視ループで予期せぬエラーが発生しました: cannot access local variable 'uploaded_image_url' where it is not associated with a value
Traceback (most recent call last):
  File "C:\Users\pc\OneDrive\Desktop\phantom_alert_bot\signal_runner_loop.py", line 230, in _run
UnboundLocalError: cannot access local variable 'uploaded_image_url' where it is not associated with a value
2025-06-12 00:23:36,347 - INFO - EURUSD: 新しい足 (M5) が形成されました。データ取得とシグナル判定を実行します。
2025-06-12 00:23:36,367 - INFO - EURUSD-M5 シグナル判定結果: No signal
2025-06-12 00:23:36,368 - INFO - EURUSD-M5: シグナルなし。
2025-06-12 00:23:36,369 - ERROR - EURUSD: シグナル監視ループで予期せぬエラーが発生しました: cannot access local variable 'uploaded_image_url' where it is not associated with a value
Traceback (most recent call last):
  File "c:\Users\pc\OneDrive\Desktop\phantom_alert_bot\signal_runner_loop.py", line 230, in _run
UnboundLocalError: cannot access local variable 'uploaded_image_url' where it is not associated with a value
2025-06-12 00:24:06,310 - INFO - EURUSD: 新しい足 (M5) が形成されました。データ取得とシグナル判定を実行します。
2025-06-12 00:24:06,404 - INFO - EURUSD-M5 シグナル判定結果: No signal
2025-06-12 00:24:06,404 - INFO - EURUSD-M5: シグナルなし。
2025-06-12 00:24:06,405 - ERROR - EURUSD: シグナル監視ループで予期せぬエラーが発生しました: cannot access local variable 'uploaded_image_url' where it is not associated with a value
Traceback (most recent call last):
  File "C:\Users\pc\OneDrive\Desktop\phantom_alert_bot\signal_runner_loop.py", line 230, in _run
UnboundLocalError: cannot access local variable 'uploaded_image_url' where it is not associated with a value
2025-06-12 00:24:08,333 - INFO - EURUSD: 新しい足 (M5) が形成されました。データ取得とシグナル判定を実行します。
2025-06-12 00:24:08,354 - INFO - EURUSD-M5 シグナル判定結果: No signal
2025-06-12 00:24:08,355 - INFO - EURUSD-M5: シグナルなし。
2025-06-12 00:24:08,355 - ERROR - EURUSD: シグナル監視ループで予期せぬエラーが発生しました: cannot access local variable 'uploaded_image_url' where it is not associated with a value
Traceback (most recent call last):
  File "C:\Users\pc\OneDrive\Desktop\phantom_alert_bot\signal_runner_loop.py", line 230, in _run
UnboundLocalError: cannot access local variable 'uploaded_image_url' where it is not associated with a value
2025-06-12 00:24:36,370 - INFO - EURUSD: 新しい足 (M5) が形成されました。データ取得とシグナル判定を実行します。
2025-06-12 00:24:36,391 - INFO - EURUSD-M5 シグナル判定結果: No signal
2025-06-12 00:24:36,391 - INFO - EURUSD-M5: シグナルなし。
2025-06-12 00:24:36,391 - ERROR - EURUSD: シグナル監視ループで予期せぬエラーが発生しました: cannot access local variable 'uploaded_image_url' where it is not associated with a value
Traceback (most recent call last):
  File "c:\Users\pc\OneDrive\Desktop\phantom_alert_bot\signal_runner_loop.py", line 230, in _run
UnboundLocalError: cannot access local variable 'uploaded_image_url' where it is not associated with a value
2025-06-12 00:25:06,406 - INFO - EURUSD: 新しい足 (M5) が形成されました。データ取得とシグナル判定を実行します。
2025-06-12 00:25:06,433 - INFO - EURUSD-M5 シグナル判定結果: No signal
2025-06-12 00:25:06,433 - INFO - EURUSD-M5: シグナルなし。
2025-06-12 00:25:06,434 - ERROR - EURUSD: シグナル監視ループで予期せぬエラーが発生しました: cannot access local variable 'uploaded_image_url' where it is not associated with a value
Traceback (most recent call last):
  File "C:\Users\pc\OneDrive\Desktop\phantom_alert_bot\signal_runner_loop.py", line 230, in _run
UnboundLocalError: cannot access local variable 'uploaded_image_url' where it is not associated with a value
2025-06-12 00:25:08,357 - INFO - EURUSD: 新しい足 (M5) が形成されました。データ取得とシグナル判定を実行します。
2025-06-12 00:25:08,383 - INFO - EURUSD-M5 シグナル判定結果: No signal
2025-06-12 00:25:08,384 - INFO - EURUSD-M5: シグナルなし。
2025-06-12 00:25:08,384 - ERROR - EURUSD: シグナル監視ループで予期せぬエラーが発生しました: cannot access local variable 'uploaded_image_url' where it is not associated with a value
Traceback (most recent call last):
  File "C:\Users\pc\OneDrive\Desktop\phantom_alert_bot\signal_runner_loop.py", line 230, in _run
UnboundLocalError: cannot access local variable 'uploaded_image_url' where it is not associated with a value
2025-06-12 00:25:36,392 - INFO - EURUSD: 新しい足 (M5) が形成されました。データ取得とシグナル判定を実行します。
2025-06-12 00:25:36,426 - INFO - EURUSD-M5 シグナル判定結果: No signal
2025-06-12 00:25:36,426 - INFO - EURUSD-M5: シグナルなし。
2025-06-12 00:25:36,426 - ERROR - EURUSD: シグナル監視ループで予期せぬエラーが発生しました: cannot access local variable 'uploaded_image_url' where it is not associated with a value
Traceback (most recent call last):
  File "c:\Users\pc\OneDrive\Desktop\phantom_alert_bot\signal_runner_loop.py", line 230, in _run
UnboundLocalError: cannot access local variable 'uploaded_image_url' where it is not associated with a value
2025-06-12 00:26:06,436 - INFO - EURUSD: 新しい足 (M5) が形成されました。データ取得とシグナル判定を実行します。
2025-06-12 00:26:06,458 - INFO - EURUSD-M5 シグナル判定結果: No signal
2025-06-12 00:26:06,458 - INFO - EURUSD-M5: シグナルなし。
2025-06-12 00:26:06,458 - ERROR - EURUSD: シグナル監視ループで予期せぬエラーが発生しました: cannot access local variable 'uploaded_image_url' where it is not associated with a value
Traceback (most recent call last):
  File "C:\Users\pc\OneDrive\Desktop\phantom_alert_bot\signal_runner_loop.py", line 230, in _run
UnboundLocalError: cannot access local variable 'uploaded_image_url' where it is not associated with a value
2025-06-12 00:26:08,386 - INFO - EURUSD: 新しい足 (M5) が形成されました。データ取得とシグナル判定を実行します。
2025-06-12 00:26:08,412 - INFO - EURUSD-M5 シグナル判定結果: No signal
2025-06-12 00:26:08,412 - INFO - EURUSD-M5: シグナルなし。
2025-06-12 00:26:08,412 - ERROR - EURUSD: シグナル監視ループで予期せぬエラーが発生しました: cannot access local variable 'uploaded_image_url' where it is not associated with a value
Traceback (most recent call last):
  File "C:\Users\pc\OneDrive\Desktop\phantom_alert_bot\signal_runner_loop.py", line 230, in _run
UnboundLocalError: cannot access local variable 'uploaded_image_url' where it is not associated with a value
2025-06-12 00:26:36,428 - INFO - EURUSD: 新しい足 (M5) が形成されました。データ取得とシグナル判定を実行します。
2025-06-12 00:26:36,449 - INFO - EURUSD-M5 シグナル判定結果: No signal
2025-06-12 00:26:36,450 - INFO - EURUSD-M5: シグナルなし。
2025-06-12 00:26:36,450 - ERROR - EURUSD: シグナル監視ループで予期せぬエラーが発生しました: cannot access local variable 'uploaded_image_url' where it is not associated with a value
Traceback (most recent call last):
  File "c:\Users\pc\OneDrive\Desktop\phantom_alert_bot\signal_runner_loop.py", line 230, in _run
UnboundLocalError: cannot access local variable 'uploaded_image_url' where it is not associated with a value
2025-06-12 00:27:06,460 - INFO - EURUSD: 新しい足 (M5) が形成されました。データ取得とシグナル判定を実行します。
2025-06-12 00:27:06,484 - INFO - EURUSD-M5 シグナル判定結果: No signal
2025-06-12 00:27:06,485 - INFO - EURUSD-M5: シグナルなし。
2025-06-12 00:27:06,485 - ERROR - EURUSD: シグナル監視ループで予期せぬエラーが発生しました: cannot access local variable 'uploaded_image_url' where it is not associated with a value
Traceback (most recent call last):
  File "C:\Users\pc\OneDrive\Desktop\phantom_alert_bot\signal_runner_loop.py", line 230, in _run
UnboundLocalError: cannot access local variable 'uploaded_image_url' where it is not associated with a value
2025-06-12 00:27:08,415 - INFO - EURUSD: 新しい足 (M5) が形成されました。データ取得とシグナル判定を実行します。
2025-06-12 00:27:08,502 - INFO - EURUSD-M5 シグナル判定結果: No signal
2025-06-12 00:27:08,521 - INFO - EURUSD-M5: シグナルなし。
2025-06-12 00:27:08,530 - ERROR - EURUSD: シグナル監視ループで予期せぬエラーが発生しました: cannot access local variable 'uploaded_image_url' where it is not associated with a value
Traceback (most recent call last):
  File "C:\Users\pc\OneDrive\Desktop\phantom_alert_bot\signal_runner_loop.py", line 230, in _run
UnboundLocalError: cannot access local variable 'uploaded_image_url' where it is not associated with a value
2025-06-12 00:27:36,451 - INFO - EURUSD: 新しい足 (M5) が形成されました。データ取得とシグナル判定を実行します。
2025-06-12 00:27:36,472 - INFO - EURUSD-M5 シグナル判定結果: No signal
2025-06-12 00:27:36,472 - INFO - EURUSD-M5: シグナルなし。
2025-06-12 00:27:36,473 - ERROR - EURUSD: シグナル監視ループで予期せぬエラーが発生しました: cannot access local variable 'uploaded_image_url' where it is not associated with a value
Traceback (most recent call last):
  File "c:\Users\pc\OneDrive\Desktop\phantom_alert_bot\signal_runner_loop.py", line 230, in _run
UnboundLocalError: cannot access local variable 'uploaded_image_url' where it is not associated with a value
2025-06-12 00:28:06,487 - INFO - EURUSD: 新しい足 (M5) が形成されました。データ取得とシグナル判定を実行します。
2025-06-12 00:28:06,508 - INFO - EURUSD-M5 シグナル判定結果: No signal
2025-06-12 00:28:06,508 - INFO - EURUSD-M5: シグナルなし。
2025-06-12 00:28:06,509 - ERROR - EURUSD: シグナル監視ループで予期せぬエラーが発生しました: cannot access local variable 'uploaded_image_url' where it is not associated with a value
Traceback (most recent call last):
  File "C:\Users\pc\OneDrive\Desktop\phantom_alert_bot\signal_runner_loop.py", line 230, in _run
UnboundLocalError: cannot access local variable 'uploaded_image_url' where it is not associated with a value
2025-06-12 00:28:08,538 - INFO - EURUSD: 新しい足 (M5) が形成されました。データ取得とシグナル判定を実行します。
2025-06-12 00:28:08,564 - INFO - EURUSD-M5 シグナル判定結果: No signal
2025-06-12 00:28:08,564 - INFO - EURUSD-M5: シグナルなし。
2025-06-12 00:28:08,565 - ERROR - EURUSD: シグナル監視ループで予期せぬエラーが発生しました: cannot access local variable 'uploaded_image_url' where it is not associated with a value
Traceback (most recent call last):
  File "C:\Users\pc\OneDrive\Desktop\phantom_alert_bot\signal_runner_loop.py", line 230, in _run
UnboundLocalError: cannot access local variable 'uploaded_image_url' where it is not associated with a value
2025-06-12 00:28:36,475 - INFO - EURUSD: 新しい足 (M5) が形成されました。データ取得とシグナル判定を実行します。
2025-06-12 00:28:36,508 - INFO - EURUSD-M5 シグナル判定結果: No signal
2025-06-12 00:28:36,508 - INFO - EURUSD-M5: シグナルなし。
2025-06-12 00:28:36,509 - ERROR - EURUSD: シグナル監視ループで予期せぬエラーが発生しました: cannot access local variable 'uploaded_image_url' where it is not associated with a value
Traceback (most recent call last):
  File "c:\Users\pc\OneDrive\Desktop\phantom_alert_bot\signal_runner_loop.py", line 230, in _run
UnboundLocalError: cannot access local variable 'uploaded_image_url' where it is not associated with a value
2025-06-12 00:29:06,511 - INFO - EURUSD: 新しい足 (M5) が形成されました。データ取得とシグナル判定を実行します。
2025-06-12 00:29:06,533 - INFO - EURUSD-M5 シグナル判定結果: No signal
2025-06-12 00:29:06,534 - INFO - EURUSD-M5: シグナルなし。
2025-06-12 00:29:06,534 - ERROR - EURUSD: シグナル監視ループで予期せぬエラーが発生しました: cannot access local variable 'uploaded_image_url' where it is not associated with a value
Traceback (most recent call last):
  File "C:\Users\pc\OneDrive\Desktop\phantom_alert_bot\signal_runner_loop.py", line 230, in _run
UnboundLocalError: cannot access local variable 'uploaded_image_url' where it is not associated with a value
2025-06-12 00:29:08,566 - INFO - EURUSD: 新しい足 (M5) が形成されました。データ取得とシグナル判定を実行します。
2025-06-12 00:29:08,591 - INFO - EURUSD-M5 シグナル判定結果: No signal
2025-06-12 00:29:08,591 - INFO - EURUSD-M5: シグナルなし。
2025-06-12 00:29:08,591 - ERROR - EURUSD: シグナル監視ループで予期せぬエラーが発生しました: cannot access local variable 'uploaded_image_url' where it is not associated with a value
Traceback (most recent call last):
  File "C:\Users\pc\OneDrive\Desktop\phantom_alert_bot\signal_runner_loop.py", line 230, in _run
UnboundLocalError: cannot access local variable 'uploaded_image_url' where it is not associated with a value
2025-06-12 00:29:36,510 - INFO - EURUSD: 新しい足 (M5) が形成されました。データ取得とシグナル判定を実行します。
2025-06-12 00:29:36,535 - INFO - EURUSD-M5 シグナル判定結果: No signal
2025-06-12 00:29:36,536 - INFO - EURUSD-M5: シグナルなし。
2025-06-12 00:29:36,536 - ERROR - EURUSD: シグナル監視ループで予期せぬエラーが発生しました: cannot access local variable 'uploaded_image_url' where it is not associated with a value
Traceback (most recent call last):
  File "c:\Users\pc\OneDrive\Desktop\phantom_alert_bot\signal_runner_loop.py", line 230, in _run
UnboundLocalError: cannot access local variable 'uploaded_image_url' where it is not associated with a value
2025-06-12 00:30:06,538 - INFO - EURUSD: 新しい足 (M5) が形成されました。データ取得とシグナル判定を実行します。
2025-06-12 00:30:06,558 - INFO - EURUSD-M5 シグナル判定結果: No signal
2025-06-12 00:30:06,559 - INFO - EURUSD-M5: シグナルなし。
2025-06-12 00:30:06,559 - ERROR - EURUSD: シグナル監視ループで予期せぬエラーが発生しました: cannot access local variable 'uploaded_image_url' where it is not associated with a value
Traceback (most recent call last):
  File "C:\Users\pc\OneDrive\Desktop\phantom_alert_bot\signal_runner_loop.py", line 230, in _run
UnboundLocalError: cannot access local variable 'uploaded_image_url' where it is not associated with a value
2025-06-12 00:30:08,593 - INFO - EURUSD: 新しい足 (M5) が形成されました。データ取得とシグナル判定を実行します。
2025-06-12 00:30:08,659 - INFO - EURUSD-M5 シグナル判定結果: No signal
2025-06-12 00:30:08,660 - INFO - EURUSD-M5: シグナルなし。
2025-06-12 00:30:08,661 - ERROR - EURUSD: シグナル監視ループで予期せぬエラーが発生しました: cannot access local variable 'uploaded_image_url' where it is not associated with a value
Traceback (most recent call last):
  File "C:\Users\pc\OneDrive\Desktop\phantom_alert_bot\signal_runner_loop.py", line 230, in _run
UnboundLocalError: cannot access local variable 'uploaded_image_url' where it is not associated with a value
2025-06-12 00:30:36,537 - INFO - EURUSD: 新しい足 (M5) が形成されました。データ取得とシグナル判定を実行します。
2025-06-12 00:30:36,568 - INFO - EURUSD-M5 シグナル判定結果: No signal
2025-06-12 00:30:36,569 - INFO - EURUSD-M5: シグナルなし。
2025-06-12 00:30:36,569 - ERROR - EURUSD: シグナル監視ループで予期せぬエラーが発生しました: cannot access local variable 'uploaded_image_url' where it is not associated with a value
Traceback (most recent call last):
  File "c:\Users\pc\OneDrive\Desktop\phantom_alert_bot\signal_runner_loop.py", line 230, in _run
UnboundLocalError: cannot access local variable 'uploaded_image_url' where it is not associated with a value
2025-06-12 00:31:06,561 - INFO - EURUSD: 新しい足 (M5) が形成されました。データ取得とシグナル判定を実行します。
2025-06-12 00:31:06,583 - INFO - EURUSD-M5 シグナル判定結果: No signal
2025-06-12 00:31:06,584 - INFO - EURUSD-M5: シグナルなし。
2025-06-12 00:31:06,584 - ERROR - EURUSD: シグナル監視ループで予期せぬエラーが発生しました: cannot access local variable 'uploaded_image_url' where it is not associated with a value
Traceback (most recent call last):
  File "C:\Users\pc\OneDrive\Desktop\phantom_alert_bot\signal_runner_loop.py", line 230, in _run
UnboundLocalError: cannot access local variable 'uploaded_image_url' where it is not associated with a value
2025-06-12 00:31:08,662 - INFO - EURUSD: 新しい足 (M5) が形成されました。データ取得とシグナル判定を実行します。
2025-06-12 00:31:08,725 - INFO - EURUSD-M5 シグナル判定結果: No signal
2025-06-12 00:31:08,726 - INFO - EURUSD-M5: シグナルなし。
2025-06-12 00:31:08,726 - ERROR - EURUSD: シグナル監視ループで予期せぬエラーが発生しました: cannot access local variable 'uploaded_image_url' where it is not associated with a value
Traceback (most recent call last):
  File "C:\Users\pc\OneDrive\Desktop\phantom_alert_bot\signal_runner_loop.py", line 230, in _run
UnboundLocalError: cannot access local variable 'uploaded_image_url' where it is not associated with a value
2025-06-12 00:31:36,571 - INFO - EURUSD: 新しい足 (M5) が形成されました。データ取得とシグナル判定を実行します。
2025-06-12 00:31:36,591 - INFO - EURUSD-M5 シグナル判定結果: No signal
2025-06-12 00:31:36,591 - INFO - EURUSD-M5: シグナルなし。
2025-06-12 00:31:36,592 - ERROR - EURUSD: シグナル監視ループで予期せぬエラーが発生しました: cannot access local variable 'uploaded_image_url' where it is not associated with a value
Traceback (most recent call last):
  File "c:\Users\pc\OneDrive\Desktop\phantom_alert_bot\signal_runner_loop.py", line 230, in _run
UnboundLocalError: cannot access local variable 'uploaded_image_url' where it is not associated with a value
2025-06-12 00:32:06,585 - INFO - EURUSD: 新しい足 (M5) が形成されました。データ取得とシグナル判定を実行します。
2025-06-12 00:32:06,614 - INFO - EURUSD-M5 シグナル判定結果: No signal
2025-06-12 00:32:06,615 - INFO - EURUSD-M5: シグナルなし。
2025-06-12 00:32:06,615 - ERROR - EURUSD: シグナル監視ループで予期せぬエラーが発生しました: cannot access local variable 'uploaded_image_url' where it is not associated with a value
Traceback (most recent call last):
  File "C:\Users\pc\OneDrive\Desktop\phantom_alert_bot\signal_runner_loop.py", line 230, in _run
UnboundLocalError: cannot access local variable 'uploaded_image_url' where it is not associated with a value
2025-06-12 00:32:08,728 - INFO - EURUSD: 新しい足 (M5) が形成されました。データ取得とシグナル判定を実行します。
2025-06-12 00:32:08,749 - INFO - EURUSD-M5 シグナル判定結果: No signal
2025-06-12 00:32:08,749 - INFO - EURUSD-M5: シグナルなし。
2025-06-12 00:32:08,750 - ERROR - EURUSD: シグナル監視ループで予期せぬエラーが発生しました: cannot access local variable 'uploaded_image_url' where it is not associated with a value
Traceback (most recent call last):
  File "C:\Users\pc\OneDrive\Desktop\phantom_alert_bot\signal_runner_loop.py", line 230, in _run
UnboundLocalError: cannot access local variable 'uploaded_image_url' where it is not associated with a value
2025-06-12 00:32:36,593 - INFO - EURUSD: 新しい足 (M5) が形成されました。データ取得とシグナル判定を実行します。
2025-06-12 00:32:36,613 - INFO - EURUSD-M5 シグナル判定結果: No signal
2025-06-12 00:32:36,614 - INFO - EURUSD-M5: シグナルなし。
2025-06-12 00:32:36,615 - ERROR - EURUSD: シグナル監視ループで予期せぬエラーが発生しました: cannot access local variable 'uploaded_image_url' where it is not associated with a value
Traceback (most recent call last):
  File "c:\Users\pc\OneDrive\Desktop\phantom_alert_bot\signal_runner_loop.py", line 230, in _run
UnboundLocalError: cannot access local variable 'uploaded_image_url' where it is not associated with a value
2025-06-12 00:33:06,616 - INFO - EURUSD: 新しい足 (M5) が形成されました。データ取得とシグナル判定を実行します。
2025-06-12 00:33:06,651 - INFO - EURUSD-M5 シグナル判定結果: No signal
2025-06-12 00:33:06,652 - INFO - EURUSD-M5: シグナルなし。
2025-06-12 00:33:06,652 - ERROR - EURUSD: シグナル監視ループで予期せぬエラーが発生しました: cannot access local variable 'uploaded_image_url' where it is not associated with a value
Traceback (most recent call last):
  File "C:\Users\pc\OneDrive\Desktop\phantom_alert_bot\signal_runner_loop.py", line 230, in _run
UnboundLocalError: cannot access local variable 'uploaded_image_url' where it is not associated with a value
2025-06-12 00:33:08,751 - INFO - EURUSD: 新しい足 (M5) が形成されました。データ取得とシグナル判定を実行します。
2025-06-12 00:33:08,801 - INFO - EURUSD-M5 シグナル判定結果: No signal
2025-06-12 00:33:08,801 - INFO - EURUSD-M5: シグナルなし。
2025-06-12 00:33:08,802 - ERROR - EURUSD: シグナル監視ループで予期せぬエラーが発生しました: cannot access local variable 'uploaded_image_url' where it is not associated with a value
Traceback (most recent call last):
  File "C:\Users\pc\OneDrive\Desktop\phantom_alert_bot\signal_runner_loop.py", line 230, in _run
UnboundLocalError: cannot access local variable 'uploaded_image_url' where it is not associated with a value
2025-06-12 00:33:36,617 - INFO - EURUSD: 新しい足 (M5) が形成されました。データ取得とシグナル判定を実行します。
2025-06-12 00:33:36,639 - INFO - EURUSD-M5 シグナル判定結果: No signal
2025-06-12 00:33:36,640 - INFO - EURUSD-M5: シグナルなし。
2025-06-12 00:33:36,640 - ERROR - EURUSD: シグナル監視ループで予期せぬエラーが発生しました: cannot access local variable 'uploaded_image_url' where it is not associated with a value
Traceback (most recent call last):
  File "c:\Users\pc\OneDrive\Desktop\phantom_alert_bot\signal_runner_loop.py", line 230, in _run
UnboundLocalError: cannot access local variable 'uploaded_image_url' where it is not associated with a value
2025-06-12 00:34:06,653 - INFO - EURUSD: 新しい足 (M5) が形成されました。データ取得とシグナル判定を実行します。
2025-06-12 00:34:06,682 - INFO - EURUSD-M5 シグナル判定結果: No signal
2025-06-12 00:34:06,684 - INFO - EURUSD-M5: シグナルなし。
2025-06-12 00:34:06,684 - ERROR - EURUSD: シグナル監視ループで予期せぬエラーが発生しました: cannot access local variable 'uploaded_image_url' where it is not associated with a value
Traceback (most recent call last):
  File "C:\Users\pc\OneDrive\Desktop\phantom_alert_bot\signal_runner_loop.py", line 230, in _run
UnboundLocalError: cannot access local variable 'uploaded_image_url' where it is not associated with a value
2025-06-12 00:34:08,804 - INFO - EURUSD: 新しい足 (M5) が形成されました。データ取得とシグナル判定を実行します。
2025-06-12 00:34:08,825 - INFO - EURUSD-M5 シグナル判定結果: No signal
2025-06-12 00:34:08,827 - INFO - EURUSD-M5: シグナルなし。
2025-06-12 00:34:08,827 - ERROR - EURUSD: シグナル監視ループで予期せぬエラーが発生しました: cannot access local variable 'uploaded_image_url' where it is not associated with a value
Traceback (most recent call last):
  File "C:\Users\pc\OneDrive\Desktop\phantom_alert_bot\signal_runner_loop.py", line 230, in _run
UnboundLocalError: cannot access local variable 'uploaded_image_url' where it is not associated with a value
2025-06-12 00:34:36,641 - INFO - EURUSD: 新しい足 (M5) が形成されました。データ取得とシグナル判定を実行します。
2025-06-12 00:34:36,664 - INFO - EURUSD-M5 シグナル判定結果: No signal
2025-06-12 00:34:36,664 - INFO - EURUSD-M5: シグナルなし。
2025-06-12 00:34:36,665 - ERROR - EURUSD: シグナル監視ループで予期せぬエラーが発生しました: cannot access local variable 'uploaded_image_url' where it is not associated with a value
Traceback (most recent call last):
  File "c:\Users\pc\OneDrive\Desktop\phantom_alert_bot\signal_runner_loop.py", line 230, in _run
UnboundLocalError: cannot access local variable 'uploaded_image_url' where it is not associated with a value
2025-06-12 00:35:06,686 - INFO - EURUSD: 新しい足 (M5) が形成されました。データ取得とシグナル判定を実行します。
2025-06-12 00:35:06,712 - INFO - EURUSD-M5 シグナル判定結果: No signal
2025-06-12 00:35:06,712 - INFO - EURUSD-M5: シグナルなし。
2025-06-12 00:35:06,713 - ERROR - EURUSD: シグナル監視ループで予期せぬエラーが発生しました: cannot access local variable 'uploaded_image_url' where it is not associated with a value
Traceback (most recent call last):
  File "C:\Users\pc\OneDrive\Desktop\phantom_alert_bot\signal_runner_loop.py", line 230, in _run
UnboundLocalError: cannot access local variable 'uploaded_image_url' where it is not associated with a value
2025-06-12 00:35:08,828 - INFO - EURUSD: 新しい足 (M5) が形成されました。データ取得とシグナル判定を実行します。
2025-06-12 00:35:08,857 - INFO - EURUSD-M5 シグナル判定結果: No signal
2025-06-12 00:35:08,857 - INFO - EURUSD-M5: シグナルなし。
2025-06-12 00:35:08,857 - ERROR - EURUSD: シグナル監視ループで予期せぬエラーが発生しました: cannot access local variable 'uploaded_image_url' where it is not associated with a value
Traceback (most recent call last):
  File "C:\Users\pc\OneDrive\Desktop\phantom_alert_bot\signal_runner_loop.py", line 230, in _run
UnboundLocalError: cannot access local variable 'uploaded_image_url' where it is not associated with a value
2025-06-12 00:35:36,666 - INFO - EURUSD: 新しい足 (M5) が形成されました。データ取得とシグナル判定を実行します。
2025-06-12 00:35:36,692 - INFO - EURUSD-M5 シグナル判定結果: No signal
2025-06-12 00:35:36,692 - INFO - EURUSD-M5: シグナルなし。
2025-06-12 00:35:36,692 - ERROR - EURUSD: シグナル監視ループで予期せぬエラーが発生しました: cannot access local variable 'uploaded_image_url' where it is not associated with a value
Traceback (most recent call last):
  File "c:\Users\pc\OneDrive\Desktop\phantom_alert_bot\signal_runner_loop.py", line 230, in _run
UnboundLocalError: cannot access local variable 'uploaded_image_url' where it is not associated with a value
2025-06-12 00:36:06,715 - INFO - EURUSD: 新しい足 (M5) が形成されました。データ取得とシグナル判定を実行します。
2025-06-12 00:36:06,742 - INFO - EURUSD-M5 シグナル判定結果: No signal
2025-06-12 00:36:06,743 - INFO - EURUSD-M5: シグナルなし。
2025-06-12 00:36:06,743 - ERROR - EURUSD: シグナル監視ループで予期せぬエラーが発生しました: cannot access local variable 'uploaded_image_url' where it is not associated with a value
Traceback (most recent call last):
  File "C:\Users\pc\OneDrive\Desktop\phantom_alert_bot\signal_runner_loop.py", line 230, in _run
UnboundLocalError: cannot access local variable 'uploaded_image_url' where it is not associated with a value
2025-06-12 00:36:08,861 - INFO - EURUSD: 新しい足 (M5) が形成されました。データ取得とシグナル判定を実行します。
2025-06-12 00:36:08,904 - INFO - EURUSD-M5 シグナル判定結果: No signal
2025-06-12 00:36:08,904 - INFO - EURUSD-M5: シグナルなし。
2025-06-12 00:36:08,904 - ERROR - EURUSD: シグナル監視ループで予期せぬエラーが発生しました: cannot access local variable 'uploaded_image_url' where it is not associated with a value
Traceback (most recent call last):
  File "C:\Users\pc\OneDrive\Desktop\phantom_alert_bot\signal_runner_loop.py", line 230, in _run
UnboundLocalError: cannot access local variable 'uploaded_image_url' where it is not associated with a value
2025-06-12 00:36:36,694 - INFO - EURUSD: 新しい足 (M5) が形成されました。データ取得とシグナル判定を実行します。
2025-06-12 00:36:36,723 - INFO - EURUSD-M5 シグナル判定結果: No signal
2025-06-12 00:36:36,723 - INFO - EURUSD-M5: シグナルなし。
2025-06-12 00:36:36,723 - ERROR - EURUSD: シグナル監視ループで予期せぬエラーが発生しました: cannot access local variable 'uploaded_image_url' where it is not associated with a value
Traceback (most recent call last):
  File "c:\Users\pc\OneDrive\Desktop\phantom_alert_bot\signal_runner_loop.py", line 230, in _run
UnboundLocalError: cannot access local variable 'uploaded_image_url' where it is not associated with a value
2025-06-12 00:37:06,744 - INFO - EURUSD: 新しい足 (M5) が形成されました。データ取得とシグナル判定を実行します。
2025-06-12 00:37:06,766 - INFO - EURUSD-M5 シグナル判定結果: No signal
2025-06-12 00:37:06,766 - INFO - EURUSD-M5: シグナルなし。
2025-06-12 00:37:06,767 - ERROR - EURUSD: シグナル監視ループで予期せぬエラーが発生しました: cannot access local variable 'uploaded_image_url' where it is not associated with a value
Traceback (most recent call last):
  File "C:\Users\pc\OneDrive\Desktop\phantom_alert_bot\signal_runner_loop.py", line 230, in _run
UnboundLocalError: cannot access local variable 'uploaded_image_url' where it is not associated with a value
2025-06-12 00:37:08,906 - INFO - EURUSD: 新しい足 (M5) が形成されました。データ取得とシグナル判定を実行します。
2025-06-12 00:37:08,946 - INFO - EURUSD-M5 シグナル判定結果: No signal
2025-06-12 00:37:08,946 - INFO - EURUSD-M5: シグナルなし。
2025-06-12 00:37:08,946 - ERROR - EURUSD: シグナル監視ループで予期せぬエラーが発生しました: cannot access local variable 'uploaded_image_url' where it is not associated with a value
Traceback (most recent call last):
  File "C:\Users\pc\OneDrive\Desktop\phantom_alert_bot\signal_runner_loop.py", line 230, in _run
UnboundLocalError: cannot access local variable 'uploaded_image_url' where it is not associated with a value
2025-06-12 00:37:36,724 - INFO - EURUSD: 新しい足 (M5) が形成されました。データ取得とシグナル判定を実行します。
2025-06-12 00:37:36,752 - INFO - EURUSD-M5 シグナル判定結果: No signal
2025-06-12 00:37:36,752 - INFO - EURUSD-M5: シグナルなし。
2025-06-12 00:37:36,753 - ERROR - EURUSD: シグナル監視ループで予期せぬエラーが発生しました: cannot access local variable 'uploaded_image_url' where it is not associated with a value
Traceback (most recent call last):
  File "c:\Users\pc\OneDrive\Desktop\phantom_alert_bot\signal_runner_loop.py", line 230, in _run
UnboundLocalError: cannot access local variable 'uploaded_image_url' where it is not associated with a value
2025-06-12 00:38:06,767 - INFO - EURUSD: 新しい足 (M5) が形成されました。データ取得とシグナル判定を実行します。
2025-06-12 00:38:06,794 - INFO - EURUSD-M5 シグナル判定結果: No signal
2025-06-12 00:38:06,795 - INFO - EURUSD-M5: シグナルなし。
2025-06-12 00:38:06,795 - ERROR - EURUSD: シグナル監視ループで予期せぬエラーが発生しました: cannot access local variable 'uploaded_image_url' where it is not associated with a value
Traceback (most recent call last):
  File "C:\Users\pc\OneDrive\Desktop\phantom_alert_bot\signal_runner_loop.py", line 230, in _run
UnboundLocalError: cannot access local variable 'uploaded_image_url' where it is not associated with a value
2025-06-12 00:38:08,948 - INFO - EURUSD: 新しい足 (M5) が形成されました。データ取得とシグナル判定を実行します。
2025-06-12 00:38:09,007 - INFO - EURUSD-M5 シグナル判定結果: No signal
2025-06-12 00:38:09,008 - INFO - EURUSD-M5: シグナルなし。
2025-06-12 00:38:09,008 - ERROR - EURUSD: シグナル監視ループで予期せぬエラーが発生しました: cannot access local variable 'uploaded_image_url' where it is not associated with a value
Traceback (most recent call last):
  File "C:\Users\pc\OneDrive\Desktop\phantom_alert_bot\signal_runner_loop.py", line 230, in _run
UnboundLocalError: cannot access local variable 'uploaded_image_url' where it is not associated with a value
2025-06-12 00:38:36,754 - INFO - EURUSD: 新しい足 (M5) が形成されました。データ取得とシグナル判定を実行します。
2025-06-12 00:38:36,780 - INFO - EURUSD-M5 シグナル判定結果: No signal
2025-06-12 00:38:36,780 - INFO - EURUSD-M5: シグナルなし。
2025-06-12 00:38:36,781 - ERROR - EURUSD: シグナル監視ループで予期せぬエラーが発生しました: cannot access local variable 'uploaded_image_url' where it is not associated with a value
Traceback (most recent call last):
  File "c:\Users\pc\OneDrive\Desktop\phantom_alert_bot\signal_runner_loop.py", line 230, in _run
UnboundLocalError: cannot access local variable 'uploaded_image_url' where it is not associated with a value
2025-06-12 00:39:06,796 - INFO - EURUSD: 新しい足 (M5) が形成されました。データ取得とシグナル判定を実行します。
2025-06-12 00:39:06,818 - INFO - EURUSD-M5 シグナル判定結果: No signal
2025-06-12 00:39:06,818 - INFO - EURUSD-M5: シグナルなし。
2025-06-12 00:39:06,819 - ERROR - EURUSD: シグナル監視ループで予期せぬエラーが発生しました: cannot access local variable 'uploaded_image_url' where it is not associated with a value
Traceback (most recent call last):
  File "C:\Users\pc\OneDrive\Desktop\phantom_alert_bot\signal_runner_loop.py", line 230, in _run
UnboundLocalError: cannot access local variable 'uploaded_image_url' where it is not associated with a value
2025-06-12 00:39:09,010 - INFO - EURUSD: 新しい足 (M5) が形成されました。データ取得とシグナル判定を実行します。
2025-06-12 00:39:09,083 - INFO - EURUSD-M5 シグナル判定結果: No signal
2025-06-12 00:39:09,083 - INFO - EURUSD-M5: シグナルなし。
2025-06-12 00:39:09,084 - ERROR - EURUSD: シグナル監視ループで予期せぬエラーが発生しました: cannot access local variable 'uploaded_image_url' where it is not associated with a value
Traceback (most recent call last):
  File "C:\Users\pc\OneDrive\Desktop\phantom_alert_bot\signal_runner_loop.py", line 230, in _run
UnboundLocalError: cannot access local variable 'uploaded_image_url' where it is not associated with a value
2025-06-12 00:39:36,783 - INFO - EURUSD: 新しい足 (M5) が形成されました。データ取得とシグナル判定を実行します。
2025-06-12 00:39:36,811 - INFO - EURUSD-M5 シグナル判定結果: No signal
2025-06-12 00:39:36,811 - INFO - EURUSD-M5: シグナルなし。
2025-06-12 00:39:36,812 - ERROR - EURUSD: シグナル監視ループで予期せぬエラーが発生しました: cannot access local variable 'uploaded_image_url' where it is not associated with a value
Traceback (most recent call last):
  File "c:\Users\pc\OneDrive\Desktop\phantom_alert_bot\signal_runner_loop.py", line 230, in _run
UnboundLocalError: cannot access local variable 'uploaded_image_url' where it is not associated with a value
2025-06-12 00:40:06,820 - INFO - EURUSD: 新しい足 (M5) が形成されました。データ取得とシグナル判定を実行します。
2025-06-12 00:40:06,842 - INFO - EURUSD-M5 シグナル判定結果: No signal
2025-06-12 00:40:06,842 - INFO - EURUSD-M5: シグナルなし。
2025-06-12 00:40:06,842 - ERROR - EURUSD: シグナル監視ループで予期せぬエラーが発生しました: cannot access local variable 'uploaded_image_url' where it is not associated with a value
Traceback (most recent call last):
  File "C:\Users\pc\OneDrive\Desktop\phantom_alert_bot\signal_runner_loop.py", line 230, in _run
UnboundLocalError: cannot access local variable 'uploaded_image_url' where it is not associated with a value
2025-06-12 00:40:09,085 - INFO - EURUSD: 新しい足 (M5) が形成されました。データ取得とシグナル判定を実行します。
2025-06-12 00:40:09,143 - INFO - EURUSD-M5 シグナル判定結果: No signal
2025-06-12 00:40:09,146 - INFO - EURUSD-M5: シグナルなし。
2025-06-12 00:40:09,147 - ERROR - EURUSD: シグナル監視ループで予期せぬエラーが発生しました: cannot access local variable 'uploaded_image_url' where it is not associated with a value
Traceback (most recent call last):
  File "C:\Users\pc\OneDrive\Desktop\phantom_alert_bot\signal_runner_loop.py", line 230, in _run
UnboundLocalError: cannot access local variable 'uploaded_image_url' where it is not associated with a value
2025-06-12 00:40:36,813 - INFO - EURUSD: 新しい足 (M5) が形成されました。データ取得とシグナル判定を実行します。
2025-06-12 00:40:36,838 - INFO - EURUSD-M5 シグナル判定結果: No signal
2025-06-12 00:40:36,838 - INFO - EURUSD-M5: シグナルなし。
2025-06-12 00:40:36,838 - ERROR - EURUSD: シグナル監視ループで予期せぬエラーが発生しました: cannot access local variable 'uploaded_image_url' where it is not associated with a value
Traceback (most recent call last):
  File "c:\Users\pc\OneDrive\Desktop\phantom_alert_bot\signal_runner_loop.py", line 230, in _run
UnboundLocalError: cannot access local variable 'uploaded_image_url' where it is not associated with a value
2025-06-12 00:41:06,843 - INFO - EURUSD: 新しい足 (M5) が形成されました。データ取得とシグナル判定を実行します。
2025-06-12 00:41:06,866 - INFO - EURUSD-M5 シグナル判定結果: No signal
2025-06-12 00:41:06,866 - INFO - EURUSD-M5: シグナルなし。
2025-06-12 00:41:06,867 - ERROR - EURUSD: シグナル監視ループで予期せぬエラーが発生しました: cannot access local variable 'uploaded_image_url' where it is not associated with a value
Traceback (most recent call last):
  File "C:\Users\pc\OneDrive\Desktop\phantom_alert_bot\signal_runner_loop.py", line 230, in _run
UnboundLocalError: cannot access local variable 'uploaded_image_url' where it is not associated with a value
2025-06-12 00:41:09,150 - INFO - EURUSD: 新しい足 (M5) が形成されました。データ取得とシグナル判定を実行します。
2025-06-12 00:41:09,205 - INFO - EURUSD-M5 シグナル判定結果: No signal
2025-06-12 00:41:09,206 - INFO - EURUSD-M5: シグナルなし。
2025-06-12 00:41:09,207 - ERROR - EURUSD: シグナル監視ループで予期せぬエラーが発生しました: cannot access local variable 'uploaded_image_url' where it is not associated with a value
Traceback (most recent call last):
  File "C:\Users\pc\OneDrive\Desktop\phantom_alert_bot\signal_runner_loop.py", line 230, in _run
UnboundLocalError: cannot access local variable 'uploaded_image_url' where it is not associated with a value
2025-06-12 00:41:36,840 - INFO - EURUSD: 新しい足 (M5) が形成されました。データ取得とシグナル判定を実行します。
2025-06-12 00:41:36,867 - INFO - EURUSD-M5 シグナル判定結果: No signal
2025-06-12 00:41:36,867 - INFO - EURUSD-M5: シグナルなし。
2025-06-12 00:41:36,868 - ERROR - EURUSD: シグナル監視ループで予期せぬエラーが発生しました: cannot access local variable 'uploaded_image_url' where it is not associated with a value
Traceback (most recent call last):
  File "c:\Users\pc\OneDrive\Desktop\phantom_alert_bot\signal_runner_loop.py", line 230, in _run
UnboundLocalError: cannot access local variable 'uploaded_image_url' where it is not associated with a value
2025-06-12 00:42:06,868 - INFO - EURUSD: 新しい足 (M5) が形成されました。データ取得とシグナル判定を実行します。
2025-06-12 00:42:06,894 - INFO - EURUSD-M5 シグナル判定結果: No signal
2025-06-12 00:42:06,894 - INFO - EURUSD-M5: シグナルなし。
2025-06-12 00:42:06,894 - ERROR - EURUSD: シグナル監視ループで予期せぬエラーが発生しました: cannot access local variable 'uploaded_image_url' where it is not associated with a value
Traceback (most recent call last):
  File "C:\Users\pc\OneDrive\Desktop\phantom_alert_bot\signal_runner_loop.py", line 230, in _run
UnboundLocalError: cannot access local variable 'uploaded_image_url' where it is not associated with a value
2025-06-12 00:42:09,209 - INFO - EURUSD: 新しい足 (M5) が形成されました。データ取得とシグナル判定を実行します。
2025-06-12 00:42:09,272 - INFO - EURUSD-M5 シグナル判定結果: No signal
2025-06-12 00:42:09,272 - INFO - EURUSD-M5: シグナルなし。
2025-06-12 00:42:09,272 - ERROR - EURUSD: シグナル監視ループで予期せぬエラーが発生しました: cannot access local variable 'uploaded_image_url' where it is not associated with a value
Traceback (most recent call last):
  File "C:\Users\pc\OneDrive\Desktop\phantom_alert_bot\signal_runner_loop.py", line 230, in _run
UnboundLocalError: cannot access local variable 'uploaded_image_url' where it is not associated with a value
2025-06-12 00:42:36,869 - INFO - EURUSD: 新しい足 (M5) が形成されました。データ取得とシグナル判定を実行します。
2025-06-12 00:42:36,899 - INFO - EURUSD-M5 シグナル判定結果: No signal
2025-06-12 00:42:36,900 - INFO - EURUSD-M5: シグナルなし。
2025-06-12 00:42:36,900 - ERROR - EURUSD: シグナル監視ループで予期せぬエラーが発生しました: cannot access local variable 'uploaded_image_url' where it is not associated with a value
Traceback (most recent call last):
  File "c:\Users\pc\OneDrive\Desktop\phantom_alert_bot\signal_runner_loop.py", line 230, in _run
UnboundLocalError: cannot access local variable 'uploaded_image_url' where it is not associated with a value
2025-06-12 00:43:06,895 - INFO - EURUSD: 新しい足 (M5) が形成されました。データ取得とシグナル判定を実行します。
2025-06-12 00:43:06,921 - INFO - EURUSD-M5 シグナル判定結果: No signal
2025-06-12 00:43:06,921 - INFO - EURUSD-M5: シグナルなし。
2025-06-12 00:43:06,921 - ERROR - EURUSD: シグナル監視ループで予期せぬエラーが発生しました: cannot access local variable 'uploaded_image_url' where it is not associated with a value
Traceback (most recent call last):
  File "C:\Users\pc\OneDrive\Desktop\phantom_alert_bot\signal_runner_loop.py", line 230, in _run
UnboundLocalError: cannot access local variable 'uploaded_image_url' where it is not associated with a value
2025-06-12 00:43:09,275 - INFO - EURUSD: 新しい足 (M5) が形成されました。データ取得とシグナル判定を実行します。
2025-06-12 00:43:09,341 - INFO - EURUSD-M5 シグナル判定結果: No signal
2025-06-12 00:43:09,341 - INFO - EURUSD-M5: シグナルなし。
2025-06-12 00:43:09,341 - ERROR - EURUSD: シグナル監視ループで予期せぬエラーが発生しました: cannot access local variable 'uploaded_image_url' where it is not associated with a value
Traceback (most recent call last):
  File "C:\Users\pc\OneDrive\Desktop\phantom_alert_bot\signal_runner_loop.py", line 230, in _run
UnboundLocalError: cannot access local variable 'uploaded_image_url' where it is not associated with a value
2025-06-12 00:43:36,902 - INFO - EURUSD: 新しい足 (M5) が形成されました。データ取得とシグナル判定を実行します。
2025-06-12 00:43:36,925 - INFO - EURUSD-M5 シグナル判定結果: No signal
2025-06-12 00:43:36,925 - INFO - EURUSD-M5: シグナルなし。
2025-06-12 00:43:36,925 - ERROR - EURUSD: シグナル監視ループで予期せぬエラーが発生しました: cannot access local variable 'uploaded_image_url' where it is not associated with a value
Traceback (most recent call last):
  File "c:\Users\pc\OneDrive\Desktop\phantom_alert_bot\signal_runner_loop.py", line 230, in _run
UnboundLocalError: cannot access local variable 'uploaded_image_url' where it is not associated with a value
2025-06-12 00:44:06,923 - INFO - EURUSD: 新しい足 (M5) が形成されました。データ取得とシグナル判定を実行します。
2025-06-12 00:44:06,951 - INFO - EURUSD-M5 シグナル判定結果: No signal
2025-06-12 00:44:06,951 - INFO - EURUSD-M5: シグナルなし。
2025-06-12 00:44:06,951 - ERROR - EURUSD: シグナル監視ループで予期せぬエラーが発生しました: cannot access local variable 'uploaded_image_url' where it is not associated with a value
Traceback (most recent call last):
  File "C:\Users\pc\OneDrive\Desktop\phantom_alert_bot\signal_runner_loop.py", line 230, in _run
UnboundLocalError: cannot access local variable 'uploaded_image_url' where it is not associated with a value
2025-06-12 00:44:09,358 - INFO - EURUSD: 新しい足 (M5) が形成されました。データ取得とシグナル判定を実行します。
2025-06-12 00:44:09,463 - INFO - EURUSD-M5 シグナル判定結果: No signal
2025-06-12 00:44:09,463 - INFO - EURUSD-M5: シグナルなし。
2025-06-12 00:44:09,466 - ERROR - EURUSD: シグナル監視ループで予期せぬエラーが発生しました: cannot access local variable 'uploaded_image_url' where it is not associated with a value
Traceback (most recent call last):
  File "C:\Users\pc\OneDrive\Desktop\phantom_alert_bot\signal_runner_loop.py", line 230, in _run
UnboundLocalError: cannot access local variable 'uploaded_image_url' where it is not associated with a value
2025-06-12 00:44:36,927 - INFO - EURUSD: 新しい足 (M5) が形成されました。データ取得とシグナル判定を実行します。
2025-06-12 00:44:36,949 - INFO - EURUSD-M5 シグナル判定結果: No signal
2025-06-12 00:44:36,949 - INFO - EURUSD-M5: シグナルなし。
2025-06-12 00:44:36,949 - ERROR - EURUSD: シグナル監視ループで予期せぬエラーが発生しました: cannot access local variable 'uploaded_image_url' where it is not associated with a value
Traceback (most recent call last):
  File "c:\Users\pc\OneDrive\Desktop\phantom_alert_bot\signal_runner_loop.py", line 230, in _run
UnboundLocalError: cannot access local variable 'uploaded_image_url' where it is not associated with a value
2025-06-12 00:45:06,952 - INFO - EURUSD: 新しい足 (M5) が形成されました。データ取得とシグナル判定を実行します。
2025-06-12 00:45:06,981 - INFO - EURUSD-M5 シグナル判定結果: No signal
2025-06-12 00:45:06,982 - INFO - EURUSD-M5: シグナルなし。
2025-06-12 00:45:06,982 - ERROR - EURUSD: シグナル監視ループで予期せぬエラーが発生しました: cannot access local variable 'uploaded_image_url' where it is not associated with a value
Traceback (most recent call last):
  File "C:\Users\pc\OneDrive\Desktop\phantom_alert_bot\signal_runner_loop.py", line 230, in _run
UnboundLocalError: cannot access local variable 'uploaded_image_url' where it is not associated with a value
2025-06-12 00:45:09,467 - INFO - EURUSD: 新しい足 (M5) が形成されました。データ取得とシグナル判定を実行します。
2025-06-12 00:45:09,514 - INFO - EURUSD-M5 シグナル判定結果: No signal
2025-06-12 00:45:09,515 - INFO - EURUSD-M5: シグナルなし。
2025-06-12 00:45:09,515 - ERROR - EURUSD: シグナル監視ループで予期せぬエラーが発生しました: cannot access local variable 'uploaded_image_url' where it is not associated with a value
Traceback (most recent call last):
  File "C:\Users\pc\OneDrive\Desktop\phantom_alert_bot\signal_runner_loop.py", line 230, in _run
UnboundLocalError: cannot access local variable 'uploaded_image_url' where it is not associated with a value
2025-06-12 00:45:36,951 - INFO - EURUSD: 新しい足 (M5) が形成されました。データ取得とシグナル判定を実行します。
2025-06-12 00:45:36,984 - INFO - EURUSD-M5 シグナル判定結果: No signal
2025-06-12 00:45:36,985 - INFO - EURUSD-M5: シグナルなし。
2025-06-12 00:45:36,985 - ERROR - EURUSD: シグナル監視ループで予期せぬエラーが発生しました: cannot access local variable 'uploaded_image_url' where it is not associated with a value
Traceback (most recent call last):
  File "c:\Users\pc\OneDrive\Desktop\phantom_alert_bot\signal_runner_loop.py", line 230, in _run
UnboundLocalError: cannot access local variable 'uploaded_image_url' where it is not associated with a value
2025-06-12 00:46:06,983 - INFO - EURUSD: 新しい足 (M5) が形成されました。データ取得とシグナル判定を実行します。
2025-06-12 00:46:07,006 - INFO - EURUSD-M5 シグナル判定結果: No signal
2025-06-12 00:46:07,006 - INFO - EURUSD-M5: シグナルなし。
2025-06-12 00:46:07,007 - ERROR - EURUSD: シグナル監視ループで予期せぬエラーが発生しました: cannot access local variable 'uploaded_image_url' where it is not associated with a value
Traceback (most recent call last):
  File "C:\Users\pc\OneDrive\Desktop\phantom_alert_bot\signal_runner_loop.py", line 230, in _run
UnboundLocalError: cannot access local variable 'uploaded_image_url' where it is not associated with a value
2025-06-12 00:46:09,517 - INFO - EURUSD: 新しい足 (M5) が形成されました。データ取得とシグナル判定を実行します。
2025-06-12 00:46:09,548 - INFO - EURUSD-M5 シグナル判定結果: No signal
2025-06-12 00:46:09,548 - INFO - EURUSD-M5: シグナルなし。
2025-06-12 00:46:09,548 - ERROR - EURUSD: シグナル監視ループで予期せぬエラーが発生しました: cannot access local variable 'uploaded_image_url' where it is not associated with a value
Traceback (most recent call last):
  File "C:\Users\pc\OneDrive\Desktop\phantom_alert_bot\signal_runner_loop.py", line 230, in _run
UnboundLocalError: cannot access local variable 'uploaded_image_url' where it is not associated with a value
2025-06-12 00:46:36,987 - INFO - EURUSD: 新しい足 (M5) が形成されました。データ取得とシグナル判定を実行します。
2025-06-12 00:46:37,010 - INFO - EURUSD-M5 シグナル判定結果: Balanced Sell Signal (Confluence: MACD Dead Cross, Stochastic Dead Cross)
2025-06-12 00:46:37,010 - ERROR - EURUSD: シグナル監視ループで予期せぬエラーが発生しました: 'SignalRunner' object has no attribute '_generate_chart_and_upload'
Traceback (most recent call last):
  File "c:\Users\pc\OneDrive\Desktop\phantom_alert_bot\signal_runner_loop.py", line 199, in _run
    # シグナルが出た場合、LINE通知とチャート画像生成・アップロード
                      ^^^^^^^^^^^^^^^^^^^^^^
AttributeError: 'SignalRunner' object has no attribute '_generate_chart_and_upload'
2025-06-12 00:47:07,008 - INFO - EURUSD: 新しい足 (M5) が形成されました。データ取得とシグナル判定を実行します。
2025-06-12 00:47:07,029 - INFO - EURUSD-M5 シグナル判定結果: Balanced Sell Signal (Confluence: MACD Dead Cross, Stochastic Dead Cross)
2025-06-12 00:47:07,029 - ERROR - EURUSD: シグナル監視ループで予期せぬエラーが発生しました: 'SignalRunner' object has no attribute '_generate_chart_and_upload'
Traceback (most recent call last):
  File "C:\Users\pc\OneDrive\Desktop\phantom_alert_bot\signal_runner_loop.py", line 199, in _run
    # シグナルが出た場合、LINE通知とチャート画像生成・アップロード
                      ^^^^^^^^^^^^^^^^^^^^^^
AttributeError: 'SignalRunner' object has no attribute '_generate_chart_and_upload'
2025-06-12 00:47:09,550 - INFO - EURUSD: 新しい足 (M5) が形成されました。データ取得とシグナル判定を実行します。
2025-06-12 00:47:09,575 - INFO - EURUSD-M5 シグナル判定結果: Balanced Sell Signal (Confluence: MACD Dead Cross, Stochastic Dead Cross)
2025-06-12 00:47:09,575 - ERROR - EURUSD: シグナル監視ループで予期せぬエラーが発生しました: 'SignalRunner' object has no attribute '_generate_chart_and_upload'
Traceback (most recent call last):
  File "C:\Users\pc\OneDrive\Desktop\phantom_alert_bot\signal_runner_loop.py", line 199, in _run
    # シグナルが出た場合、LINE通知とチャート画像生成・アップロード
                      ^^^^^^^^^^^^^^^^^^^^^^
AttributeError: 'SignalRunner' object has no attribute '_generate_chart_and_upload'
2025-06-12 10:40:26,285 - INFO - ✅ EURUSD-M5 シグナルランナーが初期化されました。
2025-06-12 10:40:31,344 - INFO - EURUSD-M5 シグナル監視ループを開始します。
2025-06-12 10:40:31,347 - INFO - EURUSD: MT5クライアントを初期化しています...
2025-06-12 10:40:31,350 - INFO - ✅ EURUSD: MT5クライアントの初期化に成功しました。
2025-06-12 10:40:31,352 - INFO - EURUSD: 新しい足 (M5) が形成されました。データ取得とシグナル判定を実行します。
2025-06-12 10:40:31,443 - ERROR - EURUSD: シグナル監視ループで予期せぬエラーが発生しました: 'MACD_Signal'
Traceback (most recent call last):
  File "C:\Users\pc\AppData\Local\Programs\Python\Python312\Lib\site-packages\pandas\core\indexes\base.py", line 3812, in get_loc
    return self._engine.get_loc(casted_key)
           ^^^^^^^^^^^^^^^^^^^^^^^^^^^^^^^^
  File "pandas/_libs/index.pyx", line 167, in pandas._libs.index.IndexEngine.get_loc
  File "pandas/_libs/index.pyx", line 196, in pandas._libs.index.IndexEngine.get_loc
  File "pandas/_libs/hashtable_class_helper.pxi", line 7088, in pandas._libs.hashtable.PyObjectHashTable.get_item
  File "pandas/_libs/hashtable_class_helper.pxi", line 7096, in pandas._libs.hashtable.PyObjectHashTable.get_item
KeyError: 'MACD_Signal'

The above exception was the direct cause of the following exception:

Traceback (most recent call last):
  File "c:\Users\pc\OneDrive\Desktop\phantom_alert_bot\signal_runner_loop.py", line 196, in _run
    signal_info = generate_signal(df, mode="realtime", logic=DEFAULT_LOGIC) # modeとlogicを渡す
                  ^^^^^^^^^^^^^^^^^^^^^^^^^^^^^^^^^^^^^^^^^^^^^^^^^^^^^^^^^
  File "c:\Users\pc\OneDrive\Desktop\phantom_alert_bot\signal_generator.py", line 71, in generate_signal
    signal_info = _generate_balanced_signal(df_ind, current_price)
                  ^^^^^^^^^^^^^^^^^^^^^^^^^^^^^^^^^^^^^^^^^^^^^^^^
  File "c:\Users\pc\OneDrive\Desktop\phantom_alert_bot\signal_generator.py", line 192, in _generate_balanced_signal
    macd_buy = (df_ind['MACD'].iloc[-1] > df_ind['MACD_Signal'].iloc[-1]) # MACDゴールデンクロス
                                          ~~~~~~^^^^^^^^^^^^^^^
  File "C:\Users\pc\AppData\Local\Programs\Python\Python312\Lib\site-packages\pandas\core\frame.py", line 4107, in __getitem__
    indexer = self.columns.get_loc(key)
              ^^^^^^^^^^^^^^^^^^^^^^^^^
  File "C:\Users\pc\AppData\Local\Programs\Python\Python312\Lib\site-packages\pandas\core\indexes\base.py", line 3819, in get_loc
    raise KeyError(key) from err
KeyError: 'MACD_Signal'
2025-06-12 10:41:31,447 - INFO - EURUSD: 新しい足 (M5) が形成されました。データ取得とシグナル判定を実行します。
2025-06-12 10:41:31,514 - ERROR - EURUSD: シグナル監視ループで予期せぬエラーが発生しました: 'MACD_Signal'
Traceback (most recent call last):
  File "C:\Users\pc\AppData\Local\Programs\Python\Python312\Lib\site-packages\pandas\core\indexes\base.py", line 3812, in get_loc
    return self._engine.get_loc(casted_key)
           ^^^^^^^^^^^^^^^^^^^^^^^^^^^^^^^^
  File "pandas/_libs/index.pyx", line 167, in pandas._libs.index.IndexEngine.get_loc
  File "pandas/_libs/index.pyx", line 196, in pandas._libs.index.IndexEngine.get_loc
  File "pandas/_libs/hashtable_class_helper.pxi", line 7088, in pandas._libs.hashtable.PyObjectHashTable.get_item
  File "pandas/_libs/hashtable_class_helper.pxi", line 7096, in pandas._libs.hashtable.PyObjectHashTable.get_item
KeyError: 'MACD_Signal'

The above exception was the direct cause of the following exception:

Traceback (most recent call last):
  File "c:\Users\pc\OneDrive\Desktop\phantom_alert_bot\signal_runner_loop.py", line 196, in _run
    signal_info = generate_signal(df, mode="realtime", logic=DEFAULT_LOGIC) # modeとlogicを渡す
                  ^^^^^^^^^^^^^^^^^^^^^^^^^^^^^^^^^^^^^^^^^^^^^^^^^^^^^^^^^
  File "c:\Users\pc\OneDrive\Desktop\phantom_alert_bot\signal_generator.py", line 71, in generate_signal
    signal_info = _generate_balanced_signal(df_ind, current_price)
                  ^^^^^^^^^^^^^^^^^^^^^^^^^^^^^^^^^^^^^^^^^^^^^^^^
  File "c:\Users\pc\OneDrive\Desktop\phantom_alert_bot\signal_generator.py", line 192, in _generate_balanced_signal
    macd_buy = (df_ind['MACD'].iloc[-1] > df_ind['MACD_Signal'].iloc[-1]) # MACDゴールデンクロス
                                          ~~~~~~^^^^^^^^^^^^^^^
  File "C:\Users\pc\AppData\Local\Programs\Python\Python312\Lib\site-packages\pandas\core\frame.py", line 4107, in __getitem__
    indexer = self.columns.get_loc(key)
              ^^^^^^^^^^^^^^^^^^^^^^^^^
  File "C:\Users\pc\AppData\Local\Programs\Python\Python312\Lib\site-packages\pandas\core\indexes\base.py", line 3819, in get_loc
    raise KeyError(key) from err
KeyError: 'MACD_Signal'
2025-06-13 01:18:32,287 - INFO - ✅ EURUSD-M5 シグナルランナーが初期化されました。
2025-06-13 01:18:37,317 - INFO - EURUSD-M5 シグナル監視ループを開始します。
2025-06-13 01:18:37,318 - INFO - EURUSD: MT5クライアントを初期化しています...
2025-06-13 01:18:37,321 - INFO - ✅ EURUSD: MT5クライアントの初期化に成功しました。
2025-06-13 01:18:37,322 - INFO - EURUSD: 新しい足 (M5) が形成されました。データ取得とシグナル判定を実行します。
2025-06-13 01:18:37,332 - ERROR - EURUSD: シグナル監視ループで予期せぬエラーが発生しました: Cannot convert tz-naive timestamps, use tz_localize to localize
Traceback (most recent call last):
  File "C:\Users\pc\OneDrive\Desktop\phantom_alert_bot\signal_runner_loop.py", line 192, in _run
    df, latest_time_tokyo = self._get_current_ohlc()
                            ^^^^^^^^^^^^^^^^^^^^^^^^
  File "C:\Users\pc\OneDrive\Desktop\phantom_alert_bot\signal_runner_loop.py", line 116, in _get_current_ohlc
    df.index = df.index.tz_convert('Asia/Tokyo') # チャート描画時などのため
               ^^^^^^^^^^^^^^^^^^^^^^^^^^^^^^^^^
  File "C:\Users\pc\OneDrive\Desktop\phantom_alert_bot\venv\Lib\site-packages\pandas\core\indexes\datetimes.py", line 283, in tz_convert
    arr = self._data.tz_convert(tz)
          ^^^^^^^^^^^^^^^^^^^^^^^^^
  File "C:\Users\pc\OneDrive\Desktop\phantom_alert_bot\venv\Lib\site-packages\pandas\core\arrays\datetimes.py", line 917, in tz_convert
    raise TypeError(
TypeError: Cannot convert tz-naive timestamps, use tz_localize to localize
2025-06-13 01:19:37,335 - INFO - EURUSD: 新しい足 (M5) が形成されました。データ取得とシグナル判定を実行します。
2025-06-13 01:19:37,338 - ERROR - EURUSD: シグナル監視ループで予期せぬエラーが発生しました: Cannot convert tz-naive timestamps, use tz_localize to localize
Traceback (most recent call last):
  File "C:\Users\pc\OneDrive\Desktop\phantom_alert_bot\signal_runner_loop.py", line 192, in _run
    df, latest_time_tokyo = self._get_current_ohlc()
                            ^^^^^^^^^^^^^^^^^^^^^^^^
  File "C:\Users\pc\OneDrive\Desktop\phantom_alert_bot\signal_runner_loop.py", line 116, in _get_current_ohlc
    df.index = df.index.tz_convert('Asia/Tokyo') # チャート描画時などのため
               ^^^^^^^^^^^^^^^^^^^^^^^^^^^^^^^^^
  File "C:\Users\pc\OneDrive\Desktop\phantom_alert_bot\venv\Lib\site-packages\pandas\core\indexes\datetimes.py", line 283, in tz_convert
    arr = self._data.tz_convert(tz)
          ^^^^^^^^^^^^^^^^^^^^^^^^^
  File "C:\Users\pc\OneDrive\Desktop\phantom_alert_bot\venv\Lib\site-packages\pandas\core\arrays\datetimes.py", line 917, in tz_convert
    raise TypeError(
TypeError: Cannot convert tz-naive timestamps, use tz_localize to localize
2025-06-13 01:20:37,339 - INFO - EURUSD: 新しい足 (M5) が形成されました。データ取得とシグナル判定を実行します。
2025-06-13 01:20:37,342 - ERROR - EURUSD: シグナル監視ループで予期せぬエラーが発生しました: Cannot convert tz-naive timestamps, use tz_localize to localize
Traceback (most recent call last):
  File "C:\Users\pc\OneDrive\Desktop\phantom_alert_bot\signal_runner_loop.py", line 192, in _run
    df, latest_time_tokyo = self._get_current_ohlc()
                            ^^^^^^^^^^^^^^^^^^^^^^^^
  File "C:\Users\pc\OneDrive\Desktop\phantom_alert_bot\signal_runner_loop.py", line 116, in _get_current_ohlc
    df.index = df.index.tz_convert('Asia/Tokyo') # チャート描画時などのため
               ^^^^^^^^^^^^^^^^^^^^^^^^^^^^^^^^^
  File "C:\Users\pc\OneDrive\Desktop\phantom_alert_bot\venv\Lib\site-packages\pandas\core\indexes\datetimes.py", line 283, in tz_convert
    arr = self._data.tz_convert(tz)
          ^^^^^^^^^^^^^^^^^^^^^^^^^
  File "C:\Users\pc\OneDrive\Desktop\phantom_alert_bot\venv\Lib\site-packages\pandas\core\arrays\datetimes.py", line 917, in tz_convert
    raise TypeError(
TypeError: Cannot convert tz-naive timestamps, use tz_localize to localize
2025-06-13 01:21:37,344 - INFO - EURUSD: 新しい足 (M5) が形成されました。データ取得とシグナル判定を実行します。
2025-06-13 01:21:37,348 - ERROR - EURUSD: シグナル監視ループで予期せぬエラーが発生しました: Cannot convert tz-naive timestamps, use tz_localize to localize
Traceback (most recent call last):
  File "C:\Users\pc\OneDrive\Desktop\phantom_alert_bot\signal_runner_loop.py", line 192, in _run
    df, latest_time_tokyo = self._get_current_ohlc()
                            ^^^^^^^^^^^^^^^^^^^^^^^^
  File "C:\Users\pc\OneDrive\Desktop\phantom_alert_bot\signal_runner_loop.py", line 116, in _get_current_ohlc
    df.index = df.index.tz_convert('Asia/Tokyo') # チャート描画時などのため
               ^^^^^^^^^^^^^^^^^^^^^^^^^^^^^^^^^
  File "C:\Users\pc\OneDrive\Desktop\phantom_alert_bot\venv\Lib\site-packages\pandas\core\indexes\datetimes.py", line 283, in tz_convert
    arr = self._data.tz_convert(tz)
          ^^^^^^^^^^^^^^^^^^^^^^^^^
  File "C:\Users\pc\OneDrive\Desktop\phantom_alert_bot\venv\Lib\site-packages\pandas\core\arrays\datetimes.py", line 917, in tz_convert
    raise TypeError(
TypeError: Cannot convert tz-naive timestamps, use tz_localize to localize
2025-06-13 01:22:37,350 - INFO - EURUSD: 新しい足 (M5) が形成されました。データ取得とシグナル判定を実行します。
2025-06-13 01:22:37,355 - ERROR - EURUSD: シグナル監視ループで予期せぬエラーが発生しました: Cannot convert tz-naive timestamps, use tz_localize to localize
Traceback (most recent call last):
  File "C:\Users\pc\OneDrive\Desktop\phantom_alert_bot\signal_runner_loop.py", line 192, in _run
    df, latest_time_tokyo = self._get_current_ohlc()
                            ^^^^^^^^^^^^^^^^^^^^^^^^
  File "C:\Users\pc\OneDrive\Desktop\phantom_alert_bot\signal_runner_loop.py", line 116, in _get_current_ohlc
    df.index = df.index.tz_convert('Asia/Tokyo') # チャート描画時などのため
               ^^^^^^^^^^^^^^^^^^^^^^^^^^^^^^^^^
  File "C:\Users\pc\OneDrive\Desktop\phantom_alert_bot\venv\Lib\site-packages\pandas\core\indexes\datetimes.py", line 283, in tz_convert
    arr = self._data.tz_convert(tz)
          ^^^^^^^^^^^^^^^^^^^^^^^^^
  File "C:\Users\pc\OneDrive\Desktop\phantom_alert_bot\venv\Lib\site-packages\pandas\core\arrays\datetimes.py", line 917, in tz_convert
    raise TypeError(
TypeError: Cannot convert tz-naive timestamps, use tz_localize to localize
2025-06-13 01:23:37,356 - INFO - EURUSD: 新しい足 (M5) が形成されました。データ取得とシグナル判定を実行します。
2025-06-13 01:23:37,364 - ERROR - EURUSD: シグナル監視ループで予期せぬエラーが発生しました: Cannot convert tz-naive timestamps, use tz_localize to localize
Traceback (most recent call last):
  File "C:\Users\pc\OneDrive\Desktop\phantom_alert_bot\signal_runner_loop.py", line 192, in _run
    df, latest_time_tokyo = self._get_current_ohlc()
                            ^^^^^^^^^^^^^^^^^^^^^^^^
  File "C:\Users\pc\OneDrive\Desktop\phantom_alert_bot\signal_runner_loop.py", line 116, in _get_current_ohlc
    df.index = df.index.tz_convert('Asia/Tokyo') # チャート描画時などのため
               ^^^^^^^^^^^^^^^^^^^^^^^^^^^^^^^^^
  File "C:\Users\pc\OneDrive\Desktop\phantom_alert_bot\venv\Lib\site-packages\pandas\core\indexes\datetimes.py", line 283, in tz_convert
    arr = self._data.tz_convert(tz)
          ^^^^^^^^^^^^^^^^^^^^^^^^^
  File "C:\Users\pc\OneDrive\Desktop\phantom_alert_bot\venv\Lib\site-packages\pandas\core\arrays\datetimes.py", line 917, in tz_convert
    raise TypeError(
TypeError: Cannot convert tz-naive timestamps, use tz_localize to localize
2025-06-13 01:24:37,368 - INFO - EURUSD: 新しい足 (M5) が形成されました。データ取得とシグナル判定を実行します。
2025-06-13 01:24:37,371 - ERROR - EURUSD: シグナル監視ループで予期せぬエラーが発生しました: Cannot convert tz-naive timestamps, use tz_localize to localize
Traceback (most recent call last):
  File "C:\Users\pc\OneDrive\Desktop\phantom_alert_bot\signal_runner_loop.py", line 192, in _run
    df, latest_time_tokyo = self._get_current_ohlc()
                            ^^^^^^^^^^^^^^^^^^^^^^^^
  File "C:\Users\pc\OneDrive\Desktop\phantom_alert_bot\signal_runner_loop.py", line 116, in _get_current_ohlc
    df.index = df.index.tz_convert('Asia/Tokyo') # チャート描画時などのため
               ^^^^^^^^^^^^^^^^^^^^^^^^^^^^^^^^^
  File "C:\Users\pc\OneDrive\Desktop\phantom_alert_bot\venv\Lib\site-packages\pandas\core\indexes\datetimes.py", line 283, in tz_convert
    arr = self._data.tz_convert(tz)
          ^^^^^^^^^^^^^^^^^^^^^^^^^
  File "C:\Users\pc\OneDrive\Desktop\phantom_alert_bot\venv\Lib\site-packages\pandas\core\arrays\datetimes.py", line 917, in tz_convert
    raise TypeError(
TypeError: Cannot convert tz-naive timestamps, use tz_localize to localize
2025-06-13 01:25:37,373 - INFO - EURUSD: 新しい足 (M5) が形成されました。データ取得とシグナル判定を実行します。
2025-06-13 01:25:37,380 - ERROR - EURUSD: シグナル監視ループで予期せぬエラーが発生しました: Cannot convert tz-naive timestamps, use tz_localize to localize
Traceback (most recent call last):
  File "C:\Users\pc\OneDrive\Desktop\phantom_alert_bot\signal_runner_loop.py", line 192, in _run
    df, latest_time_tokyo = self._get_current_ohlc()
                            ^^^^^^^^^^^^^^^^^^^^^^^^
  File "C:\Users\pc\OneDrive\Desktop\phantom_alert_bot\signal_runner_loop.py", line 116, in _get_current_ohlc
    df.index = df.index.tz_convert('Asia/Tokyo') # チャート描画時などのため
               ^^^^^^^^^^^^^^^^^^^^^^^^^^^^^^^^^
  File "C:\Users\pc\OneDrive\Desktop\phantom_alert_bot\venv\Lib\site-packages\pandas\core\indexes\datetimes.py", line 283, in tz_convert
    arr = self._data.tz_convert(tz)
          ^^^^^^^^^^^^^^^^^^^^^^^^^
  File "C:\Users\pc\OneDrive\Desktop\phantom_alert_bot\venv\Lib\site-packages\pandas\core\arrays\datetimes.py", line 917, in tz_convert
    raise TypeError(
TypeError: Cannot convert tz-naive timestamps, use tz_localize to localize
2025-06-13 01:26:37,383 - INFO - EURUSD: 新しい足 (M5) が形成されました。データ取得とシグナル判定を実行します。
2025-06-13 01:26:37,388 - ERROR - EURUSD: シグナル監視ループで予期せぬエラーが発生しました: Cannot convert tz-naive timestamps, use tz_localize to localize
Traceback (most recent call last):
  File "C:\Users\pc\OneDrive\Desktop\phantom_alert_bot\signal_runner_loop.py", line 192, in _run
    df, latest_time_tokyo = self._get_current_ohlc()
                            ^^^^^^^^^^^^^^^^^^^^^^^^
  File "C:\Users\pc\OneDrive\Desktop\phantom_alert_bot\signal_runner_loop.py", line 116, in _get_current_ohlc
    df.index = df.index.tz_convert('Asia/Tokyo') # チャート描画時などのため
               ^^^^^^^^^^^^^^^^^^^^^^^^^^^^^^^^^
  File "C:\Users\pc\OneDrive\Desktop\phantom_alert_bot\venv\Lib\site-packages\pandas\core\indexes\datetimes.py", line 283, in tz_convert
    arr = self._data.tz_convert(tz)
          ^^^^^^^^^^^^^^^^^^^^^^^^^
  File "C:\Users\pc\OneDrive\Desktop\phantom_alert_bot\venv\Lib\site-packages\pandas\core\arrays\datetimes.py", line 917, in tz_convert
    raise TypeError(
TypeError: Cannot convert tz-naive timestamps, use tz_localize to localize
2025-06-13 01:27:37,391 - INFO - EURUSD: 新しい足 (M5) が形成されました。データ取得とシグナル判定を実行します。
2025-06-13 01:27:37,399 - ERROR - EURUSD: シグナル監視ループで予期せぬエラーが発生しました: Cannot convert tz-naive timestamps, use tz_localize to localize
Traceback (most recent call last):
  File "C:\Users\pc\OneDrive\Desktop\phantom_alert_bot\signal_runner_loop.py", line 192, in _run
    df, latest_time_tokyo = self._get_current_ohlc()
                            ^^^^^^^^^^^^^^^^^^^^^^^^
  File "C:\Users\pc\OneDrive\Desktop\phantom_alert_bot\signal_runner_loop.py", line 116, in _get_current_ohlc
    df.index = df.index.tz_convert('Asia/Tokyo') # チャート描画時などのため
               ^^^^^^^^^^^^^^^^^^^^^^^^^^^^^^^^^
  File "C:\Users\pc\OneDrive\Desktop\phantom_alert_bot\venv\Lib\site-packages\pandas\core\indexes\datetimes.py", line 283, in tz_convert
    arr = self._data.tz_convert(tz)
          ^^^^^^^^^^^^^^^^^^^^^^^^^
  File "C:\Users\pc\OneDrive\Desktop\phantom_alert_bot\venv\Lib\site-packages\pandas\core\arrays\datetimes.py", line 917, in tz_convert
    raise TypeError(
TypeError: Cannot convert tz-naive timestamps, use tz_localize to localize
2025-06-13 01:28:37,402 - INFO - EURUSD: 新しい足 (M5) が形成されました。データ取得とシグナル判定を実行します。
2025-06-13 01:28:37,409 - ERROR - EURUSD: シグナル監視ループで予期せぬエラーが発生しました: Cannot convert tz-naive timestamps, use tz_localize to localize
Traceback (most recent call last):
  File "C:\Users\pc\OneDrive\Desktop\phantom_alert_bot\signal_runner_loop.py", line 192, in _run
    if self.line_notifier:
                        ^^^
  File "C:\Users\pc\OneDrive\Desktop\phantom_alert_bot\signal_runner_loop.py", line 116, in _get_current_ohlc
  File "C:\Users\pc\OneDrive\Desktop\phantom_alert_bot\venv\Lib\site-packages\pandas\core\indexes\datetimes.py", line 283, in tz_convert
    arr = self._data.tz_convert(tz)
          ^^^^^^^^^^^^^^^^^^^^^^^^^
  File "C:\Users\pc\OneDrive\Desktop\phantom_alert_bot\venv\Lib\site-packages\pandas\core\arrays\datetimes.py", line 917, in tz_convert
    raise TypeError(
TypeError: Cannot convert tz-naive timestamps, use tz_localize to localize
