2025-06-11 18:43:24,125 - INFO - ✅ BTCUSDT-H1 シグナルランナーが初期化されました。
2025-06-11 18:43:39,165 - INFO - BTCUSDT-H1 シグナル監視ループを開始します。
2025-06-11 18:43:39,167 - INFO - BTCUSDT: MT5クライアントを初期化しています...
2025-06-11 18:43:39,169 - INFO - ✅ BTCUSDT: MT5クライアントの初期化に成功しました。
2025-06-11 18:43:39,169 - INFO - BTCUSDT: 新しい足 (H1) が形成されました。データ取得とシグナル判定を実行します。
2025-06-11 18:43:39,170 - ERROR - BTCUSDT: シグナル監視ループで予期せぬエラーが発生しました: module 'MetaTrader5' has no attribute 'is_connected'
Traceback (most recent call last):
  File "c:\Users\pc\OneDrive\Desktop\phantom_alert_bot\signal_runner_loop.py", line 190, in _run
    df, latest_time_tokyo = self._get_current_ohlc()
                            ~~~~~~~~~~~~~~~~~~~~~~^^
  File "c:\Users\pc\OneDrive\Desktop\phantom_alert_bot\signal_runner_loop.py", line 85, in _get_current_ohlc
    if not self._initialize_mt5():
           ~~~~~~~~~~~~~~~~~~~~^^
  File "c:\Users\pc\OneDrive\Desktop\phantom_alert_bot\signal_runner_loop.py", line 65, in _initialize_mt5
    if not self.mt5_initialized or not mt5.is_connected():
                                       ^^^^^^^^^^^^^^^^
AttributeError: module 'MetaTrader5' has no attribute 'is_connected'
2025-06-11 18:54:29,467 - INFO - ✅ BTCUSDT-H1 シグナルランナーが初期化されました。
2025-06-11 18:54:44,522 - INFO - BTCUSDT-H1 シグナル監視ループを開始します。
2025-06-11 18:54:44,524 - INFO - BTCUSDT: MT5クライアントを初期化しています...
2025-06-11 18:54:44,525 - INFO - ✅ BTCUSDT: MT5クライアントの初期化に成功しました。
2025-06-11 18:54:44,526 - INFO - BTCUSDT: 新しい足 (H1) が形成されました。データ取得とシグナル判定を実行します。
2025-06-11 18:54:44,575 - ERROR - BTCUSDT: シグナル監視ループで予期せぬエラーが発生しました: generate_signal() got an unexpected keyword argument 'logic'
Traceback (most recent call last):
  File "c:\Users\pc\OneDrive\Desktop\phantom_alert_bot\signal_runner_loop.py", line 177, in _run
    signal_info = generate_signal(df, mode="realtime", logic=DEFAULT_LOGIC) # modeとlogicを渡す
TypeError: generate_signal() got an unexpected keyword argument 'logic'
2025-06-12 00:09:30,909 - INFO - ✅ BTCUSDT-H1 シグナルランナーが初期化されました。
2025-06-12 00:09:46,003 - INFO - BTCUSDT-H1 シグナル監視ループを開始します。
2025-06-12 00:09:46,003 - INFO - BTCUSDT: MT5クライアントを初期化しています...
2025-06-12 00:09:46,003 - INFO - ✅ BTCUSDT: MT5クライアントの初期化に成功しました。
2025-06-12 00:09:46,003 - INFO - BTCUSDT: 新しい足 (H1) が形成されました。データ取得とシグナル判定を実行します。
2025-06-12 00:09:46,026 - INFO - BTCUSDT-H1 シグナル判定結果: No signal
2025-06-12 00:09:46,026 - INFO - BTCUSDT-H1: シグナルなし。
2025-06-12 00:09:46,026 - ERROR - BTCUSDT: シグナル監視ループで予期せぬエラーが発生しました: cannot access local variable 'uploaded_image_url' where it is not associated with a value
Traceback (most recent call last):
  File "c:\Users\pc\OneDrive\Desktop\phantom_alert_bot\signal_runner_loop.py", line 230, in _run
    image_url=uploaded_image_url # ImgurのURLを保存
              ^^^^^^^^^^^^^^^^^^
UnboundLocalError: cannot access local variable 'uploaded_image_url' where it is not associated with a value
2025-06-12 00:10:15,493 - INFO - ✅ BTCUSDT-H1 シグナルランナーが初期化されました。
2025-06-12 00:10:30,532 - INFO - BTCUSDT-H1 シグナル監視ループを開始します。
2025-06-12 00:10:30,536 - INFO - BTCUSDT: MT5クライアントを初期化しています...
2025-06-12 00:10:30,538 - INFO - ✅ BTCUSDT: MT5クライアントの初期化に成功しました。
2025-06-12 00:10:30,540 - INFO - BTCUSDT: 新しい足 (H1) が形成されました。データ取得とシグナル判定を実行します。
2025-06-12 00:10:30,589 - INFO - BTCUSDT-H1 シグナル判定結果: No signal
2025-06-12 00:10:30,590 - INFO - BTCUSDT-H1: シグナルなし。
2025-06-12 00:10:30,590 - ERROR - BTCUSDT: シグナル監視ループで予期せぬエラーが発生しました: cannot access local variable 'uploaded_image_url' where it is not associated with a value
Traceback (most recent call last):
  File "C:\Users\pc\OneDrive\Desktop\phantom_alert_bot\signal_runner_loop.py", line 230, in _run
    image_url=uploaded_image_url # ImgurのURLを保存
              ^^^^^^^^^^^^^^^^^^
UnboundLocalError: cannot access local variable 'uploaded_image_url' where it is not associated with a value
2025-06-12 00:11:00,900 - INFO - ✅ BTCUSDT-H1 シグナルランナーが初期化されました。
2025-06-12 00:11:02,797 - INFO - ✅ BTCUSDT-H1 シグナルランナーが初期化されました。
2025-06-12 00:11:15,931 - INFO - BTCUSDT-H1 シグナル監視ループを開始します。
2025-06-12 00:11:15,933 - INFO - BTCUSDT: MT5クライアントを初期化しています...
2025-06-12 00:11:15,934 - INFO - ✅ BTCUSDT: MT5クライアントの初期化に成功しました。
2025-06-12 00:11:15,935 - INFO - BTCUSDT: 新しい足 (H1) が形成されました。データ取得とシグナル判定を実行します。
2025-06-12 00:11:15,970 - INFO - BTCUSDT-H1 シグナル判定結果: No signal
2025-06-12 00:11:15,970 - INFO - BTCUSDT-H1: シグナルなし。
2025-06-12 00:11:15,971 - ERROR - BTCUSDT: シグナル監視ループで予期せぬエラーが発生しました: cannot access local variable 'uploaded_image_url' where it is not associated with a value
Traceback (most recent call last):
  File "C:\Users\pc\OneDrive\Desktop\phantom_alert_bot\signal_runner_loop.py", line 230, in _run
    image_url=uploaded_image_url # ImgurのURLを保存
              ^^^^^^^^^^^^^^^^^^
UnboundLocalError: cannot access local variable 'uploaded_image_url' where it is not associated with a value
2025-06-12 00:11:17,838 - INFO - BTCUSDT-H1 シグナル監視ループを開始します。
2025-06-12 00:11:17,839 - INFO - BTCUSDT: MT5クライアントを初期化しています...
2025-06-12 00:11:17,839 - INFO - ✅ BTCUSDT: MT5クライアントの初期化に成功しました。
2025-06-12 00:11:17,840 - INFO - BTCUSDT: 新しい足 (H1) が形成されました。データ取得とシグナル判定を実行します。
2025-06-12 00:11:17,869 - INFO - BTCUSDT-H1 シグナル判定結果: No signal
2025-06-12 00:11:17,869 - INFO - BTCUSDT-H1: シグナルなし。
2025-06-12 00:11:17,869 - ERROR - BTCUSDT: シグナル監視ループで予期せぬエラーが発生しました: cannot access local variable 'uploaded_image_url' where it is not associated with a value
Traceback (most recent call last):
  File "C:\Users\pc\OneDrive\Desktop\phantom_alert_bot\signal_runner_loop.py", line 230, in _run
    image_url=uploaded_image_url # ImgurのURLを保存
              ^^^^^^^^^^^^^^^^^^
UnboundLocalError: cannot access local variable 'uploaded_image_url' where it is not associated with a value
2025-06-12 00:21:46,028 - INFO - BTCUSDT: 新しい足 (H1) が形成されました。データ取得とシグナル判定を実行します。
2025-06-12 00:21:46,052 - INFO - BTCUSDT-H1 シグナル判定結果: No signal
2025-06-12 00:21:46,052 - INFO - BTCUSDT-H1: シグナルなし。
2025-06-12 00:21:46,053 - ERROR - BTCUSDT: シグナル監視ループで予期せぬエラーが発生しました: cannot access local variable 'uploaded_image_url' where it is not associated with a value
Traceback (most recent call last):
  File "c:\Users\pc\OneDrive\Desktop\phantom_alert_bot\signal_runner_loop.py", line 230, in _run
UnboundLocalError: cannot access local variable 'uploaded_image_url' where it is not associated with a value
2025-06-12 00:23:15,985 - INFO - BTCUSDT: 新しい足 (H1) が形成されました。データ取得とシグナル判定を実行します。
2025-06-12 00:23:16,037 - INFO - BTCUSDT-H1 シグナル判定結果: No signal
2025-06-12 00:23:16,037 - INFO - BTCUSDT-H1: シグナルなし。
2025-06-12 00:23:16,037 - ERROR - BTCUSDT: シグナル監視ループで予期せぬエラーが発生しました: cannot access local variable 'uploaded_image_url' where it is not associated with a value
Traceback (most recent call last):
  File "C:\Users\pc\OneDrive\Desktop\phantom_alert_bot\signal_runner_loop.py", line 230, in _run
UnboundLocalError: cannot access local variable 'uploaded_image_url' where it is not associated with a value
2025-06-12 00:23:17,871 - INFO - BTCUSDT: 新しい足 (H1) が形成されました。データ取得とシグナル判定を実行します。
2025-06-12 00:23:17,917 - INFO - BTCUSDT-H1 シグナル判定結果: No signal
2025-06-12 00:23:17,917 - INFO - BTCUSDT-H1: シグナルなし。
2025-06-12 00:23:17,918 - ERROR - BTCUSDT: シグナル監視ループで予期せぬエラーが発生しました: cannot access local variable 'uploaded_image_url' where it is not associated with a value
Traceback (most recent call last):
  File "C:\Users\pc\OneDrive\Desktop\phantom_alert_bot\signal_runner_loop.py", line 230, in _run
UnboundLocalError: cannot access local variable 'uploaded_image_url' where it is not associated with a value
2025-06-12 00:33:46,055 - INFO - BTCUSDT: 新しい足 (H1) が形成されました。データ取得とシグナル判定を実行します。
2025-06-12 00:33:46,105 - INFO - BTCUSDT-H1 シグナル判定結果: No signal
2025-06-12 00:33:46,105 - INFO - BTCUSDT-H1: シグナルなし。
2025-06-12 00:33:46,108 - ERROR - BTCUSDT: シグナル監視ループで予期せぬエラーが発生しました: cannot access local variable 'uploaded_image_url' where it is not associated with a value
Traceback (most recent call last):
  File "c:\Users\pc\OneDrive\Desktop\phantom_alert_bot\signal_runner_loop.py", line 230, in _run
UnboundLocalError: cannot access local variable 'uploaded_image_url' where it is not associated with a value
2025-06-12 00:35:16,039 - INFO - BTCUSDT: 新しい足 (H1) が形成されました。データ取得とシグナル判定を実行します。
2025-06-12 00:35:16,085 - INFO - BTCUSDT-H1 シグナル判定結果: No signal
2025-06-12 00:35:16,085 - INFO - BTCUSDT-H1: シグナルなし。
2025-06-12 00:35:16,086 - ERROR - BTCUSDT: シグナル監視ループで予期せぬエラーが発生しました: cannot access local variable 'uploaded_image_url' where it is not associated with a value
Traceback (most recent call last):
  File "C:\Users\pc\OneDrive\Desktop\phantom_alert_bot\signal_runner_loop.py", line 230, in _run
UnboundLocalError: cannot access local variable 'uploaded_image_url' where it is not associated with a value
2025-06-12 00:35:17,920 - INFO - BTCUSDT: 新しい足 (H1) が形成されました。データ取得とシグナル判定を実行します。
2025-06-12 00:35:17,959 - INFO - BTCUSDT-H1 シグナル判定結果: No signal
2025-06-12 00:35:17,961 - INFO - BTCUSDT-H1: シグナルなし。
2025-06-12 00:35:17,962 - ERROR - BTCUSDT: シグナル監視ループで予期せぬエラーが発生しました: cannot access local variable 'uploaded_image_url' where it is not associated with a value
Traceback (most recent call last):
  File "C:\Users\pc\OneDrive\Desktop\phantom_alert_bot\signal_runner_loop.py", line 230, in _run
UnboundLocalError: cannot access local variable 'uploaded_image_url' where it is not associated with a value
2025-06-12 00:45:46,112 - INFO - BTCUSDT: 新しい足 (H1) が形成されました。データ取得とシグナル判定を実行します。
2025-06-12 00:45:46,170 - INFO - BTCUSDT-H1 シグナル判定結果: No signal
2025-06-12 00:45:46,171 - INFO - BTCUSDT-H1: シグナルなし。
2025-06-12 00:45:46,171 - ERROR - BTCUSDT: シグナル監視ループで予期せぬエラーが発生しました: cannot access local variable 'uploaded_image_url' where it is not associated with a value
Traceback (most recent call last):
  File "c:\Users\pc\OneDrive\Desktop\phantom_alert_bot\signal_runner_loop.py", line 230, in _run
UnboundLocalError: cannot access local variable 'uploaded_image_url' where it is not associated with a value
2025-06-12 00:47:16,087 - INFO - BTCUSDT: 新しい足 (H1) が形成されました。データ取得とシグナル判定を実行します。
2025-06-12 00:47:16,127 - INFO - BTCUSDT-H1 シグナル判定結果: No signal
2025-06-12 00:47:16,128 - INFO - BTCUSDT-H1: シグナルなし。
2025-06-12 00:47:16,128 - ERROR - BTCUSDT: シグナル監視ループで予期せぬエラーが発生しました: cannot access local variable 'uploaded_image_url' where it is not associated with a value
Traceback (most recent call last):
  File "C:\Users\pc\OneDrive\Desktop\phantom_alert_bot\signal_runner_loop.py", line 230, in _run
UnboundLocalError: cannot access local variable 'uploaded_image_url' where it is not associated with a value
2025-06-12 00:47:17,965 - INFO - BTCUSDT: 新しい足 (H1) が形成されました。データ取得とシグナル判定を実行します。
2025-06-12 00:47:18,004 - INFO - BTCUSDT-H1 シグナル判定結果: No signal
2025-06-12 00:47:18,005 - INFO - BTCUSDT-H1: シグナルなし。
2025-06-12 00:47:18,005 - ERROR - BTCUSDT: シグナル監視ループで予期せぬエラーが発生しました: cannot access local variable 'uploaded_image_url' where it is not associated with a value
Traceback (most recent call last):
  File "C:\Users\pc\OneDrive\Desktop\phantom_alert_bot\signal_runner_loop.py", line 230, in _run
UnboundLocalError: cannot access local variable 'uploaded_image_url' where it is not associated with a value
2025-06-12 10:40:26,322 - INFO - ✅ BTCUSDT-H1 シグナルランナーが初期化されました。
2025-06-12 10:40:41,380 - INFO - BTCUSDT-H1 シグナル監視ループを開始します。
2025-06-12 10:40:41,382 - INFO - BTCUSDT: MT5クライアントを初期化しています...
2025-06-12 10:40:41,385 - INFO - ✅ BTCUSDT: MT5クライアントの初期化に成功しました。
2025-06-12 10:40:41,386 - INFO - BTCUSDT: 新しい足 (H1) が形成されました。データ取得とシグナル判定を実行します。
2025-06-12 10:40:41,464 - ERROR - BTCUSDT: シグナル監視ループで予期せぬエラーが発生しました: 'MACD_Signal'
Traceback (most recent call last):
  File "C:\Users\pc\AppData\Local\Programs\Python\Python312\Lib\site-packages\pandas\core\indexes\base.py", line 3812, in get_loc
    return self._engine.get_loc(casted_key)
           ^^^^^^^^^^^^^^^^^^^^^^^^^^^^^^^^
  File "pandas/_libs/index.pyx", line 167, in pandas._libs.index.IndexEngine.get_loc
  File "pandas/_libs/index.pyx", line 196, in pandas._libs.index.IndexEngine.get_loc
  File "pandas/_libs/hashtable_class_helper.pxi", line 7088, in pandas._libs.hashtable.PyObjectHashTable.get_item
  File "pandas/_libs/hashtable_class_helper.pxi", line 7096, in pandas._libs.hashtable.PyObjectHashTable.get_item
KeyError: 'MACD_Signal'

The above exception was the direct cause of the following exception:

Traceback (most recent call last):
  File "c:\Users\pc\OneDrive\Desktop\phantom_alert_bot\signal_runner_loop.py", line 196, in _run
    signal_info = generate_signal(df, mode="realtime", logic=DEFAULT_LOGIC) # modeとlogicを渡す
                  ^^^^^^^^^^^^^^^^^^^^^^^^^^^^^^^^^^^^^^^^^^^^^^^^^^^^^^^^^
  File "c:\Users\pc\OneDrive\Desktop\phantom_alert_bot\signal_generator.py", line 71, in generate_signal
    signal_info = _generate_balanced_signal(df_ind, current_price)
                  ^^^^^^^^^^^^^^^^^^^^^^^^^^^^^^^^^^^^^^^^^^^^^^^^
  File "c:\Users\pc\OneDrive\Desktop\phantom_alert_bot\signal_generator.py", line 192, in _generate_balanced_signal
    macd_buy = (df_ind['MACD'].iloc[-1] > df_ind['MACD_Signal'].iloc[-1]) # MACDゴールデンクロス
                                          ~~~~~~^^^^^^^^^^^^^^^
  File "C:\Users\pc\AppData\Local\Programs\Python\Python312\Lib\site-packages\pandas\core\frame.py", line 4107, in __getitem__
    indexer = self.columns.get_loc(key)
              ^^^^^^^^^^^^^^^^^^^^^^^^^
  File "C:\Users\pc\AppData\Local\Programs\Python\Python312\Lib\site-packages\pandas\core\indexes\base.py", line 3819, in get_loc
    raise KeyError(key) from err
KeyError: 'MACD_Signal'
2025-06-13 01:18:32,307 - INFO - ✅ BTCUSDT-H1 シグナルランナーが初期化されました。
2025-06-13 01:18:47,359 - INFO - BTCUSDT-H1 シグナル監視ループを開始します。
2025-06-13 01:18:47,363 - INFO - BTCUSDT: MT5クライアントを初期化しています...
2025-06-13 01:18:47,367 - INFO - ✅ BTCUSDT: MT5クライアントの初期化に成功しました。
2025-06-13 01:18:47,369 - INFO - BTCUSDT: 新しい足 (H1) が形成されました。データ取得とシグナル判定を実行します。
2025-06-13 01:18:47,383 - ERROR - BTCUSDT: シグナル監視ループで予期せぬエラーが発生しました: Cannot convert tz-naive timestamps, use tz_localize to localize
Traceback (most recent call last):
  File "C:\Users\pc\OneDrive\Desktop\phantom_alert_bot\signal_runner_loop.py", line 192, in _run
    df, latest_time_tokyo = self._get_current_ohlc()
                            ^^^^^^^^^^^^^^^^^^^^^^^^
  File "C:\Users\pc\OneDrive\Desktop\phantom_alert_bot\signal_runner_loop.py", line 116, in _get_current_ohlc
    df.index = df.index.tz_convert('Asia/Tokyo') # チャート描画時などのため
               ^^^^^^^^^^^^^^^^^^^^^^^^^^^^^^^^^
  File "C:\Users\pc\OneDrive\Desktop\phantom_alert_bot\venv\Lib\site-packages\pandas\core\indexes\datetimes.py", line 283, in tz_convert
    arr = self._data.tz_convert(tz)
          ^^^^^^^^^^^^^^^^^^^^^^^^^
  File "C:\Users\pc\OneDrive\Desktop\phantom_alert_bot\venv\Lib\site-packages\pandas\core\arrays\datetimes.py", line 917, in tz_convert
    raise TypeError(
TypeError: Cannot convert tz-naive timestamps, use tz_localize to localize
