2025-06-11 18:43:24,104 - INFO - ✅ GOLD_USD-M5 シグナルランナーが初期化されました。
2025-06-11 18:43:33,149 - INFO - GOLD_USD-M5 シグナル監視ループを開始します。
2025-06-11 18:43:33,150 - INFO - GOLD_USD: MT5クライアントを初期化しています...
2025-06-11 18:43:33,152 - INFO - ✅ GOLD_USD: MT5クライアントの初期化に成功しました。
2025-06-11 18:43:33,153 - INFO - GOLD_USD: 新しい足 (M5) が形成されました。データ取得とシグナル判定を実行します。
2025-06-11 18:43:33,154 - ERROR - GOLD_USD: シグナル監視ループで予期せぬエラーが発生しました: module 'MetaTrader5' has no attribute 'is_connected'
Traceback (most recent call last):
  File "c:\Users\pc\OneDrive\Desktop\phantom_alert_bot\signal_runner_loop.py", line 190, in _run
    df, latest_time_tokyo = self._get_current_ohlc()
                            ~~~~~~~~~~~~~~~~~~~~~~^^
  File "c:\Users\pc\OneDrive\Desktop\phantom_alert_bot\signal_runner_loop.py", line 85, in _get_current_ohlc
    if not self._initialize_mt5():
           ~~~~~~~~~~~~~~~~~~~~^^
  File "c:\Users\pc\OneDrive\Desktop\phantom_alert_bot\signal_runner_loop.py", line 65, in _initialize_mt5
    if not self.mt5_initialized or not mt5.is_connected():
                                       ^^^^^^^^^^^^^^^^
AttributeError: module 'MetaTrader5' has no attribute 'is_connected'
2025-06-11 18:44:33,163 - INFO - GOLD_USD: 新しい足 (M5) が形成されました。データ取得とシグナル判定を実行します。
2025-06-11 18:44:33,164 - ERROR - GOLD_USD: シグナル監視ループで予期せぬエラーが発生しました: module 'MetaTrader5' has no attribute 'is_connected'
Traceback (most recent call last):
  File "c:\Users\pc\OneDrive\Desktop\phantom_alert_bot\signal_runner_loop.py", line 190, in _run
    df, latest_time_tokyo = self._get_current_ohlc()
                            ~~~~~~~~~~~~~~~~~~~~~~^^
  File "c:\Users\pc\OneDrive\Desktop\phantom_alert_bot\signal_runner_loop.py", line 85, in _get_current_ohlc
    if not self._initialize_mt5():
           ~~~~~~~~~~~~~~~~~~~~^^
  File "c:\Users\pc\OneDrive\Desktop\phantom_alert_bot\signal_runner_loop.py", line 65, in _initialize_mt5
    if not self.mt5_initialized or not mt5.is_connected():
                                       ^^^^^^^^^^^^^^^^
AttributeError: module 'MetaTrader5' has no attribute 'is_connected'
2025-06-11 18:45:33,167 - INFO - GOLD_USD: 新しい足 (M5) が形成されました。データ取得とシグナル判定を実行します。
2025-06-11 18:45:33,168 - ERROR - GOLD_USD: シグナル監視ループで予期せぬエラーが発生しました: module 'MetaTrader5' has no attribute 'is_connected'
Traceback (most recent call last):
  File "c:\Users\pc\OneDrive\Desktop\phantom_alert_bot\signal_runner_loop.py", line 190, in _run
    df, latest_time_tokyo = self._get_current_ohlc()
                            ~~~~~~~~~~~~~~~~~~~~~~^^
  File "c:\Users\pc\OneDrive\Desktop\phantom_alert_bot\signal_runner_loop.py", line 85, in _get_current_ohlc
    if not self._initialize_mt5():
           ~~~~~~~~~~~~~~~~~~~~^^
  File "c:\Users\pc\OneDrive\Desktop\phantom_alert_bot\signal_runner_loop.py", line 65, in _initialize_mt5
    if not self.mt5_initialized or not mt5.is_connected():
                                       ^^^^^^^^^^^^^^^^
AttributeError: module 'MetaTrader5' has no attribute 'is_connected'
2025-06-11 18:46:33,172 - INFO - GOLD_USD: 新しい足 (M5) が形成されました。データ取得とシグナル判定を実行します。
2025-06-11 18:46:33,173 - ERROR - GOLD_USD: シグナル監視ループで予期せぬエラーが発生しました: module 'MetaTrader5' has no attribute 'is_connected'
Traceback (most recent call last):
  File "c:\Users\pc\OneDrive\Desktop\phantom_alert_bot\signal_runner_loop.py", line 190, in _run
    df, latest_time_tokyo = self._get_current_ohlc()
                            ~~~~~~~~~~~~~~~~~~~~~~^^
  File "c:\Users\pc\OneDrive\Desktop\phantom_alert_bot\signal_runner_loop.py", line 85, in _get_current_ohlc
    if not self._initialize_mt5():
           ~~~~~~~~~~~~~~~~~~~~^^
  File "c:\Users\pc\OneDrive\Desktop\phantom_alert_bot\signal_runner_loop.py", line 65, in _initialize_mt5
    if not self.mt5_initialized or not mt5.is_connected():
                                       ^^^^^^^^^^^^^^^^
AttributeError: module 'MetaTrader5' has no attribute 'is_connected'
2025-06-11 18:47:33,177 - INFO - GOLD_USD: 新しい足 (M5) が形成されました。データ取得とシグナル判定を実行します。
2025-06-11 18:47:33,179 - ERROR - GOLD_USD: シグナル監視ループで予期せぬエラーが発生しました: module 'MetaTrader5' has no attribute 'is_connected'
Traceback (most recent call last):
  File "c:\Users\pc\OneDrive\Desktop\phantom_alert_bot\signal_runner_loop.py", line 190, in _run
    df, latest_time_tokyo = self._get_current_ohlc()
                            ~~~~~~~~~~~~~~~~~~~~~~^^
  File "c:\Users\pc\OneDrive\Desktop\phantom_alert_bot\signal_runner_loop.py", line 85, in _get_current_ohlc
    if not self._initialize_mt5():
           ~~~~~~~~~~~~~~~~~~~~^^
  File "c:\Users\pc\OneDrive\Desktop\phantom_alert_bot\signal_runner_loop.py", line 65, in _initialize_mt5
    if not self.mt5_initialized or not mt5.is_connected():
                                       ^^^^^^^^^^^^^^^^
AttributeError: module 'MetaTrader5' has no attribute 'is_connected'
2025-06-11 18:48:33,184 - INFO - GOLD_USD: 新しい足 (M5) が形成されました。データ取得とシグナル判定を実行します。
2025-06-11 18:48:33,185 - ERROR - GOLD_USD: シグナル監視ループで予期せぬエラーが発生しました: module 'MetaTrader5' has no attribute 'is_connected'
Traceback (most recent call last):
  File "c:\Users\pc\OneDrive\Desktop\phantom_alert_bot\signal_runner_loop.py", line 190, in _run
    df, latest_time_tokyo = self._get_current_ohlc()
                            ~~~~~~~~~~~~~~~~~~~~~~^^
  File "c:\Users\pc\OneDrive\Desktop\phantom_alert_bot\signal_runner_loop.py", line 85, in _get_current_ohlc
    if not self._initialize_mt5():
           ~~~~~~~~~~~~~~~~~~~~^^
  File "c:\Users\pc\OneDrive\Desktop\phantom_alert_bot\signal_runner_loop.py", line 65, in _initialize_mt5
    if not self.mt5_initialized or not mt5.is_connected():
                                       ^^^^^^^^^^^^^^^^
AttributeError: module 'MetaTrader5' has no attribute 'is_connected'
2025-06-11 18:49:33,186 - INFO - GOLD_USD: 新しい足 (M5) が形成されました。データ取得とシグナル判定を実行します。
2025-06-11 18:49:33,186 - ERROR - GOLD_USD: シグナル監視ループで予期せぬエラーが発生しました: module 'MetaTrader5' has no attribute 'is_connected'
Traceback (most recent call last):
  File "c:\Users\pc\OneDrive\Desktop\phantom_alert_bot\signal_runner_loop.py", line 190, in _run
    df, latest_time_tokyo = self._get_current_ohlc()
                            ~~~~~~~~~~~~~~~~~~~~~~^^
  File "c:\Users\pc\OneDrive\Desktop\phantom_alert_bot\signal_runner_loop.py", line 85, in _get_current_ohlc
    if not self._initialize_mt5():
           ~~~~~~~~~~~~~~~~~~~~^^
  File "c:\Users\pc\OneDrive\Desktop\phantom_alert_bot\signal_runner_loop.py", line 65, in _initialize_mt5
    if not self.mt5_initialized or not mt5.is_connected():
                                       ^^^^^^^^^^^^^^^^
AttributeError: module 'MetaTrader5' has no attribute 'is_connected'
2025-06-11 18:50:33,188 - INFO - GOLD_USD: 新しい足 (M5) が形成されました。データ取得とシグナル判定を実行します。
2025-06-11 18:50:33,189 - ERROR - GOLD_USD: シグナル監視ループで予期せぬエラーが発生しました: module 'MetaTrader5' has no attribute 'is_connected'
Traceback (most recent call last):
  File "c:\Users\pc\OneDrive\Desktop\phantom_alert_bot\signal_runner_loop.py", line 190, in _run
  File "c:\Users\pc\OneDrive\Desktop\phantom_alert_bot\signal_runner_loop.py", line 85, in _get_current_ohlc
    self.logger.info(f"✅ {self.symbol}: MT5クライアントをシャットダウンしました。")
       ^^^^^^^^^^^^^^^^^^^^^
  File "c:\Users\pc\OneDrive\Desktop\phantom_alert_bot\signal_runner_loop.py", line 65, in _initialize_mt5
    # mt5.is_connected() は最新のMetaTrader5 APIには存在しないため削除
AttributeError: module 'MetaTrader5' has no attribute 'is_connected'
2025-06-11 18:54:29,457 - INFO - ✅ GOLD_USD-M5 シグナルランナーが初期化されました。
2025-06-11 18:54:38,498 - INFO - GOLD_USD-M5 シグナル監視ループを開始します。
2025-06-11 18:54:38,499 - INFO - GOLD_USD: MT5クライアントを初期化しています...
2025-06-11 18:54:38,501 - INFO - ✅ GOLD_USD: MT5クライアントの初期化に成功しました。
2025-06-11 18:54:38,503 - INFO - GOLD_USD: 新しい足 (M5) が形成されました。データ取得とシグナル判定を実行します。
2025-06-11 18:54:38,540 - ERROR - GOLD_USD: シグナル監視ループで予期せぬエラーが発生しました: generate_signal() got an unexpected keyword argument 'logic'
Traceback (most recent call last):
  File "c:\Users\pc\OneDrive\Desktop\phantom_alert_bot\signal_runner_loop.py", line 177, in _run
    signal_info = generate_signal(df, mode="realtime", logic=DEFAULT_LOGIC) # modeとlogicを渡す
TypeError: generate_signal() got an unexpected keyword argument 'logic'
2025-06-11 18:55:38,542 - INFO - GOLD_USD: 新しい足 (M5) が形成されました。データ取得とシグナル判定を実行します。
2025-06-11 18:55:38,544 - ERROR - GOLD_USD: シグナル監視ループで予期せぬエラーが発生しました: generate_signal() got an unexpected keyword argument 'logic'
Traceback (most recent call last):
  File "c:\Users\pc\OneDrive\Desktop\phantom_alert_bot\signal_runner_loop.py", line 177, in _run
    signal_info = generate_signal(df, mode="realtime", logic=DEFAULT_LOGIC) # modeとlogicを渡す
TypeError: generate_signal() got an unexpected keyword argument 'logic'
2025-06-11 18:56:38,546 - INFO - GOLD_USD: 新しい足 (M5) が形成されました。データ取得とシグナル判定を実行します。
2025-06-11 18:56:38,552 - ERROR - GOLD_USD: シグナル監視ループで予期せぬエラーが発生しました: generate_signal() got an unexpected keyword argument 'logic'
Traceback (most recent call last):
  File "c:\Users\pc\OneDrive\Desktop\phantom_alert_bot\signal_runner_loop.py", line 177, in _run
    signal_info = generate_signal(df, mode="realtime", logic=DEFAULT_LOGIC) # modeとlogicを渡す
TypeError: generate_signal() got an unexpected keyword argument 'logic'
2025-06-11 18:57:38,554 - INFO - GOLD_USD: 新しい足 (M5) が形成されました。データ取得とシグナル判定を実行します。
2025-06-11 18:57:38,563 - ERROR - GOLD_USD: シグナル監視ループで予期せぬエラーが発生しました: generate_signal() got an unexpected keyword argument 'logic'
Traceback (most recent call last):
  File "c:\Users\pc\OneDrive\Desktop\phantom_alert_bot\signal_runner_loop.py", line 177, in _run
    signal_info = generate_signal(df, mode="realtime", logic=DEFAULT_LOGIC) # modeとlogicを渡す
TypeError: generate_signal() got an unexpected keyword argument 'logic'
2025-06-11 18:58:38,566 - INFO - GOLD_USD: 新しい足 (M5) が形成されました。データ取得とシグナル判定を実行します。
2025-06-11 18:58:38,571 - ERROR - GOLD_USD: シグナル監視ループで予期せぬエラーが発生しました: generate_signal() got an unexpected keyword argument 'logic'
Traceback (most recent call last):
  File "c:\Users\pc\OneDrive\Desktop\phantom_alert_bot\signal_runner_loop.py", line 177, in _run
    signal_info = generate_signal(df, mode="realtime", logic=DEFAULT_LOGIC) # modeとlogicを渡す
TypeError: generate_signal() got an unexpected keyword argument 'logic'
2025-06-11 18:59:38,574 - INFO - GOLD_USD: 新しい足 (M5) が形成されました。データ取得とシグナル判定を実行します。
2025-06-11 18:59:38,577 - ERROR - GOLD_USD: シグナル監視ループで予期せぬエラーが発生しました: generate_signal() got an unexpected keyword argument 'logic'
Traceback (most recent call last):
  File "c:\Users\pc\OneDrive\Desktop\phantom_alert_bot\signal_runner_loop.py", line 177, in _run
    signal_info = generate_signal(df, mode="realtime", logic=DEFAULT_LOGIC) # modeとlogicを渡す
TypeError: generate_signal() got an unexpected keyword argument 'logic'
2025-06-12 00:09:30,866 - INFO - ✅ GOLD_USD-M5 シグナルランナーが初期化されました。
2025-06-12 00:09:39,983 - INFO - GOLD_USD-M5 シグナル監視ループを開始します。
2025-06-12 00:09:39,985 - INFO - GOLD_USD: MT5クライアントを初期化しています...
2025-06-12 00:09:39,987 - INFO - ✅ GOLD_USD: MT5クライアントの初期化に成功しました。
2025-06-12 00:09:39,988 - INFO - GOLD_USD: 新しい足 (M5) が形成されました。データ取得とシグナル判定を実行します。
2025-06-12 00:09:40,046 - INFO - GOLD_USD-M5 シグナル判定結果: Balanced Buy Signal (Confluence: MACD Golden Cross, Stochastic Golden Cross)
2025-06-12 00:09:40,047 - ERROR - GOLD_USD: シグナル監視ループで予期せぬエラーが発生しました: 'SignalRunner' object has no attribute '_generate_chart_and_upload'
Traceback (most recent call last):
  File "c:\Users\pc\OneDrive\Desktop\phantom_alert_bot\signal_runner_loop.py", line 199, in _run
    uploaded_image_url = self._generate_chart_and_upload(df, signal_info, image_filename)
                         ^^^^^^^^^^^^^^^^^^^^^^^^^^^^^^^
AttributeError: 'SignalRunner' object has no attribute '_generate_chart_and_upload'
2025-06-12 00:10:15,485 - INFO - ✅ GOLD_USD-M5 シグナルランナーが初期化されました。
2025-06-12 00:10:24,519 - INFO - GOLD_USD-M5 シグナル監視ループを開始します。
2025-06-12 00:10:24,520 - INFO - GOLD_USD: MT5クライアントを初期化しています...
2025-06-12 00:10:24,522 - INFO - ✅ GOLD_USD: MT5クライアントの初期化に成功しました。
2025-06-12 00:10:24,523 - INFO - GOLD_USD: 新しい足 (M5) が形成されました。データ取得とシグナル判定を実行します。
2025-06-12 00:10:24,578 - INFO - GOLD_USD-M5 シグナル判定結果: No signal
2025-06-12 00:10:24,579 - INFO - GOLD_USD-M5: シグナルなし。
2025-06-12 00:10:24,580 - ERROR - GOLD_USD: シグナル監視ループで予期せぬエラーが発生しました: cannot access local variable 'uploaded_image_url' where it is not associated with a value
Traceback (most recent call last):
  File "C:\Users\pc\OneDrive\Desktop\phantom_alert_bot\signal_runner_loop.py", line 230, in _run
    image_url=uploaded_image_url # ImgurのURLを保存
              ^^^^^^^^^^^^^^^^^^
UnboundLocalError: cannot access local variable 'uploaded_image_url' where it is not associated with a value
2025-06-12 00:10:40,050 - INFO - GOLD_USD: 新しい足 (M5) が形成されました。データ取得とシグナル判定を実行します。
2025-06-12 00:10:40,074 - INFO - GOLD_USD-M5 シグナル判定結果: No signal
2025-06-12 00:10:40,075 - INFO - GOLD_USD-M5: シグナルなし。
2025-06-12 00:10:40,075 - ERROR - GOLD_USD: シグナル監視ループで予期せぬエラーが発生しました: cannot access local variable 'uploaded_image_url' where it is not associated with a value
Traceback (most recent call last):
  File "c:\Users\pc\OneDrive\Desktop\phantom_alert_bot\signal_runner_loop.py", line 230, in _run
    image_url=uploaded_image_url # ImgurのURLを保存
              ^^^^^^^^^^^^^^^^^^
UnboundLocalError: cannot access local variable 'uploaded_image_url' where it is not associated with a value
2025-06-12 00:11:00,893 - INFO - ✅ GOLD_USD-M5 シグナルランナーが初期化されました。
2025-06-12 00:11:02,791 - INFO - ✅ GOLD_USD-M5 シグナルランナーが初期化されました。
2025-06-12 00:11:09,920 - INFO - GOLD_USD-M5 シグナル監視ループを開始します。
2025-06-12 00:11:09,921 - INFO - GOLD_USD: MT5クライアントを初期化しています...
2025-06-12 00:11:09,922 - INFO - ✅ GOLD_USD: MT5クライアントの初期化に成功しました。
2025-06-12 00:11:09,922 - INFO - GOLD_USD: 新しい足 (M5) が形成されました。データ取得とシグナル判定を実行します。
2025-06-12 00:11:09,946 - INFO - GOLD_USD-M5 シグナル判定結果: No signal
2025-06-12 00:11:09,947 - INFO - GOLD_USD-M5: シグナルなし。
2025-06-12 00:11:09,947 - ERROR - GOLD_USD: シグナル監視ループで予期せぬエラーが発生しました: cannot access local variable 'uploaded_image_url' where it is not associated with a value
Traceback (most recent call last):
  File "C:\Users\pc\OneDrive\Desktop\phantom_alert_bot\signal_runner_loop.py", line 230, in _run
    image_url=uploaded_image_url # ImgurのURLを保存
              ^^^^^^^^^^^^^^^^^^
UnboundLocalError: cannot access local variable 'uploaded_image_url' where it is not associated with a value
2025-06-12 00:11:11,819 - INFO - GOLD_USD-M5 シグナル監視ループを開始します。
2025-06-12 00:11:11,820 - INFO - GOLD_USD: MT5クライアントを初期化しています...
2025-06-12 00:11:11,822 - INFO - ✅ GOLD_USD: MT5クライアントの初期化に成功しました。
2025-06-12 00:11:11,822 - INFO - GOLD_USD: 新しい足 (M5) が形成されました。データ取得とシグナル判定を実行します。
2025-06-12 00:11:11,846 - INFO - GOLD_USD-M5 シグナル判定結果: No signal
2025-06-12 00:11:11,846 - INFO - GOLD_USD-M5: シグナルなし。
2025-06-12 00:11:11,846 - ERROR - GOLD_USD: シグナル監視ループで予期せぬエラーが発生しました: cannot access local variable 'uploaded_image_url' where it is not associated with a value
Traceback (most recent call last):
  File "C:\Users\pc\OneDrive\Desktop\phantom_alert_bot\signal_runner_loop.py", line 230, in _run
    image_url=uploaded_image_url # ImgurのURLを保存
              ^^^^^^^^^^^^^^^^^^
UnboundLocalError: cannot access local variable 'uploaded_image_url' where it is not associated with a value
2025-06-12 00:11:24,583 - INFO - GOLD_USD: 新しい足 (M5) が形成されました。データ取得とシグナル判定を実行します。
2025-06-12 00:11:24,622 - INFO - GOLD_USD-M5 シグナル判定結果: No signal
2025-06-12 00:11:24,623 - INFO - GOLD_USD-M5: シグナルなし。
2025-06-12 00:11:24,623 - ERROR - GOLD_USD: シグナル監視ループで予期せぬエラーが発生しました: cannot access local variable 'uploaded_image_url' where it is not associated with a value
Traceback (most recent call last):
  File "C:\Users\pc\OneDrive\Desktop\phantom_alert_bot\signal_runner_loop.py", line 230, in _run
    image_url=uploaded_image_url # ImgurのURLを保存
              ^^^^^^^^^^^^^^^^^^
UnboundLocalError: cannot access local variable 'uploaded_image_url' where it is not associated with a value
2025-06-12 00:11:40,077 - INFO - GOLD_USD: 新しい足 (M5) が形成されました。データ取得とシグナル判定を実行します。
2025-06-12 00:11:40,098 - INFO - GOLD_USD-M5 シグナル判定結果: Balanced Buy Signal (Confluence: MACD Golden Cross, Stochastic Golden Cross)
2025-06-12 00:11:40,098 - ERROR - GOLD_USD: シグナル監視ループで予期せぬエラーが発生しました: 'SignalRunner' object has no attribute '_generate_chart_and_upload'
Traceback (most recent call last):
  File "c:\Users\pc\OneDrive\Desktop\phantom_alert_bot\signal_runner_loop.py", line 199, in _run
    uploaded_image_url = self._generate_chart_and_upload(df, signal_info, image_filename)
                         ^^^^^^^^^^^^^^^^^^^^^^^^^^^^^^^
AttributeError: 'SignalRunner' object has no attribute '_generate_chart_and_upload'
2025-06-12 00:12:09,948 - INFO - GOLD_USD: 新しい足 (M5) が形成されました。データ取得とシグナル判定を実行します。
2025-06-12 00:12:10,002 - INFO - GOLD_USD-M5 シグナル判定結果: No signal
2025-06-12 00:12:10,003 - INFO - GOLD_USD-M5: シグナルなし。
2025-06-12 00:12:10,003 - ERROR - GOLD_USD: シグナル監視ループで予期せぬエラーが発生しました: cannot access local variable 'uploaded_image_url' where it is not associated with a value
Traceback (most recent call last):
  File "C:\Users\pc\OneDrive\Desktop\phantom_alert_bot\signal_runner_loop.py", line 230, in _run
    image_url=uploaded_image_url # ImgurのURLを保存
              ^^^^^^^^^^^^^^^^^^
UnboundLocalError: cannot access local variable 'uploaded_image_url' where it is not associated with a value
2025-06-12 00:12:11,848 - INFO - GOLD_USD: 新しい足 (M5) が形成されました。データ取得とシグナル判定を実行します。
2025-06-12 00:12:11,910 - INFO - GOLD_USD-M5 シグナル判定結果: Balanced Buy Signal (Confluence: MACD Golden Cross, Stochastic Golden Cross)
2025-06-12 00:12:11,911 - ERROR - GOLD_USD: シグナル監視ループで予期せぬエラーが発生しました: 'SignalRunner' object has no attribute '_generate_chart_and_upload'
Traceback (most recent call last):
  File "C:\Users\pc\OneDrive\Desktop\phantom_alert_bot\signal_runner_loop.py", line 199, in _run
    uploaded_image_url = self._generate_chart_and_upload(df, signal_info, image_filename)
                         ^^^^^^^^^^^^^^^^^^^^^^^^^^^^^^^
AttributeError: 'SignalRunner' object has no attribute '_generate_chart_and_upload'
2025-06-12 00:12:24,625 - INFO - GOLD_USD: 新しい足 (M5) が形成されました。データ取得とシグナル判定を実行します。
2025-06-12 00:12:24,667 - INFO - GOLD_USD-M5 シグナル判定結果: Balanced Buy Signal (Confluence: MACD Golden Cross, Stochastic Golden Cross)
2025-06-12 00:12:24,667 - ERROR - GOLD_USD: シグナル監視ループで予期せぬエラーが発生しました: 'SignalRunner' object has no attribute '_generate_chart_and_upload'
Traceback (most recent call last):
  File "C:\Users\pc\OneDrive\Desktop\phantom_alert_bot\signal_runner_loop.py", line 199, in _run
    uploaded_image_url = self._generate_chart_and_upload(df, signal_info, image_filename)
                         ^^^^^^^^^^^^^^^^^^^^^^^^^^^^^^^
AttributeError: 'SignalRunner' object has no attribute '_generate_chart_and_upload'
2025-06-12 00:12:40,101 - INFO - GOLD_USD: 新しい足 (M5) が形成されました。データ取得とシグナル判定を実行します。
2025-06-12 00:12:40,121 - INFO - GOLD_USD-M5 シグナル判定結果: No signal
2025-06-12 00:12:40,121 - INFO - GOLD_USD-M5: シグナルなし。
2025-06-12 00:12:40,121 - ERROR - GOLD_USD: シグナル監視ループで予期せぬエラーが発生しました: cannot access local variable 'uploaded_image_url' where it is not associated with a value
Traceback (most recent call last):
  File "c:\Users\pc\OneDrive\Desktop\phantom_alert_bot\signal_runner_loop.py", line 230, in _run
    image_url=uploaded_image_url # ImgurのURLを保存
              ^^^^^^^^^^^^^^^^^^
UnboundLocalError: cannot access local variable 'uploaded_image_url' where it is not associated with a value
2025-06-12 00:13:10,005 - INFO - GOLD_USD: 新しい足 (M5) が形成されました。データ取得とシグナル判定を実行します。
2025-06-12 00:13:10,049 - INFO - GOLD_USD-M5 シグナル判定結果: No signal
2025-06-12 00:13:10,049 - INFO - GOLD_USD-M5: シグナルなし。
2025-06-12 00:13:10,050 - ERROR - GOLD_USD: シグナル監視ループで予期せぬエラーが発生しました: cannot access local variable 'uploaded_image_url' where it is not associated with a value
Traceback (most recent call last):
  File "C:\Users\pc\OneDrive\Desktop\phantom_alert_bot\signal_runner_loop.py", line 230, in _run
    image_url=uploaded_image_url # ImgurのURLを保存
              ^^^^^^^^^^^^^^^^^^
UnboundLocalError: cannot access local variable 'uploaded_image_url' where it is not associated with a value
2025-06-12 00:13:11,913 - INFO - GOLD_USD: 新しい足 (M5) が形成されました。データ取得とシグナル判定を実行します。
2025-06-12 00:13:11,958 - INFO - GOLD_USD-M5 シグナル判定結果: No signal
2025-06-12 00:13:11,959 - INFO - GOLD_USD-M5: シグナルなし。
2025-06-12 00:13:11,959 - ERROR - GOLD_USD: シグナル監視ループで予期せぬエラーが発生しました: cannot access local variable 'uploaded_image_url' where it is not associated with a value
Traceback (most recent call last):
  File "C:\Users\pc\OneDrive\Desktop\phantom_alert_bot\signal_runner_loop.py", line 230, in _run
    image_url=uploaded_image_url # ImgurのURLを保存
              ^^^^^^^^^^^^^^^^^^
UnboundLocalError: cannot access local variable 'uploaded_image_url' where it is not associated with a value
2025-06-12 00:13:24,669 - INFO - GOLD_USD: 新しい足 (M5) が形成されました。データ取得とシグナル判定を実行します。
2025-06-12 00:13:24,719 - INFO - GOLD_USD-M5 シグナル判定結果: No signal
2025-06-12 00:13:24,719 - INFO - GOLD_USD-M5: シグナルなし。
2025-06-12 00:13:24,720 - ERROR - GOLD_USD: シグナル監視ループで予期せぬエラーが発生しました: cannot access local variable 'uploaded_image_url' where it is not associated with a value
Traceback (most recent call last):
  File "C:\Users\pc\OneDrive\Desktop\phantom_alert_bot\signal_runner_loop.py", line 230, in _run
    image_url=uploaded_image_url # ImgurのURLを保存
              ^^^^^^^^^^^^^^^^^^
UnboundLocalError: cannot access local variable 'uploaded_image_url' where it is not associated with a value
2025-06-12 00:13:40,123 - INFO - GOLD_USD: 新しい足 (M5) が形成されました。データ取得とシグナル判定を実行します。
2025-06-12 00:13:40,143 - INFO - GOLD_USD-M5 シグナル判定結果: No signal
2025-06-12 00:13:40,143 - INFO - GOLD_USD-M5: シグナルなし。
2025-06-12 00:13:40,144 - ERROR - GOLD_USD: シグナル監視ループで予期せぬエラーが発生しました: cannot access local variable 'uploaded_image_url' where it is not associated with a value
Traceback (most recent call last):
  File "c:\Users\pc\OneDrive\Desktop\phantom_alert_bot\signal_runner_loop.py", line 230, in _run
    image_url=uploaded_image_url # ImgurのURLを保存
              ^^^^^^^^^^^^^^^^^^
UnboundLocalError: cannot access local variable 'uploaded_image_url' where it is not associated with a value
2025-06-12 00:14:10,051 - INFO - GOLD_USD: 新しい足 (M5) が形成されました。データ取得とシグナル判定を実行します。
2025-06-12 00:14:10,071 - INFO - GOLD_USD-M5 シグナル判定結果: No signal
2025-06-12 00:14:10,071 - INFO - GOLD_USD-M5: シグナルなし。
2025-06-12 00:14:10,071 - ERROR - GOLD_USD: シグナル監視ループで予期せぬエラーが発生しました: cannot access local variable 'uploaded_image_url' where it is not associated with a value
Traceback (most recent call last):
  File "C:\Users\pc\OneDrive\Desktop\phantom_alert_bot\signal_runner_loop.py", line 230, in _run
    image_url=uploaded_image_url # ImgurのURLを保存
              ^^^^^^^^^^^^^^^^^^
UnboundLocalError: cannot access local variable 'uploaded_image_url' where it is not associated with a value
2025-06-12 00:14:11,961 - INFO - GOLD_USD: 新しい足 (M5) が形成されました。データ取得とシグナル判定を実行します。
2025-06-12 00:14:11,981 - INFO - GOLD_USD-M5 シグナル判定結果: No signal
2025-06-12 00:14:11,982 - INFO - GOLD_USD-M5: シグナルなし。
2025-06-12 00:14:11,982 - ERROR - GOLD_USD: シグナル監視ループで予期せぬエラーが発生しました: cannot access local variable 'uploaded_image_url' where it is not associated with a value
Traceback (most recent call last):
  File "C:\Users\pc\OneDrive\Desktop\phantom_alert_bot\signal_runner_loop.py", line 230, in _run
    image_url=uploaded_image_url # ImgurのURLを保存
              ^^^^^^^^^^^^^^^^^^
UnboundLocalError: cannot access local variable 'uploaded_image_url' where it is not associated with a value
2025-06-12 00:14:24,722 - INFO - GOLD_USD: 新しい足 (M5) が形成されました。データ取得とシグナル判定を実行します。
2025-06-12 00:14:24,748 - INFO - GOLD_USD-M5 シグナル判定結果: No signal
2025-06-12 00:14:24,748 - INFO - GOLD_USD-M5: シグナルなし。
2025-06-12 00:14:24,749 - ERROR - GOLD_USD: シグナル監視ループで予期せぬエラーが発生しました: cannot access local variable 'uploaded_image_url' where it is not associated with a value
Traceback (most recent call last):
  File "C:\Users\pc\OneDrive\Desktop\phantom_alert_bot\signal_runner_loop.py", line 230, in _run
    image_url=uploaded_image_url # ImgurのURLを保存
              ^^^^^^^^^^^^^^^^^^
UnboundLocalError: cannot access local variable 'uploaded_image_url' where it is not associated with a value
2025-06-12 00:14:40,145 - INFO - GOLD_USD: 新しい足 (M5) が形成されました。データ取得とシグナル判定を実行します。
2025-06-12 00:14:40,173 - INFO - GOLD_USD-M5 シグナル判定結果: No signal
2025-06-12 00:14:40,173 - INFO - GOLD_USD-M5: シグナルなし。
2025-06-12 00:14:40,173 - ERROR - GOLD_USD: シグナル監視ループで予期せぬエラーが発生しました: cannot access local variable 'uploaded_image_url' where it is not associated with a value
Traceback (most recent call last):
  File "c:\Users\pc\OneDrive\Desktop\phantom_alert_bot\signal_runner_loop.py", line 230, in _run
    image_url=uploaded_image_url # ImgurのURLを保存
              ^^^^^^^^^^^^^^^^^^
UnboundLocalError: cannot access local variable 'uploaded_image_url' where it is not associated with a value
2025-06-12 00:15:10,073 - INFO - GOLD_USD: 新しい足 (M5) が形成されました。データ取得とシグナル判定を実行します。
2025-06-12 00:15:10,106 - INFO - GOLD_USD-M5 シグナル判定結果: No signal
2025-06-12 00:15:10,107 - INFO - GOLD_USD-M5: シグナルなし。
2025-06-12 00:15:10,108 - ERROR - GOLD_USD: シグナル監視ループで予期せぬエラーが発生しました: cannot access local variable 'uploaded_image_url' where it is not associated with a value
Traceback (most recent call last):
  File "C:\Users\pc\OneDrive\Desktop\phantom_alert_bot\signal_runner_loop.py", line 230, in _run
UnboundLocalError: cannot access local variable 'uploaded_image_url' where it is not associated with a value
2025-06-12 00:15:11,983 - INFO - GOLD_USD: 新しい足 (M5) が形成されました。データ取得とシグナル判定を実行します。
2025-06-12 00:15:12,019 - INFO - GOLD_USD-M5 シグナル判定結果: No signal
2025-06-12 00:15:12,019 - INFO - GOLD_USD-M5: シグナルなし。
2025-06-12 00:15:12,020 - ERROR - GOLD_USD: シグナル監視ループで予期せぬエラーが発生しました: cannot access local variable 'uploaded_image_url' where it is not associated with a value
Traceback (most recent call last):
  File "C:\Users\pc\OneDrive\Desktop\phantom_alert_bot\signal_runner_loop.py", line 230, in _run
UnboundLocalError: cannot access local variable 'uploaded_image_url' where it is not associated with a value
2025-06-12 00:15:24,750 - INFO - GOLD_USD: 新しい足 (M5) が形成されました。データ取得とシグナル判定を実行します。
2025-06-12 00:15:24,776 - INFO - GOLD_USD-M5 シグナル判定結果: No signal
2025-06-12 00:15:24,776 - INFO - GOLD_USD-M5: シグナルなし。
2025-06-12 00:15:24,776 - ERROR - GOLD_USD: シグナル監視ループで予期せぬエラーが発生しました: cannot access local variable 'uploaded_image_url' where it is not associated with a value
Traceback (most recent call last):
  File "C:\Users\pc\OneDrive\Desktop\phantom_alert_bot\signal_runner_loop.py", line 230, in _run
UnboundLocalError: cannot access local variable 'uploaded_image_url' where it is not associated with a value
2025-06-12 00:15:40,175 - INFO - GOLD_USD: 新しい足 (M5) が形成されました。データ取得とシグナル判定を実行します。
2025-06-12 00:15:40,201 - INFO - GOLD_USD-M5 シグナル判定結果: No signal
2025-06-12 00:15:40,202 - INFO - GOLD_USD-M5: シグナルなし。
2025-06-12 00:15:40,203 - ERROR - GOLD_USD: シグナル監視ループで予期せぬエラーが発生しました: cannot access local variable 'uploaded_image_url' where it is not associated with a value
Traceback (most recent call last):
  File "c:\Users\pc\OneDrive\Desktop\phantom_alert_bot\signal_runner_loop.py", line 230, in _run
UnboundLocalError: cannot access local variable 'uploaded_image_url' where it is not associated with a value
2025-06-12 00:16:10,109 - INFO - GOLD_USD: 新しい足 (M5) が形成されました。データ取得とシグナル判定を実行します。
2025-06-12 00:16:10,149 - INFO - GOLD_USD-M5 シグナル判定結果: No signal
2025-06-12 00:16:10,150 - INFO - GOLD_USD-M5: シグナルなし。
2025-06-12 00:16:10,151 - ERROR - GOLD_USD: シグナル監視ループで予期せぬエラーが発生しました: cannot access local variable 'uploaded_image_url' where it is not associated with a value
Traceback (most recent call last):
  File "C:\Users\pc\OneDrive\Desktop\phantom_alert_bot\signal_runner_loop.py", line 230, in _run
UnboundLocalError: cannot access local variable 'uploaded_image_url' where it is not associated with a value
2025-06-12 00:16:12,022 - INFO - GOLD_USD: 新しい足 (M5) が形成されました。データ取得とシグナル判定を実行します。
2025-06-12 00:16:12,074 - INFO - GOLD_USD-M5 シグナル判定結果: No signal
2025-06-12 00:16:12,075 - INFO - GOLD_USD-M5: シグナルなし。
2025-06-12 00:16:12,075 - ERROR - GOLD_USD: シグナル監視ループで予期せぬエラーが発生しました: cannot access local variable 'uploaded_image_url' where it is not associated with a value
Traceback (most recent call last):
  File "C:\Users\pc\OneDrive\Desktop\phantom_alert_bot\signal_runner_loop.py", line 230, in _run
UnboundLocalError: cannot access local variable 'uploaded_image_url' where it is not associated with a value
2025-06-12 00:16:24,778 - INFO - GOLD_USD: 新しい足 (M5) が形成されました。データ取得とシグナル判定を実行します。
2025-06-12 00:16:24,802 - INFO - GOLD_USD-M5 シグナル判定結果: No signal
2025-06-12 00:16:24,802 - INFO - GOLD_USD-M5: シグナルなし。
2025-06-12 00:16:24,803 - ERROR - GOLD_USD: シグナル監視ループで予期せぬエラーが発生しました: cannot access local variable 'uploaded_image_url' where it is not associated with a value
Traceback (most recent call last):
  File "C:\Users\pc\OneDrive\Desktop\phantom_alert_bot\signal_runner_loop.py", line 230, in _run
UnboundLocalError: cannot access local variable 'uploaded_image_url' where it is not associated with a value
2025-06-12 00:16:40,204 - INFO - GOLD_USD: 新しい足 (M5) が形成されました。データ取得とシグナル判定を実行します。
2025-06-12 00:16:40,226 - INFO - GOLD_USD-M5 シグナル判定結果: No signal
2025-06-12 00:16:40,226 - INFO - GOLD_USD-M5: シグナルなし。
2025-06-12 00:16:40,227 - ERROR - GOLD_USD: シグナル監視ループで予期せぬエラーが発生しました: cannot access local variable 'uploaded_image_url' where it is not associated with a value
Traceback (most recent call last):
  File "c:\Users\pc\OneDrive\Desktop\phantom_alert_bot\signal_runner_loop.py", line 230, in _run
UnboundLocalError: cannot access local variable 'uploaded_image_url' where it is not associated with a value
2025-06-12 00:17:10,153 - INFO - GOLD_USD: 新しい足 (M5) が形成されました。データ取得とシグナル判定を実行します。
2025-06-12 00:17:10,204 - INFO - GOLD_USD-M5 シグナル判定結果: No signal
2025-06-12 00:17:10,205 - INFO - GOLD_USD-M5: シグナルなし。
2025-06-12 00:17:10,205 - ERROR - GOLD_USD: シグナル監視ループで予期せぬエラーが発生しました: cannot access local variable 'uploaded_image_url' where it is not associated with a value
Traceback (most recent call last):
  File "C:\Users\pc\OneDrive\Desktop\phantom_alert_bot\signal_runner_loop.py", line 230, in _run
UnboundLocalError: cannot access local variable 'uploaded_image_url' where it is not associated with a value
2025-06-12 00:17:12,077 - INFO - GOLD_USD: 新しい足 (M5) が形成されました。データ取得とシグナル判定を実行します。
2025-06-12 00:17:12,128 - INFO - GOLD_USD-M5 シグナル判定結果: No signal
2025-06-12 00:17:12,129 - INFO - GOLD_USD-M5: シグナルなし。
2025-06-12 00:17:12,130 - ERROR - GOLD_USD: シグナル監視ループで予期せぬエラーが発生しました: cannot access local variable 'uploaded_image_url' where it is not associated with a value
Traceback (most recent call last):
  File "C:\Users\pc\OneDrive\Desktop\phantom_alert_bot\signal_runner_loop.py", line 230, in _run
UnboundLocalError: cannot access local variable 'uploaded_image_url' where it is not associated with a value
2025-06-12 00:17:24,803 - INFO - GOLD_USD: 新しい足 (M5) が形成されました。データ取得とシグナル判定を実行します。
2025-06-12 00:17:24,827 - INFO - GOLD_USD-M5 シグナル判定結果: No signal
2025-06-12 00:17:24,827 - INFO - GOLD_USD-M5: シグナルなし。
2025-06-12 00:17:24,828 - ERROR - GOLD_USD: シグナル監視ループで予期せぬエラーが発生しました: cannot access local variable 'uploaded_image_url' where it is not associated with a value
Traceback (most recent call last):
  File "C:\Users\pc\OneDrive\Desktop\phantom_alert_bot\signal_runner_loop.py", line 230, in _run
UnboundLocalError: cannot access local variable 'uploaded_image_url' where it is not associated with a value
2025-06-12 00:17:40,229 - INFO - GOLD_USD: 新しい足 (M5) が形成されました。データ取得とシグナル判定を実行します。
2025-06-12 00:17:40,267 - INFO - GOLD_USD-M5 シグナル判定結果: No signal
2025-06-12 00:17:40,267 - INFO - GOLD_USD-M5: シグナルなし。
2025-06-12 00:17:40,268 - ERROR - GOLD_USD: シグナル監視ループで予期せぬエラーが発生しました: cannot access local variable 'uploaded_image_url' where it is not associated with a value
Traceback (most recent call last):
  File "c:\Users\pc\OneDrive\Desktop\phantom_alert_bot\signal_runner_loop.py", line 230, in _run
UnboundLocalError: cannot access local variable 'uploaded_image_url' where it is not associated with a value
2025-06-12 00:18:10,207 - INFO - GOLD_USD: 新しい足 (M5) が形成されました。データ取得とシグナル判定を実行します。
2025-06-12 00:18:10,234 - INFO - GOLD_USD-M5 シグナル判定結果: No signal
2025-06-12 00:18:10,235 - INFO - GOLD_USD-M5: シグナルなし。
2025-06-12 00:18:10,235 - ERROR - GOLD_USD: シグナル監視ループで予期せぬエラーが発生しました: cannot access local variable 'uploaded_image_url' where it is not associated with a value
Traceback (most recent call last):
  File "C:\Users\pc\OneDrive\Desktop\phantom_alert_bot\signal_runner_loop.py", line 230, in _run
UnboundLocalError: cannot access local variable 'uploaded_image_url' where it is not associated with a value
2025-06-12 00:18:12,132 - INFO - GOLD_USD: 新しい足 (M5) が形成されました。データ取得とシグナル判定を実行します。
2025-06-12 00:18:12,170 - INFO - GOLD_USD-M5 シグナル判定結果: No signal
2025-06-12 00:18:12,171 - INFO - GOLD_USD-M5: シグナルなし。
2025-06-12 00:18:12,171 - ERROR - GOLD_USD: シグナル監視ループで予期せぬエラーが発生しました: cannot access local variable 'uploaded_image_url' where it is not associated with a value
Traceback (most recent call last):
  File "C:\Users\pc\OneDrive\Desktop\phantom_alert_bot\signal_runner_loop.py", line 230, in _run
UnboundLocalError: cannot access local variable 'uploaded_image_url' where it is not associated with a value
2025-06-12 00:18:24,829 - INFO - GOLD_USD: 新しい足 (M5) が形成されました。データ取得とシグナル判定を実行します。
2025-06-12 00:18:24,887 - INFO - GOLD_USD-M5 シグナル判定結果: No signal
2025-06-12 00:18:24,888 - INFO - GOLD_USD-M5: シグナルなし。
2025-06-12 00:18:24,889 - ERROR - GOLD_USD: シグナル監視ループで予期せぬエラーが発生しました: cannot access local variable 'uploaded_image_url' where it is not associated with a value
Traceback (most recent call last):
  File "C:\Users\pc\OneDrive\Desktop\phantom_alert_bot\signal_runner_loop.py", line 230, in _run
UnboundLocalError: cannot access local variable 'uploaded_image_url' where it is not associated with a value
2025-06-12 00:18:40,269 - INFO - GOLD_USD: 新しい足 (M5) が形成されました。データ取得とシグナル判定を実行します。
2025-06-12 00:18:40,311 - INFO - GOLD_USD-M5 シグナル判定結果: No signal
2025-06-12 00:18:40,311 - INFO - GOLD_USD-M5: シグナルなし。
2025-06-12 00:18:40,312 - ERROR - GOLD_USD: シグナル監視ループで予期せぬエラーが発生しました: cannot access local variable 'uploaded_image_url' where it is not associated with a value
Traceback (most recent call last):
  File "c:\Users\pc\OneDrive\Desktop\phantom_alert_bot\signal_runner_loop.py", line 230, in _run
UnboundLocalError: cannot access local variable 'uploaded_image_url' where it is not associated with a value
2025-06-12 00:19:10,237 - INFO - GOLD_USD: 新しい足 (M5) が形成されました。データ取得とシグナル判定を実行します。
2025-06-12 00:19:10,294 - INFO - GOLD_USD-M5 シグナル判定結果: No signal
2025-06-12 00:19:10,294 - INFO - GOLD_USD-M5: シグナルなし。
2025-06-12 00:19:10,295 - ERROR - GOLD_USD: シグナル監視ループで予期せぬエラーが発生しました: cannot access local variable 'uploaded_image_url' where it is not associated with a value
Traceback (most recent call last):
  File "C:\Users\pc\OneDrive\Desktop\phantom_alert_bot\signal_runner_loop.py", line 230, in _run
UnboundLocalError: cannot access local variable 'uploaded_image_url' where it is not associated with a value
2025-06-12 00:19:12,173 - INFO - GOLD_USD: 新しい足 (M5) が形成されました。データ取得とシグナル判定を実行します。
2025-06-12 00:19:12,221 - INFO - GOLD_USD-M5 シグナル判定結果: No signal
2025-06-12 00:19:12,222 - INFO - GOLD_USD-M5: シグナルなし。
2025-06-12 00:19:12,223 - ERROR - GOLD_USD: シグナル監視ループで予期せぬエラーが発生しました: cannot access local variable 'uploaded_image_url' where it is not associated with a value
Traceback (most recent call last):
  File "C:\Users\pc\OneDrive\Desktop\phantom_alert_bot\signal_runner_loop.py", line 230, in _run
UnboundLocalError: cannot access local variable 'uploaded_image_url' where it is not associated with a value
2025-06-12 00:19:40,314 - INFO - GOLD_USD: 新しい足 (M5) が形成されました。データ取得とシグナル判定を実行します。
2025-06-12 00:19:40,337 - INFO - GOLD_USD-M5 シグナル判定結果: No signal
2025-06-12 00:19:40,337 - INFO - GOLD_USD-M5: シグナルなし。
2025-06-12 00:19:40,338 - ERROR - GOLD_USD: シグナル監視ループで予期せぬエラーが発生しました: cannot access local variable 'uploaded_image_url' where it is not associated with a value
Traceback (most recent call last):
  File "c:\Users\pc\OneDrive\Desktop\phantom_alert_bot\signal_runner_loop.py", line 230, in _run
UnboundLocalError: cannot access local variable 'uploaded_image_url' where it is not associated with a value
2025-06-12 00:20:10,296 - INFO - GOLD_USD: 新しい足 (M5) が形成されました。データ取得とシグナル判定を実行します。
2025-06-12 00:20:10,315 - INFO - GOLD_USD-M5 シグナル判定結果: No signal
2025-06-12 00:20:10,317 - INFO - GOLD_USD-M5: シグナルなし。
2025-06-12 00:20:10,317 - ERROR - GOLD_USD: シグナル監視ループで予期せぬエラーが発生しました: cannot access local variable 'uploaded_image_url' where it is not associated with a value
Traceback (most recent call last):
  File "C:\Users\pc\OneDrive\Desktop\phantom_alert_bot\signal_runner_loop.py", line 230, in _run
UnboundLocalError: cannot access local variable 'uploaded_image_url' where it is not associated with a value
2025-06-12 00:20:12,224 - INFO - GOLD_USD: 新しい足 (M5) が形成されました。データ取得とシグナル判定を実行します。
2025-06-12 00:20:12,245 - INFO - GOLD_USD-M5 シグナル判定結果: No signal
2025-06-12 00:20:12,245 - INFO - GOLD_USD-M5: シグナルなし。
2025-06-12 00:20:12,245 - ERROR - GOLD_USD: シグナル監視ループで予期せぬエラーが発生しました: cannot access local variable 'uploaded_image_url' where it is not associated with a value
Traceback (most recent call last):
  File "C:\Users\pc\OneDrive\Desktop\phantom_alert_bot\signal_runner_loop.py", line 230, in _run
UnboundLocalError: cannot access local variable 'uploaded_image_url' where it is not associated with a value
2025-06-12 00:20:40,339 - INFO - GOLD_USD: 新しい足 (M5) が形成されました。データ取得とシグナル判定を実行します。
2025-06-12 00:20:40,389 - INFO - GOLD_USD-M5 シグナル判定結果: No signal
2025-06-12 00:20:40,390 - INFO - GOLD_USD-M5: シグナルなし。
2025-06-12 00:20:40,391 - ERROR - GOLD_USD: シグナル監視ループで予期せぬエラーが発生しました: cannot access local variable 'uploaded_image_url' where it is not associated with a value
Traceback (most recent call last):
  File "c:\Users\pc\OneDrive\Desktop\phantom_alert_bot\signal_runner_loop.py", line 230, in _run
UnboundLocalError: cannot access local variable 'uploaded_image_url' where it is not associated with a value
2025-06-12 00:21:10,319 - INFO - GOLD_USD: 新しい足 (M5) が形成されました。データ取得とシグナル判定を実行します。
2025-06-12 00:21:10,360 - INFO - GOLD_USD-M5 シグナル判定結果: No signal
2025-06-12 00:21:10,360 - INFO - GOLD_USD-M5: シグナルなし。
2025-06-12 00:21:10,361 - ERROR - GOLD_USD: シグナル監視ループで予期せぬエラーが発生しました: cannot access local variable 'uploaded_image_url' where it is not associated with a value
Traceback (most recent call last):
  File "C:\Users\pc\OneDrive\Desktop\phantom_alert_bot\signal_runner_loop.py", line 230, in _run
UnboundLocalError: cannot access local variable 'uploaded_image_url' where it is not associated with a value
2025-06-12 00:21:12,246 - INFO - GOLD_USD: 新しい足 (M5) が形成されました。データ取得とシグナル判定を実行します。
2025-06-12 00:21:12,297 - INFO - GOLD_USD-M5 シグナル判定結果: No signal
2025-06-12 00:21:12,298 - INFO - GOLD_USD-M5: シグナルなし。
2025-06-12 00:21:12,299 - ERROR - GOLD_USD: シグナル監視ループで予期せぬエラーが発生しました: cannot access local variable 'uploaded_image_url' where it is not associated with a value
Traceback (most recent call last):
  File "C:\Users\pc\OneDrive\Desktop\phantom_alert_bot\signal_runner_loop.py", line 230, in _run
UnboundLocalError: cannot access local variable 'uploaded_image_url' where it is not associated with a value
2025-06-12 00:21:40,394 - INFO - GOLD_USD: 新しい足 (M5) が形成されました。データ取得とシグナル判定を実行します。
2025-06-12 00:21:40,426 - INFO - GOLD_USD-M5 シグナル判定結果: No signal
2025-06-12 00:21:40,427 - INFO - GOLD_USD-M5: シグナルなし。
2025-06-12 00:21:40,427 - ERROR - GOLD_USD: シグナル監視ループで予期せぬエラーが発生しました: cannot access local variable 'uploaded_image_url' where it is not associated with a value
Traceback (most recent call last):
  File "c:\Users\pc\OneDrive\Desktop\phantom_alert_bot\signal_runner_loop.py", line 230, in _run
UnboundLocalError: cannot access local variable 'uploaded_image_url' where it is not associated with a value
2025-06-12 00:22:10,363 - INFO - GOLD_USD: 新しい足 (M5) が形成されました。データ取得とシグナル判定を実行します。
2025-06-12 00:22:10,383 - INFO - GOLD_USD-M5 シグナル判定結果: No signal
2025-06-12 00:22:10,384 - INFO - GOLD_USD-M5: シグナルなし。
2025-06-12 00:22:10,384 - ERROR - GOLD_USD: シグナル監視ループで予期せぬエラーが発生しました: cannot access local variable 'uploaded_image_url' where it is not associated with a value
Traceback (most recent call last):
  File "C:\Users\pc\OneDrive\Desktop\phantom_alert_bot\signal_runner_loop.py", line 230, in _run
UnboundLocalError: cannot access local variable 'uploaded_image_url' where it is not associated with a value
2025-06-12 00:22:12,301 - INFO - GOLD_USD: 新しい足 (M5) が形成されました。データ取得とシグナル判定を実行します。
2025-06-12 00:22:12,323 - INFO - GOLD_USD-M5 シグナル判定結果: No signal
2025-06-12 00:22:12,323 - INFO - GOLD_USD-M5: シグナルなし。
2025-06-12 00:22:12,323 - ERROR - GOLD_USD: シグナル監視ループで予期せぬエラーが発生しました: cannot access local variable 'uploaded_image_url' where it is not associated with a value
Traceback (most recent call last):
  File "C:\Users\pc\OneDrive\Desktop\phantom_alert_bot\signal_runner_loop.py", line 230, in _run
UnboundLocalError: cannot access local variable 'uploaded_image_url' where it is not associated with a value
2025-06-12 00:22:40,429 - INFO - GOLD_USD: 新しい足 (M5) が形成されました。データ取得とシグナル判定を実行します。
2025-06-12 00:22:40,483 - INFO - GOLD_USD-M5 シグナル判定結果: No signal
2025-06-12 00:22:40,484 - INFO - GOLD_USD-M5: シグナルなし。
2025-06-12 00:22:40,486 - ERROR - GOLD_USD: シグナル監視ループで予期せぬエラーが発生しました: cannot access local variable 'uploaded_image_url' where it is not associated with a value
Traceback (most recent call last):
  File "c:\Users\pc\OneDrive\Desktop\phantom_alert_bot\signal_runner_loop.py", line 230, in _run
UnboundLocalError: cannot access local variable 'uploaded_image_url' where it is not associated with a value
2025-06-12 00:23:10,385 - INFO - GOLD_USD: 新しい足 (M5) が形成されました。データ取得とシグナル判定を実行します。
2025-06-12 00:23:10,407 - INFO - GOLD_USD-M5 シグナル判定結果: No signal
2025-06-12 00:23:10,409 - INFO - GOLD_USD-M5: シグナルなし。
2025-06-12 00:23:10,409 - ERROR - GOLD_USD: シグナル監視ループで予期せぬエラーが発生しました: cannot access local variable 'uploaded_image_url' where it is not associated with a value
Traceback (most recent call last):
  File "C:\Users\pc\OneDrive\Desktop\phantom_alert_bot\signal_runner_loop.py", line 230, in _run
UnboundLocalError: cannot access local variable 'uploaded_image_url' where it is not associated with a value
2025-06-12 00:23:12,325 - INFO - GOLD_USD: 新しい足 (M5) が形成されました。データ取得とシグナル判定を実行します。
2025-06-12 00:23:12,375 - INFO - GOLD_USD-M5 シグナル判定結果: No signal
2025-06-12 00:23:12,375 - INFO - GOLD_USD-M5: シグナルなし。
2025-06-12 00:23:12,376 - ERROR - GOLD_USD: シグナル監視ループで予期せぬエラーが発生しました: cannot access local variable 'uploaded_image_url' where it is not associated with a value
Traceback (most recent call last):
  File "C:\Users\pc\OneDrive\Desktop\phantom_alert_bot\signal_runner_loop.py", line 230, in _run
UnboundLocalError: cannot access local variable 'uploaded_image_url' where it is not associated with a value
2025-06-12 00:23:40,488 - INFO - GOLD_USD: 新しい足 (M5) が形成されました。データ取得とシグナル判定を実行します。
2025-06-12 00:23:40,533 - INFO - GOLD_USD-M5 シグナル判定結果: No signal
2025-06-12 00:23:40,534 - INFO - GOLD_USD-M5: シグナルなし。
2025-06-12 00:23:40,535 - ERROR - GOLD_USD: シグナル監視ループで予期せぬエラーが発生しました: cannot access local variable 'uploaded_image_url' where it is not associated with a value
Traceback (most recent call last):
  File "c:\Users\pc\OneDrive\Desktop\phantom_alert_bot\signal_runner_loop.py", line 230, in _run
UnboundLocalError: cannot access local variable 'uploaded_image_url' where it is not associated with a value
2025-06-12 00:24:10,410 - INFO - GOLD_USD: 新しい足 (M5) が形成されました。データ取得とシグナル判定を実行します。
2025-06-12 00:24:10,431 - INFO - GOLD_USD-M5 シグナル判定結果: No signal
2025-06-12 00:24:10,431 - INFO - GOLD_USD-M5: シグナルなし。
2025-06-12 00:24:10,431 - ERROR - GOLD_USD: シグナル監視ループで予期せぬエラーが発生しました: cannot access local variable 'uploaded_image_url' where it is not associated with a value
Traceback (most recent call last):
  File "C:\Users\pc\OneDrive\Desktop\phantom_alert_bot\signal_runner_loop.py", line 230, in _run
UnboundLocalError: cannot access local variable 'uploaded_image_url' where it is not associated with a value
2025-06-12 00:24:12,378 - INFO - GOLD_USD: 新しい足 (M5) が形成されました。データ取得とシグナル判定を実行します。
2025-06-12 00:24:12,398 - INFO - GOLD_USD-M5 シグナル判定結果: No signal
2025-06-12 00:24:12,399 - INFO - GOLD_USD-M5: シグナルなし。
2025-06-12 00:24:12,399 - ERROR - GOLD_USD: シグナル監視ループで予期せぬエラーが発生しました: cannot access local variable 'uploaded_image_url' where it is not associated with a value
Traceback (most recent call last):
  File "C:\Users\pc\OneDrive\Desktop\phantom_alert_bot\signal_runner_loop.py", line 230, in _run
UnboundLocalError: cannot access local variable 'uploaded_image_url' where it is not associated with a value
2025-06-12 00:24:40,537 - INFO - GOLD_USD: 新しい足 (M5) が形成されました。データ取得とシグナル判定を実行します。
2025-06-12 00:24:40,587 - INFO - GOLD_USD-M5 シグナル判定結果: No signal
2025-06-12 00:24:40,587 - INFO - GOLD_USD-M5: シグナルなし。
2025-06-12 00:24:40,588 - ERROR - GOLD_USD: シグナル監視ループで予期せぬエラーが発生しました: cannot access local variable 'uploaded_image_url' where it is not associated with a value
Traceback (most recent call last):
  File "c:\Users\pc\OneDrive\Desktop\phantom_alert_bot\signal_runner_loop.py", line 230, in _run
UnboundLocalError: cannot access local variable 'uploaded_image_url' where it is not associated with a value
2025-06-12 00:25:10,432 - INFO - GOLD_USD: 新しい足 (M5) が形成されました。データ取得とシグナル判定を実行します。
2025-06-12 00:25:10,483 - INFO - GOLD_USD-M5 シグナル判定結果: No signal
2025-06-12 00:25:10,483 - INFO - GOLD_USD-M5: シグナルなし。
2025-06-12 00:25:10,484 - ERROR - GOLD_USD: シグナル監視ループで予期せぬエラーが発生しました: cannot access local variable 'uploaded_image_url' where it is not associated with a value
Traceback (most recent call last):
  File "C:\Users\pc\OneDrive\Desktop\phantom_alert_bot\signal_runner_loop.py", line 230, in _run
UnboundLocalError: cannot access local variable 'uploaded_image_url' where it is not associated with a value
2025-06-12 00:25:12,400 - INFO - GOLD_USD: 新しい足 (M5) が形成されました。データ取得とシグナル判定を実行します。
2025-06-12 00:25:12,427 - INFO - GOLD_USD-M5 シグナル判定結果: No signal
2025-06-12 00:25:12,429 - INFO - GOLD_USD-M5: シグナルなし。
2025-06-12 00:25:12,430 - ERROR - GOLD_USD: シグナル監視ループで予期せぬエラーが発生しました: cannot access local variable 'uploaded_image_url' where it is not associated with a value
Traceback (most recent call last):
  File "C:\Users\pc\OneDrive\Desktop\phantom_alert_bot\signal_runner_loop.py", line 230, in _run
UnboundLocalError: cannot access local variable 'uploaded_image_url' where it is not associated with a value
2025-06-12 00:25:40,590 - INFO - GOLD_USD: 新しい足 (M5) が形成されました。データ取得とシグナル判定を実行します。
2025-06-12 00:25:40,646 - INFO - GOLD_USD-M5 シグナル判定結果: No signal
2025-06-12 00:25:40,646 - INFO - GOLD_USD-M5: シグナルなし。
2025-06-12 00:25:40,650 - ERROR - GOLD_USD: シグナル監視ループで予期せぬエラーが発生しました: cannot access local variable 'uploaded_image_url' where it is not associated with a value
Traceback (most recent call last):
  File "c:\Users\pc\OneDrive\Desktop\phantom_alert_bot\signal_runner_loop.py", line 230, in _run
UnboundLocalError: cannot access local variable 'uploaded_image_url' where it is not associated with a value
2025-06-12 00:26:10,486 - INFO - GOLD_USD: 新しい足 (M5) が形成されました。データ取得とシグナル判定を実行します。
2025-06-12 00:26:10,527 - INFO - GOLD_USD-M5 シグナル判定結果: No signal
2025-06-12 00:26:10,528 - INFO - GOLD_USD-M5: シグナルなし。
2025-06-12 00:26:10,528 - ERROR - GOLD_USD: シグナル監視ループで予期せぬエラーが発生しました: cannot access local variable 'uploaded_image_url' where it is not associated with a value
Traceback (most recent call last):
  File "C:\Users\pc\OneDrive\Desktop\phantom_alert_bot\signal_runner_loop.py", line 230, in _run
UnboundLocalError: cannot access local variable 'uploaded_image_url' where it is not associated with a value
2025-06-12 00:26:12,436 - INFO - GOLD_USD: 新しい足 (M5) が形成されました。データ取得とシグナル判定を実行します。
2025-06-12 00:26:12,455 - INFO - GOLD_USD-M5 シグナル判定結果: No signal
2025-06-12 00:26:12,455 - INFO - GOLD_USD-M5: シグナルなし。
2025-06-12 00:26:12,456 - ERROR - GOLD_USD: シグナル監視ループで予期せぬエラーが発生しました: cannot access local variable 'uploaded_image_url' where it is not associated with a value
Traceback (most recent call last):
  File "C:\Users\pc\OneDrive\Desktop\phantom_alert_bot\signal_runner_loop.py", line 230, in _run
UnboundLocalError: cannot access local variable 'uploaded_image_url' where it is not associated with a value
2025-06-12 00:26:40,652 - INFO - GOLD_USD: 新しい足 (M5) が形成されました。データ取得とシグナル判定を実行します。
2025-06-12 00:26:40,689 - INFO - GOLD_USD-M5 シグナル判定結果: No signal
2025-06-12 00:26:40,690 - INFO - GOLD_USD-M5: シグナルなし。
2025-06-12 00:26:40,690 - ERROR - GOLD_USD: シグナル監視ループで予期せぬエラーが発生しました: cannot access local variable 'uploaded_image_url' where it is not associated with a value
Traceback (most recent call last):
  File "c:\Users\pc\OneDrive\Desktop\phantom_alert_bot\signal_runner_loop.py", line 230, in _run
UnboundLocalError: cannot access local variable 'uploaded_image_url' where it is not associated with a value
2025-06-12 00:27:10,530 - INFO - GOLD_USD: 新しい足 (M5) が形成されました。データ取得とシグナル判定を実行します。
2025-06-12 00:27:10,549 - INFO - GOLD_USD-M5 シグナル判定結果: No signal
2025-06-12 00:27:10,549 - INFO - GOLD_USD-M5: シグナルなし。
2025-06-12 00:27:10,550 - ERROR - GOLD_USD: シグナル監視ループで予期せぬエラーが発生しました: cannot access local variable 'uploaded_image_url' where it is not associated with a value
Traceback (most recent call last):
  File "C:\Users\pc\OneDrive\Desktop\phantom_alert_bot\signal_runner_loop.py", line 230, in _run
UnboundLocalError: cannot access local variable 'uploaded_image_url' where it is not associated with a value
2025-06-12 00:27:12,458 - INFO - GOLD_USD: 新しい足 (M5) が形成されました。データ取得とシグナル判定を実行します。
2025-06-12 00:27:12,487 - INFO - GOLD_USD-M5 シグナル判定結果: No signal
2025-06-12 00:27:12,487 - INFO - GOLD_USD-M5: シグナルなし。
2025-06-12 00:27:12,488 - ERROR - GOLD_USD: シグナル監視ループで予期せぬエラーが発生しました: cannot access local variable 'uploaded_image_url' where it is not associated with a value
Traceback (most recent call last):
  File "C:\Users\pc\OneDrive\Desktop\phantom_alert_bot\signal_runner_loop.py", line 230, in _run
UnboundLocalError: cannot access local variable 'uploaded_image_url' where it is not associated with a value
2025-06-12 00:27:40,692 - INFO - GOLD_USD: 新しい足 (M5) が形成されました。データ取得とシグナル判定を実行します。
2025-06-12 00:27:40,724 - INFO - GOLD_USD-M5 シグナル判定結果: No signal
2025-06-12 00:27:40,724 - INFO - GOLD_USD-M5: シグナルなし。
2025-06-12 00:27:40,726 - ERROR - GOLD_USD: シグナル監視ループで予期せぬエラーが発生しました: cannot access local variable 'uploaded_image_url' where it is not associated with a value
Traceback (most recent call last):
  File "c:\Users\pc\OneDrive\Desktop\phantom_alert_bot\signal_runner_loop.py", line 230, in _run
UnboundLocalError: cannot access local variable 'uploaded_image_url' where it is not associated with a value
2025-06-12 00:28:10,550 - INFO - GOLD_USD: 新しい足 (M5) が形成されました。データ取得とシグナル判定を実行します。
2025-06-12 00:28:10,567 - INFO - GOLD_USD-M5 シグナル判定結果: No signal
2025-06-12 00:28:10,568 - INFO - GOLD_USD-M5: シグナルなし。
2025-06-12 00:28:10,568 - ERROR - GOLD_USD: シグナル監視ループで予期せぬエラーが発生しました: cannot access local variable 'uploaded_image_url' where it is not associated with a value
Traceback (most recent call last):
  File "C:\Users\pc\OneDrive\Desktop\phantom_alert_bot\signal_runner_loop.py", line 230, in _run
UnboundLocalError: cannot access local variable 'uploaded_image_url' where it is not associated with a value
2025-06-12 00:28:12,491 - INFO - GOLD_USD: 新しい足 (M5) が形成されました。データ取得とシグナル判定を実行します。
2025-06-12 00:28:12,528 - INFO - GOLD_USD-M5 シグナル判定結果: No signal
2025-06-12 00:28:12,529 - INFO - GOLD_USD-M5: シグナルなし。
2025-06-12 00:28:12,529 - ERROR - GOLD_USD: シグナル監視ループで予期せぬエラーが発生しました: cannot access local variable 'uploaded_image_url' where it is not associated with a value
Traceback (most recent call last):
  File "C:\Users\pc\OneDrive\Desktop\phantom_alert_bot\signal_runner_loop.py", line 230, in _run
UnboundLocalError: cannot access local variable 'uploaded_image_url' where it is not associated with a value
2025-06-12 00:28:40,727 - INFO - GOLD_USD: 新しい足 (M5) が形成されました。データ取得とシグナル判定を実行します。
2025-06-12 00:28:40,754 - INFO - GOLD_USD-M5 シグナル判定結果: No signal
2025-06-12 00:28:40,755 - INFO - GOLD_USD-M5: シグナルなし。
2025-06-12 00:28:40,755 - ERROR - GOLD_USD: シグナル監視ループで予期せぬエラーが発生しました: cannot access local variable 'uploaded_image_url' where it is not associated with a value
Traceback (most recent call last):
  File "c:\Users\pc\OneDrive\Desktop\phantom_alert_bot\signal_runner_loop.py", line 230, in _run
UnboundLocalError: cannot access local variable 'uploaded_image_url' where it is not associated with a value
2025-06-12 00:29:10,570 - INFO - GOLD_USD: 新しい足 (M5) が形成されました。データ取得とシグナル判定を実行します。
2025-06-12 00:29:10,614 - INFO - GOLD_USD-M5 シグナル判定結果: No signal
2025-06-12 00:29:10,614 - INFO - GOLD_USD-M5: シグナルなし。
2025-06-12 00:29:10,615 - ERROR - GOLD_USD: シグナル監視ループで予期せぬエラーが発生しました: cannot access local variable 'uploaded_image_url' where it is not associated with a value
Traceback (most recent call last):
  File "C:\Users\pc\OneDrive\Desktop\phantom_alert_bot\signal_runner_loop.py", line 230, in _run
UnboundLocalError: cannot access local variable 'uploaded_image_url' where it is not associated with a value
2025-06-12 00:29:12,530 - INFO - GOLD_USD: 新しい足 (M5) が形成されました。データ取得とシグナル判定を実行します。
2025-06-12 00:29:12,598 - INFO - GOLD_USD-M5 シグナル判定結果: No signal
2025-06-12 00:29:12,599 - INFO - GOLD_USD-M5: シグナルなし。
2025-06-12 00:29:12,600 - ERROR - GOLD_USD: シグナル監視ループで予期せぬエラーが発生しました: cannot access local variable 'uploaded_image_url' where it is not associated with a value
Traceback (most recent call last):
  File "C:\Users\pc\OneDrive\Desktop\phantom_alert_bot\signal_runner_loop.py", line 230, in _run
UnboundLocalError: cannot access local variable 'uploaded_image_url' where it is not associated with a value
2025-06-12 00:29:40,757 - INFO - GOLD_USD: 新しい足 (M5) が形成されました。データ取得とシグナル判定を実行します。
2025-06-12 00:29:40,788 - INFO - GOLD_USD-M5 シグナル判定結果: No signal
2025-06-12 00:29:40,788 - INFO - GOLD_USD-M5: シグナルなし。
2025-06-12 00:29:40,789 - ERROR - GOLD_USD: シグナル監視ループで予期せぬエラーが発生しました: cannot access local variable 'uploaded_image_url' where it is not associated with a value
Traceback (most recent call last):
  File "c:\Users\pc\OneDrive\Desktop\phantom_alert_bot\signal_runner_loop.py", line 230, in _run
UnboundLocalError: cannot access local variable 'uploaded_image_url' where it is not associated with a value
2025-06-12 00:30:10,617 - INFO - GOLD_USD: 新しい足 (M5) が形成されました。データ取得とシグナル判定を実行します。
2025-06-12 00:30:10,661 - INFO - GOLD_USD-M5 シグナル判定結果: No signal
2025-06-12 00:30:10,662 - INFO - GOLD_USD-M5: シグナルなし。
2025-06-12 00:30:10,662 - ERROR - GOLD_USD: シグナル監視ループで予期せぬエラーが発生しました: cannot access local variable 'uploaded_image_url' where it is not associated with a value
Traceback (most recent call last):
  File "C:\Users\pc\OneDrive\Desktop\phantom_alert_bot\signal_runner_loop.py", line 230, in _run
UnboundLocalError: cannot access local variable 'uploaded_image_url' where it is not associated with a value
2025-06-12 00:30:12,605 - INFO - GOLD_USD: 新しい足 (M5) が形成されました。データ取得とシグナル判定を実行します。
2025-06-12 00:30:12,657 - INFO - GOLD_USD-M5 シグナル判定結果: No signal
2025-06-12 00:30:12,658 - INFO - GOLD_USD-M5: シグナルなし。
2025-06-12 00:30:12,658 - ERROR - GOLD_USD: シグナル監視ループで予期せぬエラーが発生しました: cannot access local variable 'uploaded_image_url' where it is not associated with a value
Traceback (most recent call last):
  File "C:\Users\pc\OneDrive\Desktop\phantom_alert_bot\signal_runner_loop.py", line 230, in _run
UnboundLocalError: cannot access local variable 'uploaded_image_url' where it is not associated with a value
2025-06-12 00:30:40,793 - INFO - GOLD_USD: 新しい足 (M5) が形成されました。データ取得とシグナル判定を実行します。
2025-06-12 00:30:40,845 - INFO - GOLD_USD-M5 シグナル判定結果: No signal
2025-06-12 00:30:40,846 - INFO - GOLD_USD-M5: シグナルなし。
2025-06-12 00:30:40,847 - ERROR - GOLD_USD: シグナル監視ループで予期せぬエラーが発生しました: cannot access local variable 'uploaded_image_url' where it is not associated with a value
Traceback (most recent call last):
  File "c:\Users\pc\OneDrive\Desktop\phantom_alert_bot\signal_runner_loop.py", line 230, in _run
UnboundLocalError: cannot access local variable 'uploaded_image_url' where it is not associated with a value
2025-06-12 00:31:10,663 - INFO - GOLD_USD: 新しい足 (M5) が形成されました。データ取得とシグナル判定を実行します。
2025-06-12 00:31:10,718 - INFO - GOLD_USD-M5 シグナル判定結果: No signal
2025-06-12 00:31:10,718 - INFO - GOLD_USD-M5: シグナルなし。
2025-06-12 00:31:10,718 - ERROR - GOLD_USD: シグナル監視ループで予期せぬエラーが発生しました: cannot access local variable 'uploaded_image_url' where it is not associated with a value
Traceback (most recent call last):
  File "C:\Users\pc\OneDrive\Desktop\phantom_alert_bot\signal_runner_loop.py", line 230, in _run
UnboundLocalError: cannot access local variable 'uploaded_image_url' where it is not associated with a value
2025-06-12 00:31:12,661 - INFO - GOLD_USD: 新しい足 (M5) が形成されました。データ取得とシグナル判定を実行します。
2025-06-12 00:31:12,705 - INFO - GOLD_USD-M5 シグナル判定結果: No signal
2025-06-12 00:31:12,705 - INFO - GOLD_USD-M5: シグナルなし。
2025-06-12 00:31:12,706 - ERROR - GOLD_USD: シグナル監視ループで予期せぬエラーが発生しました: cannot access local variable 'uploaded_image_url' where it is not associated with a value
Traceback (most recent call last):
  File "C:\Users\pc\OneDrive\Desktop\phantom_alert_bot\signal_runner_loop.py", line 230, in _run
UnboundLocalError: cannot access local variable 'uploaded_image_url' where it is not associated with a value
2025-06-12 00:31:40,849 - INFO - GOLD_USD: 新しい足 (M5) が形成されました。データ取得とシグナル判定を実行します。
2025-06-12 00:31:40,916 - INFO - GOLD_USD-M5 シグナル判定結果: No signal
2025-06-12 00:31:40,916 - INFO - GOLD_USD-M5: シグナルなし。
2025-06-12 00:31:40,919 - ERROR - GOLD_USD: シグナル監視ループで予期せぬエラーが発生しました: cannot access local variable 'uploaded_image_url' where it is not associated with a value
Traceback (most recent call last):
  File "c:\Users\pc\OneDrive\Desktop\phantom_alert_bot\signal_runner_loop.py", line 230, in _run
UnboundLocalError: cannot access local variable 'uploaded_image_url' where it is not associated with a value
2025-06-12 00:32:10,721 - INFO - GOLD_USD: 新しい足 (M5) が形成されました。データ取得とシグナル判定を実行します。
2025-06-12 00:32:10,745 - INFO - GOLD_USD-M5 シグナル判定結果: No signal
2025-06-12 00:32:10,746 - INFO - GOLD_USD-M5: シグナルなし。
2025-06-12 00:32:10,746 - ERROR - GOLD_USD: シグナル監視ループで予期せぬエラーが発生しました: cannot access local variable 'uploaded_image_url' where it is not associated with a value
Traceback (most recent call last):
  File "C:\Users\pc\OneDrive\Desktop\phantom_alert_bot\signal_runner_loop.py", line 230, in _run
UnboundLocalError: cannot access local variable 'uploaded_image_url' where it is not associated with a value
2025-06-12 00:32:12,714 - INFO - GOLD_USD: 新しい足 (M5) が形成されました。データ取得とシグナル判定を実行します。
2025-06-12 00:32:12,771 - INFO - GOLD_USD-M5 シグナル判定結果: No signal
2025-06-12 00:32:12,771 - INFO - GOLD_USD-M5: シグナルなし。
2025-06-12 00:32:12,776 - ERROR - GOLD_USD: シグナル監視ループで予期せぬエラーが発生しました: cannot access local variable 'uploaded_image_url' where it is not associated with a value
Traceback (most recent call last):
  File "C:\Users\pc\OneDrive\Desktop\phantom_alert_bot\signal_runner_loop.py", line 230, in _run
UnboundLocalError: cannot access local variable 'uploaded_image_url' where it is not associated with a value
2025-06-12 00:32:40,921 - INFO - GOLD_USD: 新しい足 (M5) が形成されました。データ取得とシグナル判定を実行します。
2025-06-12 00:32:40,961 - INFO - GOLD_USD-M5 シグナル判定結果: No signal
2025-06-12 00:32:40,962 - INFO - GOLD_USD-M5: シグナルなし。
2025-06-12 00:32:40,972 - ERROR - GOLD_USD: シグナル監視ループで予期せぬエラーが発生しました: cannot access local variable 'uploaded_image_url' where it is not associated with a value
Traceback (most recent call last):
  File "c:\Users\pc\OneDrive\Desktop\phantom_alert_bot\signal_runner_loop.py", line 230, in _run
UnboundLocalError: cannot access local variable 'uploaded_image_url' where it is not associated with a value
2025-06-12 00:33:10,749 - INFO - GOLD_USD: 新しい足 (M5) が形成されました。データ取得とシグナル判定を実行します。
2025-06-12 00:33:10,792 - INFO - GOLD_USD-M5 シグナル判定結果: No signal
2025-06-12 00:33:10,792 - INFO - GOLD_USD-M5: シグナルなし。
2025-06-12 00:33:10,793 - ERROR - GOLD_USD: シグナル監視ループで予期せぬエラーが発生しました: cannot access local variable 'uploaded_image_url' where it is not associated with a value
Traceback (most recent call last):
  File "C:\Users\pc\OneDrive\Desktop\phantom_alert_bot\signal_runner_loop.py", line 230, in _run
UnboundLocalError: cannot access local variable 'uploaded_image_url' where it is not associated with a value
2025-06-12 00:33:12,777 - INFO - GOLD_USD: 新しい足 (M5) が形成されました。データ取得とシグナル判定を実行します。
2025-06-12 00:33:12,805 - INFO - GOLD_USD-M5 シグナル判定結果: No signal
2025-06-12 00:33:12,805 - INFO - GOLD_USD-M5: シグナルなし。
2025-06-12 00:33:12,805 - ERROR - GOLD_USD: シグナル監視ループで予期せぬエラーが発生しました: cannot access local variable 'uploaded_image_url' where it is not associated with a value
Traceback (most recent call last):
  File "C:\Users\pc\OneDrive\Desktop\phantom_alert_bot\signal_runner_loop.py", line 230, in _run
UnboundLocalError: cannot access local variable 'uploaded_image_url' where it is not associated with a value
2025-06-12 00:33:40,975 - INFO - GOLD_USD: 新しい足 (M5) が形成されました。データ取得とシグナル判定を実行します。
2025-06-12 00:33:41,022 - INFO - GOLD_USD-M5 シグナル判定結果: No signal
2025-06-12 00:33:41,022 - INFO - GOLD_USD-M5: シグナルなし。
2025-06-12 00:33:41,023 - ERROR - GOLD_USD: シグナル監視ループで予期せぬエラーが発生しました: cannot access local variable 'uploaded_image_url' where it is not associated with a value
Traceback (most recent call last):
  File "c:\Users\pc\OneDrive\Desktop\phantom_alert_bot\signal_runner_loop.py", line 230, in _run
UnboundLocalError: cannot access local variable 'uploaded_image_url' where it is not associated with a value
2025-06-12 00:34:10,794 - INFO - GOLD_USD: 新しい足 (M5) が形成されました。データ取得とシグナル判定を実行します。
2025-06-12 00:34:10,823 - INFO - GOLD_USD-M5 シグナル判定結果: No signal
2025-06-12 00:34:10,824 - INFO - GOLD_USD-M5: シグナルなし。
2025-06-12 00:34:10,824 - ERROR - GOLD_USD: シグナル監視ループで予期せぬエラーが発生しました: cannot access local variable 'uploaded_image_url' where it is not associated with a value
Traceback (most recent call last):
  File "C:\Users\pc\OneDrive\Desktop\phantom_alert_bot\signal_runner_loop.py", line 230, in _run
UnboundLocalError: cannot access local variable 'uploaded_image_url' where it is not associated with a value
2025-06-12 00:34:12,807 - INFO - GOLD_USD: 新しい足 (M5) が形成されました。データ取得とシグナル判定を実行します。
2025-06-12 00:34:12,859 - INFO - GOLD_USD-M5 シグナル判定結果: No signal
2025-06-12 00:34:12,860 - INFO - GOLD_USD-M5: シグナルなし。
2025-06-12 00:34:12,861 - ERROR - GOLD_USD: シグナル監視ループで予期せぬエラーが発生しました: cannot access local variable 'uploaded_image_url' where it is not associated with a value
Traceback (most recent call last):
  File "C:\Users\pc\OneDrive\Desktop\phantom_alert_bot\signal_runner_loop.py", line 230, in _run
UnboundLocalError: cannot access local variable 'uploaded_image_url' where it is not associated with a value
2025-06-12 00:34:41,026 - INFO - GOLD_USD: 新しい足 (M5) が形成されました。データ取得とシグナル判定を実行します。
2025-06-12 00:34:41,083 - INFO - GOLD_USD-M5 シグナル判定結果: No signal
2025-06-12 00:34:41,083 - INFO - GOLD_USD-M5: シグナルなし。
2025-06-12 00:34:41,084 - ERROR - GOLD_USD: シグナル監視ループで予期せぬエラーが発生しました: cannot access local variable 'uploaded_image_url' where it is not associated with a value
Traceback (most recent call last):
  File "c:\Users\pc\OneDrive\Desktop\phantom_alert_bot\signal_runner_loop.py", line 230, in _run
UnboundLocalError: cannot access local variable 'uploaded_image_url' where it is not associated with a value
2025-06-12 00:35:10,826 - INFO - GOLD_USD: 新しい足 (M5) が形成されました。データ取得とシグナル判定を実行します。
2025-06-12 00:35:10,876 - INFO - GOLD_USD-M5 シグナル判定結果: No signal
2025-06-12 00:35:10,876 - INFO - GOLD_USD-M5: シグナルなし。
2025-06-12 00:35:10,877 - ERROR - GOLD_USD: シグナル監視ループで予期せぬエラーが発生しました: cannot access local variable 'uploaded_image_url' where it is not associated with a value
Traceback (most recent call last):
  File "C:\Users\pc\OneDrive\Desktop\phantom_alert_bot\signal_runner_loop.py", line 230, in _run
UnboundLocalError: cannot access local variable 'uploaded_image_url' where it is not associated with a value
2025-06-12 00:35:12,862 - INFO - GOLD_USD: 新しい足 (M5) が形成されました。データ取得とシグナル判定を実行します。
2025-06-12 00:35:12,890 - INFO - GOLD_USD-M5 シグナル判定結果: No signal
2025-06-12 00:35:12,890 - INFO - GOLD_USD-M5: シグナルなし。
2025-06-12 00:35:12,890 - ERROR - GOLD_USD: シグナル監視ループで予期せぬエラーが発生しました: cannot access local variable 'uploaded_image_url' where it is not associated with a value
Traceback (most recent call last):
  File "C:\Users\pc\OneDrive\Desktop\phantom_alert_bot\signal_runner_loop.py", line 230, in _run
UnboundLocalError: cannot access local variable 'uploaded_image_url' where it is not associated with a value
2025-06-12 00:35:41,089 - INFO - GOLD_USD: 新しい足 (M5) が形成されました。データ取得とシグナル判定を実行します。
2025-06-12 00:35:41,141 - INFO - GOLD_USD-M5 シグナル判定結果: No signal
2025-06-12 00:35:41,141 - INFO - GOLD_USD-M5: シグナルなし。
2025-06-12 00:35:41,141 - ERROR - GOLD_USD: シグナル監視ループで予期せぬエラーが発生しました: cannot access local variable 'uploaded_image_url' where it is not associated with a value
Traceback (most recent call last):
  File "c:\Users\pc\OneDrive\Desktop\phantom_alert_bot\signal_runner_loop.py", line 230, in _run
UnboundLocalError: cannot access local variable 'uploaded_image_url' where it is not associated with a value
2025-06-12 00:36:10,878 - INFO - GOLD_USD: 新しい足 (M5) が形成されました。データ取得とシグナル判定を実行します。
2025-06-12 00:36:10,942 - INFO - GOLD_USD-M5 シグナル判定結果: No signal
2025-06-12 00:36:10,943 - INFO - GOLD_USD-M5: シグナルなし。
2025-06-12 00:36:10,943 - ERROR - GOLD_USD: シグナル監視ループで予期せぬエラーが発生しました: cannot access local variable 'uploaded_image_url' where it is not associated with a value
Traceback (most recent call last):
  File "C:\Users\pc\OneDrive\Desktop\phantom_alert_bot\signal_runner_loop.py", line 230, in _run
UnboundLocalError: cannot access local variable 'uploaded_image_url' where it is not associated with a value
2025-06-12 00:36:12,891 - INFO - GOLD_USD: 新しい足 (M5) が形成されました。データ取得とシグナル判定を実行します。
2025-06-12 00:36:12,921 - INFO - GOLD_USD-M5 シグナル判定結果: No signal
2025-06-12 00:36:12,921 - INFO - GOLD_USD-M5: シグナルなし。
2025-06-12 00:36:12,921 - ERROR - GOLD_USD: シグナル監視ループで予期せぬエラーが発生しました: cannot access local variable 'uploaded_image_url' where it is not associated with a value
Traceback (most recent call last):
  File "C:\Users\pc\OneDrive\Desktop\phantom_alert_bot\signal_runner_loop.py", line 230, in _run
UnboundLocalError: cannot access local variable 'uploaded_image_url' where it is not associated with a value
2025-06-12 00:36:41,142 - INFO - GOLD_USD: 新しい足 (M5) が形成されました。データ取得とシグナル判定を実行します。
2025-06-12 00:36:41,171 - INFO - GOLD_USD-M5 シグナル判定結果: No signal
2025-06-12 00:36:41,171 - INFO - GOLD_USD-M5: シグナルなし。
2025-06-12 00:36:41,172 - ERROR - GOLD_USD: シグナル監視ループで予期せぬエラーが発生しました: cannot access local variable 'uploaded_image_url' where it is not associated with a value
Traceback (most recent call last):
  File "c:\Users\pc\OneDrive\Desktop\phantom_alert_bot\signal_runner_loop.py", line 230, in _run
UnboundLocalError: cannot access local variable 'uploaded_image_url' where it is not associated with a value
2025-06-12 00:37:10,945 - INFO - GOLD_USD: 新しい足 (M5) が形成されました。データ取得とシグナル判定を実行します。
2025-06-12 00:37:11,001 - INFO - GOLD_USD-M5 シグナル判定結果: No signal
2025-06-12 00:37:11,001 - INFO - GOLD_USD-M5: シグナルなし。
2025-06-12 00:37:11,002 - ERROR - GOLD_USD: シグナル監視ループで予期せぬエラーが発生しました: cannot access local variable 'uploaded_image_url' where it is not associated with a value
Traceback (most recent call last):
  File "C:\Users\pc\OneDrive\Desktop\phantom_alert_bot\signal_runner_loop.py", line 230, in _run
UnboundLocalError: cannot access local variable 'uploaded_image_url' where it is not associated with a value
2025-06-12 00:37:12,923 - INFO - GOLD_USD: 新しい足 (M5) が形成されました。データ取得とシグナル判定を実行します。
2025-06-12 00:37:12,983 - INFO - GOLD_USD-M5 シグナル判定結果: No signal
2025-06-12 00:37:12,983 - INFO - GOLD_USD-M5: シグナルなし。
2025-06-12 00:37:12,983 - ERROR - GOLD_USD: シグナル監視ループで予期せぬエラーが発生しました: cannot access local variable 'uploaded_image_url' where it is not associated with a value
Traceback (most recent call last):
  File "C:\Users\pc\OneDrive\Desktop\phantom_alert_bot\signal_runner_loop.py", line 230, in _run
UnboundLocalError: cannot access local variable 'uploaded_image_url' where it is not associated with a value
2025-06-12 00:37:41,172 - INFO - GOLD_USD: 新しい足 (M5) が形成されました。データ取得とシグナル判定を実行します。
2025-06-12 00:37:41,208 - INFO - GOLD_USD-M5 シグナル判定結果: No signal
2025-06-12 00:37:41,208 - INFO - GOLD_USD-M5: シグナルなし。
2025-06-12 00:37:41,209 - ERROR - GOLD_USD: シグナル監視ループで予期せぬエラーが発生しました: cannot access local variable 'uploaded_image_url' where it is not associated with a value
Traceback (most recent call last):
  File "c:\Users\pc\OneDrive\Desktop\phantom_alert_bot\signal_runner_loop.py", line 230, in _run
UnboundLocalError: cannot access local variable 'uploaded_image_url' where it is not associated with a value
2025-06-12 00:38:11,003 - INFO - GOLD_USD: 新しい足 (M5) が形成されました。データ取得とシグナル判定を実行します。
2025-06-12 00:38:11,037 - INFO - GOLD_USD-M5 シグナル判定結果: No signal
2025-06-12 00:38:11,038 - INFO - GOLD_USD-M5: シグナルなし。
2025-06-12 00:38:11,038 - ERROR - GOLD_USD: シグナル監視ループで予期せぬエラーが発生しました: cannot access local variable 'uploaded_image_url' where it is not associated with a value
Traceback (most recent call last):
  File "C:\Users\pc\OneDrive\Desktop\phantom_alert_bot\signal_runner_loop.py", line 230, in _run
UnboundLocalError: cannot access local variable 'uploaded_image_url' where it is not associated with a value
2025-06-12 00:38:12,986 - INFO - GOLD_USD: 新しい足 (M5) が形成されました。データ取得とシグナル判定を実行します。
2025-06-12 00:38:13,061 - INFO - GOLD_USD-M5 シグナル判定結果: No signal
2025-06-12 00:38:13,062 - INFO - GOLD_USD-M5: シグナルなし。
2025-06-12 00:38:13,063 - ERROR - GOLD_USD: シグナル監視ループで予期せぬエラーが発生しました: cannot access local variable 'uploaded_image_url' where it is not associated with a value
Traceback (most recent call last):
  File "C:\Users\pc\OneDrive\Desktop\phantom_alert_bot\signal_runner_loop.py", line 230, in _run
UnboundLocalError: cannot access local variable 'uploaded_image_url' where it is not associated with a value
2025-06-12 00:38:41,210 - INFO - GOLD_USD: 新しい足 (M5) が形成されました。データ取得とシグナル判定を実行します。
2025-06-12 00:38:41,252 - INFO - GOLD_USD-M5 シグナル判定結果: No signal
2025-06-12 00:38:41,253 - INFO - GOLD_USD-M5: シグナルなし。
2025-06-12 00:38:41,254 - ERROR - GOLD_USD: シグナル監視ループで予期せぬエラーが発生しました: cannot access local variable 'uploaded_image_url' where it is not associated with a value
Traceback (most recent call last):
  File "c:\Users\pc\OneDrive\Desktop\phantom_alert_bot\signal_runner_loop.py", line 230, in _run
UnboundLocalError: cannot access local variable 'uploaded_image_url' where it is not associated with a value
2025-06-12 00:39:11,039 - INFO - GOLD_USD: 新しい足 (M5) が形成されました。データ取得とシグナル判定を実行します。
2025-06-12 00:39:11,098 - INFO - GOLD_USD-M5 シグナル判定結果: No signal
2025-06-12 00:39:11,098 - INFO - GOLD_USD-M5: シグナルなし。
2025-06-12 00:39:11,100 - ERROR - GOLD_USD: シグナル監視ループで予期せぬエラーが発生しました: cannot access local variable 'uploaded_image_url' where it is not associated with a value
Traceback (most recent call last):
  File "C:\Users\pc\OneDrive\Desktop\phantom_alert_bot\signal_runner_loop.py", line 230, in _run
UnboundLocalError: cannot access local variable 'uploaded_image_url' where it is not associated with a value
2025-06-12 00:39:13,065 - INFO - GOLD_USD: 新しい足 (M5) が形成されました。データ取得とシグナル判定を実行します。
2025-06-12 00:39:13,121 - INFO - GOLD_USD-M5 シグナル判定結果: No signal
2025-06-12 00:39:13,121 - INFO - GOLD_USD-M5: シグナルなし。
2025-06-12 00:39:13,121 - ERROR - GOLD_USD: シグナル監視ループで予期せぬエラーが発生しました: cannot access local variable 'uploaded_image_url' where it is not associated with a value
Traceback (most recent call last):
  File "C:\Users\pc\OneDrive\Desktop\phantom_alert_bot\signal_runner_loop.py", line 230, in _run
UnboundLocalError: cannot access local variable 'uploaded_image_url' where it is not associated with a value
2025-06-12 00:39:41,262 - INFO - GOLD_USD: 新しい足 (M5) が形成されました。データ取得とシグナル判定を実行します。
2025-06-12 00:39:41,363 - INFO - GOLD_USD-M5 シグナル判定結果: No signal
2025-06-12 00:39:41,377 - INFO - GOLD_USD-M5: シグナルなし。
2025-06-12 00:39:41,387 - ERROR - GOLD_USD: シグナル監視ループで予期せぬエラーが発生しました: cannot access local variable 'uploaded_image_url' where it is not associated with a value
Traceback (most recent call last):
  File "c:\Users\pc\OneDrive\Desktop\phantom_alert_bot\signal_runner_loop.py", line 230, in _run
UnboundLocalError: cannot access local variable 'uploaded_image_url' where it is not associated with a value
2025-06-12 00:40:11,101 - INFO - GOLD_USD: 新しい足 (M5) が形成されました。データ取得とシグナル判定を実行します。
2025-06-12 00:40:11,174 - INFO - GOLD_USD-M5 シグナル判定結果: No signal
2025-06-12 00:40:11,174 - INFO - GOLD_USD-M5: シグナルなし。
2025-06-12 00:40:11,175 - ERROR - GOLD_USD: シグナル監視ループで予期せぬエラーが発生しました: cannot access local variable 'uploaded_image_url' where it is not associated with a value
Traceback (most recent call last):
  File "C:\Users\pc\OneDrive\Desktop\phantom_alert_bot\signal_runner_loop.py", line 230, in _run
UnboundLocalError: cannot access local variable 'uploaded_image_url' where it is not associated with a value
2025-06-12 00:40:13,122 - INFO - GOLD_USD: 新しい足 (M5) が形成されました。データ取得とシグナル判定を実行します。
2025-06-12 00:40:13,199 - INFO - GOLD_USD-M5 シグナル判定結果: No signal
2025-06-12 00:40:13,200 - INFO - GOLD_USD-M5: シグナルなし。
2025-06-12 00:40:13,200 - ERROR - GOLD_USD: シグナル監視ループで予期せぬエラーが発生しました: cannot access local variable 'uploaded_image_url' where it is not associated with a value
Traceback (most recent call last):
  File "C:\Users\pc\OneDrive\Desktop\phantom_alert_bot\signal_runner_loop.py", line 230, in _run
UnboundLocalError: cannot access local variable 'uploaded_image_url' where it is not associated with a value
2025-06-12 00:40:41,396 - INFO - GOLD_USD: 新しい足 (M5) が形成されました。データ取得とシグナル判定を実行します。
2025-06-12 00:40:41,429 - INFO - GOLD_USD-M5 シグナル判定結果: No signal
2025-06-12 00:40:41,430 - INFO - GOLD_USD-M5: シグナルなし。
2025-06-12 00:40:41,430 - ERROR - GOLD_USD: シグナル監視ループで予期せぬエラーが発生しました: cannot access local variable 'uploaded_image_url' where it is not associated with a value
Traceback (most recent call last):
  File "c:\Users\pc\OneDrive\Desktop\phantom_alert_bot\signal_runner_loop.py", line 230, in _run
UnboundLocalError: cannot access local variable 'uploaded_image_url' where it is not associated with a value
2025-06-12 00:41:11,178 - INFO - GOLD_USD: 新しい足 (M5) が形成されました。データ取得とシグナル判定を実行します。
2025-06-12 00:41:11,250 - INFO - GOLD_USD-M5 シグナル判定結果: No signal
2025-06-12 00:41:11,252 - INFO - GOLD_USD-M5: シグナルなし。
2025-06-12 00:41:11,252 - ERROR - GOLD_USD: シグナル監視ループで予期せぬエラーが発生しました: cannot access local variable 'uploaded_image_url' where it is not associated with a value
Traceback (most recent call last):
  File "C:\Users\pc\OneDrive\Desktop\phantom_alert_bot\signal_runner_loop.py", line 230, in _run
UnboundLocalError: cannot access local variable 'uploaded_image_url' where it is not associated with a value
2025-06-12 00:41:13,201 - INFO - GOLD_USD: 新しい足 (M5) が形成されました。データ取得とシグナル判定を実行します。
2025-06-12 00:41:13,324 - INFO - GOLD_USD-M5 シグナル判定結果: No signal
2025-06-12 00:41:13,334 - INFO - GOLD_USD-M5: シグナルなし。
2025-06-12 00:41:13,339 - ERROR - GOLD_USD: シグナル監視ループで予期せぬエラーが発生しました: cannot access local variable 'uploaded_image_url' where it is not associated with a value
Traceback (most recent call last):
  File "C:\Users\pc\OneDrive\Desktop\phantom_alert_bot\signal_runner_loop.py", line 230, in _run
UnboundLocalError: cannot access local variable 'uploaded_image_url' where it is not associated with a value
2025-06-12 00:41:41,432 - INFO - GOLD_USD: 新しい足 (M5) が形成されました。データ取得とシグナル判定を実行します。
2025-06-12 00:41:41,507 - INFO - GOLD_USD-M5 シグナル判定結果: No signal
2025-06-12 00:41:41,507 - INFO - GOLD_USD-M5: シグナルなし。
2025-06-12 00:41:41,507 - ERROR - GOLD_USD: シグナル監視ループで予期せぬエラーが発生しました: cannot access local variable 'uploaded_image_url' where it is not associated with a value
Traceback (most recent call last):
  File "c:\Users\pc\OneDrive\Desktop\phantom_alert_bot\signal_runner_loop.py", line 230, in _run
UnboundLocalError: cannot access local variable 'uploaded_image_url' where it is not associated with a value
2025-06-12 00:42:11,255 - INFO - GOLD_USD: 新しい足 (M5) が形成されました。データ取得とシグナル判定を実行します。
2025-06-12 00:42:11,343 - INFO - GOLD_USD-M5 シグナル判定結果: No signal
2025-06-12 00:42:11,344 - INFO - GOLD_USD-M5: シグナルなし。
2025-06-12 00:42:11,344 - ERROR - GOLD_USD: シグナル監視ループで予期せぬエラーが発生しました: cannot access local variable 'uploaded_image_url' where it is not associated with a value
Traceback (most recent call last):
  File "C:\Users\pc\OneDrive\Desktop\phantom_alert_bot\signal_runner_loop.py", line 230, in _run
UnboundLocalError: cannot access local variable 'uploaded_image_url' where it is not associated with a value
2025-06-12 00:42:13,341 - INFO - GOLD_USD: 新しい足 (M5) が形成されました。データ取得とシグナル判定を実行します。
2025-06-12 00:42:13,417 - INFO - GOLD_USD-M5 シグナル判定結果: No signal
2025-06-12 00:42:13,418 - INFO - GOLD_USD-M5: シグナルなし。
2025-06-12 00:42:13,420 - ERROR - GOLD_USD: シグナル監視ループで予期せぬエラーが発生しました: cannot access local variable 'uploaded_image_url' where it is not associated with a value
Traceback (most recent call last):
  File "C:\Users\pc\OneDrive\Desktop\phantom_alert_bot\signal_runner_loop.py", line 230, in _run
UnboundLocalError: cannot access local variable 'uploaded_image_url' where it is not associated with a value
2025-06-12 00:42:41,519 - INFO - GOLD_USD: 新しい足 (M5) が形成されました。データ取得とシグナル判定を実行します。
2025-06-12 00:42:41,636 - INFO - GOLD_USD-M5 シグナル判定結果: No signal
2025-06-12 00:42:41,641 - INFO - GOLD_USD-M5: シグナルなし。
2025-06-12 00:42:41,645 - ERROR - GOLD_USD: シグナル監視ループで予期せぬエラーが発生しました: cannot access local variable 'uploaded_image_url' where it is not associated with a value
Traceback (most recent call last):
  File "c:\Users\pc\OneDrive\Desktop\phantom_alert_bot\signal_runner_loop.py", line 230, in _run
UnboundLocalError: cannot access local variable 'uploaded_image_url' where it is not associated with a value
2025-06-12 00:43:11,347 - INFO - GOLD_USD: 新しい足 (M5) が形成されました。データ取得とシグナル判定を実行します。
2025-06-12 00:43:11,426 - INFO - GOLD_USD-M5 シグナル判定結果: No signal
2025-06-12 00:43:11,427 - INFO - GOLD_USD-M5: シグナルなし。
2025-06-12 00:43:11,427 - ERROR - GOLD_USD: シグナル監視ループで予期せぬエラーが発生しました: cannot access local variable 'uploaded_image_url' where it is not associated with a value
Traceback (most recent call last):
  File "C:\Users\pc\OneDrive\Desktop\phantom_alert_bot\signal_runner_loop.py", line 230, in _run
UnboundLocalError: cannot access local variable 'uploaded_image_url' where it is not associated with a value
2025-06-12 00:43:13,421 - INFO - GOLD_USD: 新しい足 (M5) が形成されました。データ取得とシグナル判定を実行します。
2025-06-12 00:43:13,494 - INFO - GOLD_USD-M5 シグナル判定結果: No signal
2025-06-12 00:43:13,494 - INFO - GOLD_USD-M5: シグナルなし。
2025-06-12 00:43:13,495 - ERROR - GOLD_USD: シグナル監視ループで予期せぬエラーが発生しました: cannot access local variable 'uploaded_image_url' where it is not associated with a value
Traceback (most recent call last):
  File "C:\Users\pc\OneDrive\Desktop\phantom_alert_bot\signal_runner_loop.py", line 230, in _run
UnboundLocalError: cannot access local variable 'uploaded_image_url' where it is not associated with a value
2025-06-12 00:43:41,648 - INFO - GOLD_USD: 新しい足 (M5) が形成されました。データ取得とシグナル判定を実行します。
2025-06-12 00:43:41,700 - INFO - GOLD_USD-M5 シグナル判定結果: No signal
2025-06-12 00:43:41,700 - INFO - GOLD_USD-M5: シグナルなし。
2025-06-12 00:43:41,701 - ERROR - GOLD_USD: シグナル監視ループで予期せぬエラーが発生しました: cannot access local variable 'uploaded_image_url' where it is not associated with a value
Traceback (most recent call last):
  File "c:\Users\pc\OneDrive\Desktop\phantom_alert_bot\signal_runner_loop.py", line 230, in _run
UnboundLocalError: cannot access local variable 'uploaded_image_url' where it is not associated with a value
2025-06-12 00:44:11,437 - INFO - GOLD_USD: 新しい足 (M5) が形成されました。データ取得とシグナル判定を実行します。
2025-06-12 00:44:11,526 - INFO - GOLD_USD-M5 シグナル判定結果: No signal
2025-06-12 00:44:11,526 - INFO - GOLD_USD-M5: シグナルなし。
2025-06-12 00:44:11,527 - ERROR - GOLD_USD: シグナル監視ループで予期せぬエラーが発生しました: cannot access local variable 'uploaded_image_url' where it is not associated with a value
Traceback (most recent call last):
  File "C:\Users\pc\OneDrive\Desktop\phantom_alert_bot\signal_runner_loop.py", line 230, in _run
UnboundLocalError: cannot access local variable 'uploaded_image_url' where it is not associated with a value
2025-06-12 00:44:13,497 - INFO - GOLD_USD: 新しい足 (M5) が形成されました。データ取得とシグナル判定を実行します。
2025-06-12 00:44:13,576 - INFO - GOLD_USD-M5 シグナル判定結果: No signal
2025-06-12 00:44:13,577 - INFO - GOLD_USD-M5: シグナルなし。
2025-06-12 00:44:13,581 - ERROR - GOLD_USD: シグナル監視ループで予期せぬエラーが発生しました: cannot access local variable 'uploaded_image_url' where it is not associated with a value
Traceback (most recent call last):
  File "C:\Users\pc\OneDrive\Desktop\phantom_alert_bot\signal_runner_loop.py", line 230, in _run
UnboundLocalError: cannot access local variable 'uploaded_image_url' where it is not associated with a value
2025-06-12 00:44:41,703 - INFO - GOLD_USD: 新しい足 (M5) が形成されました。データ取得とシグナル判定を実行します。
2025-06-12 00:44:41,782 - INFO - GOLD_USD-M5 シグナル判定結果: Balanced Sell Signal (Confluence: MACD Dead Cross, Stochastic Dead Cross)
2025-06-12 00:44:41,782 - ERROR - GOLD_USD: シグナル監視ループで予期せぬエラーが発生しました: 'SignalRunner' object has no attribute '_generate_chart_and_upload'
Traceback (most recent call last):
  File "c:\Users\pc\OneDrive\Desktop\phantom_alert_bot\signal_runner_loop.py", line 199, in _run
    # シグナルが出た場合、LINE通知とチャート画像生成・アップロード
                      ^^^^^^^^^^^^^^^^^^^^^^
AttributeError: 'SignalRunner' object has no attribute '_generate_chart_and_upload'
2025-06-12 00:45:11,529 - INFO - GOLD_USD: 新しい足 (M5) が形成されました。データ取得とシグナル判定を実行します。
2025-06-12 00:45:11,581 - INFO - GOLD_USD-M5 シグナル判定結果: Balanced Sell Signal (Confluence: MACD Dead Cross, Stochastic Dead Cross)
2025-06-12 00:45:11,582 - ERROR - GOLD_USD: シグナル監視ループで予期せぬエラーが発生しました: 'SignalRunner' object has no attribute '_generate_chart_and_upload'
Traceback (most recent call last):
  File "C:\Users\pc\OneDrive\Desktop\phantom_alert_bot\signal_runner_loop.py", line 199, in _run
    # シグナルが出た場合、LINE通知とチャート画像生成・アップロード
                      ^^^^^^^^^^^^^^^^^^^^^^
AttributeError: 'SignalRunner' object has no attribute '_generate_chart_and_upload'
2025-06-12 00:45:13,583 - INFO - GOLD_USD: 新しい足 (M5) が形成されました。データ取得とシグナル判定を実行します。
2025-06-12 00:45:13,659 - INFO - GOLD_USD-M5 シグナル判定結果: Balanced Sell Signal (Confluence: MACD Dead Cross, Stochastic Dead Cross)
2025-06-12 00:45:13,660 - ERROR - GOLD_USD: シグナル監視ループで予期せぬエラーが発生しました: 'SignalRunner' object has no attribute '_generate_chart_and_upload'
Traceback (most recent call last):
  File "C:\Users\pc\OneDrive\Desktop\phantom_alert_bot\signal_runner_loop.py", line 199, in _run
    # シグナルが出た場合、LINE通知とチャート画像生成・アップロード
                      ^^^^^^^^^^^^^^^^^^^^^^
AttributeError: 'SignalRunner' object has no attribute '_generate_chart_and_upload'
2025-06-12 00:45:41,784 - INFO - GOLD_USD: 新しい足 (M5) が形成されました。データ取得とシグナル判定を実行します。
2025-06-12 00:45:41,849 - INFO - GOLD_USD-M5 シグナル判定結果: Balanced Sell Signal (Confluence: MACD Dead Cross, Stochastic Dead Cross)
2025-06-12 00:45:41,849 - ERROR - GOLD_USD: シグナル監視ループで予期せぬエラーが発生しました: 'SignalRunner' object has no attribute '_generate_chart_and_upload'
Traceback (most recent call last):
  File "c:\Users\pc\OneDrive\Desktop\phantom_alert_bot\signal_runner_loop.py", line 199, in _run
    # シグナルが出た場合、LINE通知とチャート画像生成・アップロード
                      ^^^^^^^^^^^^^^^^^^^^^^
AttributeError: 'SignalRunner' object has no attribute '_generate_chart_and_upload'
2025-06-12 00:46:11,583 - INFO - GOLD_USD: 新しい足 (M5) が形成されました。データ取得とシグナル判定を実行します。
2025-06-12 00:46:11,634 - INFO - GOLD_USD-M5 シグナル判定結果: Balanced Sell Signal (Confluence: MACD Dead Cross, Stochastic Dead Cross)
2025-06-12 00:46:11,635 - ERROR - GOLD_USD: シグナル監視ループで予期せぬエラーが発生しました: 'SignalRunner' object has no attribute '_generate_chart_and_upload'
Traceback (most recent call last):
  File "C:\Users\pc\OneDrive\Desktop\phantom_alert_bot\signal_runner_loop.py", line 199, in _run
    # シグナルが出た場合、LINE通知とチャート画像生成・アップロード
                      ^^^^^^^^^^^^^^^^^^^^^^
AttributeError: 'SignalRunner' object has no attribute '_generate_chart_and_upload'
2025-06-12 00:46:13,663 - INFO - GOLD_USD: 新しい足 (M5) が形成されました。データ取得とシグナル判定を実行します。
2025-06-12 00:46:13,727 - INFO - GOLD_USD-M5 シグナル判定結果: Balanced Sell Signal (Confluence: MACD Dead Cross, Stochastic Dead Cross)
2025-06-12 00:46:13,727 - ERROR - GOLD_USD: シグナル監視ループで予期せぬエラーが発生しました: 'SignalRunner' object has no attribute '_generate_chart_and_upload'
Traceback (most recent call last):
  File "C:\Users\pc\OneDrive\Desktop\phantom_alert_bot\signal_runner_loop.py", line 199, in _run
    # シグナルが出た場合、LINE通知とチャート画像生成・アップロード
                      ^^^^^^^^^^^^^^^^^^^^^^
AttributeError: 'SignalRunner' object has no attribute '_generate_chart_and_upload'
2025-06-12 00:46:41,852 - INFO - GOLD_USD: 新しい足 (M5) が形成されました。データ取得とシグナル判定を実行します。
2025-06-12 00:46:41,916 - INFO - GOLD_USD-M5 シグナル判定結果: Balanced Sell Signal (Confluence: MACD Dead Cross, Stochastic Dead Cross)
2025-06-12 00:46:41,916 - ERROR - GOLD_USD: シグナル監視ループで予期せぬエラーが発生しました: 'SignalRunner' object has no attribute '_generate_chart_and_upload'
Traceback (most recent call last):
  File "c:\Users\pc\OneDrive\Desktop\phantom_alert_bot\signal_runner_loop.py", line 199, in _run
    # シグナルが出た場合、LINE通知とチャート画像生成・アップロード
                      ^^^^^^^^^^^^^^^^^^^^^^
AttributeError: 'SignalRunner' object has no attribute '_generate_chart_and_upload'
2025-06-12 00:47:11,637 - INFO - GOLD_USD: 新しい足 (M5) が形成されました。データ取得とシグナル判定を実行します。
2025-06-12 00:47:11,818 - INFO - GOLD_USD-M5 シグナル判定結果: Balanced Sell Signal (Confluence: MACD Dead Cross, Stochastic Dead Cross)
2025-06-12 00:47:11,819 - ERROR - GOLD_USD: シグナル監視ループで予期せぬエラーが発生しました: 'SignalRunner' object has no attribute '_generate_chart_and_upload'
Traceback (most recent call last):
  File "C:\Users\pc\OneDrive\Desktop\phantom_alert_bot\signal_runner_loop.py", line 199, in _run
    # シグナルが出た場合、LINE通知とチャート画像生成・アップロード
                      ^^^^^^^^^^^^^^^^^^^^^^
AttributeError: 'SignalRunner' object has no attribute '_generate_chart_and_upload'
2025-06-12 00:47:13,729 - INFO - GOLD_USD: 新しい足 (M5) が形成されました。データ取得とシグナル判定を実行します。
2025-06-12 00:47:13,749 - INFO - GOLD_USD-M5 シグナル判定結果: Balanced Sell Signal (Confluence: MACD Dead Cross, Stochastic Dead Cross)
2025-06-12 00:47:13,749 - ERROR - GOLD_USD: シグナル監視ループで予期せぬエラーが発生しました: 'SignalRunner' object has no attribute '_generate_chart_and_upload'
Traceback (most recent call last):
  File "C:\Users\pc\OneDrive\Desktop\phantom_alert_bot\signal_runner_loop.py", line 199, in _run
    # シグナルが出た場合、LINE通知とチャート画像生成・アップロード
                      ^^^^^^^^^^^^^^^^^^^^^^
AttributeError: 'SignalRunner' object has no attribute '_generate_chart_and_upload'
2025-06-12 10:40:26,299 - INFO - ✅ GOLD_USD-M5 シグナルランナーが初期化されました。
2025-06-12 10:40:35,363 - INFO - GOLD_USD-M5 シグナル監視ループを開始します。
2025-06-12 10:40:35,366 - INFO - GOLD_USD: MT5クライアントを初期化しています...
2025-06-12 10:40:35,367 - INFO - ✅ GOLD_USD: MT5クライアントの初期化に成功しました。
2025-06-12 10:40:35,368 - INFO - GOLD_USD: 新しい足 (M5) が形成されました。データ取得とシグナル判定を実行します。
2025-06-12 10:40:35,410 - ERROR - GOLD_USD: シグナル監視ループで予期せぬエラーが発生しました: 'MACD_Signal'
Traceback (most recent call last):
  File "C:\Users\pc\AppData\Local\Programs\Python\Python312\Lib\site-packages\pandas\core\indexes\base.py", line 3812, in get_loc
    return self._engine.get_loc(casted_key)
           ^^^^^^^^^^^^^^^^^^^^^^^^^^^^^^^^
  File "pandas/_libs/index.pyx", line 167, in pandas._libs.index.IndexEngine.get_loc
  File "pandas/_libs/index.pyx", line 196, in pandas._libs.index.IndexEngine.get_loc
  File "pandas/_libs/hashtable_class_helper.pxi", line 7088, in pandas._libs.hashtable.PyObjectHashTable.get_item
  File "pandas/_libs/hashtable_class_helper.pxi", line 7096, in pandas._libs.hashtable.PyObjectHashTable.get_item
KeyError: 'MACD_Signal'

The above exception was the direct cause of the following exception:

Traceback (most recent call last):
  File "c:\Users\pc\OneDrive\Desktop\phantom_alert_bot\signal_runner_loop.py", line 196, in _run
    signal_info = generate_signal(df, mode="realtime", logic=DEFAULT_LOGIC) # modeとlogicを渡す
                  ^^^^^^^^^^^^^^^^^^^^^^^^^^^^^^^^^^^^^^^^^^^^^^^^^^^^^^^^^
  File "c:\Users\pc\OneDrive\Desktop\phantom_alert_bot\signal_generator.py", line 71, in generate_signal
    signal_info = _generate_balanced_signal(df_ind, current_price)
                  ^^^^^^^^^^^^^^^^^^^^^^^^^^^^^^^^^^^^^^^^^^^^^^^^
  File "c:\Users\pc\OneDrive\Desktop\phantom_alert_bot\signal_generator.py", line 192, in _generate_balanced_signal
    macd_buy = (df_ind['MACD'].iloc[-1] > df_ind['MACD_Signal'].iloc[-1]) # MACDゴールデンクロス
                                          ~~~~~~^^^^^^^^^^^^^^^
  File "C:\Users\pc\AppData\Local\Programs\Python\Python312\Lib\site-packages\pandas\core\frame.py", line 4107, in __getitem__
    indexer = self.columns.get_loc(key)
              ^^^^^^^^^^^^^^^^^^^^^^^^^
  File "C:\Users\pc\AppData\Local\Programs\Python\Python312\Lib\site-packages\pandas\core\indexes\base.py", line 3819, in get_loc
    raise KeyError(key) from err
KeyError: 'MACD_Signal'
2025-06-12 10:41:35,413 - INFO - GOLD_USD: 新しい足 (M5) が形成されました。データ取得とシグナル判定を実行します。
2025-06-12 10:41:35,509 - ERROR - GOLD_USD: シグナル監視ループで予期せぬエラーが発生しました: 'MACD_Signal'
Traceback (most recent call last):
  File "C:\Users\pc\AppData\Local\Programs\Python\Python312\Lib\site-packages\pandas\core\indexes\base.py", line 3812, in get_loc
    return self._engine.get_loc(casted_key)
           ^^^^^^^^^^^^^^^^^^^^^^^^^^^^^^^^
  File "pandas/_libs/index.pyx", line 167, in pandas._libs.index.IndexEngine.get_loc
  File "pandas/_libs/index.pyx", line 196, in pandas._libs.index.IndexEngine.get_loc
  File "pandas/_libs/hashtable_class_helper.pxi", line 7088, in pandas._libs.hashtable.PyObjectHashTable.get_item
  File "pandas/_libs/hashtable_class_helper.pxi", line 7096, in pandas._libs.hashtable.PyObjectHashTable.get_item
KeyError: 'MACD_Signal'

The above exception was the direct cause of the following exception:

Traceback (most recent call last):
  File "c:\Users\pc\OneDrive\Desktop\phantom_alert_bot\signal_runner_loop.py", line 196, in _run
    signal_info = generate_signal(df, mode="realtime", logic=DEFAULT_LOGIC) # modeとlogicを渡す
                  ^^^^^^^^^^^^^^^^^^^^^^^^^^^^^^^^^^^^^^^^^^^^^^^^^^^^^^^^^
  File "c:\Users\pc\OneDrive\Desktop\phantom_alert_bot\signal_generator.py", line 71, in generate_signal
    signal_info = _generate_balanced_signal(df_ind, current_price)
                  ^^^^^^^^^^^^^^^^^^^^^^^^^^^^^^^^^^^^^^^^^^^^^^^^
  File "c:\Users\pc\OneDrive\Desktop\phantom_alert_bot\signal_generator.py", line 192, in _generate_balanced_signal
    macd_buy = (df_ind['MACD'].iloc[-1] > df_ind['MACD_Signal'].iloc[-1]) # MACDゴールデンクロス
                                          ~~~~~~^^^^^^^^^^^^^^^
  File "C:\Users\pc\AppData\Local\Programs\Python\Python312\Lib\site-packages\pandas\core\frame.py", line 4107, in __getitem__
    indexer = self.columns.get_loc(key)
              ^^^^^^^^^^^^^^^^^^^^^^^^^
  File "C:\Users\pc\AppData\Local\Programs\Python\Python312\Lib\site-packages\pandas\core\indexes\base.py", line 3819, in get_loc
    raise KeyError(key) from err
KeyError: 'MACD_Signal'
2025-06-13 01:18:32,294 - INFO - ✅ GOLD_USD-M5 シグナルランナーが初期化されました。
2025-06-13 01:18:41,331 - INFO - GOLD_USD-M5 シグナル監視ループを開始します。
2025-06-13 01:18:41,335 - INFO - GOLD_USD: MT5クライアントを初期化しています...
2025-06-13 01:18:41,339 - INFO - ✅ GOLD_USD: MT5クライアントの初期化に成功しました。
2025-06-13 01:18:41,341 - INFO - GOLD_USD: 新しい足 (M5) が形成されました。データ取得とシグナル判定を実行します。
2025-06-13 01:18:41,366 - ERROR - GOLD_USD: シグナル監視ループで予期せぬエラーが発生しました: Cannot convert tz-naive timestamps, use tz_localize to localize
Traceback (most recent call last):
  File "C:\Users\pc\OneDrive\Desktop\phantom_alert_bot\signal_runner_loop.py", line 192, in _run
    df, latest_time_tokyo = self._get_current_ohlc()
                            ^^^^^^^^^^^^^^^^^^^^^^^^
  File "C:\Users\pc\OneDrive\Desktop\phantom_alert_bot\signal_runner_loop.py", line 116, in _get_current_ohlc
    df.index = df.index.tz_convert('Asia/Tokyo') # チャート描画時などのため
               ^^^^^^^^^^^^^^^^^^^^^^^^^^^^^^^^^
  File "C:\Users\pc\OneDrive\Desktop\phantom_alert_bot\venv\Lib\site-packages\pandas\core\indexes\datetimes.py", line 283, in tz_convert
    arr = self._data.tz_convert(tz)
          ^^^^^^^^^^^^^^^^^^^^^^^^^
  File "C:\Users\pc\OneDrive\Desktop\phantom_alert_bot\venv\Lib\site-packages\pandas\core\arrays\datetimes.py", line 917, in tz_convert
    raise TypeError(
TypeError: Cannot convert tz-naive timestamps, use tz_localize to localize
2025-06-13 01:19:41,369 - INFO - GOLD_USD: 新しい足 (M5) が形成されました。データ取得とシグナル判定を実行します。
2025-06-13 01:19:41,371 - ERROR - GOLD_USD: シグナル監視ループで予期せぬエラーが発生しました: Cannot convert tz-naive timestamps, use tz_localize to localize
Traceback (most recent call last):
  File "C:\Users\pc\OneDrive\Desktop\phantom_alert_bot\signal_runner_loop.py", line 192, in _run
    df, latest_time_tokyo = self._get_current_ohlc()
                            ^^^^^^^^^^^^^^^^^^^^^^^^
  File "C:\Users\pc\OneDrive\Desktop\phantom_alert_bot\signal_runner_loop.py", line 116, in _get_current_ohlc
    df.index = df.index.tz_convert('Asia/Tokyo') # チャート描画時などのため
               ^^^^^^^^^^^^^^^^^^^^^^^^^^^^^^^^^
  File "C:\Users\pc\OneDrive\Desktop\phantom_alert_bot\venv\Lib\site-packages\pandas\core\indexes\datetimes.py", line 283, in tz_convert
    arr = self._data.tz_convert(tz)
          ^^^^^^^^^^^^^^^^^^^^^^^^^
  File "C:\Users\pc\OneDrive\Desktop\phantom_alert_bot\venv\Lib\site-packages\pandas\core\arrays\datetimes.py", line 917, in tz_convert
    raise TypeError(
TypeError: Cannot convert tz-naive timestamps, use tz_localize to localize
2025-06-13 01:20:41,374 - INFO - GOLD_USD: 新しい足 (M5) が形成されました。データ取得とシグナル判定を実行します。
2025-06-13 01:20:41,376 - ERROR - GOLD_USD: シグナル監視ループで予期せぬエラーが発生しました: Cannot convert tz-naive timestamps, use tz_localize to localize
Traceback (most recent call last):
  File "C:\Users\pc\OneDrive\Desktop\phantom_alert_bot\signal_runner_loop.py", line 192, in _run
    df, latest_time_tokyo = self._get_current_ohlc()
                            ^^^^^^^^^^^^^^^^^^^^^^^^
  File "C:\Users\pc\OneDrive\Desktop\phantom_alert_bot\signal_runner_loop.py", line 116, in _get_current_ohlc
    df.index = df.index.tz_convert('Asia/Tokyo') # チャート描画時などのため
               ^^^^^^^^^^^^^^^^^^^^^^^^^^^^^^^^^
  File "C:\Users\pc\OneDrive\Desktop\phantom_alert_bot\venv\Lib\site-packages\pandas\core\indexes\datetimes.py", line 283, in tz_convert
    arr = self._data.tz_convert(tz)
          ^^^^^^^^^^^^^^^^^^^^^^^^^
  File "C:\Users\pc\OneDrive\Desktop\phantom_alert_bot\venv\Lib\site-packages\pandas\core\arrays\datetimes.py", line 917, in tz_convert
    raise TypeError(
TypeError: Cannot convert tz-naive timestamps, use tz_localize to localize
2025-06-13 01:21:41,377 - INFO - GOLD_USD: 新しい足 (M5) が形成されました。データ取得とシグナル判定を実行します。
2025-06-13 01:21:41,385 - ERROR - GOLD_USD: シグナル監視ループで予期せぬエラーが発生しました: Cannot convert tz-naive timestamps, use tz_localize to localize
Traceback (most recent call last):
  File "C:\Users\pc\OneDrive\Desktop\phantom_alert_bot\signal_runner_loop.py", line 192, in _run
    df, latest_time_tokyo = self._get_current_ohlc()
                            ^^^^^^^^^^^^^^^^^^^^^^^^
  File "C:\Users\pc\OneDrive\Desktop\phantom_alert_bot\signal_runner_loop.py", line 116, in _get_current_ohlc
    df.index = df.index.tz_convert('Asia/Tokyo') # チャート描画時などのため
               ^^^^^^^^^^^^^^^^^^^^^^^^^^^^^^^^^
  File "C:\Users\pc\OneDrive\Desktop\phantom_alert_bot\venv\Lib\site-packages\pandas\core\indexes\datetimes.py", line 283, in tz_convert
    arr = self._data.tz_convert(tz)
          ^^^^^^^^^^^^^^^^^^^^^^^^^
  File "C:\Users\pc\OneDrive\Desktop\phantom_alert_bot\venv\Lib\site-packages\pandas\core\arrays\datetimes.py", line 917, in tz_convert
    raise TypeError(
TypeError: Cannot convert tz-naive timestamps, use tz_localize to localize
2025-06-13 01:22:41,389 - INFO - GOLD_USD: 新しい足 (M5) が形成されました。データ取得とシグナル判定を実行します。
2025-06-13 01:22:41,395 - ERROR - GOLD_USD: シグナル監視ループで予期せぬエラーが発生しました: Cannot convert tz-naive timestamps, use tz_localize to localize
Traceback (most recent call last):
  File "C:\Users\pc\OneDrive\Desktop\phantom_alert_bot\signal_runner_loop.py", line 192, in _run
    df, latest_time_tokyo = self._get_current_ohlc()
                            ^^^^^^^^^^^^^^^^^^^^^^^^
  File "C:\Users\pc\OneDrive\Desktop\phantom_alert_bot\signal_runner_loop.py", line 116, in _get_current_ohlc
    df.index = df.index.tz_convert('Asia/Tokyo') # チャート描画時などのため
               ^^^^^^^^^^^^^^^^^^^^^^^^^^^^^^^^^
  File "C:\Users\pc\OneDrive\Desktop\phantom_alert_bot\venv\Lib\site-packages\pandas\core\indexes\datetimes.py", line 283, in tz_convert
    arr = self._data.tz_convert(tz)
          ^^^^^^^^^^^^^^^^^^^^^^^^^
  File "C:\Users\pc\OneDrive\Desktop\phantom_alert_bot\venv\Lib\site-packages\pandas\core\arrays\datetimes.py", line 917, in tz_convert
    raise TypeError(
TypeError: Cannot convert tz-naive timestamps, use tz_localize to localize
2025-06-13 01:23:41,398 - INFO - GOLD_USD: 新しい足 (M5) が形成されました。データ取得とシグナル判定を実行します。
2025-06-13 01:23:41,406 - ERROR - GOLD_USD: シグナル監視ループで予期せぬエラーが発生しました: Cannot convert tz-naive timestamps, use tz_localize to localize
Traceback (most recent call last):
  File "C:\Users\pc\OneDrive\Desktop\phantom_alert_bot\signal_runner_loop.py", line 192, in _run
    df, latest_time_tokyo = self._get_current_ohlc()
                            ^^^^^^^^^^^^^^^^^^^^^^^^
  File "C:\Users\pc\OneDrive\Desktop\phantom_alert_bot\signal_runner_loop.py", line 116, in _get_current_ohlc
    df.index = df.index.tz_convert('Asia/Tokyo') # チャート描画時などのため
               ^^^^^^^^^^^^^^^^^^^^^^^^^^^^^^^^^
  File "C:\Users\pc\OneDrive\Desktop\phantom_alert_bot\venv\Lib\site-packages\pandas\core\indexes\datetimes.py", line 283, in tz_convert
    arr = self._data.tz_convert(tz)
          ^^^^^^^^^^^^^^^^^^^^^^^^^
  File "C:\Users\pc\OneDrive\Desktop\phantom_alert_bot\venv\Lib\site-packages\pandas\core\arrays\datetimes.py", line 917, in tz_convert
    raise TypeError(
TypeError: Cannot convert tz-naive timestamps, use tz_localize to localize
2025-06-13 01:24:41,410 - INFO - GOLD_USD: 新しい足 (M5) が形成されました。データ取得とシグナル判定を実行します。
2025-06-13 01:24:41,412 - ERROR - GOLD_USD: シグナル監視ループで予期せぬエラーが発生しました: Cannot convert tz-naive timestamps, use tz_localize to localize
Traceback (most recent call last):
  File "C:\Users\pc\OneDrive\Desktop\phantom_alert_bot\signal_runner_loop.py", line 192, in _run
    df, latest_time_tokyo = self._get_current_ohlc()
                            ^^^^^^^^^^^^^^^^^^^^^^^^
  File "C:\Users\pc\OneDrive\Desktop\phantom_alert_bot\signal_runner_loop.py", line 116, in _get_current_ohlc
    df.index = df.index.tz_convert('Asia/Tokyo') # チャート描画時などのため
               ^^^^^^^^^^^^^^^^^^^^^^^^^^^^^^^^^
  File "C:\Users\pc\OneDrive\Desktop\phantom_alert_bot\venv\Lib\site-packages\pandas\core\indexes\datetimes.py", line 283, in tz_convert
    arr = self._data.tz_convert(tz)
          ^^^^^^^^^^^^^^^^^^^^^^^^^
  File "C:\Users\pc\OneDrive\Desktop\phantom_alert_bot\venv\Lib\site-packages\pandas\core\arrays\datetimes.py", line 917, in tz_convert
    raise TypeError(
TypeError: Cannot convert tz-naive timestamps, use tz_localize to localize
2025-06-13 01:25:41,414 - INFO - GOLD_USD: 新しい足 (M5) が形成されました。データ取得とシグナル判定を実行します。
2025-06-13 01:25:41,423 - ERROR - GOLD_USD: シグナル監視ループで予期せぬエラーが発生しました: Cannot convert tz-naive timestamps, use tz_localize to localize
Traceback (most recent call last):
  File "C:\Users\pc\OneDrive\Desktop\phantom_alert_bot\signal_runner_loop.py", line 192, in _run
    df, latest_time_tokyo = self._get_current_ohlc()
                            ^^^^^^^^^^^^^^^^^^^^^^^^
  File "C:\Users\pc\OneDrive\Desktop\phantom_alert_bot\signal_runner_loop.py", line 116, in _get_current_ohlc
    df.index = df.index.tz_convert('Asia/Tokyo') # チャート描画時などのため
               ^^^^^^^^^^^^^^^^^^^^^^^^^^^^^^^^^
  File "C:\Users\pc\OneDrive\Desktop\phantom_alert_bot\venv\Lib\site-packages\pandas\core\indexes\datetimes.py", line 283, in tz_convert
    arr = self._data.tz_convert(tz)
          ^^^^^^^^^^^^^^^^^^^^^^^^^
  File "C:\Users\pc\OneDrive\Desktop\phantom_alert_bot\venv\Lib\site-packages\pandas\core\arrays\datetimes.py", line 917, in tz_convert
    raise TypeError(
TypeError: Cannot convert tz-naive timestamps, use tz_localize to localize
2025-06-13 01:26:41,427 - INFO - GOLD_USD: 新しい足 (M5) が形成されました。データ取得とシグナル判定を実行します。
2025-06-13 01:26:41,437 - ERROR - GOLD_USD: シグナル監視ループで予期せぬエラーが発生しました: Cannot convert tz-naive timestamps, use tz_localize to localize
Traceback (most recent call last):
  File "C:\Users\pc\OneDrive\Desktop\phantom_alert_bot\signal_runner_loop.py", line 192, in _run
    df, latest_time_tokyo = self._get_current_ohlc()
                            ^^^^^^^^^^^^^^^^^^^^^^^^
  File "C:\Users\pc\OneDrive\Desktop\phantom_alert_bot\signal_runner_loop.py", line 116, in _get_current_ohlc
    df.index = df.index.tz_convert('Asia/Tokyo') # チャート描画時などのため
               ^^^^^^^^^^^^^^^^^^^^^^^^^^^^^^^^^
  File "C:\Users\pc\OneDrive\Desktop\phantom_alert_bot\venv\Lib\site-packages\pandas\core\indexes\datetimes.py", line 283, in tz_convert
    arr = self._data.tz_convert(tz)
          ^^^^^^^^^^^^^^^^^^^^^^^^^
  File "C:\Users\pc\OneDrive\Desktop\phantom_alert_bot\venv\Lib\site-packages\pandas\core\arrays\datetimes.py", line 917, in tz_convert
    raise TypeError(
TypeError: Cannot convert tz-naive timestamps, use tz_localize to localize
2025-06-13 01:27:41,440 - INFO - GOLD_USD: 新しい足 (M5) が形成されました。データ取得とシグナル判定を実行します。
2025-06-13 01:27:41,441 - ERROR - GOLD_USD: シグナル監視ループで予期せぬエラーが発生しました: Cannot convert tz-naive timestamps, use tz_localize to localize
Traceback (most recent call last):
  File "C:\Users\pc\OneDrive\Desktop\phantom_alert_bot\signal_runner_loop.py", line 192, in _run
    df, latest_time_tokyo = self._get_current_ohlc()
                            ^^^^^^^^^^^^^^^^^^^^^^^^
  File "C:\Users\pc\OneDrive\Desktop\phantom_alert_bot\signal_runner_loop.py", line 116, in _get_current_ohlc
    df.index = df.index.tz_convert('Asia/Tokyo') # チャート描画時などのため
               ^^^^^^^^^^^^^^^^^^^^^^^^^^^^^^^^^
  File "C:\Users\pc\OneDrive\Desktop\phantom_alert_bot\venv\Lib\site-packages\pandas\core\indexes\datetimes.py", line 283, in tz_convert
    arr = self._data.tz_convert(tz)
          ^^^^^^^^^^^^^^^^^^^^^^^^^
  File "C:\Users\pc\OneDrive\Desktop\phantom_alert_bot\venv\Lib\site-packages\pandas\core\arrays\datetimes.py", line 917, in tz_convert
    raise TypeError(
TypeError: Cannot convert tz-naive timestamps, use tz_localize to localize
2025-06-13 01:28:41,443 - INFO - GOLD_USD: 新しい足 (M5) が形成されました。データ取得とシグナル判定を実行します。
2025-06-13 01:28:41,450 - ERROR - GOLD_USD: シグナル監視ループで予期せぬエラーが発生しました: Cannot convert tz-naive timestamps, use tz_localize to localize
Traceback (most recent call last):
  File "C:\Users\pc\OneDrive\Desktop\phantom_alert_bot\signal_runner_loop.py", line 192, in _run
    if self.line_notifier:
                        ^^^
  File "C:\Users\pc\OneDrive\Desktop\phantom_alert_bot\signal_runner_loop.py", line 116, in _get_current_ohlc
  File "C:\Users\pc\OneDrive\Desktop\phantom_alert_bot\venv\Lib\site-packages\pandas\core\indexes\datetimes.py", line 283, in tz_convert
    arr = self._data.tz_convert(tz)
          ^^^^^^^^^^^^^^^^^^^^^^^^^
  File "C:\Users\pc\OneDrive\Desktop\phantom_alert_bot\venv\Lib\site-packages\pandas\core\arrays\datetimes.py", line 917, in tz_convert
    raise TypeError(
TypeError: Cannot convert tz-naive timestamps, use tz_localize to localize
