2025-06-11 18:43:24,099 - INFO - ✅ EURUSD-H1 シグナルランナーが初期化されました。
2025-06-11 18:43:31,142 - INFO - EURUSD-H1 シグナル監視ループを開始します。
2025-06-11 18:43:31,144 - INFO - EURUSD: MT5クライアントを初期化しています...
2025-06-11 18:43:31,145 - INFO - ✅ EURUSD: MT5クライアントの初期化に成功しました。
2025-06-11 18:43:31,146 - INFO - EURUSD: 新しい足 (H1) が形成されました。データ取得とシグナル判定を実行します。
2025-06-11 18:43:31,146 - ERROR - EURUSD: シグナル監視ループで予期せぬエラーが発生しました: module 'MetaTrader5' has no attribute 'is_connected'
Traceback (most recent call last):
  File "c:\Users\pc\OneDrive\Desktop\phantom_alert_bot\signal_runner_loop.py", line 190, in _run
    df, latest_time_tokyo = self._get_current_ohlc()
                            ~~~~~~~~~~~~~~~~~~~~~~^^
  File "c:\Users\pc\OneDrive\Desktop\phantom_alert_bot\signal_runner_loop.py", line 85, in _get_current_ohlc
    if not self._initialize_mt5():
           ~~~~~~~~~~~~~~~~~~~~^^
  File "c:\Users\pc\OneDrive\Desktop\phantom_alert_bot\signal_runner_loop.py", line 65, in _initialize_mt5
    if not self.mt5_initialized or not mt5.is_connected():
                                       ^^^^^^^^^^^^^^^^
AttributeError: module 'MetaTrader5' has no attribute 'is_connected'
2025-06-11 18:54:29,453 - INFO - ✅ EURUSD-H1 シグナルランナーが初期化されました。
2025-06-11 18:54:36,491 - INFO - EURUSD-H1 シグナル監視ループを開始します。
2025-06-11 18:54:36,491 - INFO - EURUSD: MT5クライアントを初期化しています...
2025-06-11 18:54:36,492 - INFO - ✅ EURUSD: MT5クライアントの初期化に成功しました。
2025-06-11 18:54:36,492 - INFO - EURUSD: 新しい足 (H1) が形成されました。データ取得とシグナル判定を実行します。
2025-06-11 18:54:36,516 - ERROR - EURUSD: シグナル監視ループで予期せぬエラーが発生しました: generate_signal() got an unexpected keyword argument 'logic'
Traceback (most recent call last):
  File "c:\Users\pc\OneDrive\Desktop\phantom_alert_bot\signal_runner_loop.py", line 177, in _run
    signal_info = generate_signal(df, mode="realtime", logic=DEFAULT_LOGIC) # modeとlogicを渡す
TypeError: generate_signal() got an unexpected keyword argument 'logic'
2025-06-12 00:09:30,863 - INFO - ✅ EURUSD-H1 シグナルランナーが初期化されました。
2025-06-12 00:09:37,975 - INFO - EURUSD-H1 シグナル監視ループを開始します。
2025-06-12 00:09:37,977 - INFO - EURUSD: MT5クライアントを初期化しています...
2025-06-12 00:09:37,977 - INFO - ✅ EURUSD: MT5クライアントの初期化に成功しました。
2025-06-12 00:09:37,979 - INFO - EURUSD: 新しい足 (H1) が形成されました。データ取得とシグナル判定を実行します。
2025-06-12 00:09:38,013 - INFO - EURUSD-H1 シグナル判定結果: No signal
2025-06-12 00:09:38,013 - INFO - EURUSD-H1: シグナルなし。
2025-06-12 00:09:38,013 - ERROR - EURUSD: シグナル監視ループで予期せぬエラーが発生しました: cannot access local variable 'uploaded_image_url' where it is not associated with a value
Traceback (most recent call last):
  File "c:\Users\pc\OneDrive\Desktop\phantom_alert_bot\signal_runner_loop.py", line 230, in _run
    image_url=uploaded_image_url # ImgurのURLを保存
              ^^^^^^^^^^^^^^^^^^
UnboundLocalError: cannot access local variable 'uploaded_image_url' where it is not associated with a value
2025-06-12 00:10:15,483 - INFO - ✅ EURUSD-H1 シグナルランナーが初期化されました。
2025-06-12 00:10:22,512 - INFO - EURUSD-H1 シグナル監視ループを開始します。
2025-06-12 00:10:22,513 - INFO - EURUSD: MT5クライアントを初期化しています...
2025-06-12 00:10:22,514 - INFO - ✅ EURUSD: MT5クライアントの初期化に成功しました。
2025-06-12 00:10:22,514 - INFO - EURUSD: 新しい足 (H1) が形成されました。データ取得とシグナル判定を実行します。
2025-06-12 00:10:22,541 - INFO - EURUSD-H1 シグナル判定結果: No signal
2025-06-12 00:10:22,541 - INFO - EURUSD-H1: シグナルなし。
2025-06-12 00:10:22,542 - ERROR - EURUSD: シグナル監視ループで予期せぬエラーが発生しました: cannot access local variable 'uploaded_image_url' where it is not associated with a value
Traceback (most recent call last):
  File "C:\Users\pc\OneDrive\Desktop\phantom_alert_bot\signal_runner_loop.py", line 230, in _run
    image_url=uploaded_image_url # ImgurのURLを保存
              ^^^^^^^^^^^^^^^^^^
UnboundLocalError: cannot access local variable 'uploaded_image_url' where it is not associated with a value
2025-06-12 00:11:00,890 - INFO - ✅ EURUSD-H1 シグナルランナーが初期化されました。
2025-06-12 00:11:02,788 - INFO - ✅ EURUSD-H1 シグナルランナーが初期化されました。
2025-06-12 00:11:07,916 - INFO - EURUSD-H1 シグナル監視ループを開始します。
2025-06-12 00:11:07,917 - INFO - EURUSD: MT5クライアントを初期化しています...
2025-06-12 00:11:07,918 - INFO - ✅ EURUSD: MT5クライアントの初期化に成功しました。
2025-06-12 00:11:07,918 - INFO - EURUSD: 新しい足 (H1) が形成されました。データ取得とシグナル判定を実行します。
2025-06-12 00:11:07,949 - INFO - EURUSD-H1 シグナル判定結果: No signal
2025-06-12 00:11:07,950 - INFO - EURUSD-H1: シグナルなし。
2025-06-12 00:11:07,950 - ERROR - EURUSD: シグナル監視ループで予期せぬエラーが発生しました: cannot access local variable 'uploaded_image_url' where it is not associated with a value
Traceback (most recent call last):
  File "C:\Users\pc\OneDrive\Desktop\phantom_alert_bot\signal_runner_loop.py", line 230, in _run
    image_url=uploaded_image_url # ImgurのURLを保存
              ^^^^^^^^^^^^^^^^^^
UnboundLocalError: cannot access local variable 'uploaded_image_url' where it is not associated with a value
2025-06-12 00:11:09,814 - INFO - EURUSD-H1 シグナル監視ループを開始します。
2025-06-12 00:11:09,816 - INFO - EURUSD: MT5クライアントを初期化しています...
2025-06-12 00:11:09,816 - INFO - ✅ EURUSD: MT5クライアントの初期化に成功しました。
2025-06-12 00:11:09,818 - INFO - EURUSD: 新しい足 (H1) が形成されました。データ取得とシグナル判定を実行します。
2025-06-12 00:11:09,863 - INFO - EURUSD-H1 シグナル判定結果: No signal
2025-06-12 00:11:09,863 - INFO - EURUSD-H1: シグナルなし。
2025-06-12 00:11:09,863 - ERROR - EURUSD: シグナル監視ループで予期せぬエラーが発生しました: cannot access local variable 'uploaded_image_url' where it is not associated with a value
Traceback (most recent call last):
  File "C:\Users\pc\OneDrive\Desktop\phantom_alert_bot\signal_runner_loop.py", line 230, in _run
    image_url=uploaded_image_url # ImgurのURLを保存
              ^^^^^^^^^^^^^^^^^^
UnboundLocalError: cannot access local variable 'uploaded_image_url' where it is not associated with a value
2025-06-12 00:21:38,015 - INFO - EURUSD: 新しい足 (H1) が形成されました。データ取得とシグナル判定を実行します。
2025-06-12 00:21:38,053 - INFO - EURUSD-H1 シグナル判定結果: No signal
2025-06-12 00:21:38,054 - INFO - EURUSD-H1: シグナルなし。
2025-06-12 00:21:38,059 - ERROR - EURUSD: シグナル監視ループで予期せぬエラーが発生しました: cannot access local variable 'uploaded_image_url' where it is not associated with a value
Traceback (most recent call last):
  File "c:\Users\pc\OneDrive\Desktop\phantom_alert_bot\signal_runner_loop.py", line 230, in _run
UnboundLocalError: cannot access local variable 'uploaded_image_url' where it is not associated with a value
2025-06-12 00:23:07,952 - INFO - EURUSD: 新しい足 (H1) が形成されました。データ取得とシグナル判定を実行します。
2025-06-12 00:23:07,984 - INFO - EURUSD-H1 シグナル判定結果: No signal
2025-06-12 00:23:07,984 - INFO - EURUSD-H1: シグナルなし。
2025-06-12 00:23:07,984 - ERROR - EURUSD: シグナル監視ループで予期せぬエラーが発生しました: cannot access local variable 'uploaded_image_url' where it is not associated with a value
Traceback (most recent call last):
  File "C:\Users\pc\OneDrive\Desktop\phantom_alert_bot\signal_runner_loop.py", line 230, in _run
UnboundLocalError: cannot access local variable 'uploaded_image_url' where it is not associated with a value
2025-06-12 00:23:09,866 - INFO - EURUSD: 新しい足 (H1) が形成されました。データ取得とシグナル判定を実行します。
2025-06-12 00:23:09,889 - INFO - EURUSD-H1 シグナル判定結果: No signal
2025-06-12 00:23:09,889 - INFO - EURUSD-H1: シグナルなし。
2025-06-12 00:23:09,889 - ERROR - EURUSD: シグナル監視ループで予期せぬエラーが発生しました: cannot access local variable 'uploaded_image_url' where it is not associated with a value
Traceback (most recent call last):
  File "C:\Users\pc\OneDrive\Desktop\phantom_alert_bot\signal_runner_loop.py", line 230, in _run
UnboundLocalError: cannot access local variable 'uploaded_image_url' where it is not associated with a value
2025-06-12 00:33:38,060 - INFO - EURUSD: 新しい足 (H1) が形成されました。データ取得とシグナル判定を実行します。
2025-06-12 00:33:38,129 - INFO - EURUSD-H1 シグナル判定結果: No signal
2025-06-12 00:33:38,130 - INFO - EURUSD-H1: シグナルなし。
2025-06-12 00:33:38,132 - ERROR - EURUSD: シグナル監視ループで予期せぬエラーが発生しました: cannot access local variable 'uploaded_image_url' where it is not associated with a value
Traceback (most recent call last):
  File "c:\Users\pc\OneDrive\Desktop\phantom_alert_bot\signal_runner_loop.py", line 230, in _run
UnboundLocalError: cannot access local variable 'uploaded_image_url' where it is not associated with a value
2025-06-12 00:35:07,986 - INFO - EURUSD: 新しい足 (H1) が形成されました。データ取得とシグナル判定を実行します。
2025-06-12 00:35:08,048 - INFO - EURUSD-H1 シグナル判定結果: No signal
2025-06-12 00:35:08,048 - INFO - EURUSD-H1: シグナルなし。
2025-06-12 00:35:08,049 - ERROR - EURUSD: シグナル監視ループで予期せぬエラーが発生しました: cannot access local variable 'uploaded_image_url' where it is not associated with a value
Traceback (most recent call last):
  File "C:\Users\pc\OneDrive\Desktop\phantom_alert_bot\signal_runner_loop.py", line 230, in _run
UnboundLocalError: cannot access local variable 'uploaded_image_url' where it is not associated with a value
2025-06-12 00:35:09,890 - INFO - EURUSD: 新しい足 (H1) が形成されました。データ取得とシグナル判定を実行します。
2025-06-12 00:35:09,911 - INFO - EURUSD-H1 シグナル判定結果: No signal
2025-06-12 00:35:09,911 - INFO - EURUSD-H1: シグナルなし。
2025-06-12 00:35:09,914 - ERROR - EURUSD: シグナル監視ループで予期せぬエラーが発生しました: cannot access local variable 'uploaded_image_url' where it is not associated with a value
Traceback (most recent call last):
  File "C:\Users\pc\OneDrive\Desktop\phantom_alert_bot\signal_runner_loop.py", line 230, in _run
UnboundLocalError: cannot access local variable 'uploaded_image_url' where it is not associated with a value
2025-06-12 00:45:38,134 - INFO - EURUSD: 新しい足 (H1) が形成されました。データ取得とシグナル判定を実行します。
2025-06-12 00:45:38,207 - INFO - EURUSD-H1 シグナル判定結果: No signal
2025-06-12 00:45:38,209 - INFO - EURUSD-H1: シグナルなし。
2025-06-12 00:45:38,210 - ERROR - EURUSD: シグナル監視ループで予期せぬエラーが発生しました: cannot access local variable 'uploaded_image_url' where it is not associated with a value
Traceback (most recent call last):
  File "c:\Users\pc\OneDrive\Desktop\phantom_alert_bot\signal_runner_loop.py", line 230, in _run
UnboundLocalError: cannot access local variable 'uploaded_image_url' where it is not associated with a value
2025-06-12 00:47:08,052 - INFO - EURUSD: 新しい足 (H1) が形成されました。データ取得とシグナル判定を実行します。
2025-06-12 00:47:08,130 - INFO - EURUSD-H1 シグナル判定結果: No signal
2025-06-12 00:47:08,131 - INFO - EURUSD-H1: シグナルなし。
2025-06-12 00:47:08,132 - ERROR - EURUSD: シグナル監視ループで予期せぬエラーが発生しました: cannot access local variable 'uploaded_image_url' where it is not associated with a value
Traceback (most recent call last):
  File "C:\Users\pc\OneDrive\Desktop\phantom_alert_bot\signal_runner_loop.py", line 230, in _run
UnboundLocalError: cannot access local variable 'uploaded_image_url' where it is not associated with a value
2025-06-12 00:47:09,915 - INFO - EURUSD: 新しい足 (H1) が形成されました。データ取得とシグナル判定を実行します。
2025-06-12 00:47:09,937 - INFO - EURUSD-H1 シグナル判定結果: No signal
2025-06-12 00:47:09,937 - INFO - EURUSD-H1: シグナルなし。
2025-06-12 00:47:09,938 - ERROR - EURUSD: シグナル監視ループで予期せぬエラーが発生しました: cannot access local variable 'uploaded_image_url' where it is not associated with a value
Traceback (most recent call last):
  File "C:\Users\pc\OneDrive\Desktop\phantom_alert_bot\signal_runner_loop.py", line 230, in _run
UnboundLocalError: cannot access local variable 'uploaded_image_url' where it is not associated with a value
2025-06-12 10:40:26,291 - INFO - ✅ EURUSD-H1 シグナルランナーが初期化されました。
2025-06-12 10:40:33,354 - INFO - EURUSD-H1 シグナル監視ループを開始します。
2025-06-12 10:40:33,356 - INFO - EURUSD: MT5クライアントを初期化しています...
2025-06-12 10:40:33,359 - INFO - ✅ EURUSD: MT5クライアントの初期化に成功しました。
2025-06-12 10:40:33,360 - INFO - EURUSD: 新しい足 (H1) が形成されました。データ取得とシグナル判定を実行します。
2025-06-12 10:40:33,436 - ERROR - EURUSD: シグナル監視ループで予期せぬエラーが発生しました: 'MACD_Signal'
Traceback (most recent call last):
  File "C:\Users\pc\AppData\Local\Programs\Python\Python312\Lib\site-packages\pandas\core\indexes\base.py", line 3812, in get_loc
    return self._engine.get_loc(casted_key)
           ^^^^^^^^^^^^^^^^^^^^^^^^^^^^^^^^
  File "pandas/_libs/index.pyx", line 167, in pandas._libs.index.IndexEngine.get_loc
  File "pandas/_libs/index.pyx", line 196, in pandas._libs.index.IndexEngine.get_loc
  File "pandas/_libs/hashtable_class_helper.pxi", line 7088, in pandas._libs.hashtable.PyObjectHashTable.get_item
  File "pandas/_libs/hashtable_class_helper.pxi", line 7096, in pandas._libs.hashtable.PyObjectHashTable.get_item
KeyError: 'MACD_Signal'

The above exception was the direct cause of the following exception:

Traceback (most recent call last):
  File "c:\Users\pc\OneDrive\Desktop\phantom_alert_bot\signal_runner_loop.py", line 196, in _run
    signal_info = generate_signal(df, mode="realtime", logic=DEFAULT_LOGIC) # modeとlogicを渡す
                  ^^^^^^^^^^^^^^^^^^^^^^^^^^^^^^^^^^^^^^^^^^^^^^^^^^^^^^^^^
  File "c:\Users\pc\OneDrive\Desktop\phantom_alert_bot\signal_generator.py", line 71, in generate_signal
    signal_info = _generate_balanced_signal(df_ind, current_price)
                  ^^^^^^^^^^^^^^^^^^^^^^^^^^^^^^^^^^^^^^^^^^^^^^^^
  File "c:\Users\pc\OneDrive\Desktop\phantom_alert_bot\signal_generator.py", line 192, in _generate_balanced_signal
    macd_buy = (df_ind['MACD'].iloc[-1] > df_ind['MACD_Signal'].iloc[-1]) # MACDゴールデンクロス
                                          ~~~~~~^^^^^^^^^^^^^^^
  File "C:\Users\pc\AppData\Local\Programs\Python\Python312\Lib\site-packages\pandas\core\frame.py", line 4107, in __getitem__
    indexer = self.columns.get_loc(key)
              ^^^^^^^^^^^^^^^^^^^^^^^^^
  File "C:\Users\pc\AppData\Local\Programs\Python\Python312\Lib\site-packages\pandas\core\indexes\base.py", line 3819, in get_loc
    raise KeyError(key) from err
KeyError: 'MACD_Signal'
2025-06-13 01:18:32,291 - INFO - ✅ EURUSD-H1 シグナルランナーが初期化されました。
2025-06-13 01:18:39,324 - INFO - EURUSD-H1 シグナル監視ループを開始します。
2025-06-13 01:18:39,326 - INFO - EURUSD: MT5クライアントを初期化しています...
2025-06-13 01:18:39,332 - INFO - ✅ EURUSD: MT5クライアントの初期化に成功しました。
2025-06-13 01:18:39,333 - INFO - EURUSD: 新しい足 (H1) が形成されました。データ取得とシグナル判定を実行します。
2025-06-13 01:18:39,357 - ERROR - EURUSD: シグナル監視ループで予期せぬエラーが発生しました: Cannot convert tz-naive timestamps, use tz_localize to localize
Traceback (most recent call last):
  File "C:\Users\pc\OneDrive\Desktop\phantom_alert_bot\signal_runner_loop.py", line 192, in _run
    df, latest_time_tokyo = self._get_current_ohlc()
                            ^^^^^^^^^^^^^^^^^^^^^^^^
  File "C:\Users\pc\OneDrive\Desktop\phantom_alert_bot\signal_runner_loop.py", line 116, in _get_current_ohlc
    df.index = df.index.tz_convert('Asia/Tokyo') # チャート描画時などのため
               ^^^^^^^^^^^^^^^^^^^^^^^^^^^^^^^^^
  File "C:\Users\pc\OneDrive\Desktop\phantom_alert_bot\venv\Lib\site-packages\pandas\core\indexes\datetimes.py", line 283, in tz_convert
    arr = self._data.tz_convert(tz)
          ^^^^^^^^^^^^^^^^^^^^^^^^^
  File "C:\Users\pc\OneDrive\Desktop\phantom_alert_bot\venv\Lib\site-packages\pandas\core\arrays\datetimes.py", line 917, in tz_convert
    raise TypeError(
TypeError: Cannot convert tz-naive timestamps, use tz_localize to localize
