2025-06-11 18:43:24,107 - INFO - ✅ GOLD_USD-M15 シグナルランナーが初期化されました。
2025-06-11 18:43:34,152 - INFO - GOLD_USD-M15 シグナル監視ループを開始します。
2025-06-11 18:43:34,154 - INFO - GOLD_USD: MT5クライアントを初期化しています...
2025-06-11 18:43:34,156 - INFO - ✅ GOLD_USD: MT5クライアントの初期化に成功しました。
2025-06-11 18:43:34,156 - INFO - GOLD_USD: 新しい足 (M15) が形成されました。データ取得とシグナル判定を実行します。
2025-06-11 18:43:34,157 - ERROR - GOLD_USD: シグナル監視ループで予期せぬエラーが発生しました: module 'MetaTrader5' has no attribute 'is_connected'
Traceback (most recent call last):
  File "c:\Users\pc\OneDrive\Desktop\phantom_alert_bot\signal_runner_loop.py", line 190, in _run
    df, latest_time_tokyo = self._get_current_ohlc()
                            ~~~~~~~~~~~~~~~~~~~~~~^^
  File "c:\Users\pc\OneDrive\Desktop\phantom_alert_bot\signal_runner_loop.py", line 85, in _get_current_ohlc
    if not self._initialize_mt5():
           ~~~~~~~~~~~~~~~~~~~~^^
  File "c:\Users\pc\OneDrive\Desktop\phantom_alert_bot\signal_runner_loop.py", line 65, in _initialize_mt5
    if not self.mt5_initialized or not mt5.is_connected():
                                       ^^^^^^^^^^^^^^^^
AttributeError: module 'MetaTrader5' has no attribute 'is_connected'
2025-06-11 18:46:34,166 - INFO - GOLD_USD: 新しい足 (M15) が形成されました。データ取得とシグナル判定を実行します。
2025-06-11 18:46:34,167 - ERROR - GOLD_USD: シグナル監視ループで予期せぬエラーが発生しました: module 'MetaTrader5' has no attribute 'is_connected'
Traceback (most recent call last):
  File "c:\Users\pc\OneDrive\Desktop\phantom_alert_bot\signal_runner_loop.py", line 190, in _run
    df, latest_time_tokyo = self._get_current_ohlc()
                            ~~~~~~~~~~~~~~~~~~~~~~^^
  File "c:\Users\pc\OneDrive\Desktop\phantom_alert_bot\signal_runner_loop.py", line 85, in _get_current_ohlc
    if not self._initialize_mt5():
           ~~~~~~~~~~~~~~~~~~~~^^
  File "c:\Users\pc\OneDrive\Desktop\phantom_alert_bot\signal_runner_loop.py", line 65, in _initialize_mt5
    if not self.mt5_initialized or not mt5.is_connected():
                                       ^^^^^^^^^^^^^^^^
AttributeError: module 'MetaTrader5' has no attribute 'is_connected'
2025-06-11 18:49:34,172 - INFO - GOLD_USD: 新しい足 (M15) が形成されました。データ取得とシグナル判定を実行します。
2025-06-11 18:49:34,173 - ERROR - GOLD_USD: シグナル監視ループで予期せぬエラーが発生しました: module 'MetaTrader5' has no attribute 'is_connected'
Traceback (most recent call last):
  File "c:\Users\pc\OneDrive\Desktop\phantom_alert_bot\signal_runner_loop.py", line 190, in _run
    df, latest_time_tokyo = self._get_current_ohlc()
                            ~~~~~~~~~~~~~~~~~~~~~~^^
  File "c:\Users\pc\OneDrive\Desktop\phantom_alert_bot\signal_runner_loop.py", line 85, in _get_current_ohlc
    if not self._initialize_mt5():
           ~~~~~~~~~~~~~~~~~~~~^^
  File "c:\Users\pc\OneDrive\Desktop\phantom_alert_bot\signal_runner_loop.py", line 65, in _initialize_mt5
    if not self.mt5_initialized or not mt5.is_connected():
                                       ^^^^^^^^^^^^^^^^
AttributeError: module 'MetaTrader5' has no attribute 'is_connected'
2025-06-11 18:54:29,458 - INFO - ✅ GOLD_USD-M15 シグナルランナーが初期化されました。
2025-06-11 18:54:39,502 - INFO - GOLD_USD-M15 シグナル監視ループを開始します。
2025-06-11 18:54:39,504 - INFO - GOLD_USD: MT5クライアントを初期化しています...
2025-06-11 18:54:39,506 - INFO - ✅ GOLD_USD: MT5クライアントの初期化に成功しました。
2025-06-11 18:54:39,506 - INFO - GOLD_USD: 新しい足 (M15) が形成されました。データ取得とシグナル判定を実行します。
2025-06-11 18:54:39,587 - ERROR - GOLD_USD: シグナル監視ループで予期せぬエラーが発生しました: generate_signal() got an unexpected keyword argument 'logic'
Traceback (most recent call last):
  File "c:\Users\pc\OneDrive\Desktop\phantom_alert_bot\signal_runner_loop.py", line 177, in _run
    signal_info = generate_signal(df, mode="realtime", logic=DEFAULT_LOGIC) # modeとlogicを渡す
TypeError: generate_signal() got an unexpected keyword argument 'logic'
2025-06-11 18:57:39,590 - INFO - GOLD_USD: 新しい足 (M15) が形成されました。データ取得とシグナル判定を実行します。
2025-06-11 18:57:39,599 - ERROR - GOLD_USD: シグナル監視ループで予期せぬエラーが発生しました: generate_signal() got an unexpected keyword argument 'logic'
Traceback (most recent call last):
  File "c:\Users\pc\OneDrive\Desktop\phantom_alert_bot\signal_runner_loop.py", line 177, in _run
    signal_info = generate_signal(df, mode="realtime", logic=DEFAULT_LOGIC) # modeとlogicを渡す
TypeError: generate_signal() got an unexpected keyword argument 'logic'
2025-06-12 00:09:30,881 - INFO - ✅ GOLD_USD-M15 シグナルランナーが初期化されました。
2025-06-12 00:09:40,986 - INFO - GOLD_USD-M15 シグナル監視ループを開始します。
2025-06-12 00:09:40,987 - INFO - GOLD_USD: MT5クライアントを初期化しています...
2025-06-12 00:09:40,988 - INFO - ✅ GOLD_USD: MT5クライアントの初期化に成功しました。
2025-06-12 00:09:40,989 - INFO - GOLD_USD: 新しい足 (M15) が形成されました。データ取得とシグナル判定を実行します。
2025-06-12 00:09:41,010 - INFO - GOLD_USD-M15 シグナル判定結果: Balanced Buy Signal (Confluence: MACD Golden Cross, Stochastic Golden Cross)
2025-06-12 00:09:41,011 - ERROR - GOLD_USD: シグナル監視ループで予期せぬエラーが発生しました: 'SignalRunner' object has no attribute '_generate_chart_and_upload'
Traceback (most recent call last):
  File "c:\Users\pc\OneDrive\Desktop\phantom_alert_bot\signal_runner_loop.py", line 199, in _run
    uploaded_image_url = self._generate_chart_and_upload(df, signal_info, image_filename)
                         ^^^^^^^^^^^^^^^^^^^^^^^^^^^^^^^
AttributeError: 'SignalRunner' object has no attribute '_generate_chart_and_upload'
2025-06-12 00:10:15,486 - INFO - ✅ GOLD_USD-M15 シグナルランナーが初期化されました。
2025-06-12 00:10:25,522 - INFO - GOLD_USD-M15 シグナル監視ループを開始します。
2025-06-12 00:10:25,524 - INFO - GOLD_USD: MT5クライアントを初期化しています...
2025-06-12 00:10:25,525 - INFO - ✅ GOLD_USD: MT5クライアントの初期化に成功しました。
2025-06-12 00:10:25,525 - INFO - GOLD_USD: 新しい足 (M15) が形成されました。データ取得とシグナル判定を実行します。
2025-06-12 00:10:25,562 - INFO - GOLD_USD-M15 シグナル判定結果: Balanced Buy Signal (Confluence: MACD Golden Cross, Stochastic Golden Cross)
2025-06-12 00:10:25,563 - ERROR - GOLD_USD: シグナル監視ループで予期せぬエラーが発生しました: 'SignalRunner' object has no attribute '_generate_chart_and_upload'
Traceback (most recent call last):
  File "C:\Users\pc\OneDrive\Desktop\phantom_alert_bot\signal_runner_loop.py", line 199, in _run
    uploaded_image_url = self._generate_chart_and_upload(df, signal_info, image_filename)
                         ^^^^^^^^^^^^^^^^^^^^^^^^^^^^^^^
AttributeError: 'SignalRunner' object has no attribute '_generate_chart_and_upload'
2025-06-12 00:11:00,896 - INFO - ✅ GOLD_USD-M15 シグナルランナーが初期化されました。
2025-06-12 00:11:02,792 - INFO - ✅ GOLD_USD-M15 シグナルランナーが初期化されました。
2025-06-12 00:11:10,922 - INFO - GOLD_USD-M15 シグナル監視ループを開始します。
2025-06-12 00:11:10,923 - INFO - GOLD_USD: MT5クライアントを初期化しています...
2025-06-12 00:11:10,924 - INFO - ✅ GOLD_USD: MT5クライアントの初期化に成功しました。
2025-06-12 00:11:10,924 - INFO - GOLD_USD: 新しい足 (M15) が形成されました。データ取得とシグナル判定を実行します。
2025-06-12 00:11:10,945 - INFO - GOLD_USD-M15 シグナル判定結果: Balanced Buy Signal (Confluence: MACD Golden Cross, Stochastic Golden Cross)
2025-06-12 00:11:10,945 - ERROR - GOLD_USD: シグナル監視ループで予期せぬエラーが発生しました: 'SignalRunner' object has no attribute '_generate_chart_and_upload'
Traceback (most recent call last):
  File "C:\Users\pc\OneDrive\Desktop\phantom_alert_bot\signal_runner_loop.py", line 199, in _run
    uploaded_image_url = self._generate_chart_and_upload(df, signal_info, image_filename)
                         ^^^^^^^^^^^^^^^^^^^^^^^^^^^^^^^
AttributeError: 'SignalRunner' object has no attribute '_generate_chart_and_upload'
2025-06-12 00:11:12,822 - INFO - GOLD_USD-M15 シグナル監視ループを開始します。
2025-06-12 00:11:12,823 - INFO - GOLD_USD: MT5クライアントを初期化しています...
2025-06-12 00:11:12,823 - INFO - ✅ GOLD_USD: MT5クライアントの初期化に成功しました。
2025-06-12 00:11:12,824 - INFO - GOLD_USD: 新しい足 (M15) が形成されました。データ取得とシグナル判定を実行します。
2025-06-12 00:11:12,846 - INFO - GOLD_USD-M15 シグナル判定結果: Balanced Buy Signal (Confluence: MACD Golden Cross, Stochastic Golden Cross)
2025-06-12 00:11:12,846 - ERROR - GOLD_USD: シグナル監視ループで予期せぬエラーが発生しました: 'SignalRunner' object has no attribute '_generate_chart_and_upload'
Traceback (most recent call last):
  File "C:\Users\pc\OneDrive\Desktop\phantom_alert_bot\signal_runner_loop.py", line 199, in _run
    uploaded_image_url = self._generate_chart_and_upload(df, signal_info, image_filename)
                         ^^^^^^^^^^^^^^^^^^^^^^^^^^^^^^^
AttributeError: 'SignalRunner' object has no attribute '_generate_chart_and_upload'
2025-06-12 00:12:41,013 - INFO - GOLD_USD: 新しい足 (M15) が形成されました。データ取得とシグナル判定を実行します。
2025-06-12 00:12:41,039 - INFO - GOLD_USD-M15 シグナル判定結果: Balanced Buy Signal (Confluence: MACD Golden Cross, Stochastic Golden Cross)
2025-06-12 00:12:41,039 - ERROR - GOLD_USD: シグナル監視ループで予期せぬエラーが発生しました: 'SignalRunner' object has no attribute '_generate_chart_and_upload'
Traceback (most recent call last):
  File "c:\Users\pc\OneDrive\Desktop\phantom_alert_bot\signal_runner_loop.py", line 199, in _run
    uploaded_image_url = self._generate_chart_and_upload(df, signal_info, image_filename)
                         ^^^^^^^^^^^^^^^^^^^^^^^^^^^^^^^
AttributeError: 'SignalRunner' object has no attribute '_generate_chart_and_upload'
2025-06-12 00:13:25,565 - INFO - GOLD_USD: 新しい足 (M15) が形成されました。データ取得とシグナル判定を実行します。
2025-06-12 00:13:25,588 - INFO - GOLD_USD-M15 シグナル判定結果: Balanced Buy Signal (Confluence: MACD Golden Cross, Stochastic Golden Cross)
2025-06-12 00:13:25,588 - ERROR - GOLD_USD: シグナル監視ループで予期せぬエラーが発生しました: 'SignalRunner' object has no attribute '_generate_chart_and_upload'
Traceback (most recent call last):
  File "C:\Users\pc\OneDrive\Desktop\phantom_alert_bot\signal_runner_loop.py", line 199, in _run
    uploaded_image_url = self._generate_chart_and_upload(df, signal_info, image_filename)
                         ^^^^^^^^^^^^^^^^^^^^^^^^^^^^^^^
AttributeError: 'SignalRunner' object has no attribute '_generate_chart_and_upload'
2025-06-12 00:14:10,946 - INFO - GOLD_USD: 新しい足 (M15) が形成されました。データ取得とシグナル判定を実行します。
2025-06-12 00:14:10,967 - INFO - GOLD_USD-M15 シグナル判定結果: Balanced Buy Signal (Confluence: MACD Golden Cross, Stochastic Golden Cross)
2025-06-12 00:14:10,967 - ERROR - GOLD_USD: シグナル監視ループで予期せぬエラーが発生しました: 'SignalRunner' object has no attribute '_generate_chart_and_upload'
Traceback (most recent call last):
  File "C:\Users\pc\OneDrive\Desktop\phantom_alert_bot\signal_runner_loop.py", line 199, in _run
    uploaded_image_url = self._generate_chart_and_upload(df, signal_info, image_filename)
                         ^^^^^^^^^^^^^^^^^^^^^^^^^^^^^^^
AttributeError: 'SignalRunner' object has no attribute '_generate_chart_and_upload'
2025-06-12 00:14:12,847 - INFO - GOLD_USD: 新しい足 (M15) が形成されました。データ取得とシグナル判定を実行します。
2025-06-12 00:14:12,893 - INFO - GOLD_USD-M15 シグナル判定結果: Balanced Buy Signal (Confluence: MACD Golden Cross, Stochastic Golden Cross)
2025-06-12 00:14:12,893 - ERROR - GOLD_USD: シグナル監視ループで予期せぬエラーが発生しました: 'SignalRunner' object has no attribute '_generate_chart_and_upload'
Traceback (most recent call last):
  File "C:\Users\pc\OneDrive\Desktop\phantom_alert_bot\signal_runner_loop.py", line 199, in _run
    uploaded_image_url = self._generate_chart_and_upload(df, signal_info, image_filename)
                         ^^^^^^^^^^^^^^^^^^^^^^^^^^^^^^^
AttributeError: 'SignalRunner' object has no attribute '_generate_chart_and_upload'
2025-06-12 00:15:41,041 - INFO - GOLD_USD: 新しい足 (M15) が形成されました。データ取得とシグナル判定を実行します。
2025-06-12 00:15:41,089 - INFO - GOLD_USD-M15 シグナル判定結果: Balanced Buy Signal (Confluence: MACD Golden Cross, Stochastic Golden Cross)
2025-06-12 00:15:41,090 - ERROR - GOLD_USD: シグナル監視ループで予期せぬエラーが発生しました: 'SignalRunner' object has no attribute '_generate_chart_and_upload'
Traceback (most recent call last):
  File "c:\Users\pc\OneDrive\Desktop\phantom_alert_bot\signal_runner_loop.py", line 199, in _run
    # シグナルが出た場合、LINE通知とチャート画像生成・アップロード
                      ^^^^^^^^^^^^^^^^^^^^^^
AttributeError: 'SignalRunner' object has no attribute '_generate_chart_and_upload'
2025-06-12 00:16:25,590 - INFO - GOLD_USD: 新しい足 (M15) が形成されました。データ取得とシグナル判定を実行します。
2025-06-12 00:16:25,621 - INFO - GOLD_USD-M15 シグナル判定結果: Balanced Buy Signal (Confluence: MACD Golden Cross, Stochastic Golden Cross)
2025-06-12 00:16:25,621 - ERROR - GOLD_USD: シグナル監視ループで予期せぬエラーが発生しました: 'SignalRunner' object has no attribute '_generate_chart_and_upload'
Traceback (most recent call last):
  File "C:\Users\pc\OneDrive\Desktop\phantom_alert_bot\signal_runner_loop.py", line 199, in _run
    # シグナルが出た場合、LINE通知とチャート画像生成・アップロード
                      ^^^^^^^^^^^^^^^^^^^^^^
AttributeError: 'SignalRunner' object has no attribute '_generate_chart_and_upload'
2025-06-12 00:17:10,968 - INFO - GOLD_USD: 新しい足 (M15) が形成されました。データ取得とシグナル判定を実行します。
2025-06-12 00:17:10,991 - INFO - GOLD_USD-M15 シグナル判定結果: Balanced Buy Signal (Confluence: MACD Golden Cross, Stochastic Golden Cross)
2025-06-12 00:17:10,992 - ERROR - GOLD_USD: シグナル監視ループで予期せぬエラーが発生しました: 'SignalRunner' object has no attribute '_generate_chart_and_upload'
Traceback (most recent call last):
  File "C:\Users\pc\OneDrive\Desktop\phantom_alert_bot\signal_runner_loop.py", line 199, in _run
    # シグナルが出た場合、LINE通知とチャート画像生成・アップロード
                      ^^^^^^^^^^^^^^^^^^^^^^
AttributeError: 'SignalRunner' object has no attribute '_generate_chart_and_upload'
2025-06-12 00:17:12,895 - INFO - GOLD_USD: 新しい足 (M15) が形成されました。データ取得とシグナル判定を実行します。
2025-06-12 00:17:12,920 - INFO - GOLD_USD-M15 シグナル判定結果: Balanced Buy Signal (Confluence: MACD Golden Cross, Stochastic Golden Cross)
2025-06-12 00:17:12,920 - ERROR - GOLD_USD: シグナル監視ループで予期せぬエラーが発生しました: 'SignalRunner' object has no attribute '_generate_chart_and_upload'
Traceback (most recent call last):
  File "C:\Users\pc\OneDrive\Desktop\phantom_alert_bot\signal_runner_loop.py", line 199, in _run
    # シグナルが出た場合、LINE通知とチャート画像生成・アップロード
                      ^^^^^^^^^^^^^^^^^^^^^^
AttributeError: 'SignalRunner' object has no attribute '_generate_chart_and_upload'
2025-06-12 00:18:41,093 - INFO - GOLD_USD: 新しい足 (M15) が形成されました。データ取得とシグナル判定を実行します。
2025-06-12 00:18:41,137 - INFO - GOLD_USD-M15 シグナル判定結果: Balanced Buy Signal (Confluence: MACD Golden Cross, Stochastic Golden Cross)
2025-06-12 00:18:41,137 - ERROR - GOLD_USD: シグナル監視ループで予期せぬエラーが発生しました: 'SignalRunner' object has no attribute '_generate_chart_and_upload'
Traceback (most recent call last):
  File "c:\Users\pc\OneDrive\Desktop\phantom_alert_bot\signal_runner_loop.py", line 199, in _run
    # シグナルが出た場合、LINE通知とチャート画像生成・アップロード
                      ^^^^^^^^^^^^^^^^^^^^^^
AttributeError: 'SignalRunner' object has no attribute '_generate_chart_and_upload'
2025-06-12 00:20:10,993 - INFO - GOLD_USD: 新しい足 (M15) が形成されました。データ取得とシグナル判定を実行します。
2025-06-12 00:20:11,014 - INFO - GOLD_USD-M15 シグナル判定結果: Balanced Buy Signal (Confluence: MACD Golden Cross, Stochastic Golden Cross)
2025-06-12 00:20:11,015 - ERROR - GOLD_USD: シグナル監視ループで予期せぬエラーが発生しました: 'SignalRunner' object has no attribute '_generate_chart_and_upload'
Traceback (most recent call last):
  File "C:\Users\pc\OneDrive\Desktop\phantom_alert_bot\signal_runner_loop.py", line 199, in _run
    # シグナルが出た場合、LINE通知とチャート画像生成・アップロード
                      ^^^^^^^^^^^^^^^^^^^^^^
AttributeError: 'SignalRunner' object has no attribute '_generate_chart_and_upload'
2025-06-12 00:20:12,922 - INFO - GOLD_USD: 新しい足 (M15) が形成されました。データ取得とシグナル判定を実行します。
2025-06-12 00:20:12,940 - INFO - GOLD_USD-M15 シグナル判定結果: Balanced Buy Signal (Confluence: MACD Golden Cross, Stochastic Golden Cross)
2025-06-12 00:20:12,941 - ERROR - GOLD_USD: シグナル監視ループで予期せぬエラーが発生しました: 'SignalRunner' object has no attribute '_generate_chart_and_upload'
Traceback (most recent call last):
  File "C:\Users\pc\OneDrive\Desktop\phantom_alert_bot\signal_runner_loop.py", line 199, in _run
    # シグナルが出た場合、LINE通知とチャート画像生成・アップロード
                      ^^^^^^^^^^^^^^^^^^^^^^
AttributeError: 'SignalRunner' object has no attribute '_generate_chart_and_upload'
2025-06-12 00:21:41,139 - INFO - GOLD_USD: 新しい足 (M15) が形成されました。データ取得とシグナル判定を実行します。
2025-06-12 00:21:41,167 - INFO - GOLD_USD-M15 シグナル判定結果: Balanced Buy Signal (Confluence: MACD Golden Cross, Stochastic Golden Cross)
2025-06-12 00:21:41,168 - ERROR - GOLD_USD: シグナル監視ループで予期せぬエラーが発生しました: 'SignalRunner' object has no attribute '_generate_chart_and_upload'
Traceback (most recent call last):
  File "c:\Users\pc\OneDrive\Desktop\phantom_alert_bot\signal_runner_loop.py", line 199, in _run
    # シグナルが出た場合、LINE通知とチャート画像生成・アップロード
                      ^^^^^^^^^^^^^^^^^^^^^^
AttributeError: 'SignalRunner' object has no attribute '_generate_chart_and_upload'
2025-06-12 00:23:11,017 - INFO - GOLD_USD: 新しい足 (M15) が形成されました。データ取得とシグナル判定を実行します。
2025-06-12 00:23:11,066 - INFO - GOLD_USD-M15 シグナル判定結果: Balanced Buy Signal (Confluence: MACD Golden Cross, Stochastic Golden Cross)
2025-06-12 00:23:11,081 - ERROR - GOLD_USD: シグナル監視ループで予期せぬエラーが発生しました: 'SignalRunner' object has no attribute '_generate_chart_and_upload'
Traceback (most recent call last):
  File "C:\Users\pc\OneDrive\Desktop\phantom_alert_bot\signal_runner_loop.py", line 199, in _run
    # シグナルが出た場合、LINE通知とチャート画像生成・アップロード
                      ^^^^^^^^^^^^^^^^^^^^^^
AttributeError: 'SignalRunner' object has no attribute '_generate_chart_and_upload'
2025-06-12 00:23:12,942 - INFO - GOLD_USD: 新しい足 (M15) が形成されました。データ取得とシグナル判定を実行します。
2025-06-12 00:23:12,989 - INFO - GOLD_USD-M15 シグナル判定結果: Balanced Buy Signal (Confluence: MACD Golden Cross, Stochastic Golden Cross)
2025-06-12 00:23:12,989 - ERROR - GOLD_USD: シグナル監視ループで予期せぬエラーが発生しました: 'SignalRunner' object has no attribute '_generate_chart_and_upload'
Traceback (most recent call last):
  File "C:\Users\pc\OneDrive\Desktop\phantom_alert_bot\signal_runner_loop.py", line 199, in _run
    # シグナルが出た場合、LINE通知とチャート画像生成・アップロード
                      ^^^^^^^^^^^^^^^^^^^^^^
AttributeError: 'SignalRunner' object has no attribute '_generate_chart_and_upload'
2025-06-12 00:24:41,169 - INFO - GOLD_USD: 新しい足 (M15) が形成されました。データ取得とシグナル判定を実行します。
2025-06-12 00:24:41,219 - INFO - GOLD_USD-M15 シグナル判定結果: Balanced Buy Signal (Confluence: MACD Golden Cross, Stochastic Golden Cross)
2025-06-12 00:24:41,220 - ERROR - GOLD_USD: シグナル監視ループで予期せぬエラーが発生しました: 'SignalRunner' object has no attribute '_generate_chart_and_upload'
Traceback (most recent call last):
  File "c:\Users\pc\OneDrive\Desktop\phantom_alert_bot\signal_runner_loop.py", line 199, in _run
    # シグナルが出た場合、LINE通知とチャート画像生成・アップロード
                      ^^^^^^^^^^^^^^^^^^^^^^
AttributeError: 'SignalRunner' object has no attribute '_generate_chart_and_upload'
2025-06-12 00:26:11,094 - INFO - GOLD_USD: 新しい足 (M15) が形成されました。データ取得とシグナル判定を実行します。
2025-06-12 00:26:11,124 - INFO - GOLD_USD-M15 シグナル判定結果: Balanced Buy Signal (Confluence: MACD Golden Cross, Stochastic Golden Cross)
2025-06-12 00:26:11,125 - ERROR - GOLD_USD: シグナル監視ループで予期せぬエラーが発生しました: 'SignalRunner' object has no attribute '_generate_chart_and_upload'
Traceback (most recent call last):
  File "C:\Users\pc\OneDrive\Desktop\phantom_alert_bot\signal_runner_loop.py", line 199, in _run
    # シグナルが出た場合、LINE通知とチャート画像生成・アップロード
                      ^^^^^^^^^^^^^^^^^^^^^^
AttributeError: 'SignalRunner' object has no attribute '_generate_chart_and_upload'
2025-06-12 00:26:12,991 - INFO - GOLD_USD: 新しい足 (M15) が形成されました。データ取得とシグナル判定を実行します。
2025-06-12 00:26:13,036 - INFO - GOLD_USD-M15 シグナル判定結果: Balanced Buy Signal (Confluence: MACD Golden Cross, Stochastic Golden Cross)
2025-06-12 00:26:13,037 - ERROR - GOLD_USD: シグナル監視ループで予期せぬエラーが発生しました: 'SignalRunner' object has no attribute '_generate_chart_and_upload'
Traceback (most recent call last):
  File "C:\Users\pc\OneDrive\Desktop\phantom_alert_bot\signal_runner_loop.py", line 199, in _run
    # シグナルが出た場合、LINE通知とチャート画像生成・アップロード
                      ^^^^^^^^^^^^^^^^^^^^^^
AttributeError: 'SignalRunner' object has no attribute '_generate_chart_and_upload'
2025-06-12 00:27:41,222 - INFO - GOLD_USD: 新しい足 (M15) が形成されました。データ取得とシグナル判定を実行します。
2025-06-12 00:27:41,255 - INFO - GOLD_USD-M15 シグナル判定結果: Balanced Buy Signal (Confluence: MACD Golden Cross, Stochastic Golden Cross)
2025-06-12 00:27:41,256 - ERROR - GOLD_USD: シグナル監視ループで予期せぬエラーが発生しました: 'SignalRunner' object has no attribute '_generate_chart_and_upload'
Traceback (most recent call last):
  File "c:\Users\pc\OneDrive\Desktop\phantom_alert_bot\signal_runner_loop.py", line 199, in _run
    # シグナルが出た場合、LINE通知とチャート画像生成・アップロード
                      ^^^^^^^^^^^^^^^^^^^^^^
AttributeError: 'SignalRunner' object has no attribute '_generate_chart_and_upload'
2025-06-12 00:29:11,126 - INFO - GOLD_USD: 新しい足 (M15) が形成されました。データ取得とシグナル判定を実行します。
2025-06-12 00:29:11,147 - INFO - GOLD_USD-M15 シグナル判定結果: Balanced Buy Signal (Confluence: MACD Golden Cross, Stochastic Golden Cross)
2025-06-12 00:29:11,148 - ERROR - GOLD_USD: シグナル監視ループで予期せぬエラーが発生しました: 'SignalRunner' object has no attribute '_generate_chart_and_upload'
Traceback (most recent call last):
  File "C:\Users\pc\OneDrive\Desktop\phantom_alert_bot\signal_runner_loop.py", line 199, in _run
    # シグナルが出た場合、LINE通知とチャート画像生成・アップロード
                      ^^^^^^^^^^^^^^^^^^^^^^
AttributeError: 'SignalRunner' object has no attribute '_generate_chart_and_upload'
2025-06-12 00:29:13,038 - INFO - GOLD_USD: 新しい足 (M15) が形成されました。データ取得とシグナル判定を実行します。
2025-06-12 00:29:13,095 - INFO - GOLD_USD-M15 シグナル判定結果: Balanced Buy Signal (Confluence: MACD Golden Cross, Stochastic Golden Cross)
2025-06-12 00:29:13,095 - ERROR - GOLD_USD: シグナル監視ループで予期せぬエラーが発生しました: 'SignalRunner' object has no attribute '_generate_chart_and_upload'
Traceback (most recent call last):
  File "C:\Users\pc\OneDrive\Desktop\phantom_alert_bot\signal_runner_loop.py", line 199, in _run
    # シグナルが出た場合、LINE通知とチャート画像生成・アップロード
                      ^^^^^^^^^^^^^^^^^^^^^^
AttributeError: 'SignalRunner' object has no attribute '_generate_chart_and_upload'
2025-06-12 00:30:41,258 - INFO - GOLD_USD: 新しい足 (M15) が形成されました。データ取得とシグナル判定を実行します。
2025-06-12 00:30:41,280 - INFO - GOLD_USD-M15 シグナル判定結果: Balanced Buy Signal (Confluence: MACD Golden Cross, Stochastic Golden Cross)
2025-06-12 00:30:41,281 - ERROR - GOLD_USD: シグナル監視ループで予期せぬエラーが発生しました: 'SignalRunner' object has no attribute '_generate_chart_and_upload'
Traceback (most recent call last):
  File "c:\Users\pc\OneDrive\Desktop\phantom_alert_bot\signal_runner_loop.py", line 199, in _run
    # シグナルが出た場合、LINE通知とチャート画像生成・アップロード
                      ^^^^^^^^^^^^^^^^^^^^^^
AttributeError: 'SignalRunner' object has no attribute '_generate_chart_and_upload'
2025-06-12 00:32:11,150 - INFO - GOLD_USD: 新しい足 (M15) が形成されました。データ取得とシグナル判定を実行します。
2025-06-12 00:32:11,171 - INFO - GOLD_USD-M15 シグナル判定結果: No signal
2025-06-12 00:32:11,171 - INFO - GOLD_USD-M15: シグナルなし。
2025-06-12 00:32:11,172 - ERROR - GOLD_USD: シグナル監視ループで予期せぬエラーが発生しました: cannot access local variable 'uploaded_image_url' where it is not associated with a value
Traceback (most recent call last):
  File "C:\Users\pc\OneDrive\Desktop\phantom_alert_bot\signal_runner_loop.py", line 230, in _run
UnboundLocalError: cannot access local variable 'uploaded_image_url' where it is not associated with a value
2025-06-12 00:32:13,097 - INFO - GOLD_USD: 新しい足 (M15) が形成されました。データ取得とシグナル判定を実行します。
2025-06-12 00:32:13,121 - INFO - GOLD_USD-M15 シグナル判定結果: No signal
2025-06-12 00:32:13,122 - INFO - GOLD_USD-M15: シグナルなし。
2025-06-12 00:32:13,123 - ERROR - GOLD_USD: シグナル監視ループで予期せぬエラーが発生しました: cannot access local variable 'uploaded_image_url' where it is not associated with a value
Traceback (most recent call last):
  File "C:\Users\pc\OneDrive\Desktop\phantom_alert_bot\signal_runner_loop.py", line 230, in _run
UnboundLocalError: cannot access local variable 'uploaded_image_url' where it is not associated with a value
2025-06-12 00:33:41,282 - INFO - GOLD_USD: 新しい足 (M15) が形成されました。データ取得とシグナル判定を実行します。
2025-06-12 00:33:41,328 - INFO - GOLD_USD-M15 シグナル判定結果: No signal
2025-06-12 00:33:41,329 - INFO - GOLD_USD-M15: シグナルなし。
2025-06-12 00:33:41,329 - ERROR - GOLD_USD: シグナル監視ループで予期せぬエラーが発生しました: cannot access local variable 'uploaded_image_url' where it is not associated with a value
Traceback (most recent call last):
  File "c:\Users\pc\OneDrive\Desktop\phantom_alert_bot\signal_runner_loop.py", line 230, in _run
UnboundLocalError: cannot access local variable 'uploaded_image_url' where it is not associated with a value
2025-06-12 00:35:11,175 - INFO - GOLD_USD: 新しい足 (M15) が形成されました。データ取得とシグナル判定を実行します。
2025-06-12 00:35:11,205 - INFO - GOLD_USD-M15 シグナル判定結果: No signal
2025-06-12 00:35:11,205 - INFO - GOLD_USD-M15: シグナルなし。
2025-06-12 00:35:11,207 - ERROR - GOLD_USD: シグナル監視ループで予期せぬエラーが発生しました: cannot access local variable 'uploaded_image_url' where it is not associated with a value
Traceback (most recent call last):
  File "C:\Users\pc\OneDrive\Desktop\phantom_alert_bot\signal_runner_loop.py", line 230, in _run
UnboundLocalError: cannot access local variable 'uploaded_image_url' where it is not associated with a value
2025-06-12 00:35:13,126 - INFO - GOLD_USD: 新しい足 (M15) が形成されました。データ取得とシグナル判定を実行します。
2025-06-12 00:35:13,171 - INFO - GOLD_USD-M15 シグナル判定結果: No signal
2025-06-12 00:35:13,172 - INFO - GOLD_USD-M15: シグナルなし。
2025-06-12 00:35:13,172 - ERROR - GOLD_USD: シグナル監視ループで予期せぬエラーが発生しました: cannot access local variable 'uploaded_image_url' where it is not associated with a value
Traceback (most recent call last):
  File "C:\Users\pc\OneDrive\Desktop\phantom_alert_bot\signal_runner_loop.py", line 230, in _run
UnboundLocalError: cannot access local variable 'uploaded_image_url' where it is not associated with a value
2025-06-12 00:36:41,334 - INFO - GOLD_USD: 新しい足 (M15) が形成されました。データ取得とシグナル判定を実行します。
2025-06-12 00:36:41,358 - INFO - GOLD_USD-M15 シグナル判定結果: Balanced Buy Signal (Confluence: MACD Golden Cross, Stochastic Golden Cross)
2025-06-12 00:36:41,358 - ERROR - GOLD_USD: シグナル監視ループで予期せぬエラーが発生しました: 'SignalRunner' object has no attribute '_generate_chart_and_upload'
Traceback (most recent call last):
  File "c:\Users\pc\OneDrive\Desktop\phantom_alert_bot\signal_runner_loop.py", line 199, in _run
    # シグナルが出た場合、LINE通知とチャート画像生成・アップロード
                      ^^^^^^^^^^^^^^^^^^^^^^
AttributeError: 'SignalRunner' object has no attribute '_generate_chart_and_upload'
2025-06-12 00:38:11,208 - INFO - GOLD_USD: 新しい足 (M15) が形成されました。データ取得とシグナル判定を実行します。
2025-06-12 00:38:11,291 - INFO - GOLD_USD-M15 シグナル判定結果: Balanced Buy Signal (Confluence: MACD Golden Cross, Stochastic Golden Cross)
2025-06-12 00:38:11,295 - ERROR - GOLD_USD: シグナル監視ループで予期せぬエラーが発生しました: 'SignalRunner' object has no attribute '_generate_chart_and_upload'
Traceback (most recent call last):
  File "C:\Users\pc\OneDrive\Desktop\phantom_alert_bot\signal_runner_loop.py", line 199, in _run
    # シグナルが出た場合、LINE通知とチャート画像生成・アップロード
                      ^^^^^^^^^^^^^^^^^^^^^^
AttributeError: 'SignalRunner' object has no attribute '_generate_chart_and_upload'
2025-06-12 00:38:13,174 - INFO - GOLD_USD: 新しい足 (M15) が形成されました。データ取得とシグナル判定を実行します。
2025-06-12 00:38:13,225 - INFO - GOLD_USD-M15 シグナル判定結果: Balanced Buy Signal (Confluence: MACD Golden Cross, Stochastic Golden Cross)
2025-06-12 00:38:13,226 - ERROR - GOLD_USD: シグナル監視ループで予期せぬエラーが発生しました: 'SignalRunner' object has no attribute '_generate_chart_and_upload'
Traceback (most recent call last):
  File "C:\Users\pc\OneDrive\Desktop\phantom_alert_bot\signal_runner_loop.py", line 199, in _run
    # シグナルが出た場合、LINE通知とチャート画像生成・アップロード
                      ^^^^^^^^^^^^^^^^^^^^^^
AttributeError: 'SignalRunner' object has no attribute '_generate_chart_and_upload'
2025-06-12 00:39:41,361 - INFO - GOLD_USD: 新しい足 (M15) が形成されました。データ取得とシグナル判定を実行します。
2025-06-12 00:39:41,398 - INFO - GOLD_USD-M15 シグナル判定結果: Balanced Buy Signal (Confluence: MACD Golden Cross, Stochastic Golden Cross)
2025-06-12 00:39:41,398 - ERROR - GOLD_USD: シグナル監視ループで予期せぬエラーが発生しました: 'SignalRunner' object has no attribute '_generate_chart_and_upload'
Traceback (most recent call last):
  File "c:\Users\pc\OneDrive\Desktop\phantom_alert_bot\signal_runner_loop.py", line 199, in _run
    # シグナルが出た場合、LINE通知とチャート画像生成・アップロード
                      ^^^^^^^^^^^^^^^^^^^^^^
AttributeError: 'SignalRunner' object has no attribute '_generate_chart_and_upload'
2025-06-12 00:41:11,325 - INFO - GOLD_USD: 新しい足 (M15) が形成されました。データ取得とシグナル判定を実行します。
2025-06-12 00:41:11,381 - INFO - GOLD_USD-M15 シグナル判定結果: No signal
2025-06-12 00:41:11,381 - INFO - GOLD_USD-M15: シグナルなし。
2025-06-12 00:41:11,382 - ERROR - GOLD_USD: シグナル監視ループで予期せぬエラーが発生しました: cannot access local variable 'uploaded_image_url' where it is not associated with a value
Traceback (most recent call last):
  File "C:\Users\pc\OneDrive\Desktop\phantom_alert_bot\signal_runner_loop.py", line 230, in _run
UnboundLocalError: cannot access local variable 'uploaded_image_url' where it is not associated with a value
2025-06-12 00:41:13,251 - INFO - GOLD_USD: 新しい足 (M15) が形成されました。データ取得とシグナル判定を実行します。
2025-06-12 00:41:13,338 - INFO - GOLD_USD-M15 シグナル判定結果: No signal
2025-06-12 00:41:13,339 - INFO - GOLD_USD-M15: シグナルなし。
2025-06-12 00:41:13,340 - ERROR - GOLD_USD: シグナル監視ループで予期せぬエラーが発生しました: cannot access local variable 'uploaded_image_url' where it is not associated with a value
Traceback (most recent call last):
  File "C:\Users\pc\OneDrive\Desktop\phantom_alert_bot\signal_runner_loop.py", line 230, in _run
UnboundLocalError: cannot access local variable 'uploaded_image_url' where it is not associated with a value
2025-06-12 00:42:41,400 - INFO - GOLD_USD: 新しい足 (M15) が形成されました。データ取得とシグナル判定を実行します。
2025-06-12 00:42:41,480 - INFO - GOLD_USD-M15 シグナル判定結果: No signal
2025-06-12 00:42:41,481 - INFO - GOLD_USD-M15: シグナルなし。
2025-06-12 00:42:41,482 - ERROR - GOLD_USD: シグナル監視ループで予期せぬエラーが発生しました: cannot access local variable 'uploaded_image_url' where it is not associated with a value
Traceback (most recent call last):
  File "c:\Users\pc\OneDrive\Desktop\phantom_alert_bot\signal_runner_loop.py", line 230, in _run
UnboundLocalError: cannot access local variable 'uploaded_image_url' where it is not associated with a value
2025-06-12 00:44:11,385 - INFO - GOLD_USD: 新しい足 (M15) が形成されました。データ取得とシグナル判定を実行します。
2025-06-12 00:44:11,498 - INFO - GOLD_USD-M15 シグナル判定結果: No signal
2025-06-12 00:44:11,503 - INFO - GOLD_USD-M15: シグナルなし。
2025-06-12 00:44:11,520 - ERROR - GOLD_USD: シグナル監視ループで予期せぬエラーが発生しました: cannot access local variable 'uploaded_image_url' where it is not associated with a value
Traceback (most recent call last):
  File "C:\Users\pc\OneDrive\Desktop\phantom_alert_bot\signal_runner_loop.py", line 230, in _run
UnboundLocalError: cannot access local variable 'uploaded_image_url' where it is not associated with a value
2025-06-12 00:44:13,342 - INFO - GOLD_USD: 新しい足 (M15) が形成されました。データ取得とシグナル判定を実行します。
2025-06-12 00:44:13,422 - INFO - GOLD_USD-M15 シグナル判定結果: No signal
2025-06-12 00:44:13,423 - INFO - GOLD_USD-M15: シグナルなし。
2025-06-12 00:44:13,423 - ERROR - GOLD_USD: シグナル監視ループで予期せぬエラーが発生しました: cannot access local variable 'uploaded_image_url' where it is not associated with a value
Traceback (most recent call last):
  File "C:\Users\pc\OneDrive\Desktop\phantom_alert_bot\signal_runner_loop.py", line 230, in _run
UnboundLocalError: cannot access local variable 'uploaded_image_url' where it is not associated with a value
2025-06-12 00:45:41,484 - INFO - GOLD_USD: 新しい足 (M15) が形成されました。データ取得とシグナル判定を実行します。
2025-06-12 00:45:41,523 - INFO - GOLD_USD-M15 シグナル判定結果: No signal
2025-06-12 00:45:41,523 - INFO - GOLD_USD-M15: シグナルなし。
2025-06-12 00:45:41,523 - ERROR - GOLD_USD: シグナル監視ループで予期せぬエラーが発生しました: cannot access local variable 'uploaded_image_url' where it is not associated with a value
Traceback (most recent call last):
  File "c:\Users\pc\OneDrive\Desktop\phantom_alert_bot\signal_runner_loop.py", line 230, in _run
UnboundLocalError: cannot access local variable 'uploaded_image_url' where it is not associated with a value
2025-06-12 00:47:11,526 - INFO - GOLD_USD: 新しい足 (M15) が形成されました。データ取得とシグナル判定を実行します。
2025-06-12 00:47:11,815 - INFO - GOLD_USD-M15 シグナル判定結果: Balanced Sell Signal (Confluence: MACD Dead Cross, Stochastic Dead Cross)
2025-06-12 00:47:11,819 - ERROR - GOLD_USD: シグナル監視ループで予期せぬエラーが発生しました: 'SignalRunner' object has no attribute '_generate_chart_and_upload'
Traceback (most recent call last):
  File "C:\Users\pc\OneDrive\Desktop\phantom_alert_bot\signal_runner_loop.py", line 199, in _run
    # シグナルが出た場合、LINE通知とチャート画像生成・アップロード
                      ^^^^^^^^^^^^^^^^^^^^^^
AttributeError: 'SignalRunner' object has no attribute '_generate_chart_and_upload'
2025-06-12 00:47:13,425 - INFO - GOLD_USD: 新しい足 (M15) が形成されました。データ取得とシグナル判定を実行します。
2025-06-12 00:47:13,476 - INFO - GOLD_USD-M15 シグナル判定結果: Balanced Sell Signal (Confluence: MACD Dead Cross, Stochastic Dead Cross)
2025-06-12 00:47:13,476 - ERROR - GOLD_USD: シグナル監視ループで予期せぬエラーが発生しました: 'SignalRunner' object has no attribute '_generate_chart_and_upload'
Traceback (most recent call last):
  File "C:\Users\pc\OneDrive\Desktop\phantom_alert_bot\signal_runner_loop.py", line 199, in _run
    # シグナルが出た場合、LINE通知とチャート画像生成・アップロード
                      ^^^^^^^^^^^^^^^^^^^^^^
AttributeError: 'SignalRunner' object has no attribute '_generate_chart_and_upload'
2025-06-12 10:40:26,302 - INFO - ✅ GOLD_USD-M15 シグナルランナーが初期化されました。
2025-06-12 10:40:36,366 - INFO - GOLD_USD-M15 シグナル監視ループを開始します。
2025-06-12 10:40:36,367 - INFO - GOLD_USD: MT5クライアントを初期化しています...
2025-06-12 10:40:36,369 - INFO - ✅ GOLD_USD: MT5クライアントの初期化に成功しました。
2025-06-12 10:40:36,370 - INFO - GOLD_USD: 新しい足 (M15) が形成されました。データ取得とシグナル判定を実行します。
2025-06-12 10:40:36,437 - ERROR - GOLD_USD: シグナル監視ループで予期せぬエラーが発生しました: 'MACD_Signal'
Traceback (most recent call last):
  File "C:\Users\pc\AppData\Local\Programs\Python\Python312\Lib\site-packages\pandas\core\indexes\base.py", line 3812, in get_loc
    return self._engine.get_loc(casted_key)
           ^^^^^^^^^^^^^^^^^^^^^^^^^^^^^^^^
  File "pandas/_libs/index.pyx", line 167, in pandas._libs.index.IndexEngine.get_loc
  File "pandas/_libs/index.pyx", line 196, in pandas._libs.index.IndexEngine.get_loc
  File "pandas/_libs/hashtable_class_helper.pxi", line 7088, in pandas._libs.hashtable.PyObjectHashTable.get_item
  File "pandas/_libs/hashtable_class_helper.pxi", line 7096, in pandas._libs.hashtable.PyObjectHashTable.get_item
KeyError: 'MACD_Signal'

The above exception was the direct cause of the following exception:

Traceback (most recent call last):
  File "c:\Users\pc\OneDrive\Desktop\phantom_alert_bot\signal_runner_loop.py", line 196, in _run
    signal_info = generate_signal(df, mode="realtime", logic=DEFAULT_LOGIC) # modeとlogicを渡す
                  ^^^^^^^^^^^^^^^^^^^^^^^^^^^^^^^^^^^^^^^^^^^^^^^^^^^^^^^^^
  File "c:\Users\pc\OneDrive\Desktop\phantom_alert_bot\signal_generator.py", line 71, in generate_signal
    signal_info = _generate_balanced_signal(df_ind, current_price)
                  ^^^^^^^^^^^^^^^^^^^^^^^^^^^^^^^^^^^^^^^^^^^^^^^^
  File "c:\Users\pc\OneDrive\Desktop\phantom_alert_bot\signal_generator.py", line 192, in _generate_balanced_signal
    macd_buy = (df_ind['MACD'].iloc[-1] > df_ind['MACD_Signal'].iloc[-1]) # MACDゴールデンクロス
                                          ~~~~~~^^^^^^^^^^^^^^^
  File "C:\Users\pc\AppData\Local\Programs\Python\Python312\Lib\site-packages\pandas\core\frame.py", line 4107, in __getitem__
    indexer = self.columns.get_loc(key)
              ^^^^^^^^^^^^^^^^^^^^^^^^^
  File "C:\Users\pc\AppData\Local\Programs\Python\Python312\Lib\site-packages\pandas\core\indexes\base.py", line 3819, in get_loc
    raise KeyError(key) from err
KeyError: 'MACD_Signal'
2025-06-13 01:18:32,296 - INFO - ✅ GOLD_USD-M15 シグナルランナーが初期化されました。
2025-06-13 01:18:42,335 - INFO - GOLD_USD-M15 シグナル監視ループを開始します。
2025-06-13 01:18:42,338 - INFO - GOLD_USD: MT5クライアントを初期化しています...
2025-06-13 01:18:42,344 - INFO - ✅ GOLD_USD: MT5クライアントの初期化に成功しました。
2025-06-13 01:18:42,345 - INFO - GOLD_USD: 新しい足 (M15) が形成されました。データ取得とシグナル判定を実行します。
2025-06-13 01:18:42,366 - ERROR - GOLD_USD: シグナル監視ループで予期せぬエラーが発生しました: Cannot convert tz-naive timestamps, use tz_localize to localize
Traceback (most recent call last):
  File "C:\Users\pc\OneDrive\Desktop\phantom_alert_bot\signal_runner_loop.py", line 192, in _run
    df, latest_time_tokyo = self._get_current_ohlc()
                            ^^^^^^^^^^^^^^^^^^^^^^^^
  File "C:\Users\pc\OneDrive\Desktop\phantom_alert_bot\signal_runner_loop.py", line 116, in _get_current_ohlc
    df.index = df.index.tz_convert('Asia/Tokyo') # チャート描画時などのため
               ^^^^^^^^^^^^^^^^^^^^^^^^^^^^^^^^^
  File "C:\Users\pc\OneDrive\Desktop\phantom_alert_bot\venv\Lib\site-packages\pandas\core\indexes\datetimes.py", line 283, in tz_convert
    arr = self._data.tz_convert(tz)
          ^^^^^^^^^^^^^^^^^^^^^^^^^
  File "C:\Users\pc\OneDrive\Desktop\phantom_alert_bot\venv\Lib\site-packages\pandas\core\arrays\datetimes.py", line 917, in tz_convert
    raise TypeError(
TypeError: Cannot convert tz-naive timestamps, use tz_localize to localize
2025-06-13 01:21:42,369 - INFO - GOLD_USD: 新しい足 (M15) が形成されました。データ取得とシグナル判定を実行します。
2025-06-13 01:21:42,377 - ERROR - GOLD_USD: シグナル監視ループで予期せぬエラーが発生しました: Cannot convert tz-naive timestamps, use tz_localize to localize
Traceback (most recent call last):
  File "C:\Users\pc\OneDrive\Desktop\phantom_alert_bot\signal_runner_loop.py", line 192, in _run
    df, latest_time_tokyo = self._get_current_ohlc()
                            ^^^^^^^^^^^^^^^^^^^^^^^^
  File "C:\Users\pc\OneDrive\Desktop\phantom_alert_bot\signal_runner_loop.py", line 116, in _get_current_ohlc
    df.index = df.index.tz_convert('Asia/Tokyo') # チャート描画時などのため
               ^^^^^^^^^^^^^^^^^^^^^^^^^^^^^^^^^
  File "C:\Users\pc\OneDrive\Desktop\phantom_alert_bot\venv\Lib\site-packages\pandas\core\indexes\datetimes.py", line 283, in tz_convert
    arr = self._data.tz_convert(tz)
          ^^^^^^^^^^^^^^^^^^^^^^^^^
  File "C:\Users\pc\OneDrive\Desktop\phantom_alert_bot\venv\Lib\site-packages\pandas\core\arrays\datetimes.py", line 917, in tz_convert
    raise TypeError(
TypeError: Cannot convert tz-naive timestamps, use tz_localize to localize
2025-06-13 01:24:42,379 - INFO - GOLD_USD: 新しい足 (M15) が形成されました。データ取得とシグナル判定を実行します。
2025-06-13 01:24:42,387 - ERROR - GOLD_USD: シグナル監視ループで予期せぬエラーが発生しました: Cannot convert tz-naive timestamps, use tz_localize to localize
Traceback (most recent call last):
  File "C:\Users\pc\OneDrive\Desktop\phantom_alert_bot\signal_runner_loop.py", line 192, in _run
    df, latest_time_tokyo = self._get_current_ohlc()
                            ^^^^^^^^^^^^^^^^^^^^^^^^
  File "C:\Users\pc\OneDrive\Desktop\phantom_alert_bot\signal_runner_loop.py", line 116, in _get_current_ohlc
    df.index = df.index.tz_convert('Asia/Tokyo') # チャート描画時などのため
               ^^^^^^^^^^^^^^^^^^^^^^^^^^^^^^^^^
  File "C:\Users\pc\OneDrive\Desktop\phantom_alert_bot\venv\Lib\site-packages\pandas\core\indexes\datetimes.py", line 283, in tz_convert
    arr = self._data.tz_convert(tz)
          ^^^^^^^^^^^^^^^^^^^^^^^^^
  File "C:\Users\pc\OneDrive\Desktop\phantom_alert_bot\venv\Lib\site-packages\pandas\core\arrays\datetimes.py", line 917, in tz_convert
    raise TypeError(
TypeError: Cannot convert tz-naive timestamps, use tz_localize to localize
2025-06-13 01:27:42,391 - INFO - GOLD_USD: 新しい足 (M15) が形成されました。データ取得とシグナル判定を実行します。
2025-06-13 01:27:42,401 - ERROR - GOLD_USD: シグナル監視ループで予期せぬエラーが発生しました: Cannot convert tz-naive timestamps, use tz_localize to localize
Traceback (most recent call last):
  File "C:\Users\pc\OneDrive\Desktop\phantom_alert_bot\signal_runner_loop.py", line 192, in _run
    df, latest_time_tokyo = self._get_current_ohlc()
                            ^^^^^^^^^^^^^^^^^^^^^^^^
  File "C:\Users\pc\OneDrive\Desktop\phantom_alert_bot\signal_runner_loop.py", line 116, in _get_current_ohlc
    df.index = df.index.tz_convert('Asia/Tokyo') # チャート描画時などのため
               ^^^^^^^^^^^^^^^^^^^^^^^^^^^^^^^^^
  File "C:\Users\pc\OneDrive\Desktop\phantom_alert_bot\venv\Lib\site-packages\pandas\core\indexes\datetimes.py", line 283, in tz_convert
    arr = self._data.tz_convert(tz)
          ^^^^^^^^^^^^^^^^^^^^^^^^^
  File "C:\Users\pc\OneDrive\Desktop\phantom_alert_bot\venv\Lib\site-packages\pandas\core\arrays\datetimes.py", line 917, in tz_convert
    raise TypeError(
TypeError: Cannot convert tz-naive timestamps, use tz_localize to localize
