2025-06-11 18:43:24,082 - INFO - ✅ USDJPY-M5 シグナルランナーが初期化されました。
2025-06-11 18:43:25,130 - INFO - USDJPY-M5 シグナル監視ループを開始します。
2025-06-11 18:43:25,130 - INFO - USDJPY: MT5クライアントを初期化しています...
2025-06-11 18:43:25,131 - INFO - ✅ USDJPY: MT5クライアントの初期化に成功しました。
2025-06-11 18:43:27,238 - INFO - USDJPY: 新しい足 (M5) が形成されました。データ取得とシグナル判定を実行します。
2025-06-11 18:43:27,239 - ERROR - USDJPY: シグナル監視ループで予期せぬエラーが発生しました: module 'MetaTrader5' has no attribute 'is_connected'
Traceback (most recent call last):
  File "c:\Users\pc\OneDrive\Desktop\phantom_alert_bot\signal_runner_loop.py", line 190, in _run
    df, latest_time_tokyo = self._get_current_ohlc()
                            ~~~~~~~~~~~~~~~~~~~~~~^^
  File "c:\Users\pc\OneDrive\Desktop\phantom_alert_bot\signal_runner_loop.py", line 85, in _get_current_ohlc
    if not self._initialize_mt5():
           ~~~~~~~~~~~~~~~~~~~~^^
  File "c:\Users\pc\OneDrive\Desktop\phantom_alert_bot\signal_runner_loop.py", line 65, in _initialize_mt5
    if not self.mt5_initialized or not mt5.is_connected():
                                       ^^^^^^^^^^^^^^^^
AttributeError: module 'MetaTrader5' has no attribute 'is_connected'
2025-06-11 18:44:27,244 - INFO - USDJPY: 新しい足 (M5) が形成されました。データ取得とシグナル判定を実行します。
2025-06-11 18:44:27,245 - ERROR - USDJPY: シグナル監視ループで予期せぬエラーが発生しました: module 'MetaTrader5' has no attribute 'is_connected'
Traceback (most recent call last):
  File "c:\Users\pc\OneDrive\Desktop\phantom_alert_bot\signal_runner_loop.py", line 190, in _run
    df, latest_time_tokyo = self._get_current_ohlc()
                            ~~~~~~~~~~~~~~~~~~~~~~^^
  File "c:\Users\pc\OneDrive\Desktop\phantom_alert_bot\signal_runner_loop.py", line 85, in _get_current_ohlc
    if not self._initialize_mt5():
           ~~~~~~~~~~~~~~~~~~~~^^
  File "c:\Users\pc\OneDrive\Desktop\phantom_alert_bot\signal_runner_loop.py", line 65, in _initialize_mt5
    if not self.mt5_initialized or not mt5.is_connected():
                                       ^^^^^^^^^^^^^^^^
AttributeError: module 'MetaTrader5' has no attribute 'is_connected'
2025-06-11 18:45:27,250 - INFO - USDJPY: 新しい足 (M5) が形成されました。データ取得とシグナル判定を実行します。
2025-06-11 18:45:27,251 - ERROR - USDJPY: シグナル監視ループで予期せぬエラーが発生しました: module 'MetaTrader5' has no attribute 'is_connected'
Traceback (most recent call last):
  File "c:\Users\pc\OneDrive\Desktop\phantom_alert_bot\signal_runner_loop.py", line 190, in _run
    df, latest_time_tokyo = self._get_current_ohlc()
                            ~~~~~~~~~~~~~~~~~~~~~~^^
  File "c:\Users\pc\OneDrive\Desktop\phantom_alert_bot\signal_runner_loop.py", line 85, in _get_current_ohlc
    if not self._initialize_mt5():
           ~~~~~~~~~~~~~~~~~~~~^^
  File "c:\Users\pc\OneDrive\Desktop\phantom_alert_bot\signal_runner_loop.py", line 65, in _initialize_mt5
    if not self.mt5_initialized or not mt5.is_connected():
                                       ^^^^^^^^^^^^^^^^
AttributeError: module 'MetaTrader5' has no attribute 'is_connected'
2025-06-11 18:46:27,255 - INFO - USDJPY: 新しい足 (M5) が形成されました。データ取得とシグナル判定を実行します。
2025-06-11 18:46:27,256 - ERROR - USDJPY: シグナル監視ループで予期せぬエラーが発生しました: module 'MetaTrader5' has no attribute 'is_connected'
Traceback (most recent call last):
  File "c:\Users\pc\OneDrive\Desktop\phantom_alert_bot\signal_runner_loop.py", line 190, in _run
    df, latest_time_tokyo = self._get_current_ohlc()
                            ~~~~~~~~~~~~~~~~~~~~~~^^
  File "c:\Users\pc\OneDrive\Desktop\phantom_alert_bot\signal_runner_loop.py", line 85, in _get_current_ohlc
    if not self._initialize_mt5():
           ~~~~~~~~~~~~~~~~~~~~^^
  File "c:\Users\pc\OneDrive\Desktop\phantom_alert_bot\signal_runner_loop.py", line 65, in _initialize_mt5
    if not self.mt5_initialized or not mt5.is_connected():
                                       ^^^^^^^^^^^^^^^^
AttributeError: module 'MetaTrader5' has no attribute 'is_connected'
2025-06-11 18:47:27,258 - INFO - USDJPY: 新しい足 (M5) が形成されました。データ取得とシグナル判定を実行します。
2025-06-11 18:47:27,259 - ERROR - USDJPY: シグナル監視ループで予期せぬエラーが発生しました: module 'MetaTrader5' has no attribute 'is_connected'
Traceback (most recent call last):
  File "c:\Users\pc\OneDrive\Desktop\phantom_alert_bot\signal_runner_loop.py", line 190, in _run
    df, latest_time_tokyo = self._get_current_ohlc()
                            ~~~~~~~~~~~~~~~~~~~~~~^^
  File "c:\Users\pc\OneDrive\Desktop\phantom_alert_bot\signal_runner_loop.py", line 85, in _get_current_ohlc
    if not self._initialize_mt5():
           ~~~~~~~~~~~~~~~~~~~~^^
  File "c:\Users\pc\OneDrive\Desktop\phantom_alert_bot\signal_runner_loop.py", line 65, in _initialize_mt5
    if not self.mt5_initialized or not mt5.is_connected():
                                       ^^^^^^^^^^^^^^^^
AttributeError: module 'MetaTrader5' has no attribute 'is_connected'
2025-06-11 18:48:27,264 - INFO - USDJPY: 新しい足 (M5) が形成されました。データ取得とシグナル判定を実行します。
2025-06-11 18:48:27,264 - ERROR - USDJPY: シグナル監視ループで予期せぬエラーが発生しました: module 'MetaTrader5' has no attribute 'is_connected'
Traceback (most recent call last):
  File "c:\Users\pc\OneDrive\Desktop\phantom_alert_bot\signal_runner_loop.py", line 190, in _run
    df, latest_time_tokyo = self._get_current_ohlc()
                            ~~~~~~~~~~~~~~~~~~~~~~^^
  File "c:\Users\pc\OneDrive\Desktop\phantom_alert_bot\signal_runner_loop.py", line 85, in _get_current_ohlc
    if not self._initialize_mt5():
           ~~~~~~~~~~~~~~~~~~~~^^
  File "c:\Users\pc\OneDrive\Desktop\phantom_alert_bot\signal_runner_loop.py", line 65, in _initialize_mt5
    if not self.mt5_initialized or not mt5.is_connected():
                                       ^^^^^^^^^^^^^^^^
AttributeError: module 'MetaTrader5' has no attribute 'is_connected'
2025-06-11 18:49:27,266 - INFO - USDJPY: 新しい足 (M5) が形成されました。データ取得とシグナル判定を実行します。
2025-06-11 18:49:27,266 - ERROR - USDJPY: シグナル監視ループで予期せぬエラーが発生しました: module 'MetaTrader5' has no attribute 'is_connected'
Traceback (most recent call last):
  File "c:\Users\pc\OneDrive\Desktop\phantom_alert_bot\signal_runner_loop.py", line 190, in _run
    df, latest_time_tokyo = self._get_current_ohlc()
                            ~~~~~~~~~~~~~~~~~~~~~~^^
  File "c:\Users\pc\OneDrive\Desktop\phantom_alert_bot\signal_runner_loop.py", line 85, in _get_current_ohlc
    if not self._initialize_mt5():
           ~~~~~~~~~~~~~~~~~~~~^^
  File "c:\Users\pc\OneDrive\Desktop\phantom_alert_bot\signal_runner_loop.py", line 65, in _initialize_mt5
    if not self.mt5_initialized or not mt5.is_connected():
                                       ^^^^^^^^^^^^^^^^
AttributeError: module 'MetaTrader5' has no attribute 'is_connected'
2025-06-11 18:50:27,269 - INFO - USDJPY: 新しい足 (M5) が形成されました。データ取得とシグナル判定を実行します。
2025-06-11 18:50:27,270 - ERROR - USDJPY: シグナル監視ループで予期せぬエラーが発生しました: module 'MetaTrader5' has no attribute 'is_connected'
Traceback (most recent call last):
  File "c:\Users\pc\OneDrive\Desktop\phantom_alert_bot\signal_runner_loop.py", line 190, in _run
  File "c:\Users\pc\OneDrive\Desktop\phantom_alert_bot\signal_runner_loop.py", line 85, in _get_current_ohlc
    self.logger.info(f"✅ {self.symbol}: MT5クライアントをシャットダウンしました。")
       ^^^^^^^^^^^^^^^^^^^^^
  File "c:\Users\pc\OneDrive\Desktop\phantom_alert_bot\signal_runner_loop.py", line 65, in _initialize_mt5
    # mt5.is_connected() は最新のMetaTrader5 APIには存在しないため削除
AttributeError: module 'MetaTrader5' has no attribute 'is_connected'
2025-06-11 18:54:29,432 - INFO - ✅ USDJPY-M5 シグナルランナーが初期化されました。
2025-06-11 18:54:30,469 - INFO - USDJPY-M5 シグナル監視ループを開始します。
2025-06-11 18:54:30,470 - INFO - USDJPY: MT5クライアントを初期化しています...
2025-06-11 18:54:30,471 - INFO - ✅ USDJPY: MT5クライアントの初期化に成功しました。
2025-06-11 18:54:30,472 - INFO - USDJPY: 新しい足 (M5) が形成されました。データ取得とシグナル判定を実行します。
2025-06-11 18:54:30,503 - ERROR - USDJPY: シグナル監視ループで予期せぬエラーが発生しました: generate_signal() got an unexpected keyword argument 'logic'
Traceback (most recent call last):
  File "c:\Users\pc\OneDrive\Desktop\phantom_alert_bot\signal_runner_loop.py", line 177, in _run
    signal_info = generate_signal(df, mode="realtime", logic=DEFAULT_LOGIC) # modeとlogicを渡す
TypeError: generate_signal() got an unexpected keyword argument 'logic'
2025-06-11 18:55:30,505 - INFO - USDJPY: 新しい足 (M5) が形成されました。データ取得とシグナル判定を実行します。
2025-06-11 18:55:30,513 - ERROR - USDJPY: シグナル監視ループで予期せぬエラーが発生しました: generate_signal() got an unexpected keyword argument 'logic'
Traceback (most recent call last):
  File "c:\Users\pc\OneDrive\Desktop\phantom_alert_bot\signal_runner_loop.py", line 177, in _run
    signal_info = generate_signal(df, mode="realtime", logic=DEFAULT_LOGIC) # modeとlogicを渡す
TypeError: generate_signal() got an unexpected keyword argument 'logic'
2025-06-11 18:56:30,516 - INFO - USDJPY: 新しい足 (M5) が形成されました。データ取得とシグナル判定を実行します。
2025-06-11 18:56:30,524 - ERROR - USDJPY: シグナル監視ループで予期せぬエラーが発生しました: generate_signal() got an unexpected keyword argument 'logic'
Traceback (most recent call last):
  File "c:\Users\pc\OneDrive\Desktop\phantom_alert_bot\signal_runner_loop.py", line 177, in _run
    signal_info = generate_signal(df, mode="realtime", logic=DEFAULT_LOGIC) # modeとlogicを渡す
TypeError: generate_signal() got an unexpected keyword argument 'logic'
2025-06-11 18:57:30,527 - INFO - USDJPY: 新しい足 (M5) が形成されました。データ取得とシグナル判定を実行します。
2025-06-11 18:57:30,535 - ERROR - USDJPY: シグナル監視ループで予期せぬエラーが発生しました: generate_signal() got an unexpected keyword argument 'logic'
Traceback (most recent call last):
  File "c:\Users\pc\OneDrive\Desktop\phantom_alert_bot\signal_runner_loop.py", line 177, in _run
    signal_info = generate_signal(df, mode="realtime", logic=DEFAULT_LOGIC) # modeとlogicを渡す
TypeError: generate_signal() got an unexpected keyword argument 'logic'
2025-06-11 18:58:30,537 - INFO - USDJPY: 新しい足 (M5) が形成されました。データ取得とシグナル判定を実行します。
2025-06-11 18:58:30,541 - ERROR - USDJPY: シグナル監視ループで予期せぬエラーが発生しました: generate_signal() got an unexpected keyword argument 'logic'
Traceback (most recent call last):
  File "c:\Users\pc\OneDrive\Desktop\phantom_alert_bot\signal_runner_loop.py", line 177, in _run
    signal_info = generate_signal(df, mode="realtime", logic=DEFAULT_LOGIC) # modeとlogicを渡す
TypeError: generate_signal() got an unexpected keyword argument 'logic'
2025-06-11 18:59:30,543 - INFO - USDJPY: 新しい足 (M5) が形成されました。データ取得とシグナル判定を実行します。
2025-06-11 18:59:30,551 - ERROR - USDJPY: シグナル監視ループで予期せぬエラーが発生しました: generate_signal() got an unexpected keyword argument 'logic'
Traceback (most recent call last):
  File "c:\Users\pc\OneDrive\Desktop\phantom_alert_bot\signal_runner_loop.py", line 177, in _run
    signal_info = generate_signal(df, mode="realtime", logic=DEFAULT_LOGIC) # modeとlogicを渡す
TypeError: generate_signal() got an unexpected keyword argument 'logic'
2025-06-11 19:00:30,553 - INFO - USDJPY: 新しい足 (M5) が形成されました。データ取得とシグナル判定を実行します。
2025-06-11 19:00:30,558 - ERROR - USDJPY: シグナル監視ループで予期せぬエラーが発生しました: generate_signal() got an unexpected keyword argument 'logic'
Traceback (most recent call last):
  File "c:\Users\pc\OneDrive\Desktop\phantom_alert_bot\signal_runner_loop.py", line 177, in _run
    signal_info = generate_signal(df, mode="realtime", logic=DEFAULT_LOGIC) # modeとlogicを渡す
TypeError: generate_signal() got an unexpected keyword argument 'logic'
2025-06-12 00:09:30,849 - INFO - ✅ USDJPY-M5 シグナルランナーが初期化されました。
2025-06-12 00:09:31,912 - INFO - USDJPY-M5 シグナル監視ループを開始します。
2025-06-12 00:09:31,912 - INFO - USDJPY: MT5クライアントを初期化しています...
2025-06-12 00:09:31,914 - INFO - ✅ USDJPY: MT5クライアントの初期化に成功しました。
2025-06-12 00:09:33,880 - INFO - USDJPY: 新しい足 (M5) が形成されました。データ取得とシグナル判定を実行します。
2025-06-12 00:09:34,063 - INFO - USDJPY-M5 シグナル判定結果: No signal
2025-06-12 00:09:34,066 - INFO - USDJPY-M5: シグナルなし。
2025-06-12 00:09:34,084 - ERROR - USDJPY: シグナル監視ループで予期せぬエラーが発生しました: cannot access local variable 'uploaded_image_url' where it is not associated with a value
Traceback (most recent call last):
  File "c:\Users\pc\OneDrive\Desktop\phantom_alert_bot\signal_runner_loop.py", line 230, in _run
    image_url=uploaded_image_url # ImgurのURLを保存
              ^^^^^^^^^^^^^^^^^^
UnboundLocalError: cannot access local variable 'uploaded_image_url' where it is not associated with a value
2025-06-12 00:10:15,471 - INFO - ✅ USDJPY-M5 シグナルランナーが初期化されました。
2025-06-12 00:10:16,497 - INFO - USDJPY-M5 シグナル監視ループを開始します。
2025-06-12 00:10:16,498 - INFO - USDJPY: MT5クライアントを初期化しています...
2025-06-12 00:10:16,499 - INFO - ✅ USDJPY: MT5クライアントの初期化に成功しました。
2025-06-12 00:10:16,501 - INFO - USDJPY: 新しい足 (M5) が形成されました。データ取得とシグナル判定を実行します。
2025-06-12 00:10:16,535 - INFO - USDJPY-M5 シグナル判定結果: No signal
2025-06-12 00:10:16,535 - INFO - USDJPY-M5: シグナルなし。
2025-06-12 00:10:16,536 - ERROR - USDJPY: シグナル監視ループで予期せぬエラーが発生しました: cannot access local variable 'uploaded_image_url' where it is not associated with a value
Traceback (most recent call last):
  File "C:\Users\pc\OneDrive\Desktop\phantom_alert_bot\signal_runner_loop.py", line 230, in _run
    image_url=uploaded_image_url # ImgurのURLを保存
              ^^^^^^^^^^^^^^^^^^
UnboundLocalError: cannot access local variable 'uploaded_image_url' where it is not associated with a value
2025-06-12 00:10:34,097 - INFO - USDJPY: 新しい足 (M5) が形成されました。データ取得とシグナル判定を実行します。
2025-06-12 00:10:34,124 - INFO - USDJPY-M5 シグナル判定結果: No signal
2025-06-12 00:10:34,125 - INFO - USDJPY-M5: シグナルなし。
2025-06-12 00:10:34,125 - ERROR - USDJPY: シグナル監視ループで予期せぬエラーが発生しました: cannot access local variable 'uploaded_image_url' where it is not associated with a value
Traceback (most recent call last):
  File "c:\Users\pc\OneDrive\Desktop\phantom_alert_bot\signal_runner_loop.py", line 230, in _run
    image_url=uploaded_image_url # ImgurのURLを保存
              ^^^^^^^^^^^^^^^^^^
UnboundLocalError: cannot access local variable 'uploaded_image_url' where it is not associated with a value
2025-06-12 00:11:00,882 - INFO - ✅ USDJPY-M5 シグナルランナーが初期化されました。
2025-06-12 00:11:01,903 - INFO - USDJPY-M5 シグナル監視ループを開始します。
2025-06-12 00:11:01,903 - INFO - USDJPY: MT5クライアントを初期化しています...
2025-06-12 00:11:01,904 - INFO - ✅ USDJPY: MT5クライアントの初期化に成功しました。
2025-06-12 00:11:01,904 - INFO - USDJPY: 新しい足 (M5) が形成されました。データ取得とシグナル判定を実行します。
2025-06-12 00:11:01,929 - INFO - USDJPY-M5 シグナル判定結果: No signal
2025-06-12 00:11:01,929 - INFO - USDJPY-M5: シグナルなし。
2025-06-12 00:11:01,930 - ERROR - USDJPY: シグナル監視ループで予期せぬエラーが発生しました: cannot access local variable 'uploaded_image_url' where it is not associated with a value
Traceback (most recent call last):
  File "C:\Users\pc\OneDrive\Desktop\phantom_alert_bot\signal_runner_loop.py", line 230, in _run
    image_url=uploaded_image_url # ImgurのURLを保存
              ^^^^^^^^^^^^^^^^^^
UnboundLocalError: cannot access local variable 'uploaded_image_url' where it is not associated with a value
2025-06-12 00:11:02,778 - INFO - ✅ USDJPY-M5 シグナルランナーが初期化されました。
2025-06-12 00:11:03,799 - INFO - USDJPY-M5 シグナル監視ループを開始します。
2025-06-12 00:11:03,799 - INFO - USDJPY: MT5クライアントを初期化しています...
2025-06-12 00:11:03,799 - INFO - ✅ USDJPY: MT5クライアントの初期化に成功しました。
2025-06-12 00:11:03,799 - INFO - USDJPY: 新しい足 (M5) が形成されました。データ取得とシグナル判定を実行します。
2025-06-12 00:11:03,828 - INFO - USDJPY-M5 シグナル判定結果: No signal
2025-06-12 00:11:03,828 - INFO - USDJPY-M5: シグナルなし。
2025-06-12 00:11:03,829 - ERROR - USDJPY: シグナル監視ループで予期せぬエラーが発生しました: cannot access local variable 'uploaded_image_url' where it is not associated with a value
Traceback (most recent call last):
  File "C:\Users\pc\OneDrive\Desktop\phantom_alert_bot\signal_runner_loop.py", line 230, in _run
    image_url=uploaded_image_url # ImgurのURLを保存
              ^^^^^^^^^^^^^^^^^^
UnboundLocalError: cannot access local variable 'uploaded_image_url' where it is not associated with a value
2025-06-12 00:11:16,537 - INFO - USDJPY: 新しい足 (M5) が形成されました。データ取得とシグナル判定を実行します。
2025-06-12 00:11:16,559 - INFO - USDJPY-M5 シグナル判定結果: No signal
2025-06-12 00:11:16,559 - INFO - USDJPY-M5: シグナルなし。
2025-06-12 00:11:16,559 - ERROR - USDJPY: シグナル監視ループで予期せぬエラーが発生しました: cannot access local variable 'uploaded_image_url' where it is not associated with a value
Traceback (most recent call last):
  File "C:\Users\pc\OneDrive\Desktop\phantom_alert_bot\signal_runner_loop.py", line 230, in _run
    image_url=uploaded_image_url # ImgurのURLを保存
              ^^^^^^^^^^^^^^^^^^
UnboundLocalError: cannot access local variable 'uploaded_image_url' where it is not associated with a value
2025-06-12 00:11:34,127 - INFO - USDJPY: 新しい足 (M5) が形成されました。データ取得とシグナル判定を実行します。
2025-06-12 00:11:34,145 - INFO - USDJPY-M5 シグナル判定結果: No signal
2025-06-12 00:11:34,146 - INFO - USDJPY-M5: シグナルなし。
2025-06-12 00:11:34,146 - ERROR - USDJPY: シグナル監視ループで予期せぬエラーが発生しました: cannot access local variable 'uploaded_image_url' where it is not associated with a value
Traceback (most recent call last):
  File "c:\Users\pc\OneDrive\Desktop\phantom_alert_bot\signal_runner_loop.py", line 230, in _run
    image_url=uploaded_image_url # ImgurのURLを保存
              ^^^^^^^^^^^^^^^^^^
UnboundLocalError: cannot access local variable 'uploaded_image_url' where it is not associated with a value
2025-06-12 00:12:01,931 - INFO - USDJPY: 新しい足 (M5) が形成されました。データ取得とシグナル判定を実行します。
2025-06-12 00:12:01,950 - INFO - USDJPY-M5 シグナル判定結果: No signal
2025-06-12 00:12:01,950 - INFO - USDJPY-M5: シグナルなし。
2025-06-12 00:12:01,951 - ERROR - USDJPY: シグナル監視ループで予期せぬエラーが発生しました: cannot access local variable 'uploaded_image_url' where it is not associated with a value
Traceback (most recent call last):
  File "C:\Users\pc\OneDrive\Desktop\phantom_alert_bot\signal_runner_loop.py", line 230, in _run
    image_url=uploaded_image_url # ImgurのURLを保存
              ^^^^^^^^^^^^^^^^^^
UnboundLocalError: cannot access local variable 'uploaded_image_url' where it is not associated with a value
2025-06-12 00:12:03,830 - INFO - USDJPY: 新しい足 (M5) が形成されました。データ取得とシグナル判定を実行します。
2025-06-12 00:12:03,870 - INFO - USDJPY-M5 シグナル判定結果: No signal
2025-06-12 00:12:03,870 - INFO - USDJPY-M5: シグナルなし。
2025-06-12 00:12:03,870 - ERROR - USDJPY: シグナル監視ループで予期せぬエラーが発生しました: cannot access local variable 'uploaded_image_url' where it is not associated with a value
Traceback (most recent call last):
  File "C:\Users\pc\OneDrive\Desktop\phantom_alert_bot\signal_runner_loop.py", line 230, in _run
    image_url=uploaded_image_url # ImgurのURLを保存
              ^^^^^^^^^^^^^^^^^^
UnboundLocalError: cannot access local variable 'uploaded_image_url' where it is not associated with a value
2025-06-12 00:12:16,560 - INFO - USDJPY: 新しい足 (M5) が形成されました。データ取得とシグナル判定を実行します。
2025-06-12 00:12:16,602 - INFO - USDJPY-M5 シグナル判定結果: No signal
2025-06-12 00:12:16,603 - INFO - USDJPY-M5: シグナルなし。
2025-06-12 00:12:16,603 - ERROR - USDJPY: シグナル監視ループで予期せぬエラーが発生しました: cannot access local variable 'uploaded_image_url' where it is not associated with a value
Traceback (most recent call last):
  File "C:\Users\pc\OneDrive\Desktop\phantom_alert_bot\signal_runner_loop.py", line 230, in _run
    image_url=uploaded_image_url # ImgurのURLを保存
              ^^^^^^^^^^^^^^^^^^
UnboundLocalError: cannot access local variable 'uploaded_image_url' where it is not associated with a value
2025-06-12 00:12:34,148 - INFO - USDJPY: 新しい足 (M5) が形成されました。データ取得とシグナル判定を実行します。
2025-06-12 00:12:34,167 - INFO - USDJPY-M5 シグナル判定結果: No signal
2025-06-12 00:12:34,167 - INFO - USDJPY-M5: シグナルなし。
2025-06-12 00:12:34,167 - ERROR - USDJPY: シグナル監視ループで予期せぬエラーが発生しました: cannot access local variable 'uploaded_image_url' where it is not associated with a value
Traceback (most recent call last):
  File "c:\Users\pc\OneDrive\Desktop\phantom_alert_bot\signal_runner_loop.py", line 230, in _run
    image_url=uploaded_image_url # ImgurのURLを保存
              ^^^^^^^^^^^^^^^^^^
UnboundLocalError: cannot access local variable 'uploaded_image_url' where it is not associated with a value
2025-06-12 00:13:01,952 - INFO - USDJPY: 新しい足 (M5) が形成されました。データ取得とシグナル判定を実行します。
2025-06-12 00:13:01,973 - INFO - USDJPY-M5 シグナル判定結果: No signal
2025-06-12 00:13:01,973 - INFO - USDJPY-M5: シグナルなし。
2025-06-12 00:13:01,974 - ERROR - USDJPY: シグナル監視ループで予期せぬエラーが発生しました: cannot access local variable 'uploaded_image_url' where it is not associated with a value
Traceback (most recent call last):
  File "C:\Users\pc\OneDrive\Desktop\phantom_alert_bot\signal_runner_loop.py", line 230, in _run
    image_url=uploaded_image_url # ImgurのURLを保存
              ^^^^^^^^^^^^^^^^^^
UnboundLocalError: cannot access local variable 'uploaded_image_url' where it is not associated with a value
2025-06-12 00:13:03,872 - INFO - USDJPY: 新しい足 (M5) が形成されました。データ取得とシグナル判定を実行します。
2025-06-12 00:13:03,894 - INFO - USDJPY-M5 シグナル判定結果: No signal
2025-06-12 00:13:03,894 - INFO - USDJPY-M5: シグナルなし。
2025-06-12 00:13:03,895 - ERROR - USDJPY: シグナル監視ループで予期せぬエラーが発生しました: cannot access local variable 'uploaded_image_url' where it is not associated with a value
Traceback (most recent call last):
  File "C:\Users\pc\OneDrive\Desktop\phantom_alert_bot\signal_runner_loop.py", line 230, in _run
    image_url=uploaded_image_url # ImgurのURLを保存
              ^^^^^^^^^^^^^^^^^^
UnboundLocalError: cannot access local variable 'uploaded_image_url' where it is not associated with a value
2025-06-12 00:13:16,605 - INFO - USDJPY: 新しい足 (M5) が形成されました。データ取得とシグナル判定を実行します。
2025-06-12 00:13:16,652 - INFO - USDJPY-M5 シグナル判定結果: No signal
2025-06-12 00:13:16,652 - INFO - USDJPY-M5: シグナルなし。
2025-06-12 00:13:16,653 - ERROR - USDJPY: シグナル監視ループで予期せぬエラーが発生しました: cannot access local variable 'uploaded_image_url' where it is not associated with a value
Traceback (most recent call last):
  File "C:\Users\pc\OneDrive\Desktop\phantom_alert_bot\signal_runner_loop.py", line 230, in _run
    image_url=uploaded_image_url # ImgurのURLを保存
              ^^^^^^^^^^^^^^^^^^
UnboundLocalError: cannot access local variable 'uploaded_image_url' where it is not associated with a value
2025-06-12 00:13:34,169 - INFO - USDJPY: 新しい足 (M5) が形成されました。データ取得とシグナル判定を実行します。
2025-06-12 00:13:34,188 - INFO - USDJPY-M5 シグナル判定結果: No signal
2025-06-12 00:13:34,189 - INFO - USDJPY-M5: シグナルなし。
2025-06-12 00:13:34,189 - ERROR - USDJPY: シグナル監視ループで予期せぬエラーが発生しました: cannot access local variable 'uploaded_image_url' where it is not associated with a value
Traceback (most recent call last):
  File "c:\Users\pc\OneDrive\Desktop\phantom_alert_bot\signal_runner_loop.py", line 230, in _run
    image_url=uploaded_image_url # ImgurのURLを保存
              ^^^^^^^^^^^^^^^^^^
UnboundLocalError: cannot access local variable 'uploaded_image_url' where it is not associated with a value
2025-06-12 00:14:01,975 - INFO - USDJPY: 新しい足 (M5) が形成されました。データ取得とシグナル判定を実行します。
2025-06-12 00:14:01,998 - INFO - USDJPY-M5 シグナル判定結果: No signal
2025-06-12 00:14:01,998 - INFO - USDJPY-M5: シグナルなし。
2025-06-12 00:14:01,998 - ERROR - USDJPY: シグナル監視ループで予期せぬエラーが発生しました: cannot access local variable 'uploaded_image_url' where it is not associated with a value
Traceback (most recent call last):
  File "C:\Users\pc\OneDrive\Desktop\phantom_alert_bot\signal_runner_loop.py", line 230, in _run
    image_url=uploaded_image_url # ImgurのURLを保存
              ^^^^^^^^^^^^^^^^^^
UnboundLocalError: cannot access local variable 'uploaded_image_url' where it is not associated with a value
2025-06-12 00:14:03,896 - INFO - USDJPY: 新しい足 (M5) が形成されました。データ取得とシグナル判定を実行します。
2025-06-12 00:14:03,915 - INFO - USDJPY-M5 シグナル判定結果: No signal
2025-06-12 00:14:03,915 - INFO - USDJPY-M5: シグナルなし。
2025-06-12 00:14:03,915 - ERROR - USDJPY: シグナル監視ループで予期せぬエラーが発生しました: cannot access local variable 'uploaded_image_url' where it is not associated with a value
Traceback (most recent call last):
  File "C:\Users\pc\OneDrive\Desktop\phantom_alert_bot\signal_runner_loop.py", line 230, in _run
    image_url=uploaded_image_url # ImgurのURLを保存
              ^^^^^^^^^^^^^^^^^^
UnboundLocalError: cannot access local variable 'uploaded_image_url' where it is not associated with a value
2025-06-12 00:14:16,654 - INFO - USDJPY: 新しい足 (M5) が形成されました。データ取得とシグナル判定を実行します。
2025-06-12 00:14:16,680 - INFO - USDJPY-M5 シグナル判定結果: No signal
2025-06-12 00:14:16,681 - INFO - USDJPY-M5: シグナルなし。
2025-06-12 00:14:16,681 - ERROR - USDJPY: シグナル監視ループで予期せぬエラーが発生しました: cannot access local variable 'uploaded_image_url' where it is not associated with a value
Traceback (most recent call last):
  File "C:\Users\pc\OneDrive\Desktop\phantom_alert_bot\signal_runner_loop.py", line 230, in _run
    image_url=uploaded_image_url # ImgurのURLを保存
              ^^^^^^^^^^^^^^^^^^
UnboundLocalError: cannot access local variable 'uploaded_image_url' where it is not associated with a value
2025-06-12 00:14:34,191 - INFO - USDJPY: 新しい足 (M5) が形成されました。データ取得とシグナル判定を実行します。
2025-06-12 00:14:34,209 - INFO - USDJPY-M5 シグナル判定結果: No signal
2025-06-12 00:14:34,210 - INFO - USDJPY-M5: シグナルなし。
2025-06-12 00:14:34,210 - ERROR - USDJPY: シグナル監視ループで予期せぬエラーが発生しました: cannot access local variable 'uploaded_image_url' where it is not associated with a value
Traceback (most recent call last):
  File "c:\Users\pc\OneDrive\Desktop\phantom_alert_bot\signal_runner_loop.py", line 230, in _run
    image_url=uploaded_image_url # ImgurのURLを保存
              ^^^^^^^^^^^^^^^^^^
UnboundLocalError: cannot access local variable 'uploaded_image_url' where it is not associated with a value
2025-06-12 00:15:01,999 - INFO - USDJPY: 新しい足 (M5) が形成されました。データ取得とシグナル判定を実行します。
2025-06-12 00:15:02,021 - INFO - USDJPY-M5 シグナル判定結果: Balanced Sell Signal (Confluence: MACD Dead Cross, Stochastic Dead Cross)
2025-06-12 00:15:02,022 - ERROR - USDJPY: シグナル監視ループで予期せぬエラーが発生しました: 'SignalRunner' object has no attribute '_generate_chart_and_upload'
Traceback (most recent call last):
  File "C:\Users\pc\OneDrive\Desktop\phantom_alert_bot\signal_runner_loop.py", line 199, in _run
    uploaded_image_url = self._generate_chart_and_upload(df, signal_info, image_filename)
                         ^^^^^^^^^^^^^^^^^^^^^^^^^^^^^^^
AttributeError: 'SignalRunner' object has no attribute '_generate_chart_and_upload'
2025-06-12 00:15:03,917 - INFO - USDJPY: 新しい足 (M5) が形成されました。データ取得とシグナル判定を実行します。
2025-06-12 00:15:03,956 - INFO - USDJPY-M5 シグナル判定結果: Balanced Sell Signal (Confluence: MACD Dead Cross, Stochastic Dead Cross)
2025-06-12 00:15:03,957 - ERROR - USDJPY: シグナル監視ループで予期せぬエラーが発生しました: 'SignalRunner' object has no attribute '_generate_chart_and_upload'
Traceback (most recent call last):
  File "C:\Users\pc\OneDrive\Desktop\phantom_alert_bot\signal_runner_loop.py", line 199, in _run
    uploaded_image_url = self._generate_chart_and_upload(df, signal_info, image_filename)
                         ^^^^^^^^^^^^^^^^^^^^^^^^^^^^^^^
AttributeError: 'SignalRunner' object has no attribute '_generate_chart_and_upload'
2025-06-12 00:15:16,683 - INFO - USDJPY: 新しい足 (M5) が形成されました。データ取得とシグナル判定を実行します。
2025-06-12 00:15:16,720 - INFO - USDJPY-M5 シグナル判定結果: No signal
2025-06-12 00:15:16,720 - INFO - USDJPY-M5: シグナルなし。
2025-06-12 00:15:16,721 - ERROR - USDJPY: シグナル監視ループで予期せぬエラーが発生しました: cannot access local variable 'uploaded_image_url' where it is not associated with a value
Traceback (most recent call last):
  File "C:\Users\pc\OneDrive\Desktop\phantom_alert_bot\signal_runner_loop.py", line 230, in _run
UnboundLocalError: cannot access local variable 'uploaded_image_url' where it is not associated with a value
2025-06-12 00:15:34,211 - INFO - USDJPY: 新しい足 (M5) が形成されました。データ取得とシグナル判定を実行します。
2025-06-12 00:15:34,231 - INFO - USDJPY-M5 シグナル判定結果: No signal
2025-06-12 00:15:34,231 - INFO - USDJPY-M5: シグナルなし。
2025-06-12 00:15:34,231 - ERROR - USDJPY: シグナル監視ループで予期せぬエラーが発生しました: cannot access local variable 'uploaded_image_url' where it is not associated with a value
Traceback (most recent call last):
  File "c:\Users\pc\OneDrive\Desktop\phantom_alert_bot\signal_runner_loop.py", line 230, in _run
UnboundLocalError: cannot access local variable 'uploaded_image_url' where it is not associated with a value
2025-06-12 00:16:02,023 - INFO - USDJPY: 新しい足 (M5) が形成されました。データ取得とシグナル判定を実行します。
2025-06-12 00:16:02,044 - INFO - USDJPY-M5 シグナル判定結果: No signal
2025-06-12 00:16:02,044 - INFO - USDJPY-M5: シグナルなし。
2025-06-12 00:16:02,044 - ERROR - USDJPY: シグナル監視ループで予期せぬエラーが発生しました: cannot access local variable 'uploaded_image_url' where it is not associated with a value
Traceback (most recent call last):
  File "C:\Users\pc\OneDrive\Desktop\phantom_alert_bot\signal_runner_loop.py", line 230, in _run
UnboundLocalError: cannot access local variable 'uploaded_image_url' where it is not associated with a value
2025-06-12 00:16:03,959 - INFO - USDJPY: 新しい足 (M5) が形成されました。データ取得とシグナル判定を実行します。
2025-06-12 00:16:04,008 - INFO - USDJPY-M5 シグナル判定結果: Balanced Sell Signal (Confluence: MACD Dead Cross, Stochastic Dead Cross)
2025-06-12 00:16:04,008 - ERROR - USDJPY: シグナル監視ループで予期せぬエラーが発生しました: 'SignalRunner' object has no attribute '_generate_chart_and_upload'
Traceback (most recent call last):
  File "C:\Users\pc\OneDrive\Desktop\phantom_alert_bot\signal_runner_loop.py", line 199, in _run
    # シグナルが出た場合、LINE通知とチャート画像生成・アップロード
                      ^^^^^^^^^^^^^^^^^^^^^^
AttributeError: 'SignalRunner' object has no attribute '_generate_chart_and_upload'
2025-06-12 00:16:16,723 - INFO - USDJPY: 新しい足 (M5) が形成されました。データ取得とシグナル判定を実行します。
2025-06-12 00:16:16,744 - INFO - USDJPY-M5 シグナル判定結果: Balanced Sell Signal (Confluence: MACD Dead Cross, Stochastic Dead Cross)
2025-06-12 00:16:16,744 - ERROR - USDJPY: シグナル監視ループで予期せぬエラーが発生しました: 'SignalRunner' object has no attribute '_generate_chart_and_upload'
Traceback (most recent call last):
  File "C:\Users\pc\OneDrive\Desktop\phantom_alert_bot\signal_runner_loop.py", line 199, in _run
    # シグナルが出た場合、LINE通知とチャート画像生成・アップロード
                      ^^^^^^^^^^^^^^^^^^^^^^
AttributeError: 'SignalRunner' object has no attribute '_generate_chart_and_upload'
2025-06-12 00:16:34,232 - INFO - USDJPY: 新しい足 (M5) が形成されました。データ取得とシグナル判定を実行します。
2025-06-12 00:16:34,255 - INFO - USDJPY-M5 シグナル判定結果: No signal
2025-06-12 00:16:34,256 - INFO - USDJPY-M5: シグナルなし。
2025-06-12 00:16:34,256 - ERROR - USDJPY: シグナル監視ループで予期せぬエラーが発生しました: cannot access local variable 'uploaded_image_url' where it is not associated with a value
Traceback (most recent call last):
  File "c:\Users\pc\OneDrive\Desktop\phantom_alert_bot\signal_runner_loop.py", line 230, in _run
UnboundLocalError: cannot access local variable 'uploaded_image_url' where it is not associated with a value
2025-06-12 00:17:02,045 - INFO - USDJPY: 新しい足 (M5) が形成されました。データ取得とシグナル判定を実行します。
2025-06-12 00:17:02,063 - INFO - USDJPY-M5 シグナル判定結果: No signal
2025-06-12 00:17:02,064 - INFO - USDJPY-M5: シグナルなし。
2025-06-12 00:17:02,064 - ERROR - USDJPY: シグナル監視ループで予期せぬエラーが発生しました: cannot access local variable 'uploaded_image_url' where it is not associated with a value
Traceback (most recent call last):
  File "C:\Users\pc\OneDrive\Desktop\phantom_alert_bot\signal_runner_loop.py", line 230, in _run
UnboundLocalError: cannot access local variable 'uploaded_image_url' where it is not associated with a value
2025-06-12 00:17:04,011 - INFO - USDJPY: 新しい足 (M5) が形成されました。データ取得とシグナル判定を実行します。
2025-06-12 00:17:04,044 - INFO - USDJPY-M5 シグナル判定結果: No signal
2025-06-12 00:17:04,045 - INFO - USDJPY-M5: シグナルなし。
2025-06-12 00:17:04,045 - ERROR - USDJPY: シグナル監視ループで予期せぬエラーが発生しました: cannot access local variable 'uploaded_image_url' where it is not associated with a value
Traceback (most recent call last):
  File "C:\Users\pc\OneDrive\Desktop\phantom_alert_bot\signal_runner_loop.py", line 230, in _run
UnboundLocalError: cannot access local variable 'uploaded_image_url' where it is not associated with a value
2025-06-12 00:17:16,745 - INFO - USDJPY: 新しい足 (M5) が形成されました。データ取得とシグナル判定を実行します。
2025-06-12 00:17:16,774 - INFO - USDJPY-M5 シグナル判定結果: Balanced Sell Signal (Confluence: MACD Dead Cross, Stochastic Dead Cross)
2025-06-12 00:17:16,774 - ERROR - USDJPY: シグナル監視ループで予期せぬエラーが発生しました: 'SignalRunner' object has no attribute '_generate_chart_and_upload'
Traceback (most recent call last):
  File "C:\Users\pc\OneDrive\Desktop\phantom_alert_bot\signal_runner_loop.py", line 199, in _run
    # シグナルが出た場合、LINE通知とチャート画像生成・アップロード
                      ^^^^^^^^^^^^^^^^^^^^^^
AttributeError: 'SignalRunner' object has no attribute '_generate_chart_and_upload'
2025-06-12 00:17:34,257 - INFO - USDJPY: 新しい足 (M5) が形成されました。データ取得とシグナル判定を実行します。
2025-06-12 00:17:34,277 - INFO - USDJPY-M5 シグナル判定結果: No signal
2025-06-12 00:17:34,277 - INFO - USDJPY-M5: シグナルなし。
2025-06-12 00:17:34,277 - ERROR - USDJPY: シグナル監視ループで予期せぬエラーが発生しました: cannot access local variable 'uploaded_image_url' where it is not associated with a value
Traceback (most recent call last):
  File "c:\Users\pc\OneDrive\Desktop\phantom_alert_bot\signal_runner_loop.py", line 230, in _run
UnboundLocalError: cannot access local variable 'uploaded_image_url' where it is not associated with a value
2025-06-12 00:18:02,065 - INFO - USDJPY: 新しい足 (M5) が形成されました。データ取得とシグナル判定を実行します。
2025-06-12 00:18:02,088 - INFO - USDJPY-M5 シグナル判定結果: No signal
2025-06-12 00:18:02,088 - INFO - USDJPY-M5: シグナルなし。
2025-06-12 00:18:02,088 - ERROR - USDJPY: シグナル監視ループで予期せぬエラーが発生しました: cannot access local variable 'uploaded_image_url' where it is not associated with a value
Traceback (most recent call last):
  File "C:\Users\pc\OneDrive\Desktop\phantom_alert_bot\signal_runner_loop.py", line 230, in _run
UnboundLocalError: cannot access local variable 'uploaded_image_url' where it is not associated with a value
2025-06-12 00:18:04,046 - INFO - USDJPY: 新しい足 (M5) が形成されました。データ取得とシグナル判定を実行します。
2025-06-12 00:18:04,071 - INFO - USDJPY-M5 シグナル判定結果: No signal
2025-06-12 00:18:04,071 - INFO - USDJPY-M5: シグナルなし。
2025-06-12 00:18:04,071 - ERROR - USDJPY: シグナル監視ループで予期せぬエラーが発生しました: cannot access local variable 'uploaded_image_url' where it is not associated with a value
Traceback (most recent call last):
  File "C:\Users\pc\OneDrive\Desktop\phantom_alert_bot\signal_runner_loop.py", line 230, in _run
UnboundLocalError: cannot access local variable 'uploaded_image_url' where it is not associated with a value
2025-06-12 00:18:16,775 - INFO - USDJPY: 新しい足 (M5) が形成されました。データ取得とシグナル判定を実行します。
2025-06-12 00:18:16,803 - INFO - USDJPY-M5 シグナル判定結果: No signal
2025-06-12 00:18:16,804 - INFO - USDJPY-M5: シグナルなし。
2025-06-12 00:18:16,804 - ERROR - USDJPY: シグナル監視ループで予期せぬエラーが発生しました: cannot access local variable 'uploaded_image_url' where it is not associated with a value
Traceback (most recent call last):
  File "C:\Users\pc\OneDrive\Desktop\phantom_alert_bot\signal_runner_loop.py", line 230, in _run
UnboundLocalError: cannot access local variable 'uploaded_image_url' where it is not associated with a value
2025-06-12 00:18:34,278 - INFO - USDJPY: 新しい足 (M5) が形成されました。データ取得とシグナル判定を実行します。
2025-06-12 00:18:34,301 - INFO - USDJPY-M5 シグナル判定結果: No signal
2025-06-12 00:18:34,302 - INFO - USDJPY-M5: シグナルなし。
2025-06-12 00:18:34,302 - ERROR - USDJPY: シグナル監視ループで予期せぬエラーが発生しました: cannot access local variable 'uploaded_image_url' where it is not associated with a value
Traceback (most recent call last):
  File "c:\Users\pc\OneDrive\Desktop\phantom_alert_bot\signal_runner_loop.py", line 230, in _run
UnboundLocalError: cannot access local variable 'uploaded_image_url' where it is not associated with a value
2025-06-12 00:19:02,089 - INFO - USDJPY: 新しい足 (M5) が形成されました。データ取得とシグナル判定を実行します。
2025-06-12 00:19:02,110 - INFO - USDJPY-M5 シグナル判定結果: No signal
2025-06-12 00:19:02,112 - INFO - USDJPY-M5: シグナルなし。
2025-06-12 00:19:02,112 - ERROR - USDJPY: シグナル監視ループで予期せぬエラーが発生しました: cannot access local variable 'uploaded_image_url' where it is not associated with a value
Traceback (most recent call last):
  File "C:\Users\pc\OneDrive\Desktop\phantom_alert_bot\signal_runner_loop.py", line 230, in _run
UnboundLocalError: cannot access local variable 'uploaded_image_url' where it is not associated with a value
2025-06-12 00:19:04,073 - INFO - USDJPY: 新しい足 (M5) が形成されました。データ取得とシグナル判定を実行します。
2025-06-12 00:19:04,128 - INFO - USDJPY-M5 シグナル判定結果: No signal
2025-06-12 00:19:04,130 - INFO - USDJPY-M5: シグナルなし。
2025-06-12 00:19:04,130 - ERROR - USDJPY: シグナル監視ループで予期せぬエラーが発生しました: cannot access local variable 'uploaded_image_url' where it is not associated with a value
Traceback (most recent call last):
  File "C:\Users\pc\OneDrive\Desktop\phantom_alert_bot\signal_runner_loop.py", line 230, in _run
UnboundLocalError: cannot access local variable 'uploaded_image_url' where it is not associated with a value
2025-06-12 00:19:34,303 - INFO - USDJPY: 新しい足 (M5) が形成されました。データ取得とシグナル判定を実行します。
2025-06-12 00:19:34,321 - INFO - USDJPY-M5 シグナル判定結果: No signal
2025-06-12 00:19:34,322 - INFO - USDJPY-M5: シグナルなし。
2025-06-12 00:19:34,322 - ERROR - USDJPY: シグナル監視ループで予期せぬエラーが発生しました: cannot access local variable 'uploaded_image_url' where it is not associated with a value
Traceback (most recent call last):
  File "c:\Users\pc\OneDrive\Desktop\phantom_alert_bot\signal_runner_loop.py", line 230, in _run
UnboundLocalError: cannot access local variable 'uploaded_image_url' where it is not associated with a value
2025-06-12 00:20:02,113 - INFO - USDJPY: 新しい足 (M5) が形成されました。データ取得とシグナル判定を実行します。
2025-06-12 00:20:02,132 - INFO - USDJPY-M5 シグナル判定結果: No signal
2025-06-12 00:20:02,132 - INFO - USDJPY-M5: シグナルなし。
2025-06-12 00:20:02,132 - ERROR - USDJPY: シグナル監視ループで予期せぬエラーが発生しました: cannot access local variable 'uploaded_image_url' where it is not associated with a value
Traceback (most recent call last):
  File "C:\Users\pc\OneDrive\Desktop\phantom_alert_bot\signal_runner_loop.py", line 230, in _run
UnboundLocalError: cannot access local variable 'uploaded_image_url' where it is not associated with a value
2025-06-12 00:20:04,132 - INFO - USDJPY: 新しい足 (M5) が形成されました。データ取得とシグナル判定を実行します。
2025-06-12 00:20:04,151 - INFO - USDJPY-M5 シグナル判定結果: No signal
2025-06-12 00:20:04,151 - INFO - USDJPY-M5: シグナルなし。
2025-06-12 00:20:04,151 - ERROR - USDJPY: シグナル監視ループで予期せぬエラーが発生しました: cannot access local variable 'uploaded_image_url' where it is not associated with a value
Traceback (most recent call last):
  File "C:\Users\pc\OneDrive\Desktop\phantom_alert_bot\signal_runner_loop.py", line 230, in _run
UnboundLocalError: cannot access local variable 'uploaded_image_url' where it is not associated with a value
2025-06-12 00:20:34,323 - INFO - USDJPY: 新しい足 (M5) が形成されました。データ取得とシグナル判定を実行します。
2025-06-12 00:20:34,353 - INFO - USDJPY-M5 シグナル判定結果: No signal
2025-06-12 00:20:34,354 - INFO - USDJPY-M5: シグナルなし。
2025-06-12 00:20:34,354 - ERROR - USDJPY: シグナル監視ループで予期せぬエラーが発生しました: cannot access local variable 'uploaded_image_url' where it is not associated with a value
Traceback (most recent call last):
  File "c:\Users\pc\OneDrive\Desktop\phantom_alert_bot\signal_runner_loop.py", line 230, in _run
UnboundLocalError: cannot access local variable 'uploaded_image_url' where it is not associated with a value
2025-06-12 00:21:02,133 - INFO - USDJPY: 新しい足 (M5) が形成されました。データ取得とシグナル判定を実行します。
2025-06-12 00:21:02,152 - INFO - USDJPY-M5 シグナル判定結果: No signal
2025-06-12 00:21:02,153 - INFO - USDJPY-M5: シグナルなし。
2025-06-12 00:21:02,153 - ERROR - USDJPY: シグナル監視ループで予期せぬエラーが発生しました: cannot access local variable 'uploaded_image_url' where it is not associated with a value
Traceback (most recent call last):
  File "C:\Users\pc\OneDrive\Desktop\phantom_alert_bot\signal_runner_loop.py", line 230, in _run
UnboundLocalError: cannot access local variable 'uploaded_image_url' where it is not associated with a value
2025-06-12 00:21:04,153 - INFO - USDJPY: 新しい足 (M5) が形成されました。データ取得とシグナル判定を実行します。
2025-06-12 00:21:04,196 - INFO - USDJPY-M5 シグナル判定結果: No signal
2025-06-12 00:21:04,196 - INFO - USDJPY-M5: シグナルなし。
2025-06-12 00:21:04,197 - ERROR - USDJPY: シグナル監視ループで予期せぬエラーが発生しました: cannot access local variable 'uploaded_image_url' where it is not associated with a value
Traceback (most recent call last):
  File "C:\Users\pc\OneDrive\Desktop\phantom_alert_bot\signal_runner_loop.py", line 230, in _run
UnboundLocalError: cannot access local variable 'uploaded_image_url' where it is not associated with a value
2025-06-12 00:21:34,356 - INFO - USDJPY: 新しい足 (M5) が形成されました。データ取得とシグナル判定を実行します。
2025-06-12 00:21:34,410 - INFO - USDJPY-M5 シグナル判定結果: No signal
2025-06-12 00:21:34,411 - INFO - USDJPY-M5: シグナルなし。
2025-06-12 00:21:34,411 - ERROR - USDJPY: シグナル監視ループで予期せぬエラーが発生しました: cannot access local variable 'uploaded_image_url' where it is not associated with a value
Traceback (most recent call last):
  File "c:\Users\pc\OneDrive\Desktop\phantom_alert_bot\signal_runner_loop.py", line 230, in _run
UnboundLocalError: cannot access local variable 'uploaded_image_url' where it is not associated with a value
2025-06-12 00:22:02,155 - INFO - USDJPY: 新しい足 (M5) が形成されました。データ取得とシグナル判定を実行します。
2025-06-12 00:22:02,182 - INFO - USDJPY-M5 シグナル判定結果: No signal
2025-06-12 00:22:02,183 - INFO - USDJPY-M5: シグナルなし。
2025-06-12 00:22:02,183 - ERROR - USDJPY: シグナル監視ループで予期せぬエラーが発生しました: cannot access local variable 'uploaded_image_url' where it is not associated with a value
Traceback (most recent call last):
  File "C:\Users\pc\OneDrive\Desktop\phantom_alert_bot\signal_runner_loop.py", line 230, in _run
UnboundLocalError: cannot access local variable 'uploaded_image_url' where it is not associated with a value
2025-06-12 00:22:04,199 - INFO - USDJPY: 新しい足 (M5) が形成されました。データ取得とシグナル判定を実行します。
2025-06-12 00:22:04,235 - INFO - USDJPY-M5 シグナル判定結果: No signal
2025-06-12 00:22:04,236 - INFO - USDJPY-M5: シグナルなし。
2025-06-12 00:22:04,236 - ERROR - USDJPY: シグナル監視ループで予期せぬエラーが発生しました: cannot access local variable 'uploaded_image_url' where it is not associated with a value
Traceback (most recent call last):
  File "C:\Users\pc\OneDrive\Desktop\phantom_alert_bot\signal_runner_loop.py", line 230, in _run
UnboundLocalError: cannot access local variable 'uploaded_image_url' where it is not associated with a value
2025-06-12 00:22:34,412 - INFO - USDJPY: 新しい足 (M5) が形成されました。データ取得とシグナル判定を実行します。
2025-06-12 00:22:34,438 - INFO - USDJPY-M5 シグナル判定結果: No signal
2025-06-12 00:22:34,438 - INFO - USDJPY-M5: シグナルなし。
2025-06-12 00:22:34,439 - ERROR - USDJPY: シグナル監視ループで予期せぬエラーが発生しました: cannot access local variable 'uploaded_image_url' where it is not associated with a value
Traceback (most recent call last):
  File "c:\Users\pc\OneDrive\Desktop\phantom_alert_bot\signal_runner_loop.py", line 230, in _run
UnboundLocalError: cannot access local variable 'uploaded_image_url' where it is not associated with a value
2025-06-12 00:23:02,184 - INFO - USDJPY: 新しい足 (M5) が形成されました。データ取得とシグナル判定を実行します。
2025-06-12 00:23:02,207 - INFO - USDJPY-M5 シグナル判定結果: No signal
2025-06-12 00:23:02,208 - INFO - USDJPY-M5: シグナルなし。
2025-06-12 00:23:02,208 - ERROR - USDJPY: シグナル監視ループで予期せぬエラーが発生しました: cannot access local variable 'uploaded_image_url' where it is not associated with a value
Traceback (most recent call last):
  File "C:\Users\pc\OneDrive\Desktop\phantom_alert_bot\signal_runner_loop.py", line 230, in _run
UnboundLocalError: cannot access local variable 'uploaded_image_url' where it is not associated with a value
2025-06-12 00:23:04,237 - INFO - USDJPY: 新しい足 (M5) が形成されました。データ取得とシグナル判定を実行します。
2025-06-12 00:23:04,262 - INFO - USDJPY-M5 シグナル判定結果: No signal
2025-06-12 00:23:04,264 - INFO - USDJPY-M5: シグナルなし。
2025-06-12 00:23:04,264 - ERROR - USDJPY: シグナル監視ループで予期せぬエラーが発生しました: cannot access local variable 'uploaded_image_url' where it is not associated with a value
Traceback (most recent call last):
  File "C:\Users\pc\OneDrive\Desktop\phantom_alert_bot\signal_runner_loop.py", line 230, in _run
UnboundLocalError: cannot access local variable 'uploaded_image_url' where it is not associated with a value
2025-06-12 00:23:34,441 - INFO - USDJPY: 新しい足 (M5) が形成されました。データ取得とシグナル判定を実行します。
2025-06-12 00:23:34,491 - INFO - USDJPY-M5 シグナル判定結果: No signal
2025-06-12 00:23:34,492 - INFO - USDJPY-M5: シグナルなし。
2025-06-12 00:23:34,492 - ERROR - USDJPY: シグナル監視ループで予期せぬエラーが発生しました: cannot access local variable 'uploaded_image_url' where it is not associated with a value
Traceback (most recent call last):
  File "c:\Users\pc\OneDrive\Desktop\phantom_alert_bot\signal_runner_loop.py", line 230, in _run
UnboundLocalError: cannot access local variable 'uploaded_image_url' where it is not associated with a value
2025-06-12 00:24:02,210 - INFO - USDJPY: 新しい足 (M5) が形成されました。データ取得とシグナル判定を実行します。
2025-06-12 00:24:02,241 - INFO - USDJPY-M5 シグナル判定結果: No signal
2025-06-12 00:24:02,242 - INFO - USDJPY-M5: シグナルなし。
2025-06-12 00:24:02,243 - ERROR - USDJPY: シグナル監視ループで予期せぬエラーが発生しました: cannot access local variable 'uploaded_image_url' where it is not associated with a value
Traceback (most recent call last):
  File "C:\Users\pc\OneDrive\Desktop\phantom_alert_bot\signal_runner_loop.py", line 230, in _run
UnboundLocalError: cannot access local variable 'uploaded_image_url' where it is not associated with a value
2025-06-12 00:24:04,266 - INFO - USDJPY: 新しい足 (M5) が形成されました。データ取得とシグナル判定を実行します。
2025-06-12 00:24:04,294 - INFO - USDJPY-M5 シグナル判定結果: No signal
2025-06-12 00:24:04,294 - INFO - USDJPY-M5: シグナルなし。
2025-06-12 00:24:04,295 - ERROR - USDJPY: シグナル監視ループで予期せぬエラーが発生しました: cannot access local variable 'uploaded_image_url' where it is not associated with a value
Traceback (most recent call last):
  File "C:\Users\pc\OneDrive\Desktop\phantom_alert_bot\signal_runner_loop.py", line 230, in _run
UnboundLocalError: cannot access local variable 'uploaded_image_url' where it is not associated with a value
2025-06-12 00:24:34,494 - INFO - USDJPY: 新しい足 (M5) が形成されました。データ取得とシグナル判定を実行します。
2025-06-12 00:24:34,516 - INFO - USDJPY-M5 シグナル判定結果: No signal
2025-06-12 00:24:34,517 - INFO - USDJPY-M5: シグナルなし。
2025-06-12 00:24:34,517 - ERROR - USDJPY: シグナル監視ループで予期せぬエラーが発生しました: cannot access local variable 'uploaded_image_url' where it is not associated with a value
Traceback (most recent call last):
  File "c:\Users\pc\OneDrive\Desktop\phantom_alert_bot\signal_runner_loop.py", line 230, in _run
UnboundLocalError: cannot access local variable 'uploaded_image_url' where it is not associated with a value
2025-06-12 00:25:02,245 - INFO - USDJPY: 新しい足 (M5) が形成されました。データ取得とシグナル判定を実行します。
2025-06-12 00:25:02,275 - INFO - USDJPY-M5 シグナル判定結果: No signal
2025-06-12 00:25:02,275 - INFO - USDJPY-M5: シグナルなし。
2025-06-12 00:25:02,275 - ERROR - USDJPY: シグナル監視ループで予期せぬエラーが発生しました: cannot access local variable 'uploaded_image_url' where it is not associated with a value
Traceback (most recent call last):
  File "C:\Users\pc\OneDrive\Desktop\phantom_alert_bot\signal_runner_loop.py", line 230, in _run
UnboundLocalError: cannot access local variable 'uploaded_image_url' where it is not associated with a value
2025-06-12 00:25:04,296 - INFO - USDJPY: 新しい足 (M5) が形成されました。データ取得とシグナル判定を実行します。
2025-06-12 00:25:04,325 - INFO - USDJPY-M5 シグナル判定結果: No signal
2025-06-12 00:25:04,325 - INFO - USDJPY-M5: シグナルなし。
2025-06-12 00:25:04,326 - ERROR - USDJPY: シグナル監視ループで予期せぬエラーが発生しました: cannot access local variable 'uploaded_image_url' where it is not associated with a value
Traceback (most recent call last):
  File "C:\Users\pc\OneDrive\Desktop\phantom_alert_bot\signal_runner_loop.py", line 230, in _run
UnboundLocalError: cannot access local variable 'uploaded_image_url' where it is not associated with a value
2025-06-12 00:25:34,519 - INFO - USDJPY: 新しい足 (M5) が形成されました。データ取得とシグナル判定を実行します。
2025-06-12 00:25:34,551 - INFO - USDJPY-M5 シグナル判定結果: No signal
2025-06-12 00:25:34,552 - INFO - USDJPY-M5: シグナルなし。
2025-06-12 00:25:34,552 - ERROR - USDJPY: シグナル監視ループで予期せぬエラーが発生しました: cannot access local variable 'uploaded_image_url' where it is not associated with a value
Traceback (most recent call last):
  File "c:\Users\pc\OneDrive\Desktop\phantom_alert_bot\signal_runner_loop.py", line 230, in _run
UnboundLocalError: cannot access local variable 'uploaded_image_url' where it is not associated with a value
2025-06-12 00:26:02,277 - INFO - USDJPY: 新しい足 (M5) が形成されました。データ取得とシグナル判定を実行します。
2025-06-12 00:26:02,298 - INFO - USDJPY-M5 シグナル判定結果: No signal
2025-06-12 00:26:02,299 - INFO - USDJPY-M5: シグナルなし。
2025-06-12 00:26:02,299 - ERROR - USDJPY: シグナル監視ループで予期せぬエラーが発生しました: cannot access local variable 'uploaded_image_url' where it is not associated with a value
Traceback (most recent call last):
  File "C:\Users\pc\OneDrive\Desktop\phantom_alert_bot\signal_runner_loop.py", line 230, in _run
UnboundLocalError: cannot access local variable 'uploaded_image_url' where it is not associated with a value
2025-06-12 00:26:04,327 - INFO - USDJPY: 新しい足 (M5) が形成されました。データ取得とシグナル判定を実行します。
2025-06-12 00:26:04,378 - INFO - USDJPY-M5 シグナル判定結果: No signal
2025-06-12 00:26:04,379 - INFO - USDJPY-M5: シグナルなし。
2025-06-12 00:26:04,380 - ERROR - USDJPY: シグナル監視ループで予期せぬエラーが発生しました: cannot access local variable 'uploaded_image_url' where it is not associated with a value
Traceback (most recent call last):
  File "C:\Users\pc\OneDrive\Desktop\phantom_alert_bot\signal_runner_loop.py", line 230, in _run
UnboundLocalError: cannot access local variable 'uploaded_image_url' where it is not associated with a value
2025-06-12 00:26:34,555 - INFO - USDJPY: 新しい足 (M5) が形成されました。データ取得とシグナル判定を実行します。
2025-06-12 00:26:34,614 - INFO - USDJPY-M5 シグナル判定結果: No signal
2025-06-12 00:26:34,615 - INFO - USDJPY-M5: シグナルなし。
2025-06-12 00:26:34,616 - ERROR - USDJPY: シグナル監視ループで予期せぬエラーが発生しました: cannot access local variable 'uploaded_image_url' where it is not associated with a value
Traceback (most recent call last):
  File "c:\Users\pc\OneDrive\Desktop\phantom_alert_bot\signal_runner_loop.py", line 230, in _run
UnboundLocalError: cannot access local variable 'uploaded_image_url' where it is not associated with a value
2025-06-12 00:27:02,301 - INFO - USDJPY: 新しい足 (M5) が形成されました。データ取得とシグナル判定を実行します。
2025-06-12 00:27:02,342 - INFO - USDJPY-M5 シグナル判定結果: No signal
2025-06-12 00:27:02,343 - INFO - USDJPY-M5: シグナルなし。
2025-06-12 00:27:02,343 - ERROR - USDJPY: シグナル監視ループで予期せぬエラーが発生しました: cannot access local variable 'uploaded_image_url' where it is not associated with a value
Traceback (most recent call last):
  File "C:\Users\pc\OneDrive\Desktop\phantom_alert_bot\signal_runner_loop.py", line 230, in _run
UnboundLocalError: cannot access local variable 'uploaded_image_url' where it is not associated with a value
2025-06-12 00:27:04,382 - INFO - USDJPY: 新しい足 (M5) が形成されました。データ取得とシグナル判定を実行します。
2025-06-12 00:27:04,403 - INFO - USDJPY-M5 シグナル判定結果: No signal
2025-06-12 00:27:04,403 - INFO - USDJPY-M5: シグナルなし。
2025-06-12 00:27:04,403 - ERROR - USDJPY: シグナル監視ループで予期せぬエラーが発生しました: cannot access local variable 'uploaded_image_url' where it is not associated with a value
Traceback (most recent call last):
  File "C:\Users\pc\OneDrive\Desktop\phantom_alert_bot\signal_runner_loop.py", line 230, in _run
UnboundLocalError: cannot access local variable 'uploaded_image_url' where it is not associated with a value
2025-06-12 00:27:34,618 - INFO - USDJPY: 新しい足 (M5) が形成されました。データ取得とシグナル判定を実行します。
2025-06-12 00:27:34,658 - INFO - USDJPY-M5 シグナル判定結果: No signal
2025-06-12 00:27:34,659 - INFO - USDJPY-M5: シグナルなし。
2025-06-12 00:27:34,660 - ERROR - USDJPY: シグナル監視ループで予期せぬエラーが発生しました: cannot access local variable 'uploaded_image_url' where it is not associated with a value
Traceback (most recent call last):
  File "c:\Users\pc\OneDrive\Desktop\phantom_alert_bot\signal_runner_loop.py", line 230, in _run
UnboundLocalError: cannot access local variable 'uploaded_image_url' where it is not associated with a value
2025-06-12 00:28:02,346 - INFO - USDJPY: 新しい足 (M5) が形成されました。データ取得とシグナル判定を実行します。
2025-06-12 00:28:02,392 - INFO - USDJPY-M5 シグナル判定結果: No signal
2025-06-12 00:28:02,393 - INFO - USDJPY-M5: シグナルなし。
2025-06-12 00:28:02,393 - ERROR - USDJPY: シグナル監視ループで予期せぬエラーが発生しました: cannot access local variable 'uploaded_image_url' where it is not associated with a value
Traceback (most recent call last):
  File "C:\Users\pc\OneDrive\Desktop\phantom_alert_bot\signal_runner_loop.py", line 230, in _run
UnboundLocalError: cannot access local variable 'uploaded_image_url' where it is not associated with a value
2025-06-12 00:28:04,405 - INFO - USDJPY: 新しい足 (M5) が形成されました。データ取得とシグナル判定を実行します。
2025-06-12 00:28:04,426 - INFO - USDJPY-M5 シグナル判定結果: No signal
2025-06-12 00:28:04,428 - INFO - USDJPY-M5: シグナルなし。
2025-06-12 00:28:04,428 - ERROR - USDJPY: シグナル監視ループで予期せぬエラーが発生しました: cannot access local variable 'uploaded_image_url' where it is not associated with a value
Traceback (most recent call last):
  File "C:\Users\pc\OneDrive\Desktop\phantom_alert_bot\signal_runner_loop.py", line 230, in _run
UnboundLocalError: cannot access local variable 'uploaded_image_url' where it is not associated with a value
2025-06-12 00:28:34,667 - INFO - USDJPY: 新しい足 (M5) が形成されました。データ取得とシグナル判定を実行します。
2025-06-12 00:28:34,761 - INFO - USDJPY-M5 シグナル判定結果: No signal
2025-06-12 00:28:34,762 - INFO - USDJPY-M5: シグナルなし。
2025-06-12 00:28:34,762 - ERROR - USDJPY: シグナル監視ループで予期せぬエラーが発生しました: cannot access local variable 'uploaded_image_url' where it is not associated with a value
Traceback (most recent call last):
  File "c:\Users\pc\OneDrive\Desktop\phantom_alert_bot\signal_runner_loop.py", line 230, in _run
UnboundLocalError: cannot access local variable 'uploaded_image_url' where it is not associated with a value
2025-06-12 00:29:02,395 - INFO - USDJPY: 新しい足 (M5) が形成されました。データ取得とシグナル判定を実行します。
2025-06-12 00:29:02,417 - INFO - USDJPY-M5 シグナル判定結果: No signal
2025-06-12 00:29:02,417 - INFO - USDJPY-M5: シグナルなし。
2025-06-12 00:29:02,417 - ERROR - USDJPY: シグナル監視ループで予期せぬエラーが発生しました: cannot access local variable 'uploaded_image_url' where it is not associated with a value
Traceback (most recent call last):
  File "C:\Users\pc\OneDrive\Desktop\phantom_alert_bot\signal_runner_loop.py", line 230, in _run
UnboundLocalError: cannot access local variable 'uploaded_image_url' where it is not associated with a value
2025-06-12 00:29:04,429 - INFO - USDJPY: 新しい足 (M5) が形成されました。データ取得とシグナル判定を実行します。
2025-06-12 00:29:04,490 - INFO - USDJPY-M5 シグナル判定結果: No signal
2025-06-12 00:29:04,490 - INFO - USDJPY-M5: シグナルなし。
2025-06-12 00:29:04,491 - ERROR - USDJPY: シグナル監視ループで予期せぬエラーが発生しました: cannot access local variable 'uploaded_image_url' where it is not associated with a value
Traceback (most recent call last):
  File "C:\Users\pc\OneDrive\Desktop\phantom_alert_bot\signal_runner_loop.py", line 230, in _run
UnboundLocalError: cannot access local variable 'uploaded_image_url' where it is not associated with a value
2025-06-12 00:29:34,766 - INFO - USDJPY: 新しい足 (M5) が形成されました。データ取得とシグナル判定を実行します。
2025-06-12 00:29:34,797 - INFO - USDJPY-M5 シグナル判定結果: No signal
2025-06-12 00:29:34,797 - INFO - USDJPY-M5: シグナルなし。
2025-06-12 00:29:34,798 - ERROR - USDJPY: シグナル監視ループで予期せぬエラーが発生しました: cannot access local variable 'uploaded_image_url' where it is not associated with a value
Traceback (most recent call last):
  File "c:\Users\pc\OneDrive\Desktop\phantom_alert_bot\signal_runner_loop.py", line 230, in _run
UnboundLocalError: cannot access local variable 'uploaded_image_url' where it is not associated with a value
2025-06-12 00:30:02,420 - INFO - USDJPY: 新しい足 (M5) が形成されました。データ取得とシグナル判定を実行します。
2025-06-12 00:30:02,444 - INFO - USDJPY-M5 シグナル判定結果: No signal
2025-06-12 00:30:02,444 - INFO - USDJPY-M5: シグナルなし。
2025-06-12 00:30:02,445 - ERROR - USDJPY: シグナル監視ループで予期せぬエラーが発生しました: cannot access local variable 'uploaded_image_url' where it is not associated with a value
Traceback (most recent call last):
  File "C:\Users\pc\OneDrive\Desktop\phantom_alert_bot\signal_runner_loop.py", line 230, in _run
UnboundLocalError: cannot access local variable 'uploaded_image_url' where it is not associated with a value
2025-06-12 00:30:04,493 - INFO - USDJPY: 新しい足 (M5) が形成されました。データ取得とシグナル判定を実行します。
2025-06-12 00:30:04,542 - INFO - USDJPY-M5 シグナル判定結果: No signal
2025-06-12 00:30:04,542 - INFO - USDJPY-M5: シグナルなし。
2025-06-12 00:30:04,543 - ERROR - USDJPY: シグナル監視ループで予期せぬエラーが発生しました: cannot access local variable 'uploaded_image_url' where it is not associated with a value
Traceback (most recent call last):
  File "C:\Users\pc\OneDrive\Desktop\phantom_alert_bot\signal_runner_loop.py", line 230, in _run
UnboundLocalError: cannot access local variable 'uploaded_image_url' where it is not associated with a value
2025-06-12 00:30:34,800 - INFO - USDJPY: 新しい足 (M5) が形成されました。データ取得とシグナル判定を実行します。
2025-06-12 00:30:34,826 - INFO - USDJPY-M5 シグナル判定結果: No signal
2025-06-12 00:30:34,828 - INFO - USDJPY-M5: シグナルなし。
2025-06-12 00:30:34,829 - ERROR - USDJPY: シグナル監視ループで予期せぬエラーが発生しました: cannot access local variable 'uploaded_image_url' where it is not associated with a value
Traceback (most recent call last):
  File "c:\Users\pc\OneDrive\Desktop\phantom_alert_bot\signal_runner_loop.py", line 230, in _run
UnboundLocalError: cannot access local variable 'uploaded_image_url' where it is not associated with a value
2025-06-12 00:31:02,446 - INFO - USDJPY: 新しい足 (M5) が形成されました。データ取得とシグナル判定を実行します。
2025-06-12 00:31:02,478 - INFO - USDJPY-M5 シグナル判定結果: No signal
2025-06-12 00:31:02,479 - INFO - USDJPY-M5: シグナルなし。
2025-06-12 00:31:02,480 - ERROR - USDJPY: シグナル監視ループで予期せぬエラーが発生しました: cannot access local variable 'uploaded_image_url' where it is not associated with a value
Traceback (most recent call last):
  File "C:\Users\pc\OneDrive\Desktop\phantom_alert_bot\signal_runner_loop.py", line 230, in _run
UnboundLocalError: cannot access local variable 'uploaded_image_url' where it is not associated with a value
2025-06-12 00:31:04,545 - INFO - USDJPY: 新しい足 (M5) が形成されました。データ取得とシグナル判定を実行します。
2025-06-12 00:31:04,584 - INFO - USDJPY-M5 シグナル判定結果: No signal
2025-06-12 00:31:04,584 - INFO - USDJPY-M5: シグナルなし。
2025-06-12 00:31:04,585 - ERROR - USDJPY: シグナル監視ループで予期せぬエラーが発生しました: cannot access local variable 'uploaded_image_url' where it is not associated with a value
Traceback (most recent call last):
  File "C:\Users\pc\OneDrive\Desktop\phantom_alert_bot\signal_runner_loop.py", line 230, in _run
UnboundLocalError: cannot access local variable 'uploaded_image_url' where it is not associated with a value
2025-06-12 00:31:34,830 - INFO - USDJPY: 新しい足 (M5) が形成されました。データ取得とシグナル判定を実行します。
2025-06-12 00:31:34,884 - INFO - USDJPY-M5 シグナル判定結果: No signal
2025-06-12 00:31:34,887 - INFO - USDJPY-M5: シグナルなし。
2025-06-12 00:31:34,889 - ERROR - USDJPY: シグナル監視ループで予期せぬエラーが発生しました: cannot access local variable 'uploaded_image_url' where it is not associated with a value
Traceback (most recent call last):
  File "c:\Users\pc\OneDrive\Desktop\phantom_alert_bot\signal_runner_loop.py", line 230, in _run
UnboundLocalError: cannot access local variable 'uploaded_image_url' where it is not associated with a value
2025-06-12 00:32:02,482 - INFO - USDJPY: 新しい足 (M5) が形成されました。データ取得とシグナル判定を実行します。
2025-06-12 00:32:02,503 - INFO - USDJPY-M5 シグナル判定結果: No signal
2025-06-12 00:32:02,504 - INFO - USDJPY-M5: シグナルなし。
2025-06-12 00:32:02,504 - ERROR - USDJPY: シグナル監視ループで予期せぬエラーが発生しました: cannot access local variable 'uploaded_image_url' where it is not associated with a value
Traceback (most recent call last):
  File "C:\Users\pc\OneDrive\Desktop\phantom_alert_bot\signal_runner_loop.py", line 230, in _run
UnboundLocalError: cannot access local variable 'uploaded_image_url' where it is not associated with a value
2025-06-12 00:32:04,586 - INFO - USDJPY: 新しい足 (M5) が形成されました。データ取得とシグナル判定を実行します。
2025-06-12 00:32:04,634 - INFO - USDJPY-M5 シグナル判定結果: No signal
2025-06-12 00:32:04,635 - INFO - USDJPY-M5: シグナルなし。
2025-06-12 00:32:04,635 - ERROR - USDJPY: シグナル監視ループで予期せぬエラーが発生しました: cannot access local variable 'uploaded_image_url' where it is not associated with a value
Traceback (most recent call last):
  File "C:\Users\pc\OneDrive\Desktop\phantom_alert_bot\signal_runner_loop.py", line 230, in _run
UnboundLocalError: cannot access local variable 'uploaded_image_url' where it is not associated with a value
2025-06-12 00:32:34,892 - INFO - USDJPY: 新しい足 (M5) が形成されました。データ取得とシグナル判定を実行します。
2025-06-12 00:32:34,924 - INFO - USDJPY-M5 シグナル判定結果: No signal
2025-06-12 00:32:34,925 - INFO - USDJPY-M5: シグナルなし。
2025-06-12 00:32:34,925 - ERROR - USDJPY: シグナル監視ループで予期せぬエラーが発生しました: cannot access local variable 'uploaded_image_url' where it is not associated with a value
Traceback (most recent call last):
  File "c:\Users\pc\OneDrive\Desktop\phantom_alert_bot\signal_runner_loop.py", line 230, in _run
UnboundLocalError: cannot access local variable 'uploaded_image_url' where it is not associated with a value
2025-06-12 00:33:02,508 - INFO - USDJPY: 新しい足 (M5) が形成されました。データ取得とシグナル判定を実行します。
2025-06-12 00:33:02,537 - INFO - USDJPY-M5 シグナル判定結果: No signal
2025-06-12 00:33:02,538 - INFO - USDJPY-M5: シグナルなし。
2025-06-12 00:33:02,538 - ERROR - USDJPY: シグナル監視ループで予期せぬエラーが発生しました: cannot access local variable 'uploaded_image_url' where it is not associated with a value
Traceback (most recent call last):
  File "C:\Users\pc\OneDrive\Desktop\phantom_alert_bot\signal_runner_loop.py", line 230, in _run
UnboundLocalError: cannot access local variable 'uploaded_image_url' where it is not associated with a value
2025-06-12 00:33:04,637 - INFO - USDJPY: 新しい足 (M5) が形成されました。データ取得とシグナル判定を実行します。
2025-06-12 00:33:04,666 - INFO - USDJPY-M5 シグナル判定結果: No signal
2025-06-12 00:33:04,667 - INFO - USDJPY-M5: シグナルなし。
2025-06-12 00:33:04,667 - ERROR - USDJPY: シグナル監視ループで予期せぬエラーが発生しました: cannot access local variable 'uploaded_image_url' where it is not associated with a value
Traceback (most recent call last):
  File "C:\Users\pc\OneDrive\Desktop\phantom_alert_bot\signal_runner_loop.py", line 230, in _run
UnboundLocalError: cannot access local variable 'uploaded_image_url' where it is not associated with a value
2025-06-12 00:33:34,926 - INFO - USDJPY: 新しい足 (M5) が形成されました。データ取得とシグナル判定を実行します。
2025-06-12 00:33:34,974 - INFO - USDJPY-M5 シグナル判定結果: No signal
2025-06-12 00:33:34,974 - INFO - USDJPY-M5: シグナルなし。
2025-06-12 00:33:34,975 - ERROR - USDJPY: シグナル監視ループで予期せぬエラーが発生しました: cannot access local variable 'uploaded_image_url' where it is not associated with a value
Traceback (most recent call last):
  File "c:\Users\pc\OneDrive\Desktop\phantom_alert_bot\signal_runner_loop.py", line 230, in _run
UnboundLocalError: cannot access local variable 'uploaded_image_url' where it is not associated with a value
2025-06-12 00:34:02,539 - INFO - USDJPY: 新しい足 (M5) が形成されました。データ取得とシグナル判定を実行します。
2025-06-12 00:34:02,562 - INFO - USDJPY-M5 シグナル判定結果: No signal
2025-06-12 00:34:02,563 - INFO - USDJPY-M5: シグナルなし。
2025-06-12 00:34:02,563 - ERROR - USDJPY: シグナル監視ループで予期せぬエラーが発生しました: cannot access local variable 'uploaded_image_url' where it is not associated with a value
Traceback (most recent call last):
  File "C:\Users\pc\OneDrive\Desktop\phantom_alert_bot\signal_runner_loop.py", line 230, in _run
UnboundLocalError: cannot access local variable 'uploaded_image_url' where it is not associated with a value
2025-06-12 00:34:04,670 - INFO - USDJPY: 新しい足 (M5) が形成されました。データ取得とシグナル判定を実行します。
2025-06-12 00:34:04,814 - INFO - USDJPY-M5 シグナル判定結果: No signal
2025-06-12 00:34:04,815 - INFO - USDJPY-M5: シグナルなし。
2025-06-12 00:34:04,815 - ERROR - USDJPY: シグナル監視ループで予期せぬエラーが発生しました: cannot access local variable 'uploaded_image_url' where it is not associated with a value
Traceback (most recent call last):
  File "C:\Users\pc\OneDrive\Desktop\phantom_alert_bot\signal_runner_loop.py", line 230, in _run
UnboundLocalError: cannot access local variable 'uploaded_image_url' where it is not associated with a value
2025-06-12 00:34:34,977 - INFO - USDJPY: 新しい足 (M5) が形成されました。データ取得とシグナル判定を実行します。
2025-06-12 00:34:35,020 - INFO - USDJPY-M5 シグナル判定結果: No signal
2025-06-12 00:34:35,020 - INFO - USDJPY-M5: シグナルなし。
2025-06-12 00:34:35,021 - ERROR - USDJPY: シグナル監視ループで予期せぬエラーが発生しました: cannot access local variable 'uploaded_image_url' where it is not associated with a value
Traceback (most recent call last):
  File "c:\Users\pc\OneDrive\Desktop\phantom_alert_bot\signal_runner_loop.py", line 230, in _run
UnboundLocalError: cannot access local variable 'uploaded_image_url' where it is not associated with a value
2025-06-12 00:35:02,564 - INFO - USDJPY: 新しい足 (M5) が形成されました。データ取得とシグナル判定を実行します。
2025-06-12 00:35:02,616 - INFO - USDJPY-M5 シグナル判定結果: No signal
2025-06-12 00:35:02,617 - INFO - USDJPY-M5: シグナルなし。
2025-06-12 00:35:02,618 - ERROR - USDJPY: シグナル監視ループで予期せぬエラーが発生しました: cannot access local variable 'uploaded_image_url' where it is not associated with a value
Traceback (most recent call last):
  File "C:\Users\pc\OneDrive\Desktop\phantom_alert_bot\signal_runner_loop.py", line 230, in _run
UnboundLocalError: cannot access local variable 'uploaded_image_url' where it is not associated with a value
2025-06-12 00:35:04,817 - INFO - USDJPY: 新しい足 (M5) が形成されました。データ取得とシグナル判定を実行します。
2025-06-12 00:35:04,842 - INFO - USDJPY-M5 シグナル判定結果: No signal
2025-06-12 00:35:04,843 - INFO - USDJPY-M5: シグナルなし。
2025-06-12 00:35:04,843 - ERROR - USDJPY: シグナル監視ループで予期せぬエラーが発生しました: cannot access local variable 'uploaded_image_url' where it is not associated with a value
Traceback (most recent call last):
  File "C:\Users\pc\OneDrive\Desktop\phantom_alert_bot\signal_runner_loop.py", line 230, in _run
UnboundLocalError: cannot access local variable 'uploaded_image_url' where it is not associated with a value
2025-06-12 00:35:35,025 - INFO - USDJPY: 新しい足 (M5) が形成されました。データ取得とシグナル判定を実行します。
2025-06-12 00:35:35,049 - INFO - USDJPY-M5 シグナル判定結果: No signal
2025-06-12 00:35:35,050 - INFO - USDJPY-M5: シグナルなし。
2025-06-12 00:35:35,050 - ERROR - USDJPY: シグナル監視ループで予期せぬエラーが発生しました: cannot access local variable 'uploaded_image_url' where it is not associated with a value
Traceback (most recent call last):
  File "c:\Users\pc\OneDrive\Desktop\phantom_alert_bot\signal_runner_loop.py", line 230, in _run
UnboundLocalError: cannot access local variable 'uploaded_image_url' where it is not associated with a value
2025-06-12 00:36:02,619 - INFO - USDJPY: 新しい足 (M5) が形成されました。データ取得とシグナル判定を実行します。
2025-06-12 00:36:02,703 - INFO - USDJPY-M5 シグナル判定結果: No signal
2025-06-12 00:36:02,703 - INFO - USDJPY-M5: シグナルなし。
2025-06-12 00:36:02,703 - ERROR - USDJPY: シグナル監視ループで予期せぬエラーが発生しました: cannot access local variable 'uploaded_image_url' where it is not associated with a value
Traceback (most recent call last):
  File "C:\Users\pc\OneDrive\Desktop\phantom_alert_bot\signal_runner_loop.py", line 230, in _run
UnboundLocalError: cannot access local variable 'uploaded_image_url' where it is not associated with a value
2025-06-12 00:36:04,849 - INFO - USDJPY: 新しい足 (M5) が形成されました。データ取得とシグナル判定を実行します。
2025-06-12 00:36:04,907 - INFO - USDJPY-M5 シグナル判定結果: No signal
2025-06-12 00:36:04,907 - INFO - USDJPY-M5: シグナルなし。
2025-06-12 00:36:04,907 - ERROR - USDJPY: シグナル監視ループで予期せぬエラーが発生しました: cannot access local variable 'uploaded_image_url' where it is not associated with a value
Traceback (most recent call last):
  File "C:\Users\pc\OneDrive\Desktop\phantom_alert_bot\signal_runner_loop.py", line 230, in _run
UnboundLocalError: cannot access local variable 'uploaded_image_url' where it is not associated with a value
2025-06-12 00:36:35,052 - INFO - USDJPY: 新しい足 (M5) が形成されました。データ取得とシグナル判定を実行します。
2025-06-12 00:36:35,091 - INFO - USDJPY-M5 シグナル判定結果: No signal
2025-06-12 00:36:35,092 - INFO - USDJPY-M5: シグナルなし。
2025-06-12 00:36:35,092 - ERROR - USDJPY: シグナル監視ループで予期せぬエラーが発生しました: cannot access local variable 'uploaded_image_url' where it is not associated with a value
Traceback (most recent call last):
  File "c:\Users\pc\OneDrive\Desktop\phantom_alert_bot\signal_runner_loop.py", line 230, in _run
UnboundLocalError: cannot access local variable 'uploaded_image_url' where it is not associated with a value
2025-06-12 00:37:02,705 - INFO - USDJPY: 新しい足 (M5) が形成されました。データ取得とシグナル判定を実行します。
2025-06-12 00:37:02,760 - INFO - USDJPY-M5 シグナル判定結果: No signal
2025-06-12 00:37:02,761 - INFO - USDJPY-M5: シグナルなし。
2025-06-12 00:37:02,761 - ERROR - USDJPY: シグナル監視ループで予期せぬエラーが発生しました: cannot access local variable 'uploaded_image_url' where it is not associated with a value
Traceback (most recent call last):
  File "C:\Users\pc\OneDrive\Desktop\phantom_alert_bot\signal_runner_loop.py", line 230, in _run
UnboundLocalError: cannot access local variable 'uploaded_image_url' where it is not associated with a value
2025-06-12 00:37:04,908 - INFO - USDJPY: 新しい足 (M5) が形成されました。データ取得とシグナル判定を実行します。
2025-06-12 00:37:04,937 - INFO - USDJPY-M5 シグナル判定結果: No signal
2025-06-12 00:37:04,937 - INFO - USDJPY-M5: シグナルなし。
2025-06-12 00:37:04,937 - ERROR - USDJPY: シグナル監視ループで予期せぬエラーが発生しました: cannot access local variable 'uploaded_image_url' where it is not associated with a value
Traceback (most recent call last):
  File "C:\Users\pc\OneDrive\Desktop\phantom_alert_bot\signal_runner_loop.py", line 230, in _run
UnboundLocalError: cannot access local variable 'uploaded_image_url' where it is not associated with a value
2025-06-12 00:37:35,095 - INFO - USDJPY: 新しい足 (M5) が形成されました。データ取得とシグナル判定を実行します。
2025-06-12 00:37:35,126 - INFO - USDJPY-M5 シグナル判定結果: No signal
2025-06-12 00:37:35,127 - INFO - USDJPY-M5: シグナルなし。
2025-06-12 00:37:35,127 - ERROR - USDJPY: シグナル監視ループで予期せぬエラーが発生しました: cannot access local variable 'uploaded_image_url' where it is not associated with a value
Traceback (most recent call last):
  File "c:\Users\pc\OneDrive\Desktop\phantom_alert_bot\signal_runner_loop.py", line 230, in _run
UnboundLocalError: cannot access local variable 'uploaded_image_url' where it is not associated with a value
2025-06-12 00:38:02,763 - INFO - USDJPY: 新しい足 (M5) が形成されました。データ取得とシグナル判定を実行します。
2025-06-12 00:38:02,804 - INFO - USDJPY-M5 シグナル判定結果: No signal
2025-06-12 00:38:02,806 - INFO - USDJPY-M5: シグナルなし。
2025-06-12 00:38:02,806 - ERROR - USDJPY: シグナル監視ループで予期せぬエラーが発生しました: cannot access local variable 'uploaded_image_url' where it is not associated with a value
Traceback (most recent call last):
  File "C:\Users\pc\OneDrive\Desktop\phantom_alert_bot\signal_runner_loop.py", line 230, in _run
UnboundLocalError: cannot access local variable 'uploaded_image_url' where it is not associated with a value
2025-06-12 00:38:04,939 - INFO - USDJPY: 新しい足 (M5) が形成されました。データ取得とシグナル判定を実行します。
2025-06-12 00:38:04,990 - INFO - USDJPY-M5 シグナル判定結果: No signal
2025-06-12 00:38:04,990 - INFO - USDJPY-M5: シグナルなし。
2025-06-12 00:38:04,991 - ERROR - USDJPY: シグナル監視ループで予期せぬエラーが発生しました: cannot access local variable 'uploaded_image_url' where it is not associated with a value
Traceback (most recent call last):
  File "C:\Users\pc\OneDrive\Desktop\phantom_alert_bot\signal_runner_loop.py", line 230, in _run
UnboundLocalError: cannot access local variable 'uploaded_image_url' where it is not associated with a value
2025-06-12 00:38:35,129 - INFO - USDJPY: 新しい足 (M5) が形成されました。データ取得とシグナル判定を実行します。
2025-06-12 00:38:35,188 - INFO - USDJPY-M5 シグナル判定結果: No signal
2025-06-12 00:38:35,188 - INFO - USDJPY-M5: シグナルなし。
2025-06-12 00:38:35,189 - ERROR - USDJPY: シグナル監視ループで予期せぬエラーが発生しました: cannot access local variable 'uploaded_image_url' where it is not associated with a value
Traceback (most recent call last):
  File "c:\Users\pc\OneDrive\Desktop\phantom_alert_bot\signal_runner_loop.py", line 230, in _run
UnboundLocalError: cannot access local variable 'uploaded_image_url' where it is not associated with a value
2025-06-12 00:39:02,808 - INFO - USDJPY: 新しい足 (M5) が形成されました。データ取得とシグナル判定を実行します。
2025-06-12 00:39:02,843 - INFO - USDJPY-M5 シグナル判定結果: No signal
2025-06-12 00:39:02,844 - INFO - USDJPY-M5: シグナルなし。
2025-06-12 00:39:02,844 - ERROR - USDJPY: シグナル監視ループで予期せぬエラーが発生しました: cannot access local variable 'uploaded_image_url' where it is not associated with a value
Traceback (most recent call last):
  File "C:\Users\pc\OneDrive\Desktop\phantom_alert_bot\signal_runner_loop.py", line 230, in _run
UnboundLocalError: cannot access local variable 'uploaded_image_url' where it is not associated with a value
2025-06-12 00:39:04,992 - INFO - USDJPY: 新しい足 (M5) が形成されました。データ取得とシグナル判定を実行します。
2025-06-12 00:39:05,053 - INFO - USDJPY-M5 シグナル判定結果: No signal
2025-06-12 00:39:05,053 - INFO - USDJPY-M5: シグナルなし。
2025-06-12 00:39:05,054 - ERROR - USDJPY: シグナル監視ループで予期せぬエラーが発生しました: cannot access local variable 'uploaded_image_url' where it is not associated with a value
Traceback (most recent call last):
  File "C:\Users\pc\OneDrive\Desktop\phantom_alert_bot\signal_runner_loop.py", line 230, in _run
UnboundLocalError: cannot access local variable 'uploaded_image_url' where it is not associated with a value
2025-06-12 00:39:35,190 - INFO - USDJPY: 新しい足 (M5) が形成されました。データ取得とシグナル判定を実行します。
2025-06-12 00:39:35,251 - INFO - USDJPY-M5 シグナル判定結果: No signal
2025-06-12 00:39:35,251 - INFO - USDJPY-M5: シグナルなし。
2025-06-12 00:39:35,252 - ERROR - USDJPY: シグナル監視ループで予期せぬエラーが発生しました: cannot access local variable 'uploaded_image_url' where it is not associated with a value
Traceback (most recent call last):
  File "c:\Users\pc\OneDrive\Desktop\phantom_alert_bot\signal_runner_loop.py", line 230, in _run
UnboundLocalError: cannot access local variable 'uploaded_image_url' where it is not associated with a value
2025-06-12 00:40:02,847 - INFO - USDJPY: 新しい足 (M5) が形成されました。データ取得とシグナル判定を実行します。
2025-06-12 00:40:02,886 - INFO - USDJPY-M5 シグナル判定結果: No signal
2025-06-12 00:40:02,886 - INFO - USDJPY-M5: シグナルなし。
2025-06-12 00:40:02,886 - ERROR - USDJPY: シグナル監視ループで予期せぬエラーが発生しました: cannot access local variable 'uploaded_image_url' where it is not associated with a value
Traceback (most recent call last):
  File "C:\Users\pc\OneDrive\Desktop\phantom_alert_bot\signal_runner_loop.py", line 230, in _run
UnboundLocalError: cannot access local variable 'uploaded_image_url' where it is not associated with a value
2025-06-12 00:40:05,055 - INFO - USDJPY: 新しい足 (M5) が形成されました。データ取得とシグナル判定を実行します。
2025-06-12 00:40:05,107 - INFO - USDJPY-M5 シグナル判定結果: No signal
2025-06-12 00:40:05,107 - INFO - USDJPY-M5: シグナルなし。
2025-06-12 00:40:05,108 - ERROR - USDJPY: シグナル監視ループで予期せぬエラーが発生しました: cannot access local variable 'uploaded_image_url' where it is not associated with a value
Traceback (most recent call last):
  File "C:\Users\pc\OneDrive\Desktop\phantom_alert_bot\signal_runner_loop.py", line 230, in _run
UnboundLocalError: cannot access local variable 'uploaded_image_url' where it is not associated with a value
2025-06-12 00:40:35,253 - INFO - USDJPY: 新しい足 (M5) が形成されました。データ取得とシグナル判定を実行します。
2025-06-12 00:40:35,308 - INFO - USDJPY-M5 シグナル判定結果: No signal
2025-06-12 00:40:35,308 - INFO - USDJPY-M5: シグナルなし。
2025-06-12 00:40:35,309 - ERROR - USDJPY: シグナル監視ループで予期せぬエラーが発生しました: cannot access local variable 'uploaded_image_url' where it is not associated with a value
Traceback (most recent call last):
  File "c:\Users\pc\OneDrive\Desktop\phantom_alert_bot\signal_runner_loop.py", line 230, in _run
UnboundLocalError: cannot access local variable 'uploaded_image_url' where it is not associated with a value
2025-06-12 00:41:02,888 - INFO - USDJPY: 新しい足 (M5) が形成されました。データ取得とシグナル判定を実行します。
2025-06-12 00:41:02,931 - INFO - USDJPY-M5 シグナル判定結果: No signal
2025-06-12 00:41:02,931 - INFO - USDJPY-M5: シグナルなし。
2025-06-12 00:41:02,932 - ERROR - USDJPY: シグナル監視ループで予期せぬエラーが発生しました: cannot access local variable 'uploaded_image_url' where it is not associated with a value
Traceback (most recent call last):
  File "C:\Users\pc\OneDrive\Desktop\phantom_alert_bot\signal_runner_loop.py", line 230, in _run
UnboundLocalError: cannot access local variable 'uploaded_image_url' where it is not associated with a value
2025-06-12 00:41:05,111 - INFO - USDJPY: 新しい足 (M5) が形成されました。データ取得とシグナル判定を実行します。
2025-06-12 00:41:05,200 - INFO - USDJPY-M5 シグナル判定結果: No signal
2025-06-12 00:41:05,201 - INFO - USDJPY-M5: シグナルなし。
2025-06-12 00:41:05,226 - ERROR - USDJPY: シグナル監視ループで予期せぬエラーが発生しました: cannot access local variable 'uploaded_image_url' where it is not associated with a value
Traceback (most recent call last):
  File "C:\Users\pc\OneDrive\Desktop\phantom_alert_bot\signal_runner_loop.py", line 230, in _run
UnboundLocalError: cannot access local variable 'uploaded_image_url' where it is not associated with a value
2025-06-12 00:41:35,310 - INFO - USDJPY: 新しい足 (M5) が形成されました。データ取得とシグナル判定を実行します。
2025-06-12 00:41:35,376 - INFO - USDJPY-M5 シグナル判定結果: No signal
2025-06-12 00:41:35,377 - INFO - USDJPY-M5: シグナルなし。
2025-06-12 00:41:35,378 - ERROR - USDJPY: シグナル監視ループで予期せぬエラーが発生しました: cannot access local variable 'uploaded_image_url' where it is not associated with a value
Traceback (most recent call last):
  File "c:\Users\pc\OneDrive\Desktop\phantom_alert_bot\signal_runner_loop.py", line 230, in _run
UnboundLocalError: cannot access local variable 'uploaded_image_url' where it is not associated with a value
2025-06-12 00:42:02,933 - INFO - USDJPY: 新しい足 (M5) が形成されました。データ取得とシグナル判定を実行します。
2025-06-12 00:42:02,969 - INFO - USDJPY-M5 シグナル判定結果: No signal
2025-06-12 00:42:02,969 - INFO - USDJPY-M5: シグナルなし。
2025-06-12 00:42:02,970 - ERROR - USDJPY: シグナル監視ループで予期せぬエラーが発生しました: cannot access local variable 'uploaded_image_url' where it is not associated with a value
Traceback (most recent call last):
  File "C:\Users\pc\OneDrive\Desktop\phantom_alert_bot\signal_runner_loop.py", line 230, in _run
UnboundLocalError: cannot access local variable 'uploaded_image_url' where it is not associated with a value
2025-06-12 00:42:05,249 - INFO - USDJPY: 新しい足 (M5) が形成されました。データ取得とシグナル判定を実行します。
2025-06-12 00:42:05,327 - INFO - USDJPY-M5 シグナル判定結果: No signal
2025-06-12 00:42:05,327 - INFO - USDJPY-M5: シグナルなし。
2025-06-12 00:42:05,328 - ERROR - USDJPY: シグナル監視ループで予期せぬエラーが発生しました: cannot access local variable 'uploaded_image_url' where it is not associated with a value
Traceback (most recent call last):
  File "C:\Users\pc\OneDrive\Desktop\phantom_alert_bot\signal_runner_loop.py", line 230, in _run
UnboundLocalError: cannot access local variable 'uploaded_image_url' where it is not associated with a value
2025-06-12 00:42:35,380 - INFO - USDJPY: 新しい足 (M5) が形成されました。データ取得とシグナル判定を実行します。
2025-06-12 00:42:35,408 - INFO - USDJPY-M5 シグナル判定結果: No signal
2025-06-12 00:42:35,409 - INFO - USDJPY-M5: シグナルなし。
2025-06-12 00:42:35,409 - ERROR - USDJPY: シグナル監視ループで予期せぬエラーが発生しました: cannot access local variable 'uploaded_image_url' where it is not associated with a value
Traceback (most recent call last):
  File "c:\Users\pc\OneDrive\Desktop\phantom_alert_bot\signal_runner_loop.py", line 230, in _run
UnboundLocalError: cannot access local variable 'uploaded_image_url' where it is not associated with a value
2025-06-12 00:43:02,970 - INFO - USDJPY: 新しい足 (M5) が形成されました。データ取得とシグナル判定を実行します。
2025-06-12 00:43:03,002 - INFO - USDJPY-M5 シグナル判定結果: No signal
2025-06-12 00:43:03,003 - INFO - USDJPY-M5: シグナルなし。
2025-06-12 00:43:03,003 - ERROR - USDJPY: シグナル監視ループで予期せぬエラーが発生しました: cannot access local variable 'uploaded_image_url' where it is not associated with a value
Traceback (most recent call last):
  File "C:\Users\pc\OneDrive\Desktop\phantom_alert_bot\signal_runner_loop.py", line 230, in _run
UnboundLocalError: cannot access local variable 'uploaded_image_url' where it is not associated with a value
2025-06-12 00:43:05,329 - INFO - USDJPY: 新しい足 (M5) が形成されました。データ取得とシグナル判定を実行します。
2025-06-12 00:43:05,390 - INFO - USDJPY-M5 シグナル判定結果: No signal
2025-06-12 00:43:05,390 - INFO - USDJPY-M5: シグナルなし。
2025-06-12 00:43:05,390 - ERROR - USDJPY: シグナル監視ループで予期せぬエラーが発生しました: cannot access local variable 'uploaded_image_url' where it is not associated with a value
Traceback (most recent call last):
  File "C:\Users\pc\OneDrive\Desktop\phantom_alert_bot\signal_runner_loop.py", line 230, in _run
UnboundLocalError: cannot access local variable 'uploaded_image_url' where it is not associated with a value
2025-06-12 00:43:35,412 - INFO - USDJPY: 新しい足 (M5) が形成されました。データ取得とシグナル判定を実行します。
2025-06-12 00:43:35,448 - INFO - USDJPY-M5 シグナル判定結果: No signal
2025-06-12 00:43:35,449 - INFO - USDJPY-M5: シグナルなし。
2025-06-12 00:43:35,449 - ERROR - USDJPY: シグナル監視ループで予期せぬエラーが発生しました: cannot access local variable 'uploaded_image_url' where it is not associated with a value
Traceback (most recent call last):
  File "c:\Users\pc\OneDrive\Desktop\phantom_alert_bot\signal_runner_loop.py", line 230, in _run
UnboundLocalError: cannot access local variable 'uploaded_image_url' where it is not associated with a value
2025-06-12 00:44:03,005 - INFO - USDJPY: 新しい足 (M5) が形成されました。データ取得とシグナル判定を実行します。
2025-06-12 00:44:03,055 - INFO - USDJPY-M5 シグナル判定結果: No signal
2025-06-12 00:44:03,055 - INFO - USDJPY-M5: シグナルなし。
2025-06-12 00:44:03,055 - ERROR - USDJPY: シグナル監視ループで予期せぬエラーが発生しました: cannot access local variable 'uploaded_image_url' where it is not associated with a value
Traceback (most recent call last):
  File "C:\Users\pc\OneDrive\Desktop\phantom_alert_bot\signal_runner_loop.py", line 230, in _run
UnboundLocalError: cannot access local variable 'uploaded_image_url' where it is not associated with a value
2025-06-12 00:44:05,392 - INFO - USDJPY: 新しい足 (M5) が形成されました。データ取得とシグナル判定を実行します。
2025-06-12 00:44:05,594 - INFO - USDJPY-M5 シグナル判定結果: No signal
2025-06-12 00:44:05,595 - INFO - USDJPY-M5: シグナルなし。
2025-06-12 00:44:05,597 - ERROR - USDJPY: シグナル監視ループで予期せぬエラーが発生しました: cannot access local variable 'uploaded_image_url' where it is not associated with a value
Traceback (most recent call last):
  File "C:\Users\pc\OneDrive\Desktop\phantom_alert_bot\signal_runner_loop.py", line 230, in _run
UnboundLocalError: cannot access local variable 'uploaded_image_url' where it is not associated with a value
2025-06-12 00:44:35,450 - INFO - USDJPY: 新しい足 (M5) が形成されました。データ取得とシグナル判定を実行します。
2025-06-12 00:44:35,533 - INFO - USDJPY-M5 シグナル判定結果: No signal
2025-06-12 00:44:35,533 - INFO - USDJPY-M5: シグナルなし。
2025-06-12 00:44:35,535 - ERROR - USDJPY: シグナル監視ループで予期せぬエラーが発生しました: cannot access local variable 'uploaded_image_url' where it is not associated with a value
Traceback (most recent call last):
  File "c:\Users\pc\OneDrive\Desktop\phantom_alert_bot\signal_runner_loop.py", line 230, in _run
UnboundLocalError: cannot access local variable 'uploaded_image_url' where it is not associated with a value
2025-06-12 00:45:03,057 - INFO - USDJPY: 新しい足 (M5) が形成されました。データ取得とシグナル判定を実行します。
2025-06-12 00:45:03,096 - INFO - USDJPY-M5 シグナル判定結果: No signal
2025-06-12 00:45:03,096 - INFO - USDJPY-M5: シグナルなし。
2025-06-12 00:45:03,097 - ERROR - USDJPY: シグナル監視ループで予期せぬエラーが発生しました: cannot access local variable 'uploaded_image_url' where it is not associated with a value
Traceback (most recent call last):
  File "C:\Users\pc\OneDrive\Desktop\phantom_alert_bot\signal_runner_loop.py", line 230, in _run
UnboundLocalError: cannot access local variable 'uploaded_image_url' where it is not associated with a value
2025-06-12 00:45:05,599 - INFO - USDJPY: 新しい足 (M5) が形成されました。データ取得とシグナル判定を実行します。
2025-06-12 00:45:05,655 - INFO - USDJPY-M5 シグナル判定結果: No signal
2025-06-12 00:45:05,655 - INFO - USDJPY-M5: シグナルなし。
2025-06-12 00:45:05,656 - ERROR - USDJPY: シグナル監視ループで予期せぬエラーが発生しました: cannot access local variable 'uploaded_image_url' where it is not associated with a value
Traceback (most recent call last):
  File "C:\Users\pc\OneDrive\Desktop\phantom_alert_bot\signal_runner_loop.py", line 230, in _run
UnboundLocalError: cannot access local variable 'uploaded_image_url' where it is not associated with a value
2025-06-12 00:45:35,547 - INFO - USDJPY: 新しい足 (M5) が形成されました。データ取得とシグナル判定を実行します。
2025-06-12 00:45:35,619 - INFO - USDJPY-M5 シグナル判定結果: No signal
2025-06-12 00:45:35,619 - INFO - USDJPY-M5: シグナルなし。
2025-06-12 00:45:35,619 - ERROR - USDJPY: シグナル監視ループで予期せぬエラーが発生しました: cannot access local variable 'uploaded_image_url' where it is not associated with a value
Traceback (most recent call last):
  File "c:\Users\pc\OneDrive\Desktop\phantom_alert_bot\signal_runner_loop.py", line 230, in _run
UnboundLocalError: cannot access local variable 'uploaded_image_url' where it is not associated with a value
2025-06-12 00:46:03,098 - INFO - USDJPY: 新しい足 (M5) が形成されました。データ取得とシグナル判定を実行します。
2025-06-12 00:46:03,149 - INFO - USDJPY-M5 シグナル判定結果: No signal
2025-06-12 00:46:03,149 - INFO - USDJPY-M5: シグナルなし。
2025-06-12 00:46:03,150 - ERROR - USDJPY: シグナル監視ループで予期せぬエラーが発生しました: cannot access local variable 'uploaded_image_url' where it is not associated with a value
Traceback (most recent call last):
  File "C:\Users\pc\OneDrive\Desktop\phantom_alert_bot\signal_runner_loop.py", line 230, in _run
UnboundLocalError: cannot access local variable 'uploaded_image_url' where it is not associated with a value
2025-06-12 00:46:05,660 - INFO - USDJPY: 新しい足 (M5) が形成されました。データ取得とシグナル判定を実行します。
2025-06-12 00:46:05,729 - INFO - USDJPY-M5 シグナル判定結果: No signal
2025-06-12 00:46:05,729 - INFO - USDJPY-M5: シグナルなし。
2025-06-12 00:46:05,731 - ERROR - USDJPY: シグナル監視ループで予期せぬエラーが発生しました: cannot access local variable 'uploaded_image_url' where it is not associated with a value
Traceback (most recent call last):
  File "C:\Users\pc\OneDrive\Desktop\phantom_alert_bot\signal_runner_loop.py", line 230, in _run
UnboundLocalError: cannot access local variable 'uploaded_image_url' where it is not associated with a value
2025-06-12 00:46:35,621 - INFO - USDJPY: 新しい足 (M5) が形成されました。データ取得とシグナル判定を実行します。
2025-06-12 00:46:35,707 - INFO - USDJPY-M5 シグナル判定結果: No signal
2025-06-12 00:46:35,708 - INFO - USDJPY-M5: シグナルなし。
2025-06-12 00:46:35,741 - ERROR - USDJPY: シグナル監視ループで予期せぬエラーが発生しました: cannot access local variable 'uploaded_image_url' where it is not associated with a value
Traceback (most recent call last):
  File "c:\Users\pc\OneDrive\Desktop\phantom_alert_bot\signal_runner_loop.py", line 230, in _run
UnboundLocalError: cannot access local variable 'uploaded_image_url' where it is not associated with a value
2025-06-12 00:47:03,151 - INFO - USDJPY: 新しい足 (M5) が形成されました。データ取得とシグナル判定を実行します。
2025-06-12 00:47:03,206 - INFO - USDJPY-M5 シグナル判定結果: No signal
2025-06-12 00:47:03,207 - INFO - USDJPY-M5: シグナルなし。
2025-06-12 00:47:03,207 - ERROR - USDJPY: シグナル監視ループで予期せぬエラーが発生しました: cannot access local variable 'uploaded_image_url' where it is not associated with a value
Traceback (most recent call last):
  File "C:\Users\pc\OneDrive\Desktop\phantom_alert_bot\signal_runner_loop.py", line 230, in _run
UnboundLocalError: cannot access local variable 'uploaded_image_url' where it is not associated with a value
2025-06-12 00:47:05,732 - INFO - USDJPY: 新しい足 (M5) が形成されました。データ取得とシグナル判定を実行します。
2025-06-12 00:47:05,758 - INFO - USDJPY-M5 シグナル判定結果: No signal
2025-06-12 00:47:05,759 - INFO - USDJPY-M5: シグナルなし。
2025-06-12 00:47:05,759 - ERROR - USDJPY: シグナル監視ループで予期せぬエラーが発生しました: cannot access local variable 'uploaded_image_url' where it is not associated with a value
Traceback (most recent call last):
  File "C:\Users\pc\OneDrive\Desktop\phantom_alert_bot\signal_runner_loop.py", line 230, in _run
UnboundLocalError: cannot access local variable 'uploaded_image_url' where it is not associated with a value
2025-06-12 00:47:35,769 - INFO - USDJPY: 新しい足 (M5) が形成されました。データ取得とシグナル判定を実行します。
2025-06-12 00:47:35,838 - INFO - USDJPY-M5 シグナル判定結果: No signal
2025-06-12 00:47:35,839 - INFO - USDJPY-M5: シグナルなし。
2025-06-12 00:47:35,839 - ERROR - USDJPY: シグナル監視ループで予期せぬエラーが発生しました: cannot access local variable 'uploaded_image_url' where it is not associated with a value
Traceback (most recent call last):
  File "c:\Users\pc\OneDrive\Desktop\phantom_alert_bot\signal_runner_loop.py", line 230, in _run
UnboundLocalError: cannot access local variable 'uploaded_image_url' where it is not associated with a value
2025-06-12 10:40:26,267 - INFO - ✅ USDJPY-M5 シグナルランナーが初期化されました。
2025-06-12 10:40:27,327 - INFO - USDJPY-M5 シグナル監視ループを開始します。
2025-06-12 10:40:27,329 - INFO - USDJPY: MT5クライアントを初期化しています...
2025-06-12 10:40:27,331 - INFO - ✅ USDJPY: MT5クライアントの初期化に成功しました。
2025-06-12 10:40:27,332 - INFO - USDJPY: 新しい足 (M5) が形成されました。データ取得とシグナル判定を実行します。
2025-06-12 10:40:27,404 - ERROR - USDJPY: シグナル監視ループで予期せぬエラーが発生しました: 'MACD_Signal'
Traceback (most recent call last):
  File "C:\Users\pc\AppData\Local\Programs\Python\Python312\Lib\site-packages\pandas\core\indexes\base.py", line 3812, in get_loc
    return self._engine.get_loc(casted_key)
           ^^^^^^^^^^^^^^^^^^^^^^^^^^^^^^^^
  File "pandas/_libs/index.pyx", line 167, in pandas._libs.index.IndexEngine.get_loc
  File "pandas/_libs/index.pyx", line 196, in pandas._libs.index.IndexEngine.get_loc
  File "pandas/_libs/hashtable_class_helper.pxi", line 7088, in pandas._libs.hashtable.PyObjectHashTable.get_item
  File "pandas/_libs/hashtable_class_helper.pxi", line 7096, in pandas._libs.hashtable.PyObjectHashTable.get_item
KeyError: 'MACD_Signal'

The above exception was the direct cause of the following exception:

Traceback (most recent call last):
  File "c:\Users\pc\OneDrive\Desktop\phantom_alert_bot\signal_runner_loop.py", line 196, in _run
    signal_info = generate_signal(df, mode="realtime", logic=DEFAULT_LOGIC) # modeとlogicを渡す
                  ^^^^^^^^^^^^^^^^^^^^^^^^^^^^^^^^^^^^^^^^^^^^^^^^^^^^^^^^^
  File "c:\Users\pc\OneDrive\Desktop\phantom_alert_bot\signal_generator.py", line 71, in generate_signal
    signal_info = _generate_balanced_signal(df_ind, current_price)
                  ^^^^^^^^^^^^^^^^^^^^^^^^^^^^^^^^^^^^^^^^^^^^^^^^
  File "c:\Users\pc\OneDrive\Desktop\phantom_alert_bot\signal_generator.py", line 192, in _generate_balanced_signal
    macd_buy = (df_ind['MACD'].iloc[-1] > df_ind['MACD_Signal'].iloc[-1]) # MACDゴールデンクロス
                                          ~~~~~~^^^^^^^^^^^^^^^
  File "C:\Users\pc\AppData\Local\Programs\Python\Python312\Lib\site-packages\pandas\core\frame.py", line 4107, in __getitem__
    indexer = self.columns.get_loc(key)
              ^^^^^^^^^^^^^^^^^^^^^^^^^
  File "C:\Users\pc\AppData\Local\Programs\Python\Python312\Lib\site-packages\pandas\core\indexes\base.py", line 3819, in get_loc
    raise KeyError(key) from err
KeyError: 'MACD_Signal'
2025-06-12 10:41:27,409 - INFO - USDJPY: 新しい足 (M5) が形成されました。データ取得とシグナル判定を実行します。
2025-06-12 10:41:27,476 - ERROR - USDJPY: シグナル監視ループで予期せぬエラーが発生しました: 'MACD_Signal'
Traceback (most recent call last):
  File "C:\Users\pc\AppData\Local\Programs\Python\Python312\Lib\site-packages\pandas\core\indexes\base.py", line 3812, in get_loc
    return self._engine.get_loc(casted_key)
           ^^^^^^^^^^^^^^^^^^^^^^^^^^^^^^^^
  File "pandas/_libs/index.pyx", line 167, in pandas._libs.index.IndexEngine.get_loc
  File "pandas/_libs/index.pyx", line 196, in pandas._libs.index.IndexEngine.get_loc
  File "pandas/_libs/hashtable_class_helper.pxi", line 7088, in pandas._libs.hashtable.PyObjectHashTable.get_item
  File "pandas/_libs/hashtable_class_helper.pxi", line 7096, in pandas._libs.hashtable.PyObjectHashTable.get_item
KeyError: 'MACD_Signal'

The above exception was the direct cause of the following exception:

Traceback (most recent call last):
  File "c:\Users\pc\OneDrive\Desktop\phantom_alert_bot\signal_runner_loop.py", line 196, in _run
    signal_info = generate_signal(df, mode="realtime", logic=DEFAULT_LOGIC) # modeとlogicを渡す
                  ^^^^^^^^^^^^^^^^^^^^^^^^^^^^^^^^^^^^^^^^^^^^^^^^^^^^^^^^^
  File "c:\Users\pc\OneDrive\Desktop\phantom_alert_bot\signal_generator.py", line 71, in generate_signal
    signal_info = _generate_balanced_signal(df_ind, current_price)
                  ^^^^^^^^^^^^^^^^^^^^^^^^^^^^^^^^^^^^^^^^^^^^^^^^
  File "c:\Users\pc\OneDrive\Desktop\phantom_alert_bot\signal_generator.py", line 192, in _generate_balanced_signal
    macd_buy = (df_ind['MACD'].iloc[-1] > df_ind['MACD_Signal'].iloc[-1]) # MACDゴールデンクロス
                                          ~~~~~~^^^^^^^^^^^^^^^
  File "C:\Users\pc\AppData\Local\Programs\Python\Python312\Lib\site-packages\pandas\core\frame.py", line 4107, in __getitem__
    indexer = self.columns.get_loc(key)
              ^^^^^^^^^^^^^^^^^^^^^^^^^
  File "C:\Users\pc\AppData\Local\Programs\Python\Python312\Lib\site-packages\pandas\core\indexes\base.py", line 3819, in get_loc
    raise KeyError(key) from err
KeyError: 'MACD_Signal'
2025-06-13 01:18:32,277 - INFO - ✅ USDJPY-M5 シグナルランナーが初期化されました。
2025-06-13 01:18:33,310 - INFO - USDJPY-M5 シグナル監視ループを開始します。
2025-06-13 01:18:33,311 - INFO - USDJPY: MT5クライアントを初期化しています...
2025-06-13 01:18:33,312 - INFO - ✅ USDJPY: MT5クライアントの初期化に成功しました。
2025-06-13 01:18:35,588 - INFO - USDJPY: 新しい足 (M5) が形成されました。データ取得とシグナル判定を実行します。
2025-06-13 01:18:35,595 - ERROR - USDJPY: シグナル監視ループで予期せぬエラーが発生しました: Cannot convert tz-naive timestamps, use tz_localize to localize
Traceback (most recent call last):
  File "C:\Users\pc\OneDrive\Desktop\phantom_alert_bot\signal_runner_loop.py", line 192, in _run
    df, latest_time_tokyo = self._get_current_ohlc()
                            ^^^^^^^^^^^^^^^^^^^^^^^^
  File "C:\Users\pc\OneDrive\Desktop\phantom_alert_bot\signal_runner_loop.py", line 116, in _get_current_ohlc
    df.index = df.index.tz_convert('Asia/Tokyo') # チャート描画時などのため
               ^^^^^^^^^^^^^^^^^^^^^^^^^^^^^^^^^
  File "C:\Users\pc\OneDrive\Desktop\phantom_alert_bot\venv\Lib\site-packages\pandas\core\indexes\datetimes.py", line 283, in tz_convert
    arr = self._data.tz_convert(tz)
          ^^^^^^^^^^^^^^^^^^^^^^^^^
  File "C:\Users\pc\OneDrive\Desktop\phantom_alert_bot\venv\Lib\site-packages\pandas\core\arrays\datetimes.py", line 917, in tz_convert
    raise TypeError(
TypeError: Cannot convert tz-naive timestamps, use tz_localize to localize
2025-06-13 01:19:35,635 - INFO - USDJPY: 新しい足 (M5) が形成されました。データ取得とシグナル判定を実行します。
2025-06-13 01:19:35,637 - ERROR - USDJPY: シグナル監視ループで予期せぬエラーが発生しました: Cannot convert tz-naive timestamps, use tz_localize to localize
Traceback (most recent call last):
  File "C:\Users\pc\OneDrive\Desktop\phantom_alert_bot\signal_runner_loop.py", line 192, in _run
    df, latest_time_tokyo = self._get_current_ohlc()
                            ^^^^^^^^^^^^^^^^^^^^^^^^
  File "C:\Users\pc\OneDrive\Desktop\phantom_alert_bot\signal_runner_loop.py", line 116, in _get_current_ohlc
    df.index = df.index.tz_convert('Asia/Tokyo') # チャート描画時などのため
               ^^^^^^^^^^^^^^^^^^^^^^^^^^^^^^^^^
  File "C:\Users\pc\OneDrive\Desktop\phantom_alert_bot\venv\Lib\site-packages\pandas\core\indexes\datetimes.py", line 283, in tz_convert
    arr = self._data.tz_convert(tz)
          ^^^^^^^^^^^^^^^^^^^^^^^^^
  File "C:\Users\pc\OneDrive\Desktop\phantom_alert_bot\venv\Lib\site-packages\pandas\core\arrays\datetimes.py", line 917, in tz_convert
    raise TypeError(
TypeError: Cannot convert tz-naive timestamps, use tz_localize to localize
2025-06-13 01:20:35,639 - INFO - USDJPY: 新しい足 (M5) が形成されました。データ取得とシグナル判定を実行します。
2025-06-13 01:20:35,645 - ERROR - USDJPY: シグナル監視ループで予期せぬエラーが発生しました: Cannot convert tz-naive timestamps, use tz_localize to localize
Traceback (most recent call last):
  File "C:\Users\pc\OneDrive\Desktop\phantom_alert_bot\signal_runner_loop.py", line 192, in _run
    df, latest_time_tokyo = self._get_current_ohlc()
                            ^^^^^^^^^^^^^^^^^^^^^^^^
  File "C:\Users\pc\OneDrive\Desktop\phantom_alert_bot\signal_runner_loop.py", line 116, in _get_current_ohlc
    df.index = df.index.tz_convert('Asia/Tokyo') # チャート描画時などのため
               ^^^^^^^^^^^^^^^^^^^^^^^^^^^^^^^^^
  File "C:\Users\pc\OneDrive\Desktop\phantom_alert_bot\venv\Lib\site-packages\pandas\core\indexes\datetimes.py", line 283, in tz_convert
    arr = self._data.tz_convert(tz)
          ^^^^^^^^^^^^^^^^^^^^^^^^^
  File "C:\Users\pc\OneDrive\Desktop\phantom_alert_bot\venv\Lib\site-packages\pandas\core\arrays\datetimes.py", line 917, in tz_convert
    raise TypeError(
TypeError: Cannot convert tz-naive timestamps, use tz_localize to localize
2025-06-13 01:21:35,647 - INFO - USDJPY: 新しい足 (M5) が形成されました。データ取得とシグナル判定を実行します。
2025-06-13 01:21:35,654 - ERROR - USDJPY: シグナル監視ループで予期せぬエラーが発生しました: Cannot convert tz-naive timestamps, use tz_localize to localize
Traceback (most recent call last):
  File "C:\Users\pc\OneDrive\Desktop\phantom_alert_bot\signal_runner_loop.py", line 192, in _run
    df, latest_time_tokyo = self._get_current_ohlc()
                            ^^^^^^^^^^^^^^^^^^^^^^^^
  File "C:\Users\pc\OneDrive\Desktop\phantom_alert_bot\signal_runner_loop.py", line 116, in _get_current_ohlc
    df.index = df.index.tz_convert('Asia/Tokyo') # チャート描画時などのため
               ^^^^^^^^^^^^^^^^^^^^^^^^^^^^^^^^^
  File "C:\Users\pc\OneDrive\Desktop\phantom_alert_bot\venv\Lib\site-packages\pandas\core\indexes\datetimes.py", line 283, in tz_convert
    arr = self._data.tz_convert(tz)
          ^^^^^^^^^^^^^^^^^^^^^^^^^
  File "C:\Users\pc\OneDrive\Desktop\phantom_alert_bot\venv\Lib\site-packages\pandas\core\arrays\datetimes.py", line 917, in tz_convert
    raise TypeError(
TypeError: Cannot convert tz-naive timestamps, use tz_localize to localize
2025-06-13 01:22:35,657 - INFO - USDJPY: 新しい足 (M5) が形成されました。データ取得とシグナル判定を実行します。
2025-06-13 01:22:35,659 - ERROR - USDJPY: シグナル監視ループで予期せぬエラーが発生しました: Cannot convert tz-naive timestamps, use tz_localize to localize
Traceback (most recent call last):
  File "C:\Users\pc\OneDrive\Desktop\phantom_alert_bot\signal_runner_loop.py", line 192, in _run
    df, latest_time_tokyo = self._get_current_ohlc()
                            ^^^^^^^^^^^^^^^^^^^^^^^^
  File "C:\Users\pc\OneDrive\Desktop\phantom_alert_bot\signal_runner_loop.py", line 116, in _get_current_ohlc
    df.index = df.index.tz_convert('Asia/Tokyo') # チャート描画時などのため
               ^^^^^^^^^^^^^^^^^^^^^^^^^^^^^^^^^
  File "C:\Users\pc\OneDrive\Desktop\phantom_alert_bot\venv\Lib\site-packages\pandas\core\indexes\datetimes.py", line 283, in tz_convert
    arr = self._data.tz_convert(tz)
          ^^^^^^^^^^^^^^^^^^^^^^^^^
  File "C:\Users\pc\OneDrive\Desktop\phantom_alert_bot\venv\Lib\site-packages\pandas\core\arrays\datetimes.py", line 917, in tz_convert
    raise TypeError(
TypeError: Cannot convert tz-naive timestamps, use tz_localize to localize
2025-06-13 01:23:35,660 - INFO - USDJPY: 新しい足 (M5) が形成されました。データ取得とシグナル判定を実行します。
2025-06-13 01:23:35,670 - ERROR - USDJPY: シグナル監視ループで予期せぬエラーが発生しました: Cannot convert tz-naive timestamps, use tz_localize to localize
Traceback (most recent call last):
  File "C:\Users\pc\OneDrive\Desktop\phantom_alert_bot\signal_runner_loop.py", line 192, in _run
    df, latest_time_tokyo = self._get_current_ohlc()
                            ^^^^^^^^^^^^^^^^^^^^^^^^
  File "C:\Users\pc\OneDrive\Desktop\phantom_alert_bot\signal_runner_loop.py", line 116, in _get_current_ohlc
    df.index = df.index.tz_convert('Asia/Tokyo') # チャート描画時などのため
               ^^^^^^^^^^^^^^^^^^^^^^^^^^^^^^^^^
  File "C:\Users\pc\OneDrive\Desktop\phantom_alert_bot\venv\Lib\site-packages\pandas\core\indexes\datetimes.py", line 283, in tz_convert
    arr = self._data.tz_convert(tz)
          ^^^^^^^^^^^^^^^^^^^^^^^^^
  File "C:\Users\pc\OneDrive\Desktop\phantom_alert_bot\venv\Lib\site-packages\pandas\core\arrays\datetimes.py", line 917, in tz_convert
    raise TypeError(
TypeError: Cannot convert tz-naive timestamps, use tz_localize to localize
2025-06-13 01:24:35,674 - INFO - USDJPY: 新しい足 (M5) が形成されました。データ取得とシグナル判定を実行します。
2025-06-13 01:24:35,679 - ERROR - USDJPY: シグナル監視ループで予期せぬエラーが発生しました: Cannot convert tz-naive timestamps, use tz_localize to localize
Traceback (most recent call last):
  File "C:\Users\pc\OneDrive\Desktop\phantom_alert_bot\signal_runner_loop.py", line 192, in _run
    df, latest_time_tokyo = self._get_current_ohlc()
                            ^^^^^^^^^^^^^^^^^^^^^^^^
  File "C:\Users\pc\OneDrive\Desktop\phantom_alert_bot\signal_runner_loop.py", line 116, in _get_current_ohlc
    df.index = df.index.tz_convert('Asia/Tokyo') # チャート描画時などのため
               ^^^^^^^^^^^^^^^^^^^^^^^^^^^^^^^^^
  File "C:\Users\pc\OneDrive\Desktop\phantom_alert_bot\venv\Lib\site-packages\pandas\core\indexes\datetimes.py", line 283, in tz_convert
    arr = self._data.tz_convert(tz)
          ^^^^^^^^^^^^^^^^^^^^^^^^^
  File "C:\Users\pc\OneDrive\Desktop\phantom_alert_bot\venv\Lib\site-packages\pandas\core\arrays\datetimes.py", line 917, in tz_convert
    raise TypeError(
TypeError: Cannot convert tz-naive timestamps, use tz_localize to localize
2025-06-13 01:25:35,681 - INFO - USDJPY: 新しい足 (M5) が形成されました。データ取得とシグナル判定を実行します。
2025-06-13 01:25:35,691 - ERROR - USDJPY: シグナル監視ループで予期せぬエラーが発生しました: Cannot convert tz-naive timestamps, use tz_localize to localize
Traceback (most recent call last):
  File "C:\Users\pc\OneDrive\Desktop\phantom_alert_bot\signal_runner_loop.py", line 192, in _run
    df, latest_time_tokyo = self._get_current_ohlc()
                            ^^^^^^^^^^^^^^^^^^^^^^^^
  File "C:\Users\pc\OneDrive\Desktop\phantom_alert_bot\signal_runner_loop.py", line 116, in _get_current_ohlc
    df.index = df.index.tz_convert('Asia/Tokyo') # チャート描画時などのため
               ^^^^^^^^^^^^^^^^^^^^^^^^^^^^^^^^^
  File "C:\Users\pc\OneDrive\Desktop\phantom_alert_bot\venv\Lib\site-packages\pandas\core\indexes\datetimes.py", line 283, in tz_convert
    arr = self._data.tz_convert(tz)
          ^^^^^^^^^^^^^^^^^^^^^^^^^
  File "C:\Users\pc\OneDrive\Desktop\phantom_alert_bot\venv\Lib\site-packages\pandas\core\arrays\datetimes.py", line 917, in tz_convert
    raise TypeError(
TypeError: Cannot convert tz-naive timestamps, use tz_localize to localize
2025-06-13 01:26:35,694 - INFO - USDJPY: 新しい足 (M5) が形成されました。データ取得とシグナル判定を実行します。
2025-06-13 01:26:35,701 - ERROR - USDJPY: シグナル監視ループで予期せぬエラーが発生しました: Cannot convert tz-naive timestamps, use tz_localize to localize
Traceback (most recent call last):
  File "C:\Users\pc\OneDrive\Desktop\phantom_alert_bot\signal_runner_loop.py", line 192, in _run
    df, latest_time_tokyo = self._get_current_ohlc()
                            ^^^^^^^^^^^^^^^^^^^^^^^^
  File "C:\Users\pc\OneDrive\Desktop\phantom_alert_bot\signal_runner_loop.py", line 116, in _get_current_ohlc
    df.index = df.index.tz_convert('Asia/Tokyo') # チャート描画時などのため
               ^^^^^^^^^^^^^^^^^^^^^^^^^^^^^^^^^
  File "C:\Users\pc\OneDrive\Desktop\phantom_alert_bot\venv\Lib\site-packages\pandas\core\indexes\datetimes.py", line 283, in tz_convert
    arr = self._data.tz_convert(tz)
          ^^^^^^^^^^^^^^^^^^^^^^^^^
  File "C:\Users\pc\OneDrive\Desktop\phantom_alert_bot\venv\Lib\site-packages\pandas\core\arrays\datetimes.py", line 917, in tz_convert
    raise TypeError(
TypeError: Cannot convert tz-naive timestamps, use tz_localize to localize
2025-06-13 01:27:35,705 - INFO - USDJPY: 新しい足 (M5) が形成されました。データ取得とシグナル判定を実行します。
2025-06-13 01:27:35,712 - ERROR - USDJPY: シグナル監視ループで予期せぬエラーが発生しました: Cannot convert tz-naive timestamps, use tz_localize to localize
Traceback (most recent call last):
  File "C:\Users\pc\OneDrive\Desktop\phantom_alert_bot\signal_runner_loop.py", line 192, in _run
    df, latest_time_tokyo = self._get_current_ohlc()
                            ^^^^^^^^^^^^^^^^^^^^^^^^
  File "C:\Users\pc\OneDrive\Desktop\phantom_alert_bot\signal_runner_loop.py", line 116, in _get_current_ohlc
    df.index = df.index.tz_convert('Asia/Tokyo') # チャート描画時などのため
               ^^^^^^^^^^^^^^^^^^^^^^^^^^^^^^^^^
  File "C:\Users\pc\OneDrive\Desktop\phantom_alert_bot\venv\Lib\site-packages\pandas\core\indexes\datetimes.py", line 283, in tz_convert
    arr = self._data.tz_convert(tz)
          ^^^^^^^^^^^^^^^^^^^^^^^^^
  File "C:\Users\pc\OneDrive\Desktop\phantom_alert_bot\venv\Lib\site-packages\pandas\core\arrays\datetimes.py", line 917, in tz_convert
    raise TypeError(
TypeError: Cannot convert tz-naive timestamps, use tz_localize to localize
2025-06-13 01:28:35,715 - INFO - USDJPY: 新しい足 (M5) が形成されました。データ取得とシグナル判定を実行します。
2025-06-13 01:28:35,720 - ERROR - USDJPY: シグナル監視ループで予期せぬエラーが発生しました: Cannot convert tz-naive timestamps, use tz_localize to localize
Traceback (most recent call last):
  File "C:\Users\pc\OneDrive\Desktop\phantom_alert_bot\signal_runner_loop.py", line 192, in _run
    if self.line_notifier:
                        ^^^
  File "C:\Users\pc\OneDrive\Desktop\phantom_alert_bot\signal_runner_loop.py", line 116, in _get_current_ohlc
  File "C:\Users\pc\OneDrive\Desktop\phantom_alert_bot\venv\Lib\site-packages\pandas\core\indexes\datetimes.py", line 283, in tz_convert
    arr = self._data.tz_convert(tz)
          ^^^^^^^^^^^^^^^^^^^^^^^^^
  File "C:\Users\pc\OneDrive\Desktop\phantom_alert_bot\venv\Lib\site-packages\pandas\core\arrays\datetimes.py", line 917, in tz_convert
    raise TypeError(
TypeError: Cannot convert tz-naive timestamps, use tz_localize to localize
